Workbook

Sheet Summary
A1: M48 Filter Coating & Painting
A2: W519TC-26-Q-A086
A3: FOB DESTINATION PINE BLUFF ARSENAL
A4: Quoter Name: | B4: 0 | F4: Contractor Fill-In
A5: Cage Code: | B5: 0
A6: Proposal Date:
A8: CLINS | B8: DESCRIPTION | D8: ORDERING PERIOD 1 1 June 2026 - 31 May 2027 | E8: ORDERING PERIOD 2 1 June 2027 - 31 May 2028 | F8: TOTAL PER CLIN
A9: CLIN 1 | B9: 5-19-7355 Cap, Filter Inlet. Chromate Only | D9: =Proposal!D14 -> 0 | E9: =Proposal!F14 -> 0 | F9: =Proposal!F15 -> 0
A10: CLIN 2 | B10: 5-19-7355 Cap, Filter Inlet Chromate and Paint (Green) | D10: =Proposal!D25 -> 0 | E10: =Proposal!F25 -> 0 | F10: =Proposal!F26 -> 0
A11: CLIN 3 | B11: 5-19-7355 Cap, Filter Inlet Chromate and Paint (Tan) | D11: =Proposal!D36 -> 0 | E11: =Proposal!F36 -> 0 | F11: =Proposal!F37 -> 0
A12: CLIN 4 | B12: 5-19-7437 Filter Body, Outlet Chromate only | D12: =Proposal!D47 -> 0 | E12: =Proposal!F47 -> 0 | F12: =Proposal!F48 -> 0
A13: CLIN 5 | B13: 5-19-7437 Filter Body, Outlet Chromate and Paint (Green) | D13: =Proposal!D58 -> 0 | E13: =Proposal!F58 -> 0 | F13: =Proposal!F59 -> 0
A14: CLIN 6 | B14: 5-19-7437 Filter Body Outlet Chromate and Paint (Tan) | D14: =Proposal!D69 -> 0 | E14: =Proposal!F69 -> 0 | F14: =Proposal!F70 -> 0
A15: CLIN 7 | B15: 5-19-7443 Outer Mesh Assy. Chromate Only | D15: =Proposal!D80 -> 0 | E15: =Proposal!F80 -> 0 | F15: =Proposal!F81 -> 0
A16: CLIN 8 | B16: 5-19-7440 Inner Mesh Assy. Chromate Only | D16: =Proposal!D91 -> 0 | E16: =Proposal!F91 -> 0 | F16: =Proposal!F92 -> 0
A17: CLIN 9 | B17: 5-19-7444 Outer Gas Mesh Assy. | D17: =Proposal!D102 -> 0 | E17: =Proposal!F102 -> 0 | F17: =Proposal!F103 -> 0
A18: CLIN 10 | B18: 5-19-7236 Channel, treat per drawing. | D18: =Proposal!D113 -> 0 | E18: =Proposal!F113 -> 0 | F18: =Proposal!F114 -> 0
B19: TOTAL ALL CLINS PER ORDERING PERIOD | D19: =SUM(D9:D18) -> 0 | E19: =SUM(E9:E18) -> 0 | F19: =D19+E19 -> 0
D20: TOTAL EVALUATED PRICE | F20: =Proposal!F15+Proposal!F26+Proposal!F37+Proposal!F48+Proposal!F59+Proposal!F70+Proposal!F81+Proposal!F92+Proposal!F103+Proposal!F114 -> 0

Sheet Proposal
A1: M48 Filter Coating & Painting
A2: FOB Destination Pine Bluff Arsenal
A3: Quoter Name: | C3: =Summary!B4 -> 0
A4: CAGE code: | C4: =Summary!B5 -> 0
A6: CLIN 0001 Cap 5-19-7355 Cap, Filter Inlet. Chromate Only
D7: Ordering Period 1 | F7: Ordering Period 2
A8: Quantity Ranges | D8: Unit Price | E8: Weight | F8: Unit Price | G8: Weight
A9: 1 | B9: - | C9: 750 | D9: 0 | E9: 0.3 | F9: 0 | G9: 0.3
A10: =C9+1 -> 751 | B10: - | C10: 1500 | D10: 0 | E10: 0.3 | F10: 0 | G10: 0.3
A11: =C10+1 -> 1501 | B11: - | C11: 2250 | D11: 0 | E11: 0.2 | F11: 0 | G11: 0.2
A12: =C11+1 -> 2251 | B12: - | C12: 3000 | D12: 0 | E12: 0.2 | F12: 0 | G12: 0.2
E13: =SUM(E9:E12) -> 1 | G13: =SUM(G9:G12) -> 1
A14: Weighted Price | D14: =($C9*D9*E9)+($C10*D10*E10)+($C11*D11*E11)+($C12*D12*E12) -> 0 | F14: =($C9*F9*G9)+($C10*F10*G10)+($C11*F11*G11)+($C12*F12*G12) -> 0
A15: Total Weighted Price: | F15: =D14+F14 -> 0
A17: CLIN 0002 5-19-7355 Cap, Filter Inlet Chromate and Paint (Green)
D18: Ordering Period 1 | F18: Ordering Period 2
A19: Quantity Ranges | D19: Unit Price | E19: Weight | F19: Unit Price | G19: Weight
A20: 1 | B20: - | C20: 750 | D20: 0 | E20: 0.3 | F20: 0 | G20: 0.3
A21: =C20+1 -> 751 | B21: - | C21: 1500 | D21: 0 | E21: 0.3 | F21: 0 | G21: 0.3
A22: =C21+1 -> 1501 | B22: - | C22: 2250 | D22: 0 | E22: 0.2 | F22: 0 | G22: 0.2
A23: =C22+1 -> 2251 | B23: - | C23: 3000 | D23: 0 | E23: 0.2 | F23: 0 | G23: 0.2
E24: =SUM(E20:E23) -> 1 | G24: =SUM(G20:G23) -> 1
A25: Weighted Price: | D25: =($C20*D20*E20)+($C21*D21*E21)+($C22*D22*E22)+($C23*D23*E23) -> 0 | F25: =($C20*F20*G20)+($C21*F21*G21)+($C22*F22*G22)+($C23*F23*G23) -> 0
A26: Total Weighted Price: | F26: =D25+F25 -> 0
A28: CLIN 0003 5-19-7355 Cap, Filter Inlet Chromate and Paint (Tan)
D29: Ordering Period 1 | F29: Ordering Period 2
A30: Quantity Ranges | D30: Unit Price | E30: Weight | F30: Unit Price | G30: Weight
A31: 1 | B31: - | C31: 500 | D31: 0 | E31: 0.3 | F31: 0 | G31: 0.3
A32: =C31+1 -> 501 | B32: - | C32: 1000 | D32: 0 | E32: 0.3 | F32: 0 | G32: 0.3
A33: =C32+1 -> 1001 | B33: - | C33: 1500 | D33: 0 | E33: 0.2 | F33: 0 | G33: 0.2
A34: =C33+1 -> 1501 | B34: - | C34: 2000 | D34: 0 | E34: 0.2 | F34: 0 | G34: 0.2
E35: =SUM(E31:E34) -> 1 | G35: =SUM(G31:G34) -> 1
A36: Weighted Price: | D36: =($C31*D31*E31)+($C32*D32*E32)+($C33*D33*E33)+($C34*D34*E34) -> 0 | F36: =($C31*F31*G31)+($C32*F32*G32)+($C33*F33*G33)+($C34*F34*G34) -> 0
A37: Total Weighted Price: | F37: =D36+F36 -> 0
A39: CLIN 0004 5-19-7437 Filter Body, Outlet Chromate only
D40: Ordering Period 1 | F40: Ordering Period 2
A41: Quantity Ranges | D41: Unit Price | E41: Weight | F41: Unit Price | G41: Weight
A42: 1 | B42: - | C42: 750 | D42: 0 | E42: 0.3 | F42: 0 | G42: 0.3
A43: =C42+1 -> 751 | B43: - | C43: 1500 | D43: 0 | E43: 0.3 | F43: 0 | G43: 0.3
A44: =C43+1 -> 1501 | B44: - | C44: 2250 | D44: 0 | E44: 0.2 | F44: 0 | G44: 0.2
...
