Workbook

Sheet Instructions
A1: CONTROLLED UNCLASSIFIED INFORMATION (CUI) Source Selection Information - See FAR 2.101 and 3.104
A2: Attachment 5 – Volume III, Price
A4: Instructions
A6: This workbook provides pricing for the Department of War Education Activity (DoWEA) requirement identified in the solicitation. Offerors shall complete this Attachment strictly in accordance with the instructions below.
A8: Pricing Instructions:
A10: 1. Pricing Entry
A12: Only use the next sheet titled "Pricing Input" Enter prices only in the designated Unit Price (U/P) input cells (highlighted in yellow).
A13: Do not alter formulas, protected cells, headers, or workbook structure.
A15: 2. Currency
A17: All prices shall be entered in United States Dollars (USD).
A18: Prices shall be stated as whole dollars, or to no more than two (2) decimal places, if applicable.
A20: 3. No Formulas in Unit Price Cells
... A45: CONTROLLED UNCLASSIFIED INFORMATION (CUI) Source Selection Information - See FAR 2.101 and 3.104

Sheet Pricing input
C2: CONTROLLED UNCLASSIFIED INFORMATION (CUI) Source Selection Information - See FAR 2.101 and 3.104
B4: Contract Line Item | C4: POP/Supplies/Services | D4: Unit of Issue | E4: Qty. | F4: Unit Price | G4: Estimated Total Cost
B5: Base Year | C5: 8/1/2026 - 7/31/2027
B6: CLIN 0001 | C6: Installation per vehicle
B7: SLIN 0001AA | C7: Installation on Buses | D7: each | E7: 68 | G7: =F7*E7 -> 0
B8: SLIN 0001AB | C8: Installation on Microbuses | D8: each | E8: 13 | G8: =F8*E8 -> 0
B9: SLIN 0001AC | C9: Installation on Vans | D9: each | E9: 2 | G9: =F9*E9 -> 0
B10: CLIN 0002 | C10: Maintenance & Repairs
B11: SLIN 0002AA | C11: Bi-annual preventative maintenance per vehicle | D11: each | E11: 83 | G11: =F11*E11 -> 0
B12: SLIN 0002AB | C12: Unscheduled corrective maintenance per vehicle | D12: each | E12: 21 | G12: =F12*E12 -> 0
B13: SLIN 0002AC | C13: Materials - Not To Exceed (NTE) $5,000. | D13: each | E13: 5000 | F13: 1 | G13: =F13*E13 -> 5000
B14: CLIN 0003 | C14: Phase‑in, phase‑out removals
B15: SLIN 0003AA | C15: OBVSS Removal per vehicle | D15: each | E15: 83 | G15: =F15*E15 -> 0
C16: Total | G16: =SUM(G7:G15) -> 5000
B19: 1st Option Period | C19: 8/1/2027 - 7/31/2028
B20: CLIN 1001 | C20: Installation per vehicle
B21: SLIN 1001AA | C21: Installation on Buses | D21: each | E21: 1 | G21: =F21*E21 -> 0
B22: SLIN 1001AB | C22: Installation on Microbuses | D22: each | E22: 1 | G22: =F22*E22 -> 0
B23: SLIN 1001AC | C23: Installation on Vans | D23: each | E23: 1 | G23: =F23*E23 -> 0
B24: CLIN 1002 | C24: Maintenance & Repairs
B25: SLIN 1002AA | C25: Bi-annual preventative maintenance per vehicle | D25: each | E25: 83 | G25: =F25*E25 -> 0
B26: SLIN 1002AB | C26: Unscheduled corrective maintenance per vehicle | D26: each | E26: =E12 -> 21 | G26: =F26*E26 -> 0
B27: SLIN 1002AC | C27: Materials - Not To Exceed (NTE) $5,000. | D27: each | E27: 5000 | F27: 1 | G27: =F27*E27 -> 5000
B28: CLIN 1003 | C28: Phase‑in, phase‑out removals
B29: SLIN 1004AA | C29: OBVSS Removal per vehicle | D29: each | E29: 83 | G29: =F29*E29 -> 0
C30: Total | G30: =SUM(G21:G29) -> 5000
B33: 2nd Option Period | C33: 8/1/2028 - 7/31/2029
B34: CLIN 2001 | C34: Installation per vehicle
B35: SLIN 2001AA | C35: Installation on Buses | D35: each | E35: 1 | G35: =F35*E35 -> 0
B36: SLIN 2001AB | C36: Installation on Microbuses | D36: each | E36: 1 | G36: =F36*E36 -> 0
B37: SLIN 2001AC | C37: Installation on Vans | D37: each | E37: 1 | G37: =F37*E37 -> 0
B38: CLIN 2002 | C38: Maintenance & Repairs
B39: SLIN 2002AA | C39: Bi-annual preventative maintenance per vehicle | D39: each | E39: 83 | G39: =F39*E39 -> 0
B40: SLIN 2002AB | C40: Unscheduled corrective maintenance per vehicle | D40: each | E40: =E26 -> 21 | G40: =F40*E40 -> 0
B41: SLIN 2002AC | C41: Materials - Not To Exceed (NTE) $5,000. | D41: each | E41: 5000 | F41: 1 | G41: =F41*E41 -> 5000
B42: CLIN 2003 | C42: Phase‑in, phase‑out removals
B43: SLIN 2003AA | C43: OBVSS Removal per vehicle | D43: each | E43: 83 | G43: =F43*E43 -> 0
C44: Total | G44: =SUM(G35:G43) -> 5000
B47: 3rd Option Period | C47: 8/1/2029 - 7/31/2030
B48: CLIN 3001 | C48: Installation per vehicle
...

Sheet Summary
B1: CONTROLLED UNCLASSIFIED INFORMATION (CUI) Source Selection Information - See FAR 2.101 and 3.104
B4: DoWEA Pacific South HE125426QE047
B5: Okinawa OBVSS Services
B6: Summary of Base plus Option Periods
B8: Okinawa OBVSS | C8: Estimated Price $
B9: Base Year | C9: ='Pricing input'!G16 -> 5000
B10: Option Period Year 1 | C10: ='Pricing input'!G30 -> 5000
B11: Option Period Year 2 | C11: ='Pricing input'!G44 -> 5000
B12: Option Period Year 3 | C12: ='Pricing input'!G58 -> 5000
B13: Option Period Year 4 | C13: ='Pricing input'!G72 -> 5000
B14: Total Estimated Price | C14: =SUM(C9:C13) -> 25000
B15: Overall Total | C15: Estimated Price
B16: Okinawa OBVSS | C16: =SUM(C9:C13) -> 25000
B17: FAR 52.217-8 | C17: ='Pricing input'!G85 -> 2500
B18: Total Estimated Price | C18: =SUM(C16:C17) -> 27500
A21: CONTROLLED UNCLASSIFIED INFORMATION (CUI) Source Selection Information - See FAR 2.101 and 3.104
