Workbook

Sheet Instructions
A1: ATTACHMENT 1 TEMPLATE - 06/06/25
A2: Preparation of the Attachment 1 prior to RFQ If there are multiple buildings, see instructions below.
A3: 1 | B3: In the A column, Select SAM buy or GSA buy. If SAM buy, Hide the two columns that are purple at the top and hide the last two rows of notes at the bottom that refer to GSA. | D3: Types of Delivery
A4: 2 | B4: In the FID, Highlight the entire Table of Contents and Copy. | D4: Installation of furniture - to include any GFP in the SOW, if applicable | E4: Vendor Install all items on Att 1. GFP is Government Furnished Products (usually items in warehouse).
A5: 3 | B5: In the Prep Tab (in this form), highlight upper left cell and Paste by right clicking on your mouse and using the second Paste option (Match Destination Formatting (M)). | D5: Shipping (CONUS) Note 1 | E5: Shipping in the continental US
A6: 4 | B6: In the Prep Tab, Delete Column C. | D6: Commercial Shipping (OCONUS) | E6: Commercial shipping to locations outside of the continental US.
A7: 5 | B7: In the Prep Tab, Delete all rows that you do not want in the Attachment 1 (extra lines, titles, "Not Used"). Keep only items you want listed in the Attachment 1. | D7: Secure Shipping (CONUS/OCONUS) - Refer to SOW | E7: For projects that have security requirements like locked and sealed containers, potentially SCIFs, NOCs, Ops Centers, etc.
A8: 6 | B8: In the Prep Tab, Highlight text and Copy into columns D & E of the RFQ tab by clicking on cell F4 and Paste by right clicking on your mouse and using the second Paste option (Values (V)). NOTE: Only copy FID paragraph number & Item Code and Description into RFQ tab. | D8: Electrical Work- Hardwire all items as noted in the FID to the Facility | E8: Electrical Work - This is used if there are items to be hardwired. All items should be noted in the FID.
A9: 7 | B9: Ensure that the FID Paragraph numbers are correct and that the zero didn't drop off. For example, verify whether the paragraph is 2.10 instead of 2.1. If you can't add the "0" to the end, Format the column as Text. | D9: Oversight of Delivery | E9: Warehouse workers offload product and a representative for the Vendor is present to oversee.
A10: 8 | B10: Add title to the Att 1 and turn black - it will automatically populate on the Locations matrix. | D10: Offload Only | E10: This is unloaded by the delivery driver.
A11: 9 | B11: In the Locations matrix (right side of the Att 1), adjust row heights and then indicate quantities for each item under each room (Row T-CU). Once completed, Hide all unused columns and rows, indicated by purple boxes, up to the green cells. NOTE: Enter quantities in the Locations area only. | D11: Removal and Disposal of Existing Furniture | E11: Vendor is responsible for removal of the old furnishings and to dispose of them.
A12: 10 | B12: Hide Column A when the form is complete. (A contains the formula for the OPEN MARKET TOTAL). | D12: Removal of Existing Furniture and Moving to Designated Location | E12: Vendor is responsible for removal of the old furnishings and to moving it to another building.
A13: 11 | B13: Keep the Installation and Shipping that pertain to your order and turn the text black. Hide Installation & Shipping lines not needed. NOTE: Types of Delivery are defined in the table on the right of this page.
A14: 12 | B14: Hide all extra rows down to Furniture Subtotals.
A15: 13 | B15: Hide all tabs except RFQ. Right click on the tab and click Hide.
A16: 14 | B16: Save spreadsheet.
A18: Preparation of the Attachment 1 prior to RFQ for projects with multiple buildings | D18: Tech Review "Warranty" blank comment examples are:
A19: 1 | B19: Perform the instructions 1-8 above "Preparation of the Attachment 1 prior to RFQ" . | D19: N/A
A20: 2 | B20: File Save As for each additional building. | D20: Provide a warranty for this item.
A21: 3 | B21: Complete steps 9-14 under "Preparation of the Attachment 1 prior to RFQ" for all buildings. | D21: Warranty was provided but does not meet the FID requirement.
D22: Warranty provided and acceptable.
A23: Inserting More Rows into RFQ Tab
A24: 1 | B24: To insert more rows in the RFQ tab (there are 80 rows available in the template): A. Highlight row 84 and move your cursor down how ever many rows are needed. B. Right click and select Insert. C. Highlight row 84 and Copy to all the new blank rows. NOTE: MAKE SURE SUBTOTALS AND TOTALS ARE INCLUSIVE OF NEW ROWS!
A25: 2 | B25: To insert a row in the middle of the RFQ tab: A. Highlight the row below where you need the new row, right click, and select Insert. B. Look at the "#" to determine which numbers the new row is between and Copy the "#", "Qty", "Unit", "GSA Contract Total Cost", and "HNC Total Cost" cells from the row above. C. Then Copy the "#" cell you just pasted into the "#" cell in the row below to fix the row numbering. D. Then, enter the "FID Para." and "Item Code & Description" information. E. Enter the quantities in the appropriate rooms/areas. F. Then, in the Tech Eval tab, Insert 14 rows and copy the data from the 14 rows above into these new cells. G. Change the formulas in the top 2 rows of the rows you just copied by comparing the formulas from 14 cells above and 14 cells below to determine what number needs to be changed in the formula. I. Check to ensure everything copied and the line numbering is correct on both tabs.
A26: 3 | B26: To delete a row in the middle of the RFQ tab: A. Highlight the row to delete and delete. B. Highlight the "#" cell above the first row with "##". C. Paste the copied "#" cell into the first "#" cell with "##". Then you will need to go to the Tech Eval tab and Delete the 14 lines for the item that was removed. (Easily identified by "#REF").
A28: Inserting more Columns into Locations area
A29: 1 | B29: If you need to insert more columns in the Locations matrix (there are 80 columns in the template), highlight the green column and move your cursor to how many columns you need to add. Right click and select "Insert". Then Highlight the last column and Copy into the new columns.
A31: Printing (optional)
A32: 1 | B32: To print the Attachment 1, go to "VIEW" tab, select "Custom Views", and highlight "attach1" and click show. Then go to FILE/PRINT. It is set up to print landscape on 8.5 x 11 paper.
A33: 2 | B33: To print the Locations, go to "VIEW" tab, select "Custom Views", and highlight "locations" and click show. Then go to FILE/PRINT. It is set up to print landscape on 8.5 x 11 paper.
A35: Preparation of Tech Eval after quotes are received back from Vendors
A36: 1 | B36: A. Copy the "Tech Eval HNC USE ONLY" columns A-C, all rows that are blue (prior to the first purple cells) into Att 8 Document (Word) prior to starting the Tech Eval. B. Title the Document "1st TR - Vendor - Project Name.docx" for the Tech Eval. Each item will have a "block" of 14 rows, to allow for multiple rounds of tech evals. When dealing with a specific item, please remember there are 14 rows to copy. NOTE: DO NOT COMPLETE THE TECH REVIEW IN THE ATT 1 TEMPLATE.
A37: 2 | B37: To add more lines to the RFQ Tab: A. When lines are added to the RFQ tab you must also insert more rows in the Tech Eval tab. B. Highlight the 14 rows that reflect the tech eval block for the item directly above. C. Copy those onto the end, or in whatever location is required, repeat for each new item. D. Hand change the 7 formulas that pull data from the RFQ tab. They are in the first 5 lines of the item block. The 2 digit cell numbers will need to be changed to 85. The next one will be changed to 86 and so forth.
A38: 3 | B38: To delete lines from the RFQ Tab: A. If lines are deleted from the RFQ Tab, you will need to delete rows in the Tech Eval tab. B. The item block in the Tech Eval tab will have the #REF! error. If you come across a block that is not needed, either Delete or Hide those 14 rows.
A40: Preparation of an Revision / MOD
A41: 1 | B41: A. "Save As" the Att 1 file and add REV 00-00-0000 (date) to the title and the file name. B. To update the Att 1 for a change of product manually highlight cells in yellow that need changing (modifying). C. For a change in quantity, this includes the quantity on the Locations matrix, the total quantity for the item on the Locations matrix, and the quantity on the RFQ table, Highlight the yellow cell(s) at the bottom of the Locations matrix and use Format Paint to update the cells above. NOTE: Tan lines cannot be changed to yellow the normal way.

Sheet Prep Tab
A1: 22.1 | B1: SN03: Industrial, Ventilated Storage Cabinet, Metal
A2: 22.2 | B2: SN04: Industrial, Clear-View Storage Cabinet, Metal
A3: 22.3 | B3: SN05: Closed Industrial Storage Shelving, Metal
A4: 22.4 | B4: SN06: Pallet Rack, Metal Wire Decking
A5: 22.5 | B5: SN07: Mobile Charging Storage Cabinet, Metal
A6: 22.6 | B6: TN01: Deluxe Work Bench, Metal
A7: 22.7 | B7: TN02: Mobile Cabinet Work Bench, Metal
A8: 22.8 | B8: SN08: Clear-View, Preservation Storage Cabinet, Metal
A9: 22.9 | B9: SX01: 4-Drawer Flat File, Double-High, Metal
A10: 22.1 | B10: SX02: 6-Drawer Flat File, Double-High, Metal
A11: 22.11 | B11: SX03: Plaque Storage, Metal
A12: 22.12 | B12: TX01: Stainless Steel Work Table, Height Adjustable

Sheet RFQ
A1: Attachment #1 - Kirtland AFB, NM - Bldg. 20602 Renovations - Industrial Storage SAM.gov | P1: Admin | Q1: SAM
A2: # | B2: Qty | C2: FID Para. | D2: FID Item Code / Description | E2: Vendor Quoted | F2: Product Line Quoted | G2: Model Quoted | H2: =IF(P1="Housing","Nominal Dimensions For Information Only Provide dimensions in Inches","HIDE THESE COLUMNS") -> HIDE THESE COLUMNS | K2: =IF(Q1="GSA","GSA Contract Number OR Open Market","Hide this column") -> Hide this column | L2: =IF(Q1="GSA","GSA Contract Unit Cost") -> FALSE | M2: =IF(Q1="GSA","GSA Contract Total Cost","Hide this column") -> Hide this column | N2: HNC Unit Cost | O2: HNC Total Cost | P2: EDC-I: Hide these columns before submitting file. Select correct entries in the boxes above. These columns shows open market costs and difference from GSA | S2: ="ITEM LOCATIONS"&" *** COMPLETED BY CEHNC *** "&A1 -> ITEM LOCATIONS *** COMPLETED BY CEHNC *** Attachment #1 - Kirtland AFB, NM - Bldg. 20602 Renovations - Industrial Storage SAM.gov | V2: ROOM NAME/ TYPE/# | W2: Storage Room - 118B | X2: Storage Room - 120B | Y2: Flex Space - 121
H3: =IF($P$1="Admin","","W") | I3: =IF($P$1="Admin","","D") | J3: =IF($P$1="Admin","","H") | P3: Open Market | Q3: GSA vs HNC | S3: # | T3: FID ¶ | U3: ITEM DESCRIPTION | V3: TOTALS
A4: =IF(B4>0,A3+1,A3) -> 1 | B4: =V4 -> 2 | C4: 22.1 | D4: SN03: Industrial, Ventilated Storage Cabinet, Metal | M4: =SUM($L4*$B4) -> 0 | O4: =SUM($N4*$B4) -> 0 | P4: =IF(LEFT($K4,2)="OP", $O4,0) -> 0 | Q4: =IF($Q$1="SAM","",IF(L4="","",N4-L4)) | S4: =IF(A4=0,"",A4) -> 1 | T4: =IF(C4="","",C4) -> 22.1 | U4: =IF(D4="","",D4) -> SN03: Industrial, Ventilated Storage Cabinet, Metal | V4: =SUM(W4:CY4) -> 2 | X4: 2
A5: =IF(B5>0,A4+1,A4) -> 2 | B5: =V5 -> 6 | C5: 22.2 | D5: SN04: Industrial, Clear-View Storage Cabinet, Metal | M5: =SUM($L5*$B5) -> 0 | O5: =SUM($N5*$B5) -> 0 | P5: =IF(LEFT($K5,2)="OP", $O5,0) -> 0 | Q5: =IF($Q$1="SAM","",IF(L5="","",N5-L5)) | S5: =IF(A5=0,"",A5) -> 2 | T5: =IF(C5="","",C5) -> 22.2 | U5: =IF(D5="","",D5) -> SN04: Industrial, Clear-View Storage Cabinet, Metal | V5: =SUM(W5:CY5) -> 6 | W5: 6
A6: =IF(B6>0,A5+1,A5) -> 3 | B6: =V6 -> 7 | C6: 22.3 | D6: SN05: Closed Industrial Storage Shelving, Metal | M6: =SUM($L6*$B6) -> 0 | O6: =SUM($N6*$B6) -> 0 | P6: =IF(LEFT($K6,2)="OP", $O6,0) -> 0 | Q6: =IF($Q$1="SAM","",IF(L6="","",N6-L6)) | S6: =IF(A6=0,"",A6) -> 3 | T6: =IF(C6="","",C6) -> 22.3 | U6: =IF(D6="","",D6) -> SN05: Closed Industrial Storage Shelving, Metal | V6: =SUM(W6:CY6) -> 7 | W6: 7
A7: =IF(B7>0,A6+1,A6) -> 4 | B7: =V7 -> 6 | C7: 22.4 | D7: SN06: Pallet Rack, Metal Wire Decking | M7: =SUM($L7*$B7) -> 0 | O7: =SUM($N7*$B7) -> 0 | P7: =IF(LEFT($K7,2)="OP", $O7,0) -> 0 | Q7: =IF($Q$1="SAM","",IF(L7="","",N7-L7)) | S7: =IF(A7=0,"",A7) -> 4 | T7: =IF(C7="","",C7) -> 22.4 | U7: =IF(D7="","",D7) -> SN06: Pallet Rack, Metal Wire Decking | V7: =SUM(W7:CY7) -> 6 | W7: 6
A8: =IF(B8>0,A7+1,A7) -> 5 | B8: =V8 -> 9 | C8: 22.5 | D8: SN07: Mobile Charging Storage Cabinet, Metal | M8: =SUM($L8*$B8) -> 0 | O8: =SUM($N8*$B8) -> 0 | P8: =IF(LEFT($K8,2)="OP", $O8,0) -> 0 | Q8: =IF($Q$1="SAM","",IF(L8="","",N8-L8)) | S8: =IF(A8=0,"",A8) -> 5 | T8: =IF(C8="","",C8) -> 22.5 | U8: =IF(D8="","",D8) -> SN07: Mobile Charging Storage Cabinet, Metal | V8: =SUM(W8:CY8) -> 9 | W8: 9
A9: =IF(B9>0,A8+1,A8) -> 6 | B9: =V9 -> 3 | C9: 22.6 | D9: TN01: Deluxe Work Bench, Metal | M9: =SUM($L9*$B9) -> 0 | O9: =SUM($N9*$B9) -> 0 | P9: =IF(LEFT($K9,2)="OP", $O9,0) -> 0 | Q9: =IF($Q$1="SAM","",IF(L9="","",N9-L9)) | S9: =IF(A9=0,"",A9) -> 6 | T9: =IF(C9="","",C9) -> 22.6 | U9: =IF(D9="","",D9) -> TN01: Deluxe Work Bench, Metal | V9: =SUM(W9:CY9) -> 3 | W9: 3
A10: =IF(B10>0,A9+1,A9) -> 7 | B10: =V10 -> 1 | C10: 22.7 | D10: TN02: Mobile Cabinet Work Bench, Metal | M10: =SUM($L10*$B10) -> 0 | O10: =SUM($N10*$B10) -> 0 | P10: =IF(LEFT($K10,2)="OP", $O10,0) -> 0 | Q10: =IF($Q$1="SAM","",IF(L10="","",N10-L10)) | S10: =IF(A10=0,"",A10) -> 7 | T10: =IF(C10="","",C10) -> 22.7 | U10: =IF(D10="","",D10) -> TN02: Mobile Cabinet Work Bench, Metal | V10: =SUM(W10:CY10) -> 1 | W10: 1
A11: =IF(B11>0,A10+1,A10) -> 8 | B11: =V11 -> 3 | C11: 22.8 | D11: SN08: Clear-View, Preservation Storage Cabinet, Metal | M11: =SUM($L11*$B11) -> 0 | O11: =SUM($N11*$B11) -> 0 | P11: =IF(LEFT($K11,2)="OP", $O11,0) -> 0 | Q11: =IF($Q$1="SAM","",IF(L11="","",N11-L11)) | S11: =IF(A11=0,"",A11) -> 8 | T11: =IF(C11="","",C11) -> 22.8 | U11: =IF(D11="","",D11) -> SN08: Clear-View, Preservation Storage Cabinet, Metal | V11: =SUM(W11:CY11) -> 3 | Y11: 3
A12: =IF(B12>0,A11+1,A11) -> 9 | B12: =V12 -> 1 | C12: 22.9 | D12: SX01: 4-Drawer Flat File, Double-High, Metal | M12: =SUM($L12*$B12) -> 0 | O12: =SUM($N12*$B12) -> 0 | P12: =IF(LEFT($K12,2)="OP", $O12,0) -> 0 | Q12: =IF($Q$1="SAM","",IF(L12="","",N12-L12)) | S12: =IF(A12=0,"",A12) -> 9 | T12: =IF(C12="","",C12) -> 22.9 | U12: =IF(D12="","",D12) -> SX01: 4-Drawer Flat File, Double-High, Metal | V12: =SUM(W12:CY12) -> 1 | Y12: 1
A13: =IF(B13>0,A12+1,A12) -> 10 | B13: =V13 -> 2 | C13: 22.1 | D13: SX02: 6-Drawer Flat File, Double-High, Metal | M13: =SUM($L13*$B13) -> 0 | O13: =SUM($N13*$B13) -> 0 | P13: =IF(LEFT($K13,2)="OP", $O13,0) -> 0 | Q13: =IF($Q$1="SAM","",IF(L13="","",N13-L13)) | S13: =IF(A13=0,"",A13) -> 10 | T13: =IF(C13="","",C13) -> 22.1 | U13: =IF(D13="","",D13) -> SX02: 6-Drawer Flat File, Double-High, Metal | V13: =SUM(W13:CY13) -> 2 | Y13: 2
A14: =IF(B14>0,A13+1,A13) -> 11 | B14: =V14 -> 1 | C14: 22.11 | D14: SX03: Plaque Storage, Metal | M14: =SUM($L14*$B14) -> 0 | O14: =SUM($N14*$B14) -> 0 | P14: =IF(LEFT($K14,2)="OP", $O14,0) -> 0 | Q14: =IF($Q$1="SAM","",IF(L14="","",N14-L14)) | S14: =IF(A14=0,"",A14) -> 11 | T14: =IF(C14="","",C14) -> 22.11 | U14: =IF(D14="","",D14) -> SX03: Plaque Storage, Metal | V14: =SUM(W14:CY14) -> 1 | Y14: 1
A15: =IF(B15>0,A14+1,A14) -> 12 | B15: =V15 -> 8 | C15: 22.12 | D15: TX01: Stainless Steel Work Table, Height Adjustable | M15: =SUM($L15*$B15) -> 0 | O15: =SUM($N15*$B15) -> 0 | P15: =IF(LEFT($K15,2)="OP", $O15,0) -> 0 | Q15: =IF($Q$1="SAM","",IF(L15="","",N15-L15)) | S15: =IF(A15=0,"",A15) -> 12 | T15: =IF(C15="","",C15) -> 22.12 | U15: =IF(D15="","",D15) -> TX01: Stainless Steel Work Table, Height Adjustable | V15: =SUM(W15:CY15) -> 8 | Y15: 8
A16: =IF(B16>0,A15+1,A15) -> 12 | B16: =V16 -> 0 | M16: =SUM($L16*$B16) -> 0 | O16: =SUM($N16*$B16) -> 0 | P16: =IF(LEFT($K16,2)="OP", $O16,0) -> 0 | Q16: =IF($Q$1="SAM","",IF(L16="","",N16-L16)) | S16: =IF(A16=0,"",A16) -> 12 | T16: =IF(C16="","",C16) | U16: =IF(D16="","",D16) | V16: =SUM(W16:CY16) -> 0
A17: =IF(B17>0,A16+1,A16) -> 12 | B17: =V17 -> 0 | M17: =SUM($L17*$B17) -> 0 | O17: =SUM($N17*$B17) -> 0 | P17: =IF(LEFT($K17,2)="OP", $O17,0) -> 0 | Q17: =IF($Q$1="SAM","",IF(L17="","",N17-L17)) | S17: =IF(A17=0,"",A17) -> 12 | T17: =IF(C17="","",C17) | U17: =IF(D17="","",D17) | V17: =SUM(W17:CY17) -> 0
A18: =IF(B18>0,A17+1,A17) -> 12 | B18: =V18 -> 0 | M18: =SUM($L18*$B18) -> 0 | O18: =SUM($N18*$B18) -> 0 | P18: =IF(LEFT($K18,2)="OP", $O18,0) -> 0 | Q18: =IF($Q$1="SAM","",IF(L18="","",N18-L18)) | S18: =IF(A18=0,"",A18) -> 12 | T18: =IF(C18="","",C18) | U18: =IF(D18="","",D18) | V18: =SUM(W18:CY18) -> 0
A19: =IF(B19>0,A18+1,A18) -> 12 | B19: =V19 -> 0 | M19: =SUM($L19*$B19) -> 0 | O19: =SUM($N19*$B19) -> 0 | P19: =IF(LEFT($K19,2)="OP", $O19,0) -> 0 | Q19: =IF($Q$1="SAM","",IF(L19="","",N19-L19)) | S19: =IF(A19=0,"",A19) -> 12 | T19: =IF(C19="","",C19) | U19: =IF(D19="","",D19) | V19: =SUM(W19:CY19) -> 0
A20: =IF(B20>0,A19+1,A19) -> 12 | B20: =V20 -> 0 | M20: =SUM($L20*$B20) -> 0 | O20: =SUM($N20*$B20) -> 0 | P20: =IF(LEFT($K20,2)="OP", $O20,0) -> 0 | Q20: =IF($Q$1="SAM","",IF(L20="","",N20-L20)) | S20: =IF(A20=0,"",A20) -> 12 | T20: =IF(C20="","",C20) | U20: =IF(D20="","",D20) | V20: =SUM(W20:CY20) -> 0
A21: =IF(B21>0,A20+1,A20) -> 12 | B21: =V21 -> 0 | M21: =SUM($L21*$B21) -> 0 | O21: =SUM($N21*$B21) -> 0 | P21: =IF(LEFT($K21,2)="OP", $O21,0) -> 0 | Q21: =IF($Q$1="SAM","",IF(L21="","",N21-L21)) | S21: =IF(A21=0,"",A21) -> 12 | T21: =IF(C21="","",C21) | U21: =IF(D21="","",D21) | V21: =SUM(W21:CY21) -> 0
A22: =IF(B22>0,A21+1,A21) -> 12 | B22: =V22 -> 0 | M22: =SUM($L22*$B22) -> 0 | O22: =SUM($N22*$B22) -> 0 | P22: =IF(LEFT($K22,2)="OP", $O22,0) -> 0 | Q22: =IF($Q$1="SAM","",IF(L22="","",N22-L22)) | S22: =IF(A22=0,"",A22) -> 12 | T22: =IF(C22="","",C22) | U22: =IF(D22="","",D22) | V22: =SUM(W22:CY22) -> 0
A23: =IF(B23>0,A22+1,A22) -> 12 | B23: =V23 -> 0 | M23: =SUM($L23*$B23) -> 0 | O23: =SUM($N23*$B23) -> 0 | P23: =IF(LEFT($K23,2)="OP", $O23,0) -> 0 | Q23: =IF($Q$1="SAM","",IF(L23="","",N23-L23)) | S23: =IF(A23=0,"",A23) -> 12 | T23: =IF(C23="","",C23) | U23: =IF(D23="","",D23) | V23: =SUM(W23:CY23) -> 0
A24: =IF(B24>0,A23+1,A23) -> 12 | B24: =V24 -> 0 | M24: =SUM($L24*$B24) -> 0 | O24: =SUM($N24*$B24) -> 0 | P24: =IF(LEFT($K24,2)="OP", $O24,0) -> 0 | Q24: =IF($Q$1="SAM","",IF(L24="","",N24-L24)) | S24: =IF(A24=0,"",A24) -> 12 | T24: =IF(C24="","",C24) | U24: =IF(D24="","",D24) | V24: =SUM(W24:CY24) -> 0
A25: =IF(B25>0,A24+1,A24) -> 12 | B25: =V25 -> 0 | M25: =SUM($L25*$B25) -> 0 | O25: =SUM($N25*$B25) -> 0 | P25: =IF(LEFT($K25,2)="OP", $O25,0) -> 0 | Q25: =IF($Q$1="SAM","",IF(L25="","",N25-L25)) | S25: =IF(A25=0,"",A25) -> 12 | T25: =IF(C25="","",C25) | U25: =IF(D25="","",D25) | V25: =SUM(W25:CY25) -> 0
A26: =IF(B26>0,A25+1,A25) -> 12 | B26: =V26 -> 0 | M26: =SUM($L26*$B26) -> 0 | O26: =SUM($N26*$B26) -> 0 | P26: =IF(LEFT($K26,2)="OP", $O26,0) -> 0 | Q26: =IF($Q$1="SAM","",IF(L26="","",N26-L26)) | S26: =IF(A26=0,"",A26) -> 12 | T26: =IF(C26="","",C26) | U26: =IF(D26="","",D26) | V26: =SUM(W26:CY26) -> 0
A27: =IF(B27>0,A26+1,A26) -> 12 | B27: =V27 -> 0 | M27: =SUM($L27*$B27) -> 0 | O27: =SUM($N27*$B27) -> 0 | P27: =IF(LEFT($K27,2)="OP", $O27,0) -> 0 | Q27: =IF($Q$1="SAM","",IF(L27="","",N27-L27)) | S27: =IF(A27=0,"",A27) -> 12 | T27: =IF(C27="","",C27) | U27: =IF(D27="","",D27) | V27: =SUM(W27:CY27) -> 0
... A84: =IF(B84>0,A83+1,A83) -> 12 | B84: =V84 -> 0 | M84: =SUM($L84*$B84) -> 0 | O84: =SUM($N84*$B84) -> 0 | P84: =IF(LEFT($K84,2)="OP", $O84,0) -> 0 | Q84: =IF($Q$1="SAM","",IF(L84="","",N84-L84)) | S84: =IF(A84=0,"",A84) -> 12 | T84: =IF(C84="","",C84) | U84: =IF(D84="","",D84) | V84: =SUM(W84:CY84) -> 0
A85: Furniture Subtotals: | G85: =IF(Q1="GSA","Open Market:","") | K85: =IF(Q1="GSA",P85,"") | L85: GSA Cost: | M85: =SUM(M4:M84) -> 0 | N85: HNC Cost: | O85: =SUM(O4:O84) -> 0 | P85: =SUM(P4:P84) -> 0
A86: =IF(Q1="GSA","Please note, if one or more of the boxes above are in amber or red, please refer to RFQ, Sect. J, Instruction to Quoters for requirements for Open Market items.","") | P86: Open Market Total above
A87: Installation & Shipping:
A88: Shipping (CONUS)
A89: Commercial Shipping (OCONUS)
A90: Secure Commercial Shipping (CONUS/OCONUS) - Refer to SOW
A91: Electrical Work- Hardwire all items as noted in the FID to the Facility
A92: Tariffs
A93: Installation - Includes new and existing items, if applicable, in accordance with SOW
A94: Removal of Existing Items and Disposal/Relocation in accordance with SOW
A95: Oversight of Delivery | P95: Admin
A96: Offload Only | P96: Housing
...

Sheet Tech Eval HNC USE ONLY
A1: =IF(RFQ!D4="",0,RFQ!A4) -> 1 | B1: =IF(C1=0,0, "FID "&RFQ!C4) -> FID 22.1 | C1: =RFQ!D4 -> SN03: Industrial, Ventilated Storage Cabinet, Metal
A2: Vendor Quoted: | C2: =RFQ!E4 -> 0
A3: Product Line Quoted: | C3: =RFQ!F4 -> 0
A4: Model Quoted: | C4: =+RFQ!G4 -> 0
A5: GSA # or Open Market: | C5: =RFQ!K4 -> 0
A6: Warranty:
A7: 1st Review HNC:
A8: 1st Review Vendor:
A9: 2nd Review HNC:
A10: 2nd Review Vendor:
A11: 3rd Review HNC:
A12: 3rd Review Vendor:
A13: 4th Review HNC:
A14: 4th Review Vendor:
A15: =IF(RFQ!D5="",0,RFQ!A5) -> 2 | B15: =IF(C15=0,0, "FID "&RFQ!C5) -> FID 22.2 | C15: =RFQ!D5 -> SN04: Industrial, Clear-View Storage Cabinet, Metal
A16: Vendor Quoted: | C16: =RFQ!E5 -> 0
A17: Product Line Quoted: | C17: =RFQ!F5 -> 0
A18: Model Quoted: | C18: =RFQ!G5 -> 0
A19: GSA # or Open Market: | C19: =RFQ!K5 -> 0
A20: Warranty:
A21: 1st Review HNC:
A22: 1st Review Vendor:
A23: 2nd Review HNC:
A24: 2nd Review Vendor:
A25: 3rd Review HNC:
A26: 3rd Review Vendor:
A27: 4th Review HNC:
A28: 4th Review Vendor:
A29: =IF(RFQ!D6="",0,RFQ!A6) -> 3 | B29: =IF(C29=0,0, "FID "&RFQ!C6) -> FID 22.3 | C29: =RFQ!D6 -> SN05: Closed Industrial Storage Shelving, Metal
A30: Vendor Quoted: | C30: =RFQ!E6 -> 0
A31: Product Line Quoted: | C31: =RFQ!F6 -> 0
A32: Model Quoted: | C32: =RFQ!G6 -> 0
A33: GSA # or Open Market: | C33: =RFQ!K6 -> 0
A34: Warranty:
A35: 1st Review HNC:
A36: 1st Review Vendor:
A37: 2nd Review HNC:
A38: 2nd Review Vendor:
A39: 3rd Review HNC:
A40: 3rd Review Vendor:
...
