Workbook
Name CLIN1_Total: 'Base Year'!#REF!
Name CLIN2_Total: 'Base Year'!#REF!
Name CLIN3_Total: 'Base Year'!#REF!
Name FlatCLIN1: 'Base Year'!#REF!
Name FlatCLIN2: 'Base Year'!#REF!
Name FlatCLIN3: 'Base Year'!#REF!
Name MeasCLIN1: 'Base Year'!#REF!
Name MeasCLIN2: 'Base Year'!#REF!
Name MeasCLIN3: 'Base Year'!#REF!
Name NAME: 'Base Year'!#REF!
Name RS1_CLIN1_Total: #REF!
Name RS1_CLIN2_Total: #REF!
Name RS1_CLIN3_Total: #REF!
Name RS1_FlatCLIN1: #REF!
Name RS1_FlatCLIN2: #REF!
Name RS1_FlatCLIN3: #REF!
Name RS1_MeasCLIN1: #REF!
Name RS1_MeasCLIN2: #REF!
Name RS1_MeasCLIN3: #REF!
Name RS1_NAME: #REF!
Name RS2_CLIN1_Total: #REF!
Name RS2_CLIN2_Total: #REF!
Name RS2_CLIN3_Total: #REF!
Name RS2_FlatCLIN1: #REF!
Name RS2_FlatCLIN2: #REF!
Name RS2_FlatCLIN3: #REF!
Name RS2_MeasCLIN1: #REF!
Name RS2_MeasCLIN2: #REF!
Name RS2_MeasCLIN3: #REF!
Name RS2_NAME: #REF!

Sheet Base Year
B2: 46146 | G2: BASE YEAR
B3: Solicitation FA301626Q0004
B4: JBSA Lackland AFB / Fort Sam Houston, TX | G4: CLIN 0001 (FFP) | H4: CLIN 0002 (FFP) | J4: CLIN 0003 (FFP)
B5: Services & Function Items | G5: Non-Recurring Charges | H5: Recurring Charges | J5: Cutover
B6: SLIN | D6: DESCRIPTION | E6: Unit of Issue | F6: Quantity | G6: Annual Total NRC | H6: Per Unit Monthly | I6: Total Monthly
B8: A | D8: Installation and Cutover
B9: A | C9: A | D9: Installation (PWS Para 4.2) | E9: EA | F9: 1 | J9: 0
B10: A | C10: B | D10: Cutover (PWS Para 4.2.1) | E10: EA | F10: 1 | J10: 0
D12: Customer Service Records
B13: A | C13: C | D13: Customer Services Record (CSR) | E13: EA | F13: 2 | G13: 0
D15: SIP Trunking Traffic Study/Analysis Report
B16: A | C16: D | D16: City Trunk Traffic Analysis Study with Report | E16: EA | F16: 5 | G16: 0
B17: A | C17: E | D17: Long Distance Traffic Analysis Study with Report | E17: EA | F17: 5 | G17: 0
D19: (A) Lackland AFB
B21: B | D21: Direct Inward Dial Directory Number
B22: B | C22: A | D22: DID Directory Number | E22: HD | F22: 400 | G22: 0 | H22: 0 | I22: =F22*H22 -> 0
B23: B | C23: B | D23: Direct In Dial (DID) Directory Number Portability | E23: HD | F23: 400 | G23: 0 | H23: 0 | I23: =H23*F23 -> 0
B24: B | C24: C | D24: Taxes, Fees & Surcharges | G24: 0 | H24: 0 | I24: 0
B25: B | C25: D | D25: - BZ Reserved
B27: C | D27: Commercial Subscriber Lines
B28: C | C28: A | D28: Flat Rate, Basic Services, Analog | G28: 0 | H28: 0 | I28: =H28*F28 -> 0
B29: C | C29: B | D29: Taxes, Fees & Surcharges | G29: 0 | H29: 0 | I29: =H29*F29 -> 0
F30: 0 | G30: 0 | H30: 0 | I30: =H30*F30 -> 0
D31: Commercial Subscriber Line Features
B32: C | C32: C | D32: Touch Tone | G32: 0 | H32: 0 | I32: =H32*F32 -> 0
B33: C | C33: D | D33: - CZ Reserved | G33: 0 | H33: 0 | I33: =H33*F33 -> 0
B35: E | D35: SIP Trunking with PRI Handoff
B36: E | C36: A | D36: Concurrent Call Path | E36: EA | F36: 621 | G36: 0 | H36: 0 | I36: 0
B37: E | C37: B | D37: ISDN Primary Rate Interface | E37: EA | F37: 27 | G37: 0 | H37: 0 | I37: =H37*F37 -> 0
B38: E | C38: C | D38: Taxes, Fees & Surcharges | G38: 0 | H38: 0 | I38: =H38*F38 -> 0
B39: E | C39: D | D39: - EZ Reserved
B41: F | D41: Transport Channels
B42: F | C42: A | D42: 4-Wire Voice Circuit & Terminations | E42: EA | G42: 0 | H42: 0 | I42: =H42*F42 -> 0
B43: F | C43: B | D43: 4-Wire Voice Circuit Transport Mileage, Per Mile | E43: MI | F43: 16 | G43: 0 | H43: 0 | I43: =H43*F43 -> 0
B44: F | C44: C | D44: Taxes, Fees & Surcharges | G44: 0 | H44: 0 | I44: =H44*F44 -> 0
B45: F | C45: D | D45: 1 Gbps Circuit | E45: EA | G45: 0 | H45: 0 | I45: =H45*F45 -> 0
B46: F | C46: E | D46: 1 GbpsTransport Mileage, Per Mile | E46: MI | F46: 18 | G46: 0 | H46: 0 | I46: =H46*F46 -> 0
B47: F | C47: F | D47: Taxes, Fees & Surchages | G47: 0 | H47: 0 | I47: =H47*F47 -> 0
B48: F | C48: G | D48: - FZ Reserved | G48: 0 | H48: 0 | I48: =H48*F48 -> 0
D50: Total Lackland AFB | G50: =+SUM(G13:G48) -> 0 | H50: =+SUM(H22:H48) -> 0 | I50: =SUM(I22:I48) -> 0
...

Sheet Option Yr 1
B2: 46146 | G2: OPTION YEAR 1
B3: Solicitation FA301626Q0004
B4: JBSA Lackland AFB / Fort Sam Houston, TX | G4: CLIN 0001 (FFP) | H4: CLIN 0002 (FFP)
B5: Services & Function Items | G5: Non-Recurring Charges | H5: Recurring Charges
B6: SLIN | D6: DESCRIPTION | E6: Unit of Issue | F6: Quantity | G6: Annual Total NRC | H6: Per Unit Monthly | I6: Total Monthly
B8: A
B9: A | C9: A
B10: A | C10: B
D12: Customer Service Records
B13: A | C13: C | D13: Customer Services Record (CSR) | E13: EA | F13: 2 | G13: 0
D15: SIP Trunking Traffic Study/Analysis Report
B16: A | C16: D | D16: City Trunk Traffic Analysis Study with Report | E16: EA | F16: 5 | G16: 0
B17: A | C17: E | D17: Long Distance Traffic Analysis Study with Report | E17: EA | F17: 5 | G17: 0
D19: (A) Lackland AFB
B21: B | D21: Direct Inward Dial Directory Number
B22: B | C22: A | D22: DID Directory Number | E22: HD | F22: 400 | G22: 0 | H22: 0 | I22: =F22*H22 -> 0
B23: B | C23: B | D23: Direct In Dial (DID) Directory Number Portability | E23: HD | F23: 400 | G23: 0 | H23: 0 | I23: =H23*F23 -> 0
B24: B | C24: C | D24: Taxes, Fees & Surcharges | G24: 0 | H24: 0 | I24: 0
B25: B | C25: D | D25: - BZ Reserved
B27: C | D27: Commercial Subscriber Lines
B28: C | C28: A | D28: Flat Rate, Basic Services, Analog | G28: 0 | H28: 0 | I28: =H28*F28 -> 0
B29: C | C29: B | D29: Taxes, Fees & Surcharges | G29: 0 | H29: 0 | I29: =H29*F29 -> 0
D31: Commercial Subscriber Line Features
B32: C | C32: C | D32: Touch Tone | G32: 0 | H32: 0 | I32: =H32*F32 -> 0
B33: C | C33: D | D33: - CZ Reserved
B35: E | D35: SIP Trunking with PRI Handoff
B36: E | C36: A | D36: Concurrent Call Path | E36: EA | F36: 621 | G36: 0 | H36: 0
B37: E | C37: B | D37: ISDN Primary Rate Interface | E37: EA | F37: 27 | G37: 0 | H37: 0 | I37: =H37*F37 -> 0
B38: E | C38: C | D38: Taxes, Fees & Surcharges | G38: 0 | H38: 0 | I38: =H38*F38 -> 0
B39: E | C39: D | D39: - EZ Reserved
B41: F | D41: Transport Channels
B42: F | C42: A | D42: 4-Wire Voice Circuit & Terminations | E42: EA | G42: 0 | H42: 0 | I42: =H42*F42 -> 0
B43: F | C43: B | D43: 4-Wire Voice Circuit Transport Mileage, Per Mile | E43: MI | F43: 16 | G43: 0 | H43: 0 | I43: =H43*F43 -> 0
B44: F | C44: C | D44: Taxes, Fees & Surcharges | G44: 0 | H44: 0 | I44: =H44*F44 -> 0
B45: F | C45: D | D45: 1 Gbps Circuit | E45: EA | G45: 0 | H45: 0 | I45: =H45*F45 -> 0
B46: F | C46: E | D46: 1 GbpsTransport Mileage, Per Mile | E46: MI | F46: 18 | G46: 0 | H46: 0 | I46: =H46*F46 -> 0
B47: F | C47: F | D47: Taxes, Fees & Surchages | G47: 0 | H47: 0 | I47: =H47*F47 -> 0
B48: F | C48: G | D48: - FZ Reserved
D50: Total Lackland AFB | G50: =SUM(G13:G47) -> 0 | H50: =SUM(H22:H47) -> 0 | I50: =SUM(I22:I47) -> 0
D52: (B) Fort Sam Houston / BAMC
...

Sheet Option Yr 2
B2: 46146 | G2: OPTION YEAR 2
B3: Solicitation FA301626Q0004
B4: JBSA Lackland AFB / Fort Sam Houston, TX | G4: CLIN 0001 (FFP) | H4: CLIN 0002 (FFP)
B5: Services & Function Items | G5: Non-Recurring Charges | H5: Recurring Charges
B6: SLIN | D6: DESCRIPTION | E6: Unit of Issue | F6: Quantity | G6: Annual Total NRC | H6: Per Unit Monthly | I6: Total Monthly
B8: A
B9: A | C9: A
B10: A | C10: B
D12: Customer Service Records
B13: A | C13: C | D13: Customer Services Record (CSR) | E13: EA | F13: 2 | G13: 0
D15: SIP Trunking Traffic Study/Analysis Report
B16: A | C16: D | D16: City Trunk Traffic Analysis Study with Report | E16: EA | F16: 5 | G16: 0
B17: A | C17: E | D17: Long Distance Traffic Analysis Study with Report | E17: EA | F17: 5 | G17: 0
D19: (A) Lackland AFB
B21: B | D21: Direct Inward Dial Directory Number
B22: B | C22: A | D22: DID Directory Number | E22: HD | F22: 400 | G22: 0 | H22: 0 | I22: =F22*H22 -> 0
B23: B | C23: B | D23: Direct In Dial (DID) Directory Number Portability | E23: HD | F23: 400 | G23: 0 | H23: 0 | I23: =H23*F23 -> 0
B24: B | C24: C | D24: Taxes, Fees & Surcharges | G24: 0 | H24: 0 | I24: 0
B25: B | C25: D | D25: - BZ Reserved
B27: C | D27: Commercial Subscriber Lines
B28: C | C28: A | D28: Flat Rate, Basic Services, Analog | G28: 0 | H28: 0 | I28: =H28*F28 -> 0
B29: C | C29: B | D29: Taxes, Fees & Surcharges | G29: 0 | H29: 0 | I29: =H29*F29 -> 0
D31: Commercial Subscriber Line Features
B32: C | C32: C | D32: Touch Tone | G32: 0 | H32: 0 | I32: =H32*F32 -> 0
B33: C | C33: D | D33: - CZ Reserved
B35: E | D35: SIP Trunking with PRI Handoff
B36: E | C36: A | D36: Concurrent Call Path | E36: EA | F36: 621 | G36: 0 | H36: 0
B37: E | C37: B | D37: ISDN Primary Rate Interface | E37: EA | F37: 27 | G37: 0 | H37: 0 | I37: =H37*F37 -> 0
B38: E | C38: C | D38: Taxes, Fees & Surcharges | G38: 0 | H38: 0 | I38: =H38*F38 -> 0
B39: E | C39: D | D39: - EZ Reserved
B41: F | D41: Transport Channels
B42: F | C42: A | D42: 4-Wire Voice Circuit & Terminations | E42: EA | G42: 0 | H42: 0 | I42: =H42*F42 -> 0
B43: F | C43: B | D43: 4-Wire Voice Circuit Transport Mileage, Per Mile | E43: MI | F43: 16 | G43: 0 | H43: 0 | I43: =H43*F43 -> 0
B44: F | C44: C | D44: Taxes, Fees & Surcharges | G44: 0 | H44: 0 | I44: =H44*F44 -> 0
B45: F | C45: D | D45: 1 Gbps Circuit | E45: EA | G45: 0 | H45: 0 | I45: =H45*F45 -> 0
B46: F | C46: E | D46: 1 GbpsTransport Mileage, Per Mile | E46: MI | F46: 18 | G46: 0 | H46: 0 | I46: =H46*F46 -> 0
B47: F | C47: F | D47: Taxes, Fees & Surchages | G47: 0 | H47: 0 | I47: =H47*F47 -> 0
B48: F | C48: G | D48: - FZ Reserved
D50: Total Lackland AFB | G50: =SUM(G13:G47) -> 0 | H50: =SUM(H22:H47) -> 0 | I50: =SUM(I22:I47) -> 0
D52: (B) Fort Sam Houston / BAMC
...

Sheet Option Yr 3
B2: 46146 | G2: OPTION YEAR 3
B3: Solicitation FA301626Q0004
B4: JBSA Lackland AFB / Fort Sam Houston, TX | G4: CLIN 0001 (FFP) | H4: CLIN 0002 (FFP)
B5: Services & Function Items | G5: Non-Recurring Charges | H5: Recurring Charges
B6: SLIN | D6: DESCRIPTION | E6: Unit of Issue | F6: Quantity | G6: Annual Total NRC | H6: Per Unit Monthly | I6: Total Monthly
B8: A
B9: A | C9: A
B10: A | C10: B
D12: Customer Service Records
B13: A | C13: C | D13: Customer Services Record (CSR) | E13: EA | F13: 2 | G13: 0
D15: SIP Trunking Traffic Study/Analysis Report
B16: A | C16: D | D16: City Trunk Traffic Analysis Study with Report | E16: EA | F16: 5 | G16: 0
B17: A | C17: E | D17: Long Distance Traffic Analysis Study with Report | E17: EA | F17: 5 | G17: 0
D19: (A) Lackland AFB
B21: B | D21: Direct Inward Dial Directory Number
B22: B | C22: A | D22: DID Directory Number | E22: HD | F22: 400 | G22: 0 | H22: 0 | I22: =F22*H22 -> 0
B23: B | C23: B | D23: Direct In Dial (DID) Directory Number Portability | E23: HD | F23: 400 | G23: 0 | H23: 0 | I23: =H23*F23 -> 0
B24: B | C24: C | D24: Taxes, Fees & Surcharges | G24: 0 | H24: 0 | I24: 0
B25: B | C25: D | D25: - BZ Reserved
B27: C | D27: Commercial Subscriber Lines
B28: C | C28: A | D28: Flat Rate, Basic Services, Analog | G28: 0 | H28: 0 | I28: =H28*F28 -> 0
B29: C | C29: B | D29: Taxes, Fees & Surcharges | G29: 0 | H29: 0 | I29: =H29*F29 -> 0
G30: 0 | H30: 0 | I30: =H30*F30 -> 0
D31: Commercial Subscriber Line Features
B32: C | C32: C | D32: Touch Tone | G32: 0 | H32: 0 | I32: =H32*F32 -> 0
B33: C | C33: D | D33: - CZ Reserved
B35: E | D35: SIP Trunking with PRI Handoff
B36: E | C36: A | D36: Concurrent Call Path | E36: EA | F36: 621 | G36: 0 | H36: 0 | I36: 0
B37: E | C37: B | D37: ISDN Primary Rate Interface | E37: EA | F37: 27 | G37: 0 | H37: 0 | I37: =H37*F37 -> 0
B38: E | C38: C | D38: Taxes, Fees & Surcharges | G38: 0 | H38: 0 | I38: =H38*F38 -> 0
B39: E | C39: D | D39: - EZ Reserved
B41: F | D41: Transport Channels
B42: F | C42: A | D42: 4-Wire Voice Circuit & Terminations | E42: EA | G42: 0 | H42: 0 | I42: =H42*F42 -> 0
B43: F | C43: B | D43: 4-Wire Voice Circuit Transport Mileage, Per Mile | E43: MI | F43: 16 | G43: 0 | H43: 0 | I43: =H43*F43 -> 0
B44: F | C44: C | D44: Taxes, Fees & Surcharges | G44: 0 | H44: 0 | I44: =H44*F44 -> 0
B45: F | C45: D | D45: 1 Gbps Circuit | E45: EA | G45: 0 | H45: 0 | I45: =H45*F45 -> 0
B46: F | C46: E | D46: 1 GbpsTransport Mileage, Per Mile | E46: MI | F46: 18 | G46: 0 | H46: 0 | I46: =H46*F46 -> 0
B47: F | C47: F | D47: Taxes, Fees & Surchages | G47: 0 | H47: 0 | I47: =H47*F47 -> 0
B48: F | C48: G | D48: - FZ Reserved
D50: Total Lackland AFB | G50: =SUM(G13:G47) -> 0 | H50: =SUM(H22:H47) -> 0 | I50: =SUM(I22:I47) -> 0
...

Sheet Option Yr 4
B2: 46146 | G2: OPTION YEAR 4
B3: Solicitation FA301626Q0004
B4: JBSA Lackland AFB / Fort Sam Houston, TX | G4: CLIN 0001 (FFP) | H4: CLIN 0002 (FFP)
B5: Services & Function Items | G5: Non-Recurring Charges | H5: Recurring Charges
B6: SLIN | D6: DESCRIPTION | E6: Unit of Issue | F6: Quantity | G6: Annual Total NRC | H6: Per Unit Monthly | I6: Total Monthly
B8: A
B9: A | C9: A
B10: A | C10: B
D12: Customer Service Records
B13: A | C13: C | D13: Customer Services Record (CSR) | E13: EA | F13: 2 | G13: 0
D15: SIP Trunking Traffic Study/Analysis Report
B16: A | C16: D | D16: City Trunk Traffic Analysis Study with Report | E16: EA | F16: 5 | G16: 0
B17: A | C17: E | D17: Long Distance Traffic Analysis Study with Report | E17: EA | F17: 5 | G17: 0
D19: (A) Lackland AFB
B21: B | D21: Direct Inward Dial Directory Number
B22: B | C22: A | D22: DID Directory Number | E22: HD | F22: 400 | G22: 0 | H22: 0 | I22: =F22*H22 -> 0
B23: B | C23: B | D23: Direct In Dial (DID) Directory Number Portability | E23: HD | F23: 400 | G23: 0 | H23: 0 | I23: =H23*F23 -> 0
B24: B | C24: C | D24: Taxes, Fees & Surcharges | G24: 0 | H24: 0 | I24: 0
B25: B | C25: D | D25: - BZ Reserved
B27: C | D27: Commercial Subscriber Lines
B28: C | C28: A | D28: Flat Rate, Basic Services, Analog | G28: 0 | H28: 0 | I28: =H28*F28 -> 0
B29: C | C29: B | D29: Taxes, Fees & Surcharges | G29: 0 | H29: 0 | I29: =H29*F29 -> 0
D31: Commercial Subscriber Line Features
B32: C | C32: C | D32: Touch Tone | G32: 0 | H32: 0 | I32: =H32*F32 -> 0
B33: C | C33: D | D33: - CZ Reserved | G33: 0 | H33: 0 | I33: =H33*F33 -> 0
B35: E | D35: SIP Trunking with PRI Handoff
B36: E | C36: A | D36: Concurrent Call Path | E36: EA | F36: 621 | G36: 0 | H36: 0 | I36: 0
B37: E | C37: B | D37: ISDN Primary Rate Interface | E37: EA | F37: 27 | G37: 0 | H37: 0 | I37: =H37*F37 -> 0
B38: E | C38: C | D38: Taxes, Fees & Surcharges | G38: 0 | H38: 0 | I38: =H38*F38 -> 0
B39: E | C39: D | D39: - EZ Reserved
B41: F | D41: Transport Channels
B42: F | C42: A | D42: 4-Wire Voice Circuit & Terminations | E42: EA | G42: 0 | H42: 0 | I42: =H42*F42 -> 0
B43: F | C43: B | D43: 4-Wire Voice Circuit Transport Mileage, Per Mile | E43: MI | F43: 16 | G43: 0 | H43: 0 | I43: =H43*F43 -> 0
B44: F | C44: C | D44: Taxes, Fees & Surcharges | G44: 0 | H44: 0 | I44: =H44*F44 -> 0
B45: F | C45: D | D45: 1 Gbps Circuit | E45: EA | G45: 0 | H45: 0 | I45: =H45*F45 -> 0
B46: F | C46: E | D46: 1 GbpsTransport Mileage, Per Mile | E46: MI | F46: 18 | G46: 0 | H46: 0 | I46: =H46*F46 -> 0
B47: F | C47: F | D47: Taxes, Fees & Surchages | G47: 0 | H47: 0 | I47: =H47*F47 -> 0
B48: F | C48: G | D48: - FZ Reserved
D50: Total Lackland AFB | G50: =SUM(G13:G47) -> 0 | H50: =SUM(H22:H47) -> 0 | I50: =SUM(I22:I47) -> 0
D52: (B) Fort Sam Houston / BAMC
...

Sheet Pricing Schedule Summary
B2: ='Base Year'!B2 -> 46146
B3: PRICING SCHEDULE Solicitation FA301626Q0004
B4: LOCAL TECOMMUNICATION SERVICES
B5: ='Base Year'!B4 -> JBSA Lackland AFB / Fort Sam Houston, TX
D7: BASE YEAR | G7: OPTION YEAR ONE | J7: OPTION YEAR TWO | M7: OPTION YEAR THREE | P7: OPTION YEAR FOUR | S7: OPTIONAL 6-MO EXTENSION
D9: PRICING SUMMARY | G9: PRICING SUMMARY | J9: PRICING SUMMARY | M9: PRICING SUMMARY | P9: PRICING SUMMARY | S9: PRICING SUMMARY
B10: CLIN | C10: Services & Function Items | D10: MONTHLY | E10: ANNUALLY | G10: MONTHLY | H10: ANNUALLY | J10: MONTHLY | K10: ANNUALLY | M10: MONTHLY | N10: ANNUALLY | P10: MONTHLY | Q10: ANNUALLY | S10: MONTHLY | T10: ANNUALLY
B11: 0001 | C11: NON-RECURRING CHARGES (NRC) | E11: ='Base Year'!G88 -> 0 | H11: ='Option Yr 1'!G88 -> 0 | K11: ='Option Yr 2'!G88 -> 0 | N11: ='Option Yr 3'!G88 -> 0 | Q11: ='Option Yr 4'!G88 -> 0 | T11: =Q11/2 -> 0
B12: 0002 | C12: MONTHLY RECURRING CHARGES (MRC) | D12: ='Base Year'!I88 -> 0 | E12: =D12*12 -> 0 | G12: ='Option Yr 1'!I88 -> 0 | H12: =G12*12 -> 0 | J12: ='Option Yr 2'!I88 -> 0 | K12: =J12*12 -> 0 | M12: ='Option Yr 3'!I88 -> 0 | N12: =M12*12 -> 0 | P12: ='Option Yr 4'!I88 -> 0 | Q12: =P12*12 -> 0 | S12: ='Option Yr 4'!I88 -> 0 | T12: =S12*6 -> 0
B13: 0003 | C13: CUTOVER | E13: ='Base Year'!J88 -> 0
C15: TOTAL: | E15: =SUM(E11:E13) -> 0 | H15: =SUM(H11:H13) -> 0 | K15: =SUM(K11:K13) -> 0 | N15: =SUM(N11:N13) -> 0 | Q15: =SUM(Q11:Q13) -> 0 | S15: =P15 | T15: =SUM(T11:T13) -> 0
C17: BASE YEAR + ALL OPTION YEARS TOTAL: | E17: =E15+H15+K15+N15+Q15+T15 -> 0
