Workbook

Sheet Instructions
A2: Instructions
A3: 1 | B3: Fill in the monthly price for one FTE for each location in Column 'E'
A4: 2 | B4: If pricing is different for a group of FTEs within a single location (i.e., different building at different rates), create a new row underneath that location as a new subCLIN to list the different rate. See Example 1 for reference →
A5: 3 | B5: If your firm is unable to provide office space for a listed location, leave the price cell blank. If your firm is offering a location near an otherwise unavailable location, include a note about where the alternative location is in the area provided beneath the pricing table.
A6: 4 | B6: If there is a one time activation fee, list that in Column 'E' for CLIN 0044. If there is no activation fee, put '0' in Column 'E' for CLIN 0044.
A7: 5 | B7: If there are any additional fees, list them as subsequent CLINs (0045, 0046, etc.) and label what the fees are for. If there are no additional fees, list the price of CLIN 0045 as '0'
E9: Example 1
E10: Old* | F10: NJ | G10: (New Jersey) | H10: 0026
G11: Mt. Laurel | H11: 0026AA | I11: 8 | J11: 3 | K11: =I11*J11 -> 24 | L11: =K11*12 -> 288
G12: Newark | H12: 0026AB | I12: 1 | J12: 2 | K12: =I12*J12 -> 2 | L12: =K12*12 -> 24
E13: New* | F13: NJ | G13: (New Jersey) | H13: 0026
G14: Mt. Laurel (Building 1) | H14: 0026AA | I14: 4 | J14: 3 | K14: =I14*J14 -> 12 | L14: =K14*12 -> 144
G15: Mt. Laurel (Building 2) | H15: 0026AB | I15: 3 | J15: 4 | K15: =I15*J15 -> 12 | L15: =K15*12 -> 144
G16: Mt. Laurel (Building 3) | H16: 0026AC | I16: 1 | J16: 5 | K16: =I16*J16 -> 5 | L16: =K16*12 -> 60
G17: Newark | H17: 0026AD | I17: 1 | J17: 2 | K17: =I17*J17 -> 2 | L17: =K17*12 -> 24

Sheet Pricing Spreadsheet
A1: Attachment D - Pricing Spreadsheet - RFQ 70CMSW26Q00000009
B2: Please ONLY fill in yellow cells
A3: State | B3: City | C3: CLIN | D3: Unit | E3: FTE Price/Month | F3: Extended Price/Month | G3: Yearly Price
A4: AL | B4: (Alabama) | C4: 0001
B5: Huntsville | D5: 3 | F5: =D5*E5 -> 0 | G5: =F5*12 -> 0
B6: Montgomery | D6: 2 | F6: =D6*E6 -> 0 | G6: =F6*12 -> 0
A7: AZ | B7: (Arizona) | C7: 0002
B8: Casa Grande | D8: 1 | F8: =D8*E8 -> 0 | G8: =F8*12 -> 0
B9: Chandler | D9: 1 | F9: =D9*E9 -> 0 | G9: =F9*12 -> 0
B10: Concho | D10: 1 | F10: =D10*E10 -> 0 | G10: =F10*12 -> 0
B11: Eloy | D11: 1 | F11: =D11*E11 -> 0 | G11: =F11*12 -> 0
B12: Mesa | D12: 1 | F12: =D12*E12 -> 0 | G12: =F12*12 -> 0
B13: Phoenix | D13: 2 | F13: =D13*E13 -> 0 | G13: =F13*12 -> 0
B14: Scottsdale | D14: 2 | F14: =D14*E14 -> 0 | G14: =F14*12 -> 0
B15: Tucson | D15: 2 | F15: =D15*E15 -> 0 | G15: =F15*12 -> 0
A16: CA | B16: (California) | C16: 0003
B17: Long Beach | D17: 7 | F17: =D17*E17 -> 0 | G17: =F17*12 -> 0
B18: Morgan Hill | D18: 3 | F18: =D18*E18 -> 0 | G18: =F18*12 -> 0
B19: Rocklin | D19: 1 | F19: =D19*E19 -> 0 | G19: =F19*12 -> 0
B20: Sacramento | D20: 4 | F20: =D20*E20 -> 0 | G20: =F20*12 -> 0
B21: San Bernadino | D21: 4 | F21: =D21*E21 -> 0 | G21: =F21*12 -> 0
B22: San Diego | D22: 9 | F22: =D22*E22 -> 0 | G22: =F22*12 -> 0
B23: San Francisco | D23: 2 | F23: =D23*E23 -> 0 | G23: =F23*12 -> 0
B24: Santa Ana | D24: 5 | F24: =D24*E24 -> 0 | G24: =F24*12 -> 0
A25: CO | B25: (Colorado) | C25: 0004
B26: Colorado Springs | D26: 12 | F26: =D26*E26 -> 0 | G26: =F26*12 -> 0
A27: CT | B27: (Connecticut) | C27: 0005
B28: Hartford | D28: 5 | F28: =D28*E28 -> 0 | G28: =F28*12 -> 0
A29: DE | B29: (Delaware) | C29: 0006
B30: Wilmington | D30: 1 | F30: =D30*E30 -> 0 | G30: =F30*12 -> 0
A31: FL | B31: (Florida) | C31: 0007
B32: Bradenton | D32: 1 | F32: =D32*E32 -> 0 | G32: =F32*12 -> 0
B33: Ft. Myers | D33: 2 | F33: =D33*E33 -> 0 | G33: =F33*12 -> 0
B34: Gainesville | D34: 3 | F34: =D34*E34 -> 0 | G34: =F34*12 -> 0
B35: Jacksonville | D35: 4 | F35: =D35*E35 -> 0 | G35: =F35*12 -> 0
B36: Miami | D36: 9 | F36: =D36*E36 -> 0 | G36: =F36*12 -> 0
B37: Niceville | D37: 1 | F37: =D37*E37 -> 0 | G37: =F37*12 -> 0
B38: Orlando | D38: 4 | F38: =D38*E38 -> 0 | G38: =F38*12 -> 0
B39: Sarasota | D39: 1 | F39: =D39*E39 -> 0 | G39: =F39*12 -> 0
B40: Tampa | D40: 5 | F40: =D40*E40 -> 0 | G40: =F40*12 -> 0
...

Sheet State Totals
C3: State | D3: Monthly Total | E3: Yearly Total
C4: AL | D4: =SUM('Pricing Spreadsheet'!F5:F6) -> 0 | E4: =D4*12 -> 0
C5: AZ | D5: =SUM('Pricing Spreadsheet'!F8:F15) -> 0 | E5: =D5*12 -> 0
C6: CA | D6: =SUM('Pricing Spreadsheet'!F17:F24) -> 0 | E6: =D6*12 -> 0
C7: CO | D7: =SUM('Pricing Spreadsheet'!F26) -> 0 | E7: =D7*12 -> 0
C8: CT | D8: =SUM('Pricing Spreadsheet'!F28) -> 0 | E8: =D8*12 -> 0
C9: DE | D9: =SUM('Pricing Spreadsheet'!F30) -> 0 | E9: =D9*12 -> 0
C10: FL | D10: =SUM('Pricing Spreadsheet'!F32:F41) -> 0 | E10: =D10*12 -> 0
C11: GA | D11: =SUM('Pricing Spreadsheet'!F43:F45) -> 0 | E11: =D11*12 -> 0
C12: HI | D12: =SUM('Pricing Spreadsheet'!F47) -> 0 | E12: =D12*12 -> 0
C13: IL | D13: =SUM('Pricing Spreadsheet'!F49:F50) -> 0 | E13: =D13*12 -> 0
C14: IN | D14: =SUM('Pricing Spreadsheet'!F52) -> 0 | E14: =D14*12 -> 0
C15: KS | D15: =SUM('Pricing Spreadsheet'!F54:F55) -> 0 | E15: =D15*12 -> 0
C16: KY | D16: =SUM('Pricing Spreadsheet'!F57) -> 0 | E16: =D16*12 -> 0
C17: LA | D17: =SUM('Pricing Spreadsheet'!F59) -> 0 | E17: =D17*12 -> 0
C18: MA | D18: =SUM('Pricing Spreadsheet'!F61:F62) -> 0 | E18: =D18*12 -> 0
C19: MD | D19: =SUM('Pricing Spreadsheet'!F64:F65) -> 0 | E19: =D19*12 -> 0
C20: ME | D20: =SUM('Pricing Spreadsheet'!F67:F69) -> 0 | E20: =D20*12 -> 0
C21: MI | D21: =SUM('Pricing Spreadsheet'!F71) -> 0 | E21: =D21*12 -> 0
C22: MN | D22: =SUM('Pricing Spreadsheet'!F73) -> 0 | E22: =D22*12 -> 0
C23: MO | D23: =SUM('Pricing Spreadsheet'!F75:F76) -> 0 | E23: =D23*12 -> 0
C24: MS | D24: =SUM('Pricing Spreadsheet'!F78:F79) -> 0 | E24: =D24*12 -> 0
C25: MT | D25: =SUM('Pricing Spreadsheet'!F81) -> 0 | E25: =D25*12 -> 0
C26: NC | D26: =SUM('Pricing Spreadsheet'!F83:F85) -> 0 | E26: =D26*12 -> 0
C27: NE | D27: =SUM('Pricing Spreadsheet'!F87) -> 0 | E27: =D27*12 -> 0
C28: NH | D28: =SUM('Pricing Spreadsheet'!F89) -> 0 | E28: =D28*12 -> 0
C29: NJ | D29: =SUM('Pricing Spreadsheet'!F91:F92) -> 0 | E29: =D29*12 -> 0
C30: NY | D30: =SUM('Pricing Spreadsheet'!F94) -> 0 | E30: =D30*12 -> 0
C31: OH | D31: =SUM('Pricing Spreadsheet'!F96:F97) -> 0 | E31: =D31*12 -> 0
C32: OR | D32: =SUM('Pricing Spreadsheet'!F99:F100) -> 0 | E32: =D32*12 -> 0
C33: PA | D33: =SUM('Pricing Spreadsheet'!F102:F103) -> 0 | E33: =D33*12 -> 0
C34: PR | D34: =SUM('Pricing Spreadsheet'!F105) -> 0 | E34: =D34*12 -> 0
C35: RI | D35: =SUM('Pricing Spreadsheet'!F107) -> 0 | E35: =D35*12 -> 0
C36: SC | D36: =SUM('Pricing Spreadsheet'!F109:F110) -> 0 | E36: =D36*12 -> 0
C37: SD | D37: =SUM('Pricing Spreadsheet'!F112:F113) -> 0 | E37: =D37*12 -> 0
C38: TN | D38: =SUM('Pricing Spreadsheet'!F115:F116) -> 0 | E38: =D38*12 -> 0
C39: TX | D39: =SUM('Pricing Spreadsheet'!F118:F122) -> 0 | E39: =D39*12 -> 0
C40: UT | D40: =SUM('Pricing Spreadsheet'!F124) -> 0 | E40: =D40*12 -> 0
C41: VA | D41: =SUM('Pricing Spreadsheet'!F126:F127) -> 0 | E41: =D41*12 -> 0
C42: VT | D42: =SUM('Pricing Spreadsheet'!F129:F130) -> 0 | E42: =D42*12 -> 0
...
