Workbook

Sheet Summary
B1: HE125426QE045 - Attachment 5: Price
B2: DoWEA Pacific East District - Japan Military Community
B3: Mainland, Japan Bus Safety Attendant and Safety Aides
B4: Base Period and Options
B5: Mainland Japan Bus Safety Attendant/ Safety Aides | C5: Estimated Price
B6: Base Year | C6: ='Japan Safety AA'!F28 -> 0
B7: Option Year 1 | C7: ='Japan Safety AA'!F53 -> 0
B8: Option Year 2 | C8: ='Japan Safety AA'!F78 -> 0
B9: Option Year 3 | C9: ='Japan Safety AA'!F103 -> 0
B10: Option Year 4 | C10: ='Japan Safety AA'!F128 -> 0
B11: Total Estimated Amounts (Base - Option Year 4) | C11: =SUM(C6:C10) -> 0
B12: FAR 52.217-8 | C12: ='Japan Safety AA'!F147 -> 0
B13: Overall Estimated Amount | C13: =SUM(C11,C12) -> 0

Sheet Japan Safety AA
A1: HE125426QE045 - Attachment 5: Price | H1: Note for Base and Option Years UNIT PRICES (U/Ps): Due to potential rounding/calculation errors, do not submit U/Ps with formula (i.e. escalation) in the U/P cells. To deconflict possible errors, the U/Ps specified will be evaluated based on their face value. For example, if a U/P is YEN1.20, then the face value of YEN1.20 will be used, so the evaluated Total Cost might differ from the Offeror's stated Total Cost.
A2: DoWEA Pacific East District - Mainland Japan Military Community
A3: Mainland, Japan Bus Safety Attendant and Safety Aides
A4: Base Period and Options
A5: PAC East SA/A | C5: Base Year SY 2026 - 2027
A6: CLIN/SLIN | B6: Description | C6: Unit of Issue | D6: Estimated Quantity | E6: Unit Price | F6: Estimated Amounts
A7: 0001 | B7: PAC East Safety Attendant
A8: 0001AA | B8: Iwakuni Safety Attendant | C8: Runs | D8: 3600 | E8: 0 | F8: =D8*E8 -> 0
A9: 0001AB | B9: Misawa Safety Attendant | C9: Runs | D9: 3600 | E9: 0 | F9: =D9*E9 -> 0
A10: 0001AC | B10: Sasebo Safety Attendant | C10: Runs | D10: 5400 | E10: 0 | F10: =D10*E10 -> 0
A11: 0001AD | B11: Yokosuka Safety Attendant | C11: Runs | D11: 8280 | E11: 0 | F11: =D11*E11 -> 0
A12: 0001AE | B12: Yokota Safety Attendant | C12: Runs | D12: 6120 | E12: 0 | F12: =D12*E12 -> 0
A13: 0001AF | B13: Zama/Atsugi Safety Attendant | C13: Runs | D13: 6120 | E13: 0 | F13: =D13*E13 -> 0
A14: 0002 | B14: PAC East Safety Aide
A15: 0002AA | B15: Iwakuni Safety Aide | C15: Runs | D15: 540 | E15: 0 | F15: =D15*E15 -> 0
A16: 0002AB | B16: Misawa Safety Aide | C16: Runs | D16: 540 | E16: 0 | F16: =D16*E16 -> 0
A17: 0002AC | B17: Sasebo Safety Aide | C17: Runs | D17: 540 | E17: 0 | F17: =D17*E17 -> 0 | H17: Workload Data
A18: 0002AD | B18: Yokosuka Safety Aide | C18: Runs | D18: 1620 | E18: 0 | F18: =D18*E18 -> 0 | H18: PAC East Safety Attendant | L18: # Routes | M18: # Routes | N18: # Runs/day | O18: # School Days | P18: Total Run
A19: 0002AE | B19: Yokota Safety Aide | C19: Runs | D19: 540 | E19: 0 | F19: =D19*E19 -> 0 | H19: Iwakuni Safety Attendant | I19: Run | J19: 3600 | L19: 10 | M19: 10 | N19: 2 | O19: 180 | P19: =L19*N19*O19 -> 3600
A20: 0002AF | B20: Zama/Atsugi Safety Aide | C20: Runs | D20: 1620 | E20: 0 | F20: =D20*E20 -> 0 | H20: Misawa Safety Attendant | I20: Run | J20: 3600 | L20: 10 | M20: 10 | N20: 2 | O20: 180 | P20: =L20*N20*O20 -> 3600
A21: 0003 | B21: PAC East ESY Safety Aide | H21: Sasebo Safety Attendant | I21: Run | J21: 5400 | L21: 15 | M21: 15 | N21: 2 | O21: 180 | P21: =L21*N21*O21 -> 5400
A22: 0003AA | B22: Iwakuni ESY Safety Aide | C22: Runs | D22: 40 | E22: 0 | F22: =D22*E22 -> 0 | H22: Yokosuka Safety Attendant | I22: Run | J22: 8280 | L22: 23 | M22: 23 | N22: 2 | O22: 180 | P22: =L22*N22*O22 -> 8280
A23: 0003AB | B23: Misawa ESY Safety Aide | C23: Runs | D23: 40 | E23: 0 | F23: =D23*E23 -> 0 | H23: Yokota Safety Attendant | I23: Run | J23: 6120 | L23: 17 | M23: 17 | N23: 2 | O23: 180 | P23: =L23*N23*O23 -> 6120
A24: 0003AC | B24: Sasebo ESY Safety Aide | C24: Runs | D24: 40 | E24: 0 | F24: =D24*E24 -> 0 | H24: Zama/Atsugi Safety Attendant | I24: Run | J24: 6120 | L24: 17 | M24: 17 | N24: 2 | O24: 180 | P24: =L24*N24*O24 -> 6120
A25: 0003AD | B25: Yokosuka ESY Safety Aide | C25: Runs | D25: 80 | E25: 0 | F25: =D25*E25 -> 0 | H25: PAC East Safety Aide
A26: 0003AE | B26: Yokota ESY Safety Aide | C26: Runs | D26: 40 | E26: 0 | F26: =D26*E26 -> 0 | H26: Iwakuni Safety Aide | I26: Run | J26: 540 | L26: 1 | M26: 1 | N26: 3 | O26: 180 | P26: =L26*N26*O26 -> 540
A27: 0003AF | B27: Zama/Atsugi ESY Safety Aide | C27: Runs | D27: 40 | E27: 0 | F27: =D27*E27 -> 0 | H27: Misawa Safety Aide | I27: Run | J27: 540 | L27: 1 | M27: 1 | N27: 3 | O27: 180 | P27: =L27*N27*O27 -> 540
A28: BASE YEAR TOTAL | F28: =SUM(F8:F27) -> 0 | H28: Sasebo Safety Aide | I28: Run | J28: 540 | L28: 1 | M28: 1 | N28: 3 | O28: 180 | P28: =L28*N28*O28 -> 540
H29: Yokosuka Safety Aide | I29: Run | J29: 1620 | L29: 3 | M29: 3 | N29: 3 | O29: 180 | P29: =L29*N29*O29 -> 1620
A30: PAC East SA/A | C30: Option Year 1 SY 2027 - 2028 | H30: Yokota Safety Aide | I30: Run | J30: 540 | L30: 1 | M30: 1 | N30: 3 | O30: 180 | P30: =L30*N30*O30 -> 540
A31: CLIN/SLIN | B31: Description | C31: Unit of Issue | D31: Estimated Quantity | E31: Unit Price | F31: Estimated Amounts | H31: Zama/Atsugi Safety Aide | I31: Run | J31: 1620 | L31: 3 | M31: 3 | N31: 3 | O31: 180 | P31: =L31*N31*O31 -> 1620
A32: 1001 | B32: PAC East Safety Attendant | H32: PAC East ESY Safety Aide
A33: 1001AA | B33: Iwakuni Safety Attendant | C33: Runs | D33: 3600 | E33: 0 | F33: =D33*E33 -> 0 | H33: Iwakuni ESY Safety Aide | I33: Run | J33: 40 | L33: 1 | M33: 1 | N33: 2 | O33: 20 | P33: =L33*N33*O33 -> 40
A34: 1001AB | B34: Misawa Safety Attendant | C34: Runs | D34: 3600 | E34: 0 | F34: =D34*E34 -> 0 | H34: Misawa ESY Safety Aide | I34: Run | J34: 40 | L34: 1 | M34: 1 | N34: 2 | O34: 20 | P34: =L34*N34*O34 -> 40
A35: 1001AC | B35: Sasebo Safety Attendant | C35: Runs | D35: 5400 | E35: 0 | F35: =D35*E35 -> 0 | H35: Sasebo ESY Safety Aide | I35: Run | J35: 40 | L35: 1 | M35: 1 | N35: 2 | O35: 20 | P35: =L35*N35*O35 -> 40
A36: 1001AD | B36: Yokosuka Safety Attendant | C36: Runs | D36: 8280 | E36: 0 | F36: =D36*E36 -> 0 | H36: Yokosuka ESY Safety Aide | I36: Run | J36: 80 | L36: 2 | M36: 2 | N36: 2 | O36: 20 | P36: =L36*N36*O36 -> 80
A37: 1001AE | B37: Yokota Safety Attendant | C37: Runs | D37: 6120 | E37: 0 | F37: =D37*E37 -> 0 | H37: Yokota ESY Safety Aide | I37: Run | J37: 40 | L37: 1 | M37: 1 | N37: 2 | O37: 20 | P37: =L37*N37*O37 -> 40
A38: 1001AF | B38: Zama/Atsugi Safety Attendant | C38: Runs | D38: 6120 | E38: 0 | F38: =D38*E38 -> 0 | H38: Zama/Atsugi ESY Safety Aide | I38: Run | J38: 40 | L38: 1 | M38: 1 | N38: 2 | O38: 20 | P38: =L38*N38*O38 -> 40
A39: 1002 | B39: PAC East Safety Aide
A40: 1002AA | B40: Iwakuni Safety Aide | C40: Runs | D40: 540 | E40: 0 | F40: =D40*E40 -> 0
...
