Workbook

Sheet CLINS
A1: Bid Schedule 2 Day Per Week
A2: Armed Forces Recruiting Center Janitorial Services
A3: Furnish all labor, equipment, materials, supplies, management, and supervision to accomplish Janitorial Cleaning Services at the Armed Forces Recruiting Center in accordance with attached Performance Work Statement and Requirements Summary specifications.
A4: Base Period of Performance: Date of award and 12 months following
A5: ITEM | B5: DESCRIPTION | C5: QUANTITY | D5: UNIT | E5: UNIT PRICE | F5: AMOUNT
A6: 0001 | B6: Beeville | C6: 1 | D6: JOB | F6: =BEEVILLE!F26 -> 0
A7: Option Period 1 Total: | B7: Total | C7: Base | F7: =SUM(F6:F6) -> 0
A9: 1001 Option 1 Period of Performance: 12 months following base year
A10: ITEM | B10: DESCRIPTION | C10: QUANTITY | D10: UNIT | E10: UNIT PRICE | F10: AMOUNT
A11: 1001 | B11: Beeville | C11: 1 | D11: JOB | F11: =BEEVILLE!F50 -> 0
A12: Option Period 1 Total: | F12: =SUM(F11:F11) -> 0
A14: 2001 Option 2 Period of Performance: 12 months following option 1
A15: ITEM | B15: DESCRIPTION | C15: QUANTITY | D15: UNIT | E15: UNIT PRICE | F15: AMOUNT
A16: 2001 | B16: Beeville | C16: 1 | D16: JOB | F16: =BEEVILLE!F74 -> 0
A17: Option Period 2 Total: | F17: =SUM(F16:F16) -> 0
A19: 3001 Option 3 Period of Performance: 12 months following option 2
A20: ITEM | B20: DESCRIPTION | C20: QUANTITY | D20: UNIT | E20: UNIT PRICE | F20: AMOUNT
A21: 3001 | B21: Beeville | C21: 1 | D21: JOB | F21: =BEEVILLE!F98 -> 0
A22: Option Period 3 Total: | F22: =SUM(F21:F21) -> 0
A24: 4001 Option 4 Period of Performance: 12 months following option 3
A25: ITEM | B25: DESCRIPTION | C25: QUANTITY | D25: UNIT | E25: UNIT PRICE | F25: AMOUNT
A26: 4001 | B26: Beeville | C26: 1 | D26: JOB | F26: =BEEVILLE!F122 -> 0
A27: Option Period 4 Total: | F27: =SUM(F26:F26) -> 0
A29: TOTAL AMOUNT: (Base and Option Period) | F29: =F7+F27+F22+F17+F12 -> 0

Sheet BEEVILLE
A1: Bid Schedule 2 Day Per Week
A2: Armed Forces Recruiting Center Janitorial Services - BEEVILLE, TX
A3: Furnish all labor, equipment, materials, supplies, management, and supervision to accomplish Janitorial Cleaning Services at the Armed Forces Recruiting Center in accordance with attached Performance Work Statement and Requirements Summary specifications. **EACH = Per Year (2 Each = twice a year)
A4: 0001 Base Period of Performance: Date of award and 12 months following
A5: ITEM | B5: DESCRIPTION | C5: QUANTITY | D5: UNIT | E5: UNIT PRICE | F5: AMOUNT
A6: Base Services | C6: 1500 | D6: SF | E6: 0 | F6: =C6*E6 -> 0
B7: Floor Maintenance (Vacuum & Sweep/Mop) | C7: 2 | D7: Weekly | E7: =F7/C7 -> 0 | F7: =F6*0.2 -> 0
B8: Trash Removal | C8: 2 | D8: Weekly | E8: =F8/C8 -> 0 | F8: =F6*0.2 -> 0
B9: Drinking Fountains | C9: 2 | D9: Weekly | E9: =F9/C9 -> 0 | F9: =F6*0.2 -> 0
B10: Spot Cleaning Windows | C10: 2 | D10: Weekly | E10: =F10/C10 -> 0 | F10: =F6*0.2 -> 0
B11: Restroom Services | C11: 2 | D11: Weekly | E11: =F11/C11 -> 0 | F11: =F6*0.2 -> 0
A12: Periodic Services | C12: 1500 | D12: SF | E12: 0 | F12: =C12*E12 -> 0
B13: Professional Ceramic and Carpet Tile Floor Cleaning | C13: 2 | D13: Each | E13: =F13/C13 -> 0 | F13: =F12*0.31 -> 0
B14: Dusting | C14: 1 | D14: Monthly | E14: =F14/C14 -> 0 | F14: =F12*0.09 -> 0
B15: High Dusting/Cleaning | C15: 1 | D15: Each | E15: =F15/C15 -> 0 | F15: =F12*0.09 -> 0
B16: Clean Light Fixtures | C16: 1 | D16: Each | E16: =F16/C16 -> 0 | F16: =F12*0.09 -> 0
B17: Exterior Glass Surfaces | C17: 1 | D17: Monthly | E17: =F17/C17 -> 0 | F17: =F12*0.09 -> 0
B18: Interior Glass Surfaces | C18: 1 | D18: Monthly | E18: =F18/C18 -> 0 | F18: =F12*0.09 -> 0
B19: Clean HVAC Return, Diffuser and Grilles | C19: 4 | D19: Each | E19: =F19/C19 -> 0 | F19: =F12*0.15 -> 0
B20: De-Scale Toilet bowls and Urinals | C20: 1 | D20: Monthly | E20: =F20/C20 -> 0 | F20: =F12*0.09 -> 0
A21: Other Services | C21: 1500 | E21: 0 | F21: =C21*E21 -> 0
B22: Re-Lamping (estimated 10 bulbs per year) | C22: 10 | D22: Each | E22: =F22/C22 -> 0 | F22: =F21*0.6 -> 0
B23: Change HVAC Filters | C23: 1 | D23: Monthly | E23: =F23/C23 -> 0 | F23: =F21*0.1 -> 0
B24: Pest Control | C24: 2 | D24: Each | E24: =F24/C24 -> 0 | F24: =F21*0.3 -> 0
B25: CONTRACT MANPOWER REPORTING | C25: 1 | D25: Each | F25: 0
A26: Base Year Total: | F26: =F6+F12+F21 -> 0
A28: 1001 Option 1 Period of Performance: 12 months following base year
A29: ITEM | B29: DESCRIPTION | C29: QUANTITY | D29: UNIT | E29: UNIT PRICE | F29: AMOUNT
A30: Base Services | C30: 1500 | D30: SF | F30: =F6*1.05 -> 0
B31: Floor Maintenance (Vacuum & Sweep/Mop) | C31: 2 | D31: Weekly | E31: =F31/C31 -> 0 | F31: =$F$30*0.2 -> 0
B32: Trash Removal | C32: 2 | D32: Weekly | E32: =F32/C32 -> 0 | F32: =$F$30*0.2 -> 0
B33: Drinking Fountains | C33: 2 | D33: Weekly | E33: =F33/C33 -> 0 | F33: =$F$30*0.2 -> 0
B34: Spot Cleaning Windows | C34: 2 | D34: Weekly | E34: =F34/C34 -> 0 | F34: =$F$30*0.2 -> 0
B35: Restroom Services | C35: 2 | D35: Weekly | E35: =F35/C35 -> 0 | F35: =$F$30*0.2 -> 0
A36: Periodic Services | C36: 1500 | D36: SF | F36: =F12*1.05 -> 0
B37: Professional Ceramic and Carpet Tile Floor Cleaning | C37: 2 | D37: Each | E37: =F37/C37 -> 0 | F37: =F36*0.31 -> 0
B38: Dusting | C38: 1 | D38: Monthly | E38: =F38/C38 -> 0 | F38: =$F$36*0.09 -> 0
B39: High Dusting/Cleaning | C39: 1 | D39: Each | E39: =F39/C39 -> 0 | F39: =$F$36*0.09 -> 0
B40: Clean Light Fixtures | C40: 1 | D40: Each | E40: =F40/C40 -> 0 | F40: =$F$36*0.09 -> 0
B41: Exterior Glass Surfaces | C41: 1 | D41: Monthly | E41: =F41/C41 -> 0 | F41: =$F$36*0.09 -> 0
...
