Workbook

Sheet INSTRUCTIONS
A1: INSTRUCTIONS TO OFFERORS
A3: General
A4: 1 | B4: The Prime Offeror shall complete this Government Format Pricing Model (GFPM).
A5: 2 | B5: All proposed direct labor rates shall be in line with justifying data (historical/incurred costs, salary survey, BLS OES etc.) for each identified locality.
A6: 3 | B6: Subcontractor offerors shall complete the subcontractor GFPM (GFPM-Subs).
A7: 3a | B7: The Government has included a separate subcontractor GFPM attachment (GFPM-Subs) for the prime offeror to provide each subcontractor. The subcontractor GFPM shall be utilized for each subcontractor to show its compliance with providing a full labor buildup, per labor category and to ensure compliance with the Government provided floor rates.
A8: 3b | B8: All subcontractors must provide the subcontractor GFPM (GFPM-Subs) to the prime offeror for submittal to the Government as part of its prime offeror proposal OR each subcontractor must submit this file directly to the Government.
A9: 3c | B9: To promote consistency between subcontractor files and prime offeror files, the Government has provided a "Sub - FBLR Summary" tab within the GFPM-Subs for the subcontractor to be able to more easily transfer its proposed FBLRs, for its provided labor categories, to the prime offeror for the prime offeror to include in its proposal.
A10: "Minimum Qualifications" Tab:
A11: 1 | B11: This tab is for offerors to certify that the provided employees meet or exceed the minimum education/experience requirements identified by the USG and to provide an offeror specific labor category name for each labor category identified in the SOW.
A12: 2 | B12: In Column F, a person legally authorized to bind the offeror shall enter their name for certification. This person is certifying that the offerors (prime & subcontractor) will provide personnel that meet the minimum qualifications in accordance with the SOW throughout the entire performance period of this effort. In Column G the same person shall enter the date of certification.
A13: "Totals" Tab
A14: 1 | B14: Offerors shall input offeror name into cell C2.
A15: 2 | B15: Offerors shall input its Phase-In FFP into cell C3.
A16: 3 | B16: The FAR 52.217-8 6-Month "Option to Extend Services" is automatically calculated by multiplying the total "Ordering Period 5" prices by 50.00%.
A17: 4 | B17: The total proposed price is calculated in cell F49.
A18: 5 | B18: The total evaluated price is equal to the total proposed price less DBA Insurance, and is calculated in cell F51.
A19: 6 | B19: In cell F60, Offerors shall input the amount that corresponds to the Offeror's proposed Small Business Participation Workbook (Attachment 00XX), Roll Up' tab, 'Total Contract Amount'
A20: 7 | B20: No other offeror input necessary, all totals will auto-populate from the "Ordering Period 1", "Ordering Period 2", "Ordering Period 3", "Ordering Period 4", "Ordering Period 5" tabs. The USG may utilize this tab while evaluating the Most Probable Cost to the Government.
A21: "Ordering Period 1", "Ordering Period 2", "Ordering Period 3", "Ordering Period 4", and "Ordering Period 5" Tabs
A22: 1 | B22: Offeror input is required in all applicable cells highlighted in yellow.
A23: 2 | B23: The "Ordering Period Labor Categories & Hours" (columns A - H) contain all of the performance locations and labor categories that the USG anticipates to be necessary for completion of this effort. The "Req. Hours" column (Column F) contains the total number of hours to be proposed for each of the USG identified labor categories. The hours may be allocated to the prime contractor and/or subcontractors. All Proposed (prime & subcontractor) labor hours must be equal to the total number of hours identified in the "Req. Hours" column.
A24: 2a | B24: In the "Prime Contractor CPFF Labor" table (columns J - W in the Ordering Period 1 and Ordering Period 4 tabs and columns J - U in the Ordering Period 2, Ordering Period 3, and Ordering Period 5 tabs), offerors shall input the proposed number of hours that will be completed by the prime contractor for each of the USG identified labor categories. Offerors are required to submit fully burdened labor rates for each of the USG identified labor categories (column T in the Ordering Period 1 and Ordering Period 4 tabs and column R in the Ordering Period 2, Ordering Period 3, and Ordering Period 5 tabs). Offerors shall insert all of the cost elements (direct labor, fringe benefit costs, labor overhead costs, general & administrative cost, fee etc.) that make up all of the fully burdened labor rates proposed for each of the USG identified labor categories (columns L - S in the Ordering Period 1 and Ordering Period 4 tabs and columns K - Q in the Ordering Period 2, Ordering Period 3, and Ordering Period 5 tabs). Columns U - W in the Ordering Period 1 and Ordering Period 4 tabs and columns S - U in the Ordering Period 2, Ordering Period 3, and Ordering Period 5 tabs automatically calculate based on the offeror's inputs.
A25: 2b | B25: Offerors shall insert direct labor rates in the Ordering Period 1 tab for the applicable labor categories (L5 - L19 and L36 - L43) and in the Ordering Period 4 tab for the applicable labor categories (L39 - L46). Note: Per section L of the RFP, the proposed direct labor must meet or exceed the USG floor rates referenced in the Ordering Period 1 tab (K5 - K43) and in the Ordering Period 4 tab (K39 - K46).
A26: 3 | B26: Subcontractor offerors shall submit a detailed cost build up for each proposed fully burdened labor rate utilizing Attachment 0016 (GFPM-Subs). Subcontractors may choose to submit the cost build up data as part of the prime contractor's cost submission or as a separate submission directly to the Government. If reconciliation differences exist between the prime contractor's pricing submission and the subcontractor cost build up spreadsheets, the Government will rely on the data entered into the prime contractor's Government format spreadsheets to make any reasonableness/realism determinations.
A27: 3a | B27: In the "Subcontractor Labor" table (columns Y - AM in the Ordering Period 1 and Ordering Period 4 tabs and columns W - AK in the Ordering Period 2, Ordering Period 3, and Ordering Period 5 tabs), offerors shall input the proposed number of hours that will be completed by the subcontractor for each of the USG identified labor categories. Offerors are required to submit fully burdened labor rates for each of the USG identified labor categories (column AG in the Ordering Period 1 and Ordering Period 4 tabs and column AE in the Ordering Period 2, Ordering Period 3, and Ordering Period 5 tabs). Offerors shall insert all of the cost elements (FBLRs, prime overhead costs, prime general & administrative cost, prime fee etc.) that make up all of the fully burdened labor rates proposed for each of the USG identified labor categories (columns Z - AF in the Ordering Period 1 and Ordering Period 4 tabs and columns X - AD in the Ordering Period 2, Ordering Period 3, and Ordering Period 5 tabs). Columns AH - AJ in the Ordering Period 1 and Ordering Period 4 tabs and Columns AF - AH in the Ordering Period 2, Ordering Period 3, and Ordering Period 5 tabs automatically calculate based on the offeror's inputs. If necessary, subcontractors may submit additional cost data in it's own format to further justify the proposed single elements of the subcontractor labor costs.
A28: 3b | B28: In column AK in the Ordering Period 1 and Ordering Period 4 tabs and AI in the Ordering Period 2, Ordering Period 3, and Ordering Period 5 tabs, the prime offeror shall enter the name of the subcontractor(s) proposed to complete the hours associated with each labor category. If the prime offeror proposes more than one subcontractor for a single labor category a single FBLR (inclusive of prime contractor indirect adders and fee) shall be proposed. The proposed FBLR (inclusive of prime contractor indirect adders and fee) shall be a blend of each subcontractor’s proposed FBLR. In column AL in the Ordering Period 1 and Ordering Period 4 tabs and AJ in the Ordering Period 2, Ordering Period 3, and Ordering Period 5 tabs the prime offeror shall indicate if the proposed subcontractor FBLR is a "blended" FBLR. In column AM in the Ordering Period 1 and Ordering Period 4 tabs and AK in the Ordering Period 2, Ordering Period 3, and Ordering Period 5 tabs the prime offeror shall enter the billing nomenclature for each of the subcontracted labor categories, all subcontracted labor categories shall be differentiated from prime labor categories.
A29: 4 | B29: Columns AO-AQ in the Ordering Period 1 and Ordering Period 4 tabs and Columns AM-AO in the Ordering Period 2, Ordering Period 3, and Ordering Period 5 tabs calculate a single composite fully burdened labor rate (prime and subcontractor) for each of the USG identified labor categories.
A30: 4a | B30: All values populate based on the offerors input in the "Prime Labor" and "Subcontractor Labor" tables. No offeror input is necessary.
A31: 5 | B31: The Travel/ODC Plug Figure in cell D58 in all Ordering Period tabs are pre-populated plug figures.
A32: 5a | B32: Offerors may input an indirect ceiling rate that may apply to the USG provided Plug Figure costs in cell C59 in all Ordering Period tabs. No fee shall be applied to the USG provided plug figures.
A33: 5b | B33: The total Travel/ODC amount will be the sum of the USG plug figures and proposed indirect costs. (Cell D61)
A34: 6 | B34: Offerors shall input its estimated DBA Insurance Amount in cell D64 in all Ordering Period tabs. No indirect expense or fee shall be applied to DBA Insurance. Note that the DBA Insurance Amount should include DBA costs for both the Prime and any applicable subcontractor.
... A37: 8 | B37: The Fringe Benefit, Labor OH, G&A, and FCCOM columns are unlocked and editable.
A38: "Escalation" Tab
A39: 1 | B39: This tab provides the data for the labor escalation rates which apply to all option periods of performance tabs.
A40: 2 | B40: Per section L, for evaluation purposes only, this solicitation has set a minimum escalation for each period of performance. Offerors may choose to increase this rate in column C of the escalation tab, but shall not propose an escalation rate which is below the USG minimum.
A41: "DBA Insurance" Tab
A42: 1 | B42: Offerors may use this tab to demonstrate how the estimated DBA Insurance amount was calculated.
A43: "Composite Labor Rates" Tab
...

Sheet Minimum Qualifications
A1: Service | B1: ID | C1: Labor Category | D1: Offeror Labor Category | E1: Location | F1: Offeror Certification | G1: Date of Certification
A2: Program Management | B2: =Totals!B6 -> 001 | C2: =Totals!C6 -> Project Management Specialist | E2: =Totals!D6 -> CONUS
A3: Field Service Representative (FSR) | B3: =Totals!B7 -> 002 | C3: =Totals!C7 -> Field Service Representative | E3: =Totals!D7 -> CONUS
A4: General Maintenance | B4: =Totals!B8 -> 003 | C4: =Totals!C8 -> Heavy Equipment Mechanic | E4: =Totals!D8 -> CONUS
A5: Modified Work Orders (MWO) | B5: =Totals!B9 -> 004 | C5: =Totals!C9 -> Field Service Representative | E5: =Totals!D9 -> CONUS
B6: =Totals!B10 -> 005 | C6: =Totals!C10 -> Modified Work Orders (MWO) | E6: =Totals!D10 -> CONUS
B7: =Totals!B11 -> 006 | C7: =Totals!C11 -> Quality Assurance | E7: =Totals!D11 -> CONUS
B8: =Totals!B12 -> 007 | C8: =Totals!C12 -> Software | E8: =Totals!D12 -> CONUS
B9: =Totals!B13 -> 008 | C9: =Totals!C13 -> Welder | E9: =Totals!D13 -> CONUS
A10: New Equipment Training (NET) | B10: =Totals!B14 -> 009 | C10: =Totals!C14 -> Instructor Supervisor | E10: =Totals!D14 -> CONUS
B11: =Totals!B15 -> 010 | C11: =Totals!C15 -> Instructor | E11: =Totals!D15 -> CONUS
A12: Total Package Fielding (TPF) and De-processing | B12: =Totals!B16 -> 011 | C12: =Totals!C16 -> Heavy Equipment Mechanic | E12: =Totals!D16 -> CONUS
B13: =Totals!B17 -> 012 | C13: =Totals!C17 -> Material Handling Specialist | E13: =Totals!D17 -> CONUS
B14: =Totals!B18 -> 013 | C14: =Totals!C18 -> Quality Assurance | E14: =Totals!D18 -> CONUS
B15: =Totals!B19 -> 014 | C15: =Totals!C19 -> Supply/Procurement Specialist | E15: =Totals!D19 -> CONUS
B16: =Totals!B20 -> 015 | C16: =Totals!C20 -> Welder | E16: =Totals!D20 -> CONUS
A17: Field Service Representative (FSR) | B17: =Totals!B21 -> 016 | C17: =Totals!C21 -> Field Service Representative | E17: =Totals!D21 -> OCONUS
A18: General Maintenance | B18: =Totals!B22 -> 017 | C18: =Totals!C22 -> Heavy Equipment Mechanic | E18: =Totals!D22 -> OCONUS
A19: New Equipment Training (NET) | B19: =Totals!B23 -> 018 | C19: =Totals!C23 -> Instructor Supervisor | E19: =Totals!D23 -> OCONUS
B20: =Totals!B24 -> 019 | C20: =Totals!C24 -> Instructor | E20: =Totals!D24 -> OCONUS
A21: Total Package Fielding (TPF) and De-processing | B21: =Totals!B25 -> 020 | C21: =Totals!C25 -> Heavy Equipment Mechanic | E21: =Totals!D25 -> OCONUS
B22: =Totals!B26 -> 021 | C22: =Totals!C26 -> Material Handling Specialist | E22: =Totals!D26 -> OCONUS
B23: =Totals!B27 -> 022 | C23: =Totals!C27 -> Quality Assurance | E23: =Totals!D27 -> OCONUS
B24: =Totals!B28 -> 023 | C24: =Totals!C28 -> Supply/Procurement Specialist | E24: =Totals!D28 -> OCONUS
A25: Field Service Representative (FSR) | B25: =Totals!B29 -> 024 | C25: =Totals!C29 -> Field Service Representative | E25: =Totals!D29 -> OCONUS - IRAQ
A26: General Maintenance | B26: =Totals!B30 -> 025 | C26: =Totals!C30 -> Heavy Equipment Mechanic | E26: =Totals!D30 -> OCONUS - IRAQ
A27: New Equipment Training (NET) | B27: =Totals!B31 -> 026 | C27: =Totals!C31 -> Instructor Supervisor | E27: =Totals!D31 -> OCONUS - IRAQ
B28: =Totals!B32 -> 027 | C28: =Totals!C32 -> Instructor | E28: =Totals!D32 -> OCONUS - IRAQ
A29: Total Package Fielding (TPF) and De-processing | B29: =Totals!B33 -> 028 | C29: =Totals!C33 -> Heavy Equipment Mechanic | E29: =Totals!D33 -> OCONUS - IRAQ
B30: =Totals!B34 -> 029 | C30: =Totals!C34 -> Material Handling Specialist | E30: =Totals!D34 -> OCONUS - IRAQ
B31: =Totals!B35 -> 030 | C31: =Totals!C35 -> Quality Assurance | E31: =Totals!D35 -> OCONUS - IRAQ
B32: =Totals!B36 -> 031 | C32: =Totals!C36 -> Supply/Procurement Specialist | E32: =Totals!D36 -> OCONUS - IRAQ

Sheet Totals
A2: OFFEROR NAME:
A3: PHASE-IN (FFP):
F4: Total Proposed Price
A5: Service | B5: ID | C5: Required Labor - Labor Category | D5: Location | F5: Ordering Period 1 | H5: Ordering Period 2 | J5: Ordering Period 3 | L5: Ordering Period 4 | N5: Ordering Period 5 | O5: FAR 52.217-8 Option
A6: Program Management | B6: 001 | C6: Project Management Specialist | D6: CONUS | F6: ='Ordering Period 1'!W5+'Ordering Period 1'!AJ5 -> 0 | H6: ='Ordering Period 2'!U5+'Ordering Period 2'!AH5 -> 0 | J6: ='Ordering Period 3'!U5+'Ordering Period 3'!AH5 -> 0 | L6: ='Ordering Period 4'!W5+'Ordering Period 4'!AJ5 -> 0 | N6: ='Ordering Period 5'!U5+'Ordering Period 5'!AH5 -> 0 | O6: =ROUND(N6*0.5,0) -> 0
A7: Field Service Representative (FSR) | B7: 002 | C7: Field Service Representative | D7: CONUS | F7: ='Ordering Period 1'!W6+'Ordering Period 1'!W21+'Ordering Period 1'!AJ6+'Ordering Period 1'!AJ21 -> 0 | H7: ='Ordering Period 2'!U6+'Ordering Period 2'!U21+'Ordering Period 2'!AH6+'Ordering Period 2'!AH21 -> 0 | J7: ='Ordering Period 3'!U6+'Ordering Period 3'!U21+'Ordering Period 3'!AH6+'Ordering Period 3'!AH21 -> 0 | L7: ='Ordering Period 4'!W6+'Ordering Period 4'!W21+'Ordering Period 4'!AJ6+'Ordering Period 4'!AJ21 -> 0 | N7: ='Ordering Period 5'!U6+'Ordering Period 5'!U21+'Ordering Period 5'!AH6+'Ordering Period 5'!AH21 -> 0 | O7: =ROUND(N7*0.5,0) -> 0
A8: General Maintenance | B8: 003 | C8: Heavy Equipment Mechanic | D8: CONUS | F8: ='Ordering Period 1'!W7+'Ordering Period 1'!W22+'Ordering Period 1'!AJ7+'Ordering Period 1'!AJ22 -> 0 | H8: ='Ordering Period 2'!U7+'Ordering Period 2'!U22+'Ordering Period 2'!AH7+'Ordering Period 2'!AH22 -> 0 | J8: ='Ordering Period 3'!U7+'Ordering Period 3'!U22+'Ordering Period 3'!AH7+'Ordering Period 3'!AH22 -> 0 | L8: ='Ordering Period 4'!W7+'Ordering Period 4'!W22+'Ordering Period 4'!AJ7+'Ordering Period 4'!AJ22 -> 0 | N8: ='Ordering Period 5'!U7+'Ordering Period 5'!U22+'Ordering Period 5'!AH7+'Ordering Period 5'!AH22 -> 0 | O8: =ROUND(N8*0.5,0) -> 0
A9: Modified Work Orders (MWO) | B9: 004 | C9: Field Service Representative | D9: CONUS | F9: ='Ordering Period 1'!W8+'Ordering Period 1'!W23+'Ordering Period 1'!AJ8+'Ordering Period 1'!AJ23 -> 0 | H9: ='Ordering Period 2'!U8+'Ordering Period 2'!U23+'Ordering Period 2'!AH8+'Ordering Period 2'!AH23 -> 0 | J9: ='Ordering Period 3'!U8+'Ordering Period 3'!U23+'Ordering Period 3'!AH8+'Ordering Period 3'!AH23 -> 0 | L9: ='Ordering Period 4'!W8+'Ordering Period 4'!W23+'Ordering Period 4'!AJ8+'Ordering Period 4'!AJ23 -> 0 | N9: ='Ordering Period 5'!U8+'Ordering Period 5'!U23+'Ordering Period 5'!AH8+'Ordering Period 5'!AH23 -> 0 | O9: =ROUND(N9*0.5,0) -> 0
B10: 005 | C10: Modified Work Orders (MWO) | D10: CONUS | F10: ='Ordering Period 1'!W9+'Ordering Period 1'!W24+'Ordering Period 1'!AJ9+'Ordering Period 1'!AJ24 -> 0 | H10: ='Ordering Period 2'!U9+'Ordering Period 2'!U24+'Ordering Period 2'!AH9+'Ordering Period 2'!AH24 -> 0 | J10: ='Ordering Period 3'!U9+'Ordering Period 3'!U24+'Ordering Period 3'!AH9+'Ordering Period 3'!AH24 -> 0 | L10: ='Ordering Period 4'!W9+'Ordering Period 4'!W24+'Ordering Period 4'!AJ9+'Ordering Period 4'!AJ24 -> 0 | N10: ='Ordering Period 5'!U9+'Ordering Period 5'!U24+'Ordering Period 5'!AH9+'Ordering Period 5'!AH24 -> 0 | O10: =ROUND(N10*0.5,0) -> 0
B11: 006 | C11: Quality Assurance | D11: CONUS | F11: ='Ordering Period 1'!W10+'Ordering Period 1'!W25+'Ordering Period 1'!AJ10+'Ordering Period 1'!AJ25 -> 0 | H11: ='Ordering Period 2'!U10+'Ordering Period 2'!U25+'Ordering Period 2'!AH10+'Ordering Period 2'!AH25 -> 0 | J11: ='Ordering Period 3'!U10+'Ordering Period 3'!U25+'Ordering Period 3'!AH10+'Ordering Period 3'!AH25 -> 0 | L11: ='Ordering Period 4'!W10+'Ordering Period 4'!W25+'Ordering Period 4'!AJ10+'Ordering Period 4'!AJ25 -> 0 | N11: ='Ordering Period 5'!U10+'Ordering Period 5'!U25+'Ordering Period 5'!AH10+'Ordering Period 5'!AH25 -> 0 | O11: =ROUND(N11*0.5,0) -> 0
B12: 007 | C12: Software | D12: CONUS | F12: ='Ordering Period 1'!W11+'Ordering Period 1'!W26+'Ordering Period 1'!AJ11+'Ordering Period 1'!AJ26 -> 0 | H12: ='Ordering Period 2'!U11+'Ordering Period 2'!U26+'Ordering Period 2'!AH11+'Ordering Period 2'!AH26 -> 0 | J12: ='Ordering Period 3'!U11+'Ordering Period 3'!U26+'Ordering Period 3'!AH11+'Ordering Period 3'!AH26 -> 0 | L12: ='Ordering Period 4'!W11+'Ordering Period 4'!W26+'Ordering Period 4'!AJ11+'Ordering Period 4'!AJ26 -> 0 | N12: ='Ordering Period 5'!U11+'Ordering Period 5'!U26+'Ordering Period 5'!AH11+'Ordering Period 5'!AH26 -> 0 | O12: =ROUND(N12*0.5,0) -> 0
B13: 008 | C13: Welder | D13: CONUS | F13: ='Ordering Period 1'!W12+'Ordering Period 1'!W27+'Ordering Period 1'!AJ12+'Ordering Period 1'!AJ27 -> 0 | H13: ='Ordering Period 2'!U12+'Ordering Period 2'!U27+'Ordering Period 2'!AH12+'Ordering Period 2'!AH27 -> 0 | J13: ='Ordering Period 3'!U12+'Ordering Period 3'!U27+'Ordering Period 3'!AH12+'Ordering Period 3'!AH27 -> 0 | L13: ='Ordering Period 4'!W12+'Ordering Period 4'!W27+'Ordering Period 4'!AJ12+'Ordering Period 4'!AJ27 -> 0 | N13: ='Ordering Period 5'!U12+'Ordering Period 5'!U27+'Ordering Period 5'!AH12+'Ordering Period 5'!AH27 -> 0 | O13: =ROUND(N13*0.5,0) -> 0
A14: New Equipment Training (NET) | B14: 009 | C14: Instructor Supervisor | D14: CONUS | F14: ='Ordering Period 1'!W13+'Ordering Period 1'!W28+'Ordering Period 1'!AJ13+'Ordering Period 1'!AJ28 -> 0 | H14: ='Ordering Period 2'!U13+'Ordering Period 2'!U28+'Ordering Period 2'!AH13+'Ordering Period 2'!AH28 -> 0 | J14: ='Ordering Period 3'!U13+'Ordering Period 3'!U28+'Ordering Period 3'!AH13+'Ordering Period 3'!AH28 -> 0 | L14: ='Ordering Period 4'!W13+'Ordering Period 4'!W28+'Ordering Period 4'!AJ13+'Ordering Period 4'!AJ28 -> 0 | N14: ='Ordering Period 5'!U13+'Ordering Period 5'!U28+'Ordering Period 5'!AH13+'Ordering Period 5'!AH28 -> 0 | O14: =ROUND(N14*0.5,0) -> 0
B15: 010 | C15: Instructor | D15: CONUS | F15: ='Ordering Period 1'!W14+'Ordering Period 1'!W29+'Ordering Period 1'!AJ14+'Ordering Period 1'!AJ29 -> 0 | H15: ='Ordering Period 2'!U14+'Ordering Period 2'!U29+'Ordering Period 2'!AH14+'Ordering Period 2'!AH29 -> 0 | J15: ='Ordering Period 3'!U14+'Ordering Period 3'!U29+'Ordering Period 3'!AH14+'Ordering Period 3'!AH29 -> 0 | L15: ='Ordering Period 4'!W14+'Ordering Period 4'!W29+'Ordering Period 4'!AJ14+'Ordering Period 4'!AJ29 -> 0 | N15: ='Ordering Period 5'!U14+'Ordering Period 5'!U29+'Ordering Period 5'!AH14+'Ordering Period 5'!AH29 -> 0 | O15: =ROUND(N15*0.5,0) -> 0
A16: Total Package Fielding (TPF) and De-processing | B16: 011 | C16: Heavy Equipment Mechanic | D16: CONUS | F16: ='Ordering Period 1'!W15+'Ordering Period 1'!W30+'Ordering Period 1'!AJ15+'Ordering Period 1'!AJ30 -> 0 | H16: ='Ordering Period 2'!U15+'Ordering Period 2'!U30+'Ordering Period 2'!AH15+'Ordering Period 2'!AH30 -> 0 | J16: ='Ordering Period 3'!U15+'Ordering Period 3'!U30+'Ordering Period 3'!AH15+'Ordering Period 3'!AH30 -> 0 | L16: ='Ordering Period 4'!W15+'Ordering Period 4'!W30+'Ordering Period 4'!AJ15+'Ordering Period 4'!AJ30 -> 0 | N16: ='Ordering Period 5'!U15+'Ordering Period 5'!U30+'Ordering Period 5'!AH15+'Ordering Period 5'!AH30 -> 0 | O16: =ROUND(N16*0.5,0) -> 0
B17: 012 | C17: Material Handling Specialist | D17: CONUS | F17: ='Ordering Period 1'!W16+'Ordering Period 1'!W31+'Ordering Period 1'!AJ16+'Ordering Period 1'!AJ31 -> 0 | H17: ='Ordering Period 2'!U16+'Ordering Period 2'!U31+'Ordering Period 2'!AH16+'Ordering Period 2'!AH31 -> 0 | J17: ='Ordering Period 3'!U16+'Ordering Period 3'!U31+'Ordering Period 3'!AH16+'Ordering Period 3'!AH31 -> 0 | L17: ='Ordering Period 4'!W16+'Ordering Period 4'!W31+'Ordering Period 4'!AJ16+'Ordering Period 4'!AJ31 -> 0 | N17: ='Ordering Period 5'!U16+'Ordering Period 5'!U31+'Ordering Period 5'!AH16+'Ordering Period 5'!AH31 -> 0 | O17: =ROUND(N17*0.5,0) -> 0
B18: 013 | C18: Quality Assurance | D18: CONUS | F18: ='Ordering Period 1'!W17+'Ordering Period 1'!W32+'Ordering Period 1'!AJ17+'Ordering Period 1'!AJ32 -> 0 | H18: ='Ordering Period 2'!U17+'Ordering Period 2'!U32+'Ordering Period 2'!AH17+'Ordering Period 2'!AH32 -> 0 | J18: ='Ordering Period 3'!U17+'Ordering Period 3'!U32+'Ordering Period 3'!AH17+'Ordering Period 3'!AH32 -> 0 | L18: ='Ordering Period 4'!W17+'Ordering Period 4'!W32+'Ordering Period 4'!AJ17+'Ordering Period 4'!AJ32 -> 0 | N18: ='Ordering Period 5'!U17+'Ordering Period 5'!U32+'Ordering Period 5'!AH17+'Ordering Period 5'!AH32 -> 0 | O18: =ROUND(N18*0.5,0) -> 0
B19: 014 | C19: Supply/Procurement Specialist | D19: CONUS | F19: ='Ordering Period 1'!W18+'Ordering Period 1'!W33+'Ordering Period 1'!AJ18+'Ordering Period 1'!AJ33 -> 0 | H19: ='Ordering Period 2'!U18+'Ordering Period 2'!U33+'Ordering Period 2'!AH18+'Ordering Period 2'!AH33 -> 0 | J19: ='Ordering Period 3'!U18+'Ordering Period 3'!U33+'Ordering Period 3'!AH18+'Ordering Period 3'!AH33 -> 0 | L19: ='Ordering Period 4'!W18+'Ordering Period 4'!W33+'Ordering Period 4'!AJ18+'Ordering Period 4'!AJ33 -> 0 | N19: ='Ordering Period 5'!U18+'Ordering Period 5'!U33+'Ordering Period 5'!AH18+'Ordering Period 5'!AH33 -> 0 | O19: =ROUND(N19*0.5,0) -> 0
B20: 015 | C20: Welder | D20: CONUS | F20: ='Ordering Period 1'!W19+'Ordering Period 1'!W34+'Ordering Period 1'!AJ19+'Ordering Period 1'!AJ34 -> 0 | H20: ='Ordering Period 2'!U19+'Ordering Period 2'!U34+'Ordering Period 2'!AH19+'Ordering Period 2'!AH34 -> 0 | J20: ='Ordering Period 3'!U19+'Ordering Period 3'!U34+'Ordering Period 3'!AH19+'Ordering Period 3'!AH34 -> 0 | L20: ='Ordering Period 4'!W19+'Ordering Period 4'!W34+'Ordering Period 4'!AJ19+'Ordering Period 4'!AJ34 -> 0 | N20: ='Ordering Period 5'!U19+'Ordering Period 5'!U34+'Ordering Period 5'!AH19+'Ordering Period 5'!AH34 -> 0 | O20: =ROUND(N20*0.5,0) -> 0
A21: Field Service Representative (FSR) | B21: 016 | C21: Field Service Representative | D21: OCONUS | F21: ='Ordering Period 1'!W36+'Ordering Period 1'!AJ36 -> 0 | H21: ='Ordering Period 2'!U36+'Ordering Period 2'!AH36 -> 0 | J21: ='Ordering Period 3'!U36+'Ordering Period 3'!AH36 -> 0 | L21: ='Ordering Period 4'!W36+'Ordering Period 4'!AJ36 -> 0 | N21: ='Ordering Period 5'!U36+'Ordering Period 5'!AH36 -> 0 | O21: =ROUND(N21*0.5,0) -> 0
A22: General Maintenance | B22: 017 | C22: Heavy Equipment Mechanic | D22: OCONUS | F22: ='Ordering Period 1'!W37+'Ordering Period 1'!AJ37 -> 0 | H22: ='Ordering Period 2'!U37+'Ordering Period 2'!AH37 -> 0 | J22: ='Ordering Period 3'!U37+'Ordering Period 3'!AH37 -> 0 | L22: ='Ordering Period 4'!W37+'Ordering Period 4'!AJ37 -> 0 | N22: ='Ordering Period 5'!U37+'Ordering Period 5'!AH37 -> 0 | O22: =ROUND(N22*0.5,0) -> 0
A23: New Equipment Training (NET) | B23: 018 | C23: Instructor Supervisor | D23: OCONUS | F23: ='Ordering Period 1'!W38+'Ordering Period 1'!AJ38 -> 0 | H23: ='Ordering Period 2'!U38+'Ordering Period 2'!AH38 -> 0 | J23: ='Ordering Period 3'!U38+'Ordering Period 3'!AH38 -> 0
B24: 019 | C24: Instructor | D24: OCONUS | F24: ='Ordering Period 1'!W39+'Ordering Period 1'!AJ39 -> 0 | H24: ='Ordering Period 2'!U39+'Ordering Period 2'!AH39 -> 0 | J24: ='Ordering Period 3'!U39+'Ordering Period 3'!AH39 -> 0
A25: Total Package Fielding (TPF) and De-processing | B25: 020 | C25: Heavy Equipment Mechanic | D25: OCONUS | F25: ='Ordering Period 1'!W40+'Ordering Period 1'!AJ40 -> 0 | H25: ='Ordering Period 2'!U40+'Ordering Period 2'!AH40 -> 0 | J25: ='Ordering Period 3'!U40+'Ordering Period 3'!AH40 -> 0 | L25: ='Ordering Period 4'!W38+'Ordering Period 4'!AJ38 -> 0 | N25: ='Ordering Period 5'!U38+'Ordering Period 5'!AH38 -> 0 | O25: =ROUND(N25*0.5,0) -> 0
B26: 021 | C26: Material Handling Specialist | D26: OCONUS | F26: ='Ordering Period 1'!W41+'Ordering Period 1'!AJ41 -> 0 | H26: ='Ordering Period 2'!U41+'Ordering Period 2'!AH41 -> 0 | J26: ='Ordering Period 3'!U41+'Ordering Period 3'!AH41 -> 0
B27: 022 | C27: Quality Assurance | D27: OCONUS | F27: ='Ordering Period 1'!W42+'Ordering Period 1'!AJ42 -> 0 | H27: ='Ordering Period 2'!U42+'Ordering Period 2'!AH42 -> 0 | J27: ='Ordering Period 3'!U42+'Ordering Period 3'!AH42 -> 0
B28: 023 | C28: Supply/Procurement Specialist | D28: OCONUS | F28: ='Ordering Period 1'!W43+'Ordering Period 1'!AJ43 -> 0 | H28: ='Ordering Period 2'!U43+'Ordering Period 2'!AH43 -> 0 | J28: ='Ordering Period 3'!U43+'Ordering Period 3'!AH43 -> 0
A29: Field Service Representative (FSR) | B29: 024 | C29: Field Service Representative | D29: OCONUS - IRAQ | L29: ='Ordering Period 4'!W39+'Ordering Period 4'!AJ39 -> 0 | N29: ='Ordering Period 5'!U39+'Ordering Period 5'!AH39 -> 0 | O29: =ROUND(N29*0.5,0) -> 0
A30: General Maintenance | B30: 025 | C30: Heavy Equipment Mechanic | D30: OCONUS - IRAQ | L30: ='Ordering Period 4'!W40+'Ordering Period 4'!AJ40 -> 0 | N30: ='Ordering Period 5'!U40+'Ordering Period 5'!AH40 -> 0 | O30: =ROUND(N30*0.5,0) -> 0
A31: New Equipment Training (NET) | B31: 026 | C31: Instructor Supervisor | D31: OCONUS - IRAQ | L31: ='Ordering Period 4'!W41+'Ordering Period 4'!AJ41 -> 0 | N31: ='Ordering Period 5'!U41+'Ordering Period 5'!AH41 -> 0 | O31: =ROUND(N31*0.5,0) -> 0
B32: 027 | C32: Instructor | D32: OCONUS - IRAQ | L32: ='Ordering Period 4'!W42+'Ordering Period 4'!AJ42 -> 0 | N32: ='Ordering Period 5'!U42+'Ordering Period 5'!AH42 -> 0 | O32: =ROUND(N32*0.5,0) -> 0
A33: Total Package Fielding (TPF) and De-processing | B33: 028 | C33: Heavy Equipment Mechanic | D33: OCONUS - IRAQ | L33: ='Ordering Period 4'!W43+'Ordering Period 4'!AJ43 -> 0 | N33: ='Ordering Period 5'!U43+'Ordering Period 5'!AH43 -> 0 | O33: =ROUND(N33*0.5,0) -> 0
B34: 029 | C34: Material Handling Specialist | D34: OCONUS - IRAQ | L34: ='Ordering Period 4'!W44+'Ordering Period 4'!AJ44 -> 0 | N34: ='Ordering Period 5'!U44+'Ordering Period 5'!AH44 -> 0 | O34: =ROUND(N34*0.5,0) -> 0
B35: 030 | C35: Quality Assurance | D35: OCONUS - IRAQ | L35: ='Ordering Period 4'!W45+'Ordering Period 4'!AJ45 -> 0 | N35: ='Ordering Period 5'!U45+'Ordering Period 5'!AH45 -> 0 | O35: =ROUND(N35*0.5,0) -> 0
B36: 031 | C36: Supply/Procurement Specialist | D36: OCONUS - IRAQ | L36: ='Ordering Period 4'!W46+'Ordering Period 4'!AJ46 -> 0 | N36: ='Ordering Period 5'!U46+'Ordering Period 5'!AH46 -> 0 | O36: =ROUND(N36*0.5,0) -> 0
C38: Description: | F38: =F5 -> Ordering Period 1 | H38: =H5 -> Ordering Period 2 | J38: =J5 -> Ordering Period 3 | L38: =L5 -> Ordering Period 4 | N38: =N5 -> Ordering Period 5 | O38: =O5 -> FAR 52.217-8 Option
C41: Total Labor | F41: =SUM(F6:F36) -> 0 | H41: =SUM(H6:H36) -> 0 | J41: =SUM(J6:J36) -> 0 | L41: =SUM(L6:L36) -> 0 | N41: =SUM(N6:N36) -> 0 | O41: =SUM(O6:O36) -> 0
C43: Travel / ODC Price | F43: ='Ordering Period 1'!D61 -> 24658327 | H43: ='Ordering Period 2'!D61 -> 25176152 | J43: ='Ordering Period 3'!D61 -> 25704851 | L43: ='Ordering Period 4'!D64 -> 26244653 | N43: ='Ordering Period 5'!D64 -> 26795791 | O43: =ROUND(N43*0.5,0) -> 13397896
C45: DBA Insurance | F45: ='Ordering Period 1'!D66 -> 0 | H45: ='Ordering Period 2'!D66 -> 0 | J45: ='Ordering Period 3'!D66 -> 0 | L45: ='Ordering Period 4'!D69 -> 0 | N45: ='Ordering Period 5'!D69 -> 0 | O45: =ROUND(N45*0.5,0) -> 0
C47: Subtotal (Per Period of Performance) | F47: =SUM(C3,F41,F43,F45) -> 24658327 | H47: =H41+H43+H45 -> 25176152 | J47: =J41+J43+J45 -> 25704851 | L47: =L41+L43+L45 -> 26244653 | N47: =N41+N43+N45 -> 26795791 | O47: =O41+O43+O45 -> 13397896
...

Sheet Ordering Period 1
A1: Ordering Period 1:
A2: Ordering Period 1 Labor Categories & Hours | J2: Prime Contractor CPFF Labor | Y2: Subcontractor Labor | AO2: Composite FBLR (Prime & Sub)
A3: Service | B3: ID | C3: Labor Category | D3: Reference | E3: Location | F3: Req. Hours | G3: Prop Hours. | H3: Delta (Req. - Prop.) | J3: Prime Hours | K3: (Floor Rate) | L3: Direct Labor (Proposed) | M3: Direct Labor (Calculation) | N3: Fringe Benefit | O3: Labor OH | P3: G&A | Q3: FCCOM | R3: Cost | S3: Fee | T3: FBLR | U3: Total Cost | V3: Total Fee | W3: Total Price | Y3: Sub Hours | Z3: Sub FBLR | AA3: Sub FBLR (Calculation) | AB3: Prime OH | AC3: Prime G&A | AD3: Prime FCCOM | AE3: Cost | AF3: Prime Fee | AG3: FBLR (Inclusive of All Prime Adders) | AH3: Total Cost | AI3: Total Fee | AJ3: Total Price | AK3: Name of Subcontractor(s) | AL3: Blended Sub FBLR (Y/N) | AM3: Billing Nomenclature | AO3: CPFF
A4: CONUS | AO4: Cost | AP4: Fee | AQ4: Total
A5: Program Management | B5: 001 | C5: Project Management Specialist | D5: Section H.3.1.11 | E5: CONUS | F5: 18541 | G5: =SUM(J5,Y5) -> 0 | H5: =F5-G5 -> 18541 | K5: 42.46 | M5: =IF($J5>0,IF($L5<$K5,$K5,$L5),0) -> 0 | N5: =(M5*$N$4) -> 0 | O5: =(N5+M5)*$O$4 -> 0 | P5: =(N5+M5+O5)*$P$4 -> 0 | Q5: =(M5+N5+O5+P5)*$Q$4 -> 0 | R5: =SUM(M5:Q5) -> 0 | S5: =(R5-Q5)*$S$4 -> 0 | T5: =SUM(R5:S5) -> 0 | U5: =R5*J5 -> 0 | V5: =S5*J5 -> 0 | W5: =T5*J5 -> 0 | AA5: =IF($Y5>0,$Z5,0) -> 0 | AB5: =(AA5*$AB$4) -> 0 | AC5: =(AA5+AB5)*$AC$4 -> 0 | AE5: =SUM(AA5:AD5) -> 0 | AF5: =$AF$4*(AC5+AA5+AB5) -> 0 | AG5: =SUM(AE5:AF5) -> 0 | AH5: =AE5*Y5 -> 0 | AI5: =AF5*Y5 -> 0 | AJ5: =AG5*Y5 -> 0 | AO5: =IFERROR(SUM(U5,AH5)/G5,"") | AP5: =IFERROR(SUM(V5,AI5)/G5,"") | AQ5: =SUM(AO5:AP5) -> 0
A6: Field Service Representative (FSR) | B6: 002 | C6: Field Service Representative | D6: Section H.3.1.9 | E6: CONUS | F6: 57507 | G6: =SUM(J6,Y6) -> 0 | H6: =F6-G6 -> 57507 | K6: 29.76 | M6: =IF($J6>0,IF($L6<$K6,$K6,$L6),0) -> 0 | N6: =(M6*$N$4) -> 0 | O6: =(N6+M6)*$O$4 -> 0 | P6: =(N6+M6+O6)*$P$4 -> 0 | Q6: =(M6+N6+O6+P6)*$Q$4 -> 0 | R6: =SUM(M6:Q6) -> 0 | S6: =(R6-Q6)*$S$4 -> 0 | T6: =SUM(R6:S6) -> 0 | U6: =R6*J6 -> 0 | V6: =S6*J6 -> 0 | W6: =T6*J6 -> 0 | AA6: =IF($Y6>0,$Z6,0) -> 0 | AB6: =(AA6*$AB$4) -> 0 | AC6: =(AA6+AB6)*$AC$4 -> 0 | AE6: =SUM(AA6:AD6) -> 0 | AF6: =$AF$4*(AC6+AA6+AB6) -> 0 | AG6: =SUM(AE6:AF6) -> 0 | AH6: =AE6*Y6 -> 0 | AI6: =AF6*Y6 -> 0 | AJ6: =AG6*Y6 -> 0 | AO6: =IFERROR(SUM(U6,AH6)/G6,"") | AP6: =IFERROR(SUM(V6,AI6)/G6,"") | AQ6: =SUM(AO6:AP6) -> 0
A7: General Maintenance | B7: 003 | C7: Heavy Equipment Mechanic | D7: Section H.3.1.3 | E7: CONUS | F7: 129710 | G7: =SUM(J7,Y7) -> 0 | H7: =F7-G7 -> 129710 | K7: 29.76 | M7: =IF($J7>0,IF($L7<$K7,$K7,$L7),0) -> 0 | N7: =(M7*$N$4) -> 0 | O7: =(N7+M7)*$O$4 -> 0 | P7: =(N7+M7+O7)*$P$4 -> 0 | Q7: =(M7+N7+O7+P7)*$Q$4 -> 0 | R7: =SUM(M7:Q7) -> 0 | S7: =(R7-Q7)*$S$4 -> 0 | T7: =SUM(R7:S7) -> 0 | U7: =R7*J7 -> 0 | V7: =S7*J7 -> 0 | W7: =T7*J7 -> 0 | AA7: =IF($Y7>0,$Z7,0) -> 0 | AB7: =(AA7*$AB$4) -> 0 | AC7: =(AA7+AB7)*$AC$4 -> 0 | AE7: =SUM(AA7:AD7) -> 0 | AF7: =$AF$4*(AC7+AA7+AB7) -> 0 | AG7: =SUM(AE7:AF7) -> 0 | AH7: =AE7*Y7 -> 0 | AI7: =AF7*Y7 -> 0 | AJ7: =AG7*Y7 -> 0 | AO7: =IFERROR(SUM(U7,AH7)/G7,"") | AP7: =IFERROR(SUM(V7,AI7)/G7,"") | AQ7: =SUM(AO7:AP7) -> 0
A8: Modified Work Orders (MWO) | B8: 004 | C8: Field Service Representative | D8: Section H.3.1.9 | E8: CONUS | F8: 10953 | G8: =SUM(J8,Y8) -> 0 | H8: =F8-G8 -> 10953 | K8: 29.76 | M8: =IF($J8>0,IF($L8<$K8,$K8,$L8),0) -> 0 | N8: =(M8*$N$4) -> 0 | O8: =(N8+M8)*$O$4 -> 0 | P8: =(N8+M8+O8)*$P$4 -> 0 | Q8: =(M8+N8+O8+P8)*$Q$4 -> 0 | R8: =SUM(M8:Q8) -> 0 | S8: =(R8-Q8)*$S$4 -> 0 | T8: =SUM(R8:S8) -> 0 | U8: =R8*J8 -> 0 | V8: =S8*J8 -> 0 | W8: =T8*J8 -> 0 | AA8: =IF($Y8>0,$Z8,0) -> 0 | AB8: =(AA8*$AB$4) -> 0 | AC8: =(AA8+AB8)*$AC$4 -> 0 | AE8: =SUM(AA8:AD8) -> 0 | AF8: =$AF$4*(AC8+AA8+AB8) -> 0 | AG8: =SUM(AE8:AF8) -> 0 | AH8: =AE8*Y8 -> 0 | AI8: =AF8*Y8 -> 0 | AJ8: =AG8*Y8 -> 0 | AO8: =IFERROR(SUM(U8,AH8)/G8,"") | AP8: =IFERROR(SUM(V8,AI8)/G8,"") | AQ8: =SUM(AO8:AP8) -> 0
B9: 005 | C9: Modified Work Orders (MWO) | D9: Section H.3.1.6 | E9: CONUS | F9: 194682 | G9: =SUM(J9,Y9) -> 0 | H9: =F9-G9 -> 194682 | K9: 29.76 | M9: =IF($J9>0,IF($L9<$K9,$K9,$L9),0) -> 0 | N9: =(M9*$N$4) -> 0 | O9: =(N9+M9)*$O$4 -> 0 | P9: =(N9+M9+O9)*$P$4 -> 0 | Q9: =(M9+N9+O9+P9)*$Q$4 -> 0 | R9: =SUM(M9:Q9) -> 0 | S9: =(R9-Q9)*$S$4 -> 0 | T9: =SUM(R9:S9) -> 0 | U9: =R9*J9 -> 0 | V9: =S9*J9 -> 0 | W9: =T9*J9 -> 0 | AA9: =IF($Y9>0,$Z9,0) -> 0 | AB9: =(AA9*$AB$4) -> 0 | AC9: =(AA9+AB9)*$AC$4 -> 0 | AE9: =SUM(AA9:AD9) -> 0 | AF9: =$AF$4*(AC9+AA9+AB9) -> 0 | AG9: =SUM(AE9:AF9) -> 0 | AH9: =AE9*Y9 -> 0 | AI9: =AF9*Y9 -> 0 | AJ9: =AG9*Y9 -> 0 | AO9: =IFERROR(SUM(U9,AH9)/G9,"") | AP9: =IFERROR(SUM(V9,AI9)/G9,"") | AQ9: =SUM(AO9:AP9) -> 0
B10: 006 | C10: Quality Assurance | D10: Section H.3.1.10 | E10: CONUS | F10: 15018 | G10: =SUM(J10,Y10) -> 0 | H10: =F10-G10 -> 15018 | K10: 29.76 | M10: =IF($J10>0,IF($L10<$K10,$K10,$L10),0) -> 0 | N10: =(M10*$N$4) -> 0 | O10: =(N10+M10)*$O$4 -> 0 | P10: =(N10+M10+O10)*$P$4 -> 0 | Q10: =(M10+N10+O10+P10)*$Q$4 -> 0 | R10: =SUM(M10:Q10) -> 0 | S10: =(R10-Q10)*$S$4 -> 0 | T10: =SUM(R10:S10) -> 0 | U10: =R10*J10 -> 0 | V10: =S10*J10 -> 0 | W10: =T10*J10 -> 0 | AA10: =IF($Y10>0,$Z10,0) -> 0 | AB10: =(AA10*$AB$4) -> 0 | AC10: =(AA10+AB10)*$AC$4 -> 0 | AE10: =SUM(AA10:AD10) -> 0 | AF10: =$AF$4*(AC10+AA10+AB10) -> 0 | AG10: =SUM(AE10:AF10) -> 0 | AH10: =AE10*Y10 -> 0 | AI10: =AF10*Y10 -> 0 | AJ10: =AG10*Y10 -> 0 | AO10: =IFERROR(SUM(U10,AH10)/G10,"") | AP10: =IFERROR(SUM(V10,AI10)/G10,"") | AQ10: =SUM(AO10:AP10) -> 0
B11: 007 | C11: Software | D11: Section H.3.1.5 | E11: CONUS | F11: 17115 | G11: =SUM(J11,Y11) -> 0 | H11: =F11-G11 -> 17115 | K11: 29.76 | M11: =IF($J11>0,IF($L11<$K11,$K11,$L11),0) -> 0 | N11: =(M11*$N$4) -> 0 | O11: =(N11+M11)*$O$4 -> 0 | P11: =(N11+M11+O11)*$P$4 -> 0 | Q11: =(M11+N11+O11+P11)*$Q$4 -> 0 | R11: =SUM(M11:Q11) -> 0 | S11: =(R11-Q11)*$S$4 -> 0 | T11: =SUM(R11:S11) -> 0 | U11: =R11*J11 -> 0 | V11: =S11*J11 -> 0 | W11: =T11*J11 -> 0 | AA11: =IF($Y11>0,$Z11,0) -> 0 | AB11: =(AA11*$AB$4) -> 0 | AC11: =(AA11+AB11)*$AC$4 -> 0 | AE11: =SUM(AA11:AD11) -> 0 | AF11: =$AF$4*(AC11+AA11+AB11) -> 0 | AG11: =SUM(AE11:AF11) -> 0 | AH11: =AE11*Y11 -> 0 | AI11: =AF11*Y11 -> 0 | AJ11: =AG11*Y11 -> 0 | AO11: =IFERROR(SUM(U11,AH11)/G11,"") | AP11: =IFERROR(SUM(V11,AI11)/G11,"") | AQ11: =SUM(AO11:AP11) -> 0
B12: 008 | C12: Welder | D12: Section H.3.1.4 | E12: CONUS | F12: 25822 | G12: =SUM(J12,Y12) -> 0 | H12: =F12-G12 -> 25822 | K12: 23.57 | M12: =IF($J12>0,IF($L12<$K12,$K12,$L12),0) -> 0 | N12: =(M12*$N$4) -> 0 | O12: =(N12+M12)*$O$4 -> 0 | P12: =(N12+M12+O12)*$P$4 -> 0 | Q12: =(M12+N12+O12+P12)*$Q$4 -> 0 | R12: =SUM(M12:Q12) -> 0 | S12: =(R12-Q12)*$S$4 -> 0 | T12: =SUM(R12:S12) -> 0 | U12: =R12*J12 -> 0 | V12: =S12*J12 -> 0 | W12: =T12*J12 -> 0 | AA12: =IF($Y12>0,$Z12,0) -> 0 | AB12: =(AA12*$AB$4) -> 0 | AC12: =(AA12+AB12)*$AC$4 -> 0 | AE12: =SUM(AA12:AD12) -> 0 | AF12: =$AF$4*(AC12+AA12+AB12) -> 0 | AG12: =SUM(AE12:AF12) -> 0 | AH12: =AE12*Y12 -> 0 | AI12: =AF12*Y12 -> 0 | AJ12: =AG12*Y12 -> 0 | AO12: =IFERROR(SUM(U12,AH12)/G12,"") | AP12: =IFERROR(SUM(V12,AI12)/G12,"") | AQ12: =SUM(AO12:AP12) -> 0
A13: New Equipment Training (NET) | B13: 009 | C13: Instructor Supervisor | D13: Section H.3.1.7 | E13: CONUS | F13: 14976 | G13: =SUM(J13,Y13) -> 0 | H13: =F13-G13 -> 14976 | K13: 25.3 | M13: =IF($J13>0,IF($L13<$K13,$K13,$L13),0) -> 0 | N13: =(M13*$N$4) -> 0 | O13: =(N13+M13)*$O$4 -> 0 | P13: =(N13+M13+O13)*$P$4 -> 0 | Q13: =(M13+N13+O13+P13)*$Q$4 -> 0 | R13: =SUM(M13:Q13) -> 0 | S13: =(R13-Q13)*$S$4 -> 0 | T13: =SUM(R13:S13) -> 0 | U13: =R13*J13 -> 0 | V13: =S13*J13 -> 0 | W13: =T13*J13 -> 0 | AA13: =IF($Y13>0,$Z13,0) -> 0 | AB13: =(AA13*$AB$4) -> 0 | AC13: =(AA13+AB13)*$AC$4 -> 0 | AE13: =SUM(AA13:AD13) -> 0 | AF13: =$AF$4*(AC13+AA13+AB13) -> 0 | AG13: =SUM(AE13:AF13) -> 0 | AH13: =AE13*Y13 -> 0 | AI13: =AF13*Y13 -> 0 | AJ13: =AG13*Y13 -> 0 | AO13: =IFERROR(SUM(U13,AH13)/G13,"") | AP13: =IFERROR(SUM(V13,AI13)/G13,"") | AQ13: =SUM(AO13:AP13) -> 0
B14: 010 | C14: Instructor | D14: Section H.3.1.8 | E14: CONUS | F14: 124084 | G14: =SUM(J14,Y14) -> 0 | H14: =F14-G14 -> 124084 | K14: 25.3 | M14: =IF($J14>0,IF($L14<$K14,$K14,$L14),0) -> 0 | N14: =(M14*$N$4) -> 0 | O14: =(N14+M14)*$O$4 -> 0 | P14: =(N14+M14+O14)*$P$4 -> 0 | Q14: =(M14+N14+O14+P14)*$Q$4 -> 0 | R14: =SUM(M14:Q14) -> 0 | S14: =(R14-Q14)*$S$4 -> 0 | T14: =SUM(R14:S14) -> 0 | U14: =R14*J14 -> 0 | V14: =S14*J14 -> 0 | W14: =T14*J14 -> 0 | AA14: =IF($Y14>0,$Z14,0) -> 0 | AB14: =(AA14*$AB$4) -> 0 | AC14: =(AA14+AB14)*$AC$4 -> 0 | AE14: =SUM(AA14:AD14) -> 0 | AF14: =$AF$4*(AC14+AA14+AB14) -> 0 | AG14: =SUM(AE14:AF14) -> 0 | AH14: =AE14*Y14 -> 0 | AI14: =AF14*Y14 -> 0 | AJ14: =AG14*Y14 -> 0 | AO14: =IFERROR(SUM(U14,AH14)/G14,"") | AP14: =IFERROR(SUM(V14,AI14)/G14,"") | AQ14: =SUM(AO14:AP14) -> 0
A15: Total Package Fielding (TPF) and De-processing | B15: 011 | C15: Heavy Equipment Mechanic | D15: Section H.3.1.3 | E15: CONUS | F15: 146269 | G15: =SUM(J15,Y15) -> 0 | H15: =F15-G15 -> 146269 | K15: 29.76 | M15: =IF($J15>0,IF($L15<$K15,$K15,$L15),0) -> 0 | N15: =(M15*$N$4) -> 0 | O15: =(N15+M15)*$O$4 -> 0 | P15: =(N15+M15+O15)*$P$4 -> 0 | Q15: =(M15+N15+O15+P15)*$Q$4 -> 0 | R15: =SUM(M15:Q15) -> 0 | S15: =(R15-Q15)*$S$4 -> 0 | T15: =SUM(R15:S15) -> 0 | U15: =R15*J15 -> 0 | V15: =S15*J15 -> 0 | W15: =T15*J15 -> 0 | AA15: =IF($Y15>0,$Z15,0) -> 0 | AB15: =(AA15*$AB$4) -> 0 | AC15: =(AA15+AB15)*$AC$4 -> 0 | AE15: =SUM(AA15:AD15) -> 0 | AF15: =$AF$4*(AC15+AA15+AB15) -> 0 | AG15: =SUM(AE15:AF15) -> 0 | AH15: =AE15*Y15 -> 0 | AI15: =AF15*Y15 -> 0 | AJ15: =AG15*Y15 -> 0 | AO15: =IFERROR(SUM(U15,AH15)/G15,"") | AP15: =IFERROR(SUM(V15,AI15)/G15,"") | AQ15: =SUM(AO15:AP15) -> 0
B16: 012 | C16: Material Handling Specialist | D16: Section H.3.1.2 | E16: CONUS | F16: 14976 | G16: =SUM(J16,Y16) -> 0 | H16: =F16-G16 -> 14976 | K16: 25.91 | M16: =IF($J16>0,IF($L16<$K16,$K16,$L16),0) -> 0 | N16: =(M16*$N$4) -> 0 | O16: =(N16+M16)*$O$4 -> 0 | P16: =(N16+M16+O16)*$P$4 -> 0 | Q16: =(M16+N16+O16+P16)*$Q$4 -> 0 | R16: =SUM(M16:Q16) -> 0 | S16: =(R16-Q16)*$S$4 -> 0 | T16: =SUM(R16:S16) -> 0 | U16: =R16*J16 -> 0 | V16: =S16*J16 -> 0 | W16: =T16*J16 -> 0 | AA16: =IF($Y16>0,$Z16,0) -> 0 | AB16: =(AA16*$AB$4) -> 0 | AC16: =(AA16+AB16)*$AC$4 -> 0 | AE16: =SUM(AA16:AD16) -> 0 | AF16: =$AF$4*(AC16+AA16+AB16) -> 0 | AG16: =SUM(AE16:AF16) -> 0 | AH16: =AE16*Y16 -> 0 | AI16: =AF16*Y16 -> 0 | AJ16: =AG16*Y16 -> 0 | AO16: =IFERROR(SUM(U16,AH16)/G16,"") | AP16: =IFERROR(SUM(V16,AI16)/G16,"") | AQ16: =SUM(AO16:AP16) -> 0
B17: 013 | C17: Quality Assurance | D17: Section H.3.1.10 | E17: CONUS | F17: 4236 | G17: =SUM(J17,Y17) -> 0 | H17: =F17-G17 -> 4236 | K17: 29.76 | M17: =IF($J17>0,IF($L17<$K17,$K17,$L17),0) -> 0 | N17: =(M17*$N$4) -> 0 | O17: =(N17+M17)*$O$4 -> 0 | P17: =(N17+M17+O17)*$P$4 -> 0 | Q17: =(M17+N17+O17+P17)*$Q$4 -> 0 | R17: =SUM(M17:Q17) -> 0 | S17: =(R17-Q17)*$S$4 -> 0 | T17: =SUM(R17:S17) -> 0 | U17: =R17*J17 -> 0 | V17: =S17*J17 -> 0 | W17: =T17*J17 -> 0 | AA17: =IF($Y17>0,$Z17,0) -> 0 | AB17: =(AA17*$AB$4) -> 0 | AC17: =(AA17+AB17)*$AC$4 -> 0 | AE17: =SUM(AA17:AD17) -> 0 | AF17: =$AF$4*(AC17+AA17+AB17) -> 0 | AG17: =SUM(AE17:AF17) -> 0 | AH17: =AE17*Y17 -> 0 | AI17: =AF17*Y17 -> 0 | AJ17: =AG17*Y17 -> 0 | AO17: =IFERROR(SUM(U17,AH17)/G17,"") | AP17: =IFERROR(SUM(V17,AI17)/G17,"") | AQ17: =SUM(AO17:AP17) -> 0
B18: 014 | C18: Supply/Procurement Specialist | D18: Section H.3.1.1 | E18: CONUS | F18: 29951 | G18: =SUM(J18,Y18) -> 0 | H18: =F18-G18 -> 29951 | K18: 33.8 | M18: =IF($J18>0,IF($L18<$K18,$K18,$L18),0) -> 0 | N18: =(M18*$N$4) -> 0 | O18: =(N18+M18)*$O$4 -> 0 | P18: =(N18+M18+O18)*$P$4 -> 0 | Q18: =(M18+N18+O18+P18)*$Q$4 -> 0 | R18: =SUM(M18:Q18) -> 0 | S18: =(R18-Q18)*$S$4 -> 0 | T18: =SUM(R18:S18) -> 0 | U18: =R18*J18 -> 0 | V18: =S18*J18 -> 0 | W18: =T18*J18 -> 0 | AA18: =IF($Y18>0,$Z18,0) -> 0 | AB18: =(AA18*$AB$4) -> 0 | AC18: =(AA18+AB18)*$AC$4 -> 0 | AE18: =SUM(AA18:AD18) -> 0 | AF18: =$AF$4*(AC18+AA18+AB18) -> 0 | AG18: =SUM(AE18:AF18) -> 0 | AH18: =AE18*Y18 -> 0 | AI18: =AF18*Y18 -> 0 | AJ18: =AG18*Y18 -> 0 | AO18: =IFERROR(SUM(U18,AH18)/G18,"") | AP18: =IFERROR(SUM(V18,AI18)/G18,"") | AQ18: =SUM(AO18:AP18) -> 0
B19: 015 | C19: Welder | D19: Section H.3.1.4 | E19: CONUS | F19: 10547 | G19: =SUM(J19,Y19) -> 0 | H19: =F19-G19 -> 10547 | K19: 23.57 | M19: =IF($J19>0,IF($L19<$K19,$K19,$L19),0) -> 0 | N19: =(M19*$N$4) -> 0 | O19: =(N19+M19)*$O$4 -> 0 | P19: =(N19+M19+O19)*$P$4 -> 0 | Q19: =(M19+N19+O19+P19)*$Q$4 -> 0 | R19: =SUM(M19:Q19) -> 0 | S19: =(R19-Q19)*$S$4 -> 0 | T19: =SUM(R19:S19) -> 0 | U19: =R19*J19 -> 0 | V19: =S19*J19 -> 0 | W19: =T19*J19 -> 0 | AA19: =IF($Y19>0,$Z19,0) -> 0 | AB19: =(AA19*$AB$4) -> 0 | AC19: =(AA19+AB19)*$AC$4 -> 0 | AE19: =SUM(AA19:AD19) -> 0 | AF19: =$AF$4*(AC19+AA19+AB19) -> 0 | AG19: =SUM(AE19:AF19) -> 0 | AH19: =AE19*Y19 -> 0 | AI19: =AF19*Y19 -> 0 | AJ19: =AG19*Y19 -> 0 | AO19: =IFERROR(SUM(U19,AH19)/G19,"") | AP19: =IFERROR(SUM(V19,AI19)/G19,"") | AQ19: =SUM(AO19:AP19) -> 0
A20: CONUS - Overtime (OT)
A21: Field Service Representative (FSR) | B21: 002 | C21: Field Service Representative | D21: Section H.3.1.9 | E21: CONUS - OT | F21: 4792 | G21: =SUM(J21,Y21) -> 0 | H21: =F21-G21 -> 4792 | K21: =K6*1.5 -> 44.64 | L21: =L6*1.5 -> 0 | M21: =IF($J21>0,IF($L21<$K21,$K21,$L21),0) -> 0 | N21: =(M21*$N$4) -> 0 | O21: =(N21+M21)*$O$4 -> 0 | P21: =(N21+M21+O21)*$P$4 -> 0 | Q21: =(M21+N21+O21+P21)*$Q$4 -> 0 | R21: =SUM(M21:Q21) -> 0 | S21: =(R21-Q21)*$S$4 -> 0 | T21: =SUM(R21:S21) -> 0 | U21: =R21*J21 -> 0 | V21: =S21*J21 -> 0 | W21: =T21*J21 -> 0 | AA21: =IF($Y21>0,$Z21,0) -> 0 | AB21: =(AA21*$AB$4) -> 0 | AC21: =(AA21+AB21)*$AC$4 -> 0 | AE21: =SUM(AA21:AD21) -> 0 | AF21: =$AF$4*(AC21+AA21+AB21) -> 0 | AG21: =SUM(AE21:AF21) -> 0 | AH21: =AE21*Y21 -> 0 | AI21: =AF21*Y21 -> 0 | AJ21: =AG21*Y21 -> 0 | AO21: =IFERROR(SUM(U21,AH21)/G21,"") | AP21: =IFERROR(SUM(V21,AI21)/G21,"") | AQ21: =SUM(AO21:AP21) -> 0
A22: General Maintenance | B22: 003 | C22: Heavy Equipment Mechanic | D22: Section H.3.1.3 | E22: CONUS - OT | F22: 10809 | G22: =SUM(J22,Y22) -> 0 | H22: =F22-G22 -> 10809 | K22: =K7*1.5 -> 44.64 | L22: =L7*1.5 -> 0 | M22: =IF($J22>0,IF($L22<$K22,$K22,$L22),0) -> 0 | N22: =(M22*$N$4) -> 0 | O22: =(N22+M22)*$O$4 -> 0 | P22: =(N22+M22+O22)*$P$4 -> 0 | Q22: =(M22+N22+O22+P22)*$Q$4 -> 0 | R22: =SUM(M22:Q22) -> 0 | S22: =(R22-Q22)*$S$4 -> 0 | T22: =SUM(R22:S22) -> 0 | U22: =R22*J22 -> 0 | V22: =S22*J22 -> 0 | W22: =T22*J22 -> 0 | AA22: =IF($Y22>0,$Z22,0) -> 0 | AB22: =(AA22*$AB$4) -> 0 | AC22: =(AA22+AB22)*$AC$4 -> 0 | AE22: =SUM(AA22:AD22) -> 0 | AF22: =$AF$4*(AC22+AA22+AB22) -> 0 | AG22: =SUM(AE22:AF22) -> 0 | AH22: =AE22*Y22 -> 0 | AI22: =AF22*Y22 -> 0 | AJ22: =AG22*Y22 -> 0 | AO22: =IFERROR(SUM(U22,AH22)/G22,"") | AP22: =IFERROR(SUM(V22,AI22)/G22,"") | AQ22: =SUM(AO22:AP22) -> 0
A23: Modified Work Orders (MWO) | B23: 004 | C23: Field Service Representative | D23: Section H.3.1.9 | E23: CONUS - OT | F23: 913 | G23: =SUM(J23,Y23) -> 0 | H23: =F23-G23 -> 913 | K23: =K8*1.5 -> 44.64 | L23: =L8*1.5 -> 0 | M23: =IF($J23>0,IF($L23<$K23,$K23,$L23),0) -> 0 | N23: =(M23*$N$4) -> 0 | O23: =(N23+M23)*$O$4 -> 0 | P23: =(N23+M23+O23)*$P$4 -> 0 | Q23: =(M23+N23+O23+P23)*$Q$4 -> 0 | R23: =SUM(M23:Q23) -> 0 | S23: =(R23-Q23)*$S$4 -> 0 | T23: =SUM(R23:S23) -> 0 | U23: =R23*J23 -> 0 | V23: =S23*J23 -> 0 | W23: =T23*J23 -> 0 | AA23: =IF($Y23>0,$Z23,0) -> 0 | AB23: =(AA23*$AB$4) -> 0 | AC23: =(AA23+AB23)*$AC$4 -> 0 | AE23: =SUM(AA23:AD23) -> 0 | AF23: =$AF$4*(AC23+AA23+AB23) -> 0 | AG23: =SUM(AE23:AF23) -> 0 | AH23: =AE23*Y23 -> 0 | AI23: =AF23*Y23 -> 0 | AJ23: =AG23*Y23 -> 0 | AO23: =IFERROR(SUM(U23,AH23)/G23,"") | AP23: =IFERROR(SUM(V23,AI23)/G23,"") | AQ23: =SUM(AO23:AP23) -> 0
B24: 005 | C24: Modified Work Orders (MWO) | D24: Section H.3.1.6 | E24: CONUS - OT | F24: 16223 | G24: =SUM(J24,Y24) -> 0 | H24: =F24-G24 -> 16223 | K24: =K9*1.5 -> 44.64 | L24: =L9*1.5 -> 0 | M24: =IF($J24>0,IF($L24<$K24,$K24,$L24),0) -> 0 | N24: =(M24*$N$4) -> 0 | O24: =(N24+M24)*$O$4 -> 0 | P24: =(N24+M24+O24)*$P$4 -> 0 | Q24: =(M24+N24+O24+P24)*$Q$4 -> 0 | R24: =SUM(M24:Q24) -> 0 | S24: =(R24-Q24)*$S$4 -> 0 | T24: =SUM(R24:S24) -> 0 | U24: =R24*J24 -> 0 | V24: =S24*J24 -> 0 | W24: =T24*J24 -> 0 | AA24: =IF($Y24>0,$Z24,0) -> 0 | AB24: =(AA24*$AB$4) -> 0 | AC24: =(AA24+AB24)*$AC$4 -> 0 | AE24: =SUM(AA24:AD24) -> 0 | AF24: =$AF$4*(AC24+AA24+AB24) -> 0 | AG24: =SUM(AE24:AF24) -> 0 | AH24: =AE24*Y24 -> 0 | AI24: =AF24*Y24 -> 0 | AJ24: =AG24*Y24 -> 0 | AO24: =IFERROR(SUM(U24,AH24)/G24,"") | AP24: =IFERROR(SUM(V24,AI24)/G24,"") | AQ24: =SUM(AO24:AP24) -> 0
B25: 006 | C25: Quality Assurance | D25: Section H.3.1.10 | E25: CONUS - OT | F25: 1252 | G25: =SUM(J25,Y25) -> 0 | H25: =F25-G25 -> 1252 | K25: =K10*1.5 -> 44.64 | L25: =L10*1.5 -> 0 | M25: =IF($J25>0,IF($L25<$K25,$K25,$L25),0) -> 0 | N25: =(M25*$N$4) -> 0 | O25: =(N25+M25)*$O$4 -> 0 | P25: =(N25+M25+O25)*$P$4 -> 0 | Q25: =(M25+N25+O25+P25)*$Q$4 -> 0 | R25: =SUM(M25:Q25) -> 0 | S25: =(R25-Q25)*$S$4 -> 0 | T25: =SUM(R25:S25) -> 0 | U25: =R25*J25 -> 0 | V25: =S25*J25 -> 0 | W25: =T25*J25 -> 0 | AA25: =IF($Y25>0,$Z25,0) -> 0 | AB25: =(AA25*$AB$4) -> 0 | AC25: =(AA25+AB25)*$AC$4 -> 0 | AE25: =SUM(AA25:AD25) -> 0 | AF25: =$AF$4*(AC25+AA25+AB25) -> 0 | AG25: =SUM(AE25:AF25) -> 0 | AH25: =AE25*Y25 -> 0 | AI25: =AF25*Y25 -> 0 | AJ25: =AG25*Y25 -> 0 | AO25: =IFERROR(SUM(U25,AH25)/G25,"") | AP25: =IFERROR(SUM(V25,AI25)/G25,"") | AQ25: =SUM(AO25:AP25) -> 0
B26: 007 | C26: Software | D26: Section H.3.1.5 | E26: CONUS - OT | F26: 1426 | G26: =SUM(J26,Y26) -> 0 | H26: =F26-G26 -> 1426 | K26: =K11*1.5 -> 44.64 | L26: =L11*1.5 -> 0 | M26: =IF($J26>0,IF($L26<$K26,$K26,$L26),0) -> 0 | N26: =(M26*$N$4) -> 0 | O26: =(N26+M26)*$O$4 -> 0 | P26: =(N26+M26+O26)*$P$4 -> 0 | Q26: =(M26+N26+O26+P26)*$Q$4 -> 0 | R26: =SUM(M26:Q26) -> 0 | S26: =(R26-Q26)*$S$4 -> 0 | T26: =SUM(R26:S26) -> 0 | U26: =R26*J26 -> 0 | V26: =S26*J26 -> 0 | W26: =T26*J26 -> 0 | AA26: =IF($Y26>0,$Z26,0) -> 0 | AB26: =(AA26*$AB$4) -> 0 | AC26: =(AA26+AB26)*$AC$4 -> 0 | AE26: =SUM(AA26:AD26) -> 0 | AF26: =$AF$4*(AC26+AA26+AB26) -> 0 | AG26: =SUM(AE26:AF26) -> 0 | AH26: =AE26*Y26 -> 0 | AI26: =AF26*Y26 -> 0 | AJ26: =AG26*Y26 -> 0 | AO26: =IFERROR(SUM(U26,AH26)/G26,"") | AP26: =IFERROR(SUM(V26,AI26)/G26,"") | AQ26: =SUM(AO26:AP26) -> 0
B27: 008 | C27: Welder | D27: Section H.3.1.4 | E27: CONUS - OT | F27: 2152 | G27: =SUM(J27,Y27) -> 0 | H27: =F27-G27 -> 2152 | K27: =K12*1.5 -> 35.355 | L27: =L12*1.5 -> 0 | M27: =IF($J27>0,IF($L27<$K27,$K27,$L27),0) -> 0 | N27: =(M27*$N$4) -> 0 | O27: =(N27+M27)*$O$4 -> 0 | P27: =(N27+M27+O27)*$P$4 -> 0 | Q27: =(M27+N27+O27+P27)*$Q$4 -> 0 | R27: =SUM(M27:Q27) -> 0 | S27: =(R27-Q27)*$S$4 -> 0 | T27: =SUM(R27:S27) -> 0 | U27: =R27*J27 -> 0 | V27: =S27*J27 -> 0 | W27: =T27*J27 -> 0 | AA27: =IF($Y27>0,$Z27,0) -> 0 | AB27: =(AA27*$AB$4) -> 0 | AC27: =(AA27+AB27)*$AC$4 -> 0 | AE27: =SUM(AA27:AD27) -> 0 | AF27: =$AF$4*(AC27+AA27+AB27) -> 0 | AG27: =SUM(AE27:AF27) -> 0 | AH27: =AE27*Y27 -> 0 | AI27: =AF27*Y27 -> 0 | AJ27: =AG27*Y27 -> 0 | AO27: =IFERROR(SUM(U27,AH27)/G27,"") | AP27: =IFERROR(SUM(V27,AI27)/G27,"") | AQ27: =SUM(AO27:AP27) -> 0
A28: New Equipment Training (NET) | B28: 009 | C28: Instructor Supervisor | D28: Section H.3.1.7 | E28: CONUS - OT | F28: 1248 | G28: =SUM(J28,Y28) -> 0 | H28: =F28-G28 -> 1248 | K28: =K13*1.5 -> 37.95 | L28: =L13*1.5 -> 0 | M28: =IF($J28>0,IF($L28<$K28,$K28,$L28),0) -> 0 | N28: =(M28*$N$4) -> 0 | O28: =(N28+M28)*$O$4 -> 0 | P28: =(N28+M28+O28)*$P$4 -> 0 | Q28: =(M28+N28+O28+P28)*$Q$4 -> 0 | R28: =SUM(M28:Q28) -> 0 | S28: =(R28-Q28)*$S$4 -> 0 | T28: =SUM(R28:S28) -> 0 | U28: =R28*J28 -> 0 | V28: =S28*J28 -> 0 | W28: =T28*J28 -> 0 | AA28: =IF($Y28>0,$Z28,0) -> 0 | AB28: =(AA28*$AB$4) -> 0 | AC28: =(AA28+AB28)*$AC$4 -> 0 | AE28: =SUM(AA28:AD28) -> 0 | AF28: =$AF$4*(AC28+AA28+AB28) -> 0 | AG28: =SUM(AE28:AF28) -> 0 | AH28: =AE28*Y28 -> 0 | AI28: =AF28*Y28 -> 0 | AJ28: =AG28*Y28 -> 0 | AO28: =IFERROR(SUM(U28,AH28)/G28,"") | AP28: =IFERROR(SUM(V28,AI28)/G28,"") | AQ28: =SUM(AO28:AP28) -> 0
B29: 010 | C29: Instructor | D29: Section H.3.1.8 | E29: CONUS - OT | F29: 10340 | G29: =SUM(J29,Y29) -> 0 | H29: =F29-G29 -> 10340 | K29: =K14*1.5 -> 37.95 | L29: =L14*1.5 -> 0 | M29: =IF($J29>0,IF($L29<$K29,$K29,$L29),0) -> 0 | N29: =(M29*$N$4) -> 0 | O29: =(N29+M29)*$O$4 -> 0 | P29: =(N29+M29+O29)*$P$4 -> 0 | Q29: =(M29+N29+O29+P29)*$Q$4 -> 0 | R29: =SUM(M29:Q29) -> 0 | S29: =(R29-Q29)*$S$4 -> 0 | T29: =SUM(R29:S29) -> 0 | U29: =R29*J29 -> 0 | V29: =S29*J29 -> 0 | W29: =T29*J29 -> 0 | AA29: =IF($Y29>0,$Z29,0) -> 0 | AB29: =(AA29*$AB$4) -> 0 | AC29: =(AA29+AB29)*$AC$4 -> 0 | AE29: =SUM(AA29:AD29) -> 0 | AF29: =$AF$4*(AC29+AA29+AB29) -> 0 | AG29: =SUM(AE29:AF29) -> 0 | AH29: =AE29*Y29 -> 0 | AI29: =AF29*Y29 -> 0 | AJ29: =AG29*Y29 -> 0 | AO29: =IFERROR(SUM(U29,AH29)/G29,"") | AP29: =IFERROR(SUM(V29,AI29)/G29,"") | AQ29: =SUM(AO29:AP29) -> 0
A30: Total Package Fielding (TPF) and De-processing | B30: 011 | C30: Heavy Equipment Mechanic | D30: Section H.3.1.3 | E30: CONUS - OT | F30: 12189 | G30: =SUM(J30,Y30) -> 0 | H30: =F30-G30 -> 12189 | K30: =K15*1.5 -> 44.64 | L30: =L15*1.5 -> 0 | M30: =IF($J30>0,IF($L30<$K30,$K30,$L30),0) -> 0 | N30: =(M30*$N$4) -> 0 | O30: =(N30+M30)*$O$4 -> 0 | P30: =(N30+M30+O30)*$P$4 -> 0 | Q30: =(M30+N30+O30+P30)*$Q$4 -> 0 | R30: =SUM(M30:Q30) -> 0 | S30: =(R30-Q30)*$S$4 -> 0 | T30: =SUM(R30:S30) -> 0 | U30: =R30*J30 -> 0 | V30: =S30*J30 -> 0 | W30: =T30*J30 -> 0 | AA30: =IF($Y30>0,$Z30,0) -> 0 | AB30: =(AA30*$AB$4) -> 0 | AC30: =(AA30+AB30)*$AC$4 -> 0 | AE30: =SUM(AA30:AD30) -> 0 | AF30: =$AF$4*(AC30+AA30+AB30) -> 0 | AG30: =SUM(AE30:AF30) -> 0 | AH30: =AE30*Y30 -> 0 | AI30: =AF30*Y30 -> 0 | AJ30: =AG30*Y30 -> 0 | AO30: =IFERROR(SUM(U30,AH30)/G30,"") | AP30: =IFERROR(SUM(V30,AI30)/G30,"") | AQ30: =SUM(AO30:AP30) -> 0
B31: 012 | C31: Material Handling Specialist | D31: Section H.3.1.2 | E31: CONUS - OT | F31: 1248 | G31: =SUM(J31,Y31) -> 0 | H31: =F31-G31 -> 1248 | K31: =K16*1.5 -> 38.865 | L31: =L16*1.5 -> 0 | M31: =IF($J31>0,IF($L31<$K31,$K31,$L31),0) -> 0 | N31: =(M31*$N$4) -> 0 | O31: =(N31+M31)*$O$4 -> 0 | P31: =(N31+M31+O31)*$P$4 -> 0 | Q31: =(M31+N31+O31+P31)*$Q$4 -> 0 | R31: =SUM(M31:Q31) -> 0 | S31: =(R31-Q31)*$S$4 -> 0 | T31: =SUM(R31:S31) -> 0 | U31: =R31*J31 -> 0 | V31: =S31*J31 -> 0 | W31: =T31*J31 -> 0 | AA31: =IF($Y31>0,$Z31,0) -> 0 | AB31: =(AA31*$AB$4) -> 0 | AC31: =(AA31+AB31)*$AC$4 -> 0 | AE31: =SUM(AA31:AD31) -> 0 | AF31: =$AF$4*(AC31+AA31+AB31) -> 0 | AG31: =SUM(AE31:AF31) -> 0 | AH31: =AE31*Y31 -> 0 | AI31: =AF31*Y31 -> 0 | AJ31: =AG31*Y31 -> 0 | AO31: =IFERROR(SUM(U31,AH31)/G31,"") | AP31: =IFERROR(SUM(V31,AI31)/G31,"") | AQ31: =SUM(AO31:AP31) -> 0
B32: 013 | C32: Quality Assurance | D32: Section H.3.1.10 | E32: CONUS - OT | F32: 353 | G32: =SUM(J32,Y32) -> 0 | H32: =F32-G32 -> 353 | K32: =K17*1.5 -> 44.64 | L32: =L17*1.5 -> 0 | M32: =IF($J32>0,IF($L32<$K32,$K32,$L32),0) -> 0 | N32: =(M32*$N$4) -> 0 | O32: =(N32+M32)*$O$4 -> 0 | P32: =(N32+M32+O32)*$P$4 -> 0 | Q32: =(M32+N32+O32+P32)*$Q$4 -> 0 | R32: =SUM(M32:Q32) -> 0 | S32: =(R32-Q32)*$S$4 -> 0 | T32: =SUM(R32:S32) -> 0 | U32: =R32*J32 -> 0 | V32: =S32*J32 -> 0 | W32: =T32*J32 -> 0 | AA32: =IF($Y32>0,$Z32,0) -> 0 | AB32: =(AA32*$AB$4) -> 0 | AC32: =(AA32+AB32)*$AC$4 -> 0 | AE32: =SUM(AA32:AD32) -> 0 | AF32: =$AF$4*(AC32+AA32+AB32) -> 0 | AG32: =SUM(AE32:AF32) -> 0 | AH32: =AE32*Y32 -> 0 | AI32: =AF32*Y32 -> 0 | AJ32: =AG32*Y32 -> 0 | AO32: =IFERROR(SUM(U32,AH32)/G32,"") | AP32: =IFERROR(SUM(V32,AI32)/G32,"") | AQ32: =SUM(AO32:AP32) -> 0
B33: 014 | C33: Supply/Procurement Specialist | D33: Section H.3.1.1 | E33: CONUS - OT | F33: 2496 | G33: =SUM(J33,Y33) -> 0 | H33: =F33-G33 -> 2496 | K33: =K18*1.5 -> 50.7 | L33: =L18*1.5 -> 0 | M33: =IF($J33>0,IF($L33<$K33,$K33,$L33),0) -> 0 | N33: =(M33*$N$4) -> 0 | O33: =(N33+M33)*$O$4 -> 0 | P33: =(N33+M33+O33)*$P$4 -> 0 | Q33: =(M33+N33+O33+P33)*$Q$4 -> 0 | R33: =SUM(M33:Q33) -> 0 | S33: =(R33-Q33)*$S$4 -> 0 | T33: =SUM(R33:S33) -> 0 | U33: =R33*J33 -> 0 | V33: =S33*J33 -> 0 | W33: =T33*J33 -> 0 | AA33: =IF($Y33>0,$Z33,0) -> 0 | AB33: =(AA33*$AB$4) -> 0 | AC33: =(AA33+AB33)*$AC$4 -> 0 | AE33: =SUM(AA33:AD33) -> 0 | AF33: =$AF$4*(AC33+AA33+AB33) -> 0 | AG33: =SUM(AE33:AF33) -> 0 | AH33: =AE33*Y33 -> 0 | AI33: =AF33*Y33 -> 0 | AJ33: =AG33*Y33 -> 0 | AO33: =IFERROR(SUM(U33,AH33)/G33,"") | AP33: =IFERROR(SUM(V33,AI33)/G33,"") | AQ33: =SUM(AO33:AP33) -> 0
B34: 015 | C34: Welder | D34: Section H.3.1.4 | E34: CONUS - OT | F34: 879 | G34: =SUM(J34,Y34) -> 0 | H34: =F34-G34 -> 879 | K34: =K19*1.5 -> 35.355 | L34: =L19*1.5 -> 0 | M34: =IF($J34>0,IF($L34<$K34,$K34,$L34),0) -> 0 | N34: =(M34*$N$4) -> 0 | O34: =(N34+M34)*$O$4 -> 0 | P34: =(N34+M34+O34)*$P$4 -> 0 | Q34: =(M34+N34+O34+P34)*$Q$4 -> 0 | R34: =SUM(M34:Q34) -> 0 | S34: =(R34-Q34)*$S$4 -> 0 | T34: =SUM(R34:S34) -> 0 | U34: =R34*J34 -> 0 | V34: =S34*J34 -> 0 | W34: =T34*J34 -> 0 | AA34: =IF($Y34>0,$Z34,0) -> 0 | AB34: =(AA34*$AB$4) -> 0 | AC34: =(AA34+AB34)*$AC$4 -> 0 | AE34: =SUM(AA34:AD34) -> 0 | AF34: =$AF$4*(AC34+AA34+AB34) -> 0 | AG34: =SUM(AE34:AF34) -> 0 | AH34: =AE34*Y34 -> 0 | AI34: =AF34*Y34 -> 0 | AJ34: =AG34*Y34 -> 0 | AO34: =IFERROR(SUM(U34,AH34)/G34,"") | AP34: =IFERROR(SUM(V34,AI34)/G34,"") | AQ34: =SUM(AO34:AP34) -> 0
A35: OCONUS
A36: Field Service Representative (FSR) | B36: 016 | C36: Field Service Representative | E36: OCONUS | F36: 37440 | G36: =SUM(J36,Y36) -> 0 | H36: =F36-G36 -> 37440 | K36: 31.25 | M36: =IF($J36>0,IF($L36<$K36,$K36,$L36),0) -> 0 | N36: =(M36*$N$4) -> 0 | O36: =(N36+M36)*$O$4 -> 0 | P36: =(N36+M36+O36)*$P$4 -> 0 | Q36: =(M36+N36+O36+P36)*$Q$4 -> 0 | R36: =SUM(M36:Q36) -> 0 | S36: =(R36-Q36)*$S$4 -> 0 | T36: =SUM(R36:S36) -> 0 | U36: =R36*J36 -> 0 | V36: =S36*J36 -> 0 | W36: =T36*J36 -> 0 | AA36: =IF($Y36>0,$Z36,0) -> 0 | AB36: =(AA36*$AB$4) -> 0 | AC36: =(AA36+AB36)*$AC$4 -> 0 | AE36: =SUM(AA36:AD36) -> 0 | AF36: =$AF$4*(AC36+AA36+AB36) -> 0 | AG36: =SUM(AE36:AF36) -> 0 | AH36: =AE36*Y36 -> 0 | AI36: =AF36*Y36 -> 0 | AJ36: =AG36*Y36 -> 0 | AO36: =IFERROR(SUM(U36,AH36)/G36,"") | AP36: =IFERROR(SUM(V36,AI36)/G36,"") | AQ36: =SUM(AO36:AP36) -> 0
A37: General Maintenance | B37: 017 | C37: Heavy Equipment Mechanic | E37: OCONUS | F37: 113069 | G37: =SUM(J37,Y37) -> 0 | H37: =F37-G37 -> 113069 | K37: 31.25 | M37: =IF($J37>0,IF($L37<$K37,$K37,$L37),0) -> 0 | N37: =(M37*$N$4) -> 0 | O37: =(N37+M37)*$O$4 -> 0 | P37: =(N37+M37+O37)*$P$4 -> 0 | Q37: =(M37+N37+O37+P37)*$Q$4 -> 0 | R37: =SUM(M37:Q37) -> 0 | S37: =(R37-Q37)*$S$4 -> 0 | T37: =SUM(R37:S37) -> 0 | U37: =R37*J37 -> 0 | V37: =S37*J37 -> 0 | W37: =T37*J37 -> 0 | AA37: =IF($Y37>0,$Z37,0) -> 0 | AB37: =(AA37*$AB$4) -> 0 | AC37: =(AA37+AB37)*$AC$4 -> 0 | AE37: =SUM(AA37:AD37) -> 0 | AF37: =$AF$4*(AC37+AA37+AB37) -> 0 | AG37: =SUM(AE37:AF37) -> 0 | AH37: =AE37*Y37 -> 0 | AI37: =AF37*Y37 -> 0 | AJ37: =AG37*Y37 -> 0 | AO37: =IFERROR(SUM(U37,AH37)/G37,"") | AP37: =IFERROR(SUM(V37,AI37)/G37,"") | AQ37: =SUM(AO37:AP37) -> 0
A38: New Equipment Training (NET) | B38: 018 | C38: Instructor Supervisor | E38: OCONUS | F38: 18720 | G38: =SUM(J38,Y38) -> 0 | H38: =F38-G38 -> 18720 | K38: 26.57 | M38: =IF($J38>0,IF($L38<$K38,$K38,$L38),0) -> 0 | N38: =(M38*$N$4) -> 0 | O38: =(N38+M38)*$O$4 -> 0 | P38: =(N38+M38+O38)*$P$4 -> 0 | Q38: =(M38+N38+O38+P38)*$Q$4 -> 0 | R38: =SUM(M38:Q38) -> 0 | S38: =(R38-Q38)*$S$4 -> 0 | T38: =SUM(R38:S38) -> 0 | U38: =R38*J38 -> 0 | V38: =S38*J38 -> 0 | W38: =T38*J38 -> 0 | AA38: =IF($Y38>0,$Z38,0) -> 0 | AB38: =(AA38*$AB$4) -> 0 | AC38: =(AA38+AB38)*$AC$4 -> 0 | AE38: =SUM(AA38:AD38) -> 0 | AF38: =$AF$4*(AC38+AA38+AB38) -> 0 | AG38: =SUM(AE38:AF38) -> 0 | AH38: =AE38*Y38 -> 0 | AI38: =AF38*Y38 -> 0 | AJ38: =AG38*Y38 -> 0 | AO38: =IFERROR(SUM(U38,AH38)/G38,"") | AP38: =IFERROR(SUM(V38,AI38)/G38,"") | AQ38: =SUM(AO38:AP38) -> 0
B39: 019 | C39: Instructor | E39: OCONUS | F39: 176800 | G39: =SUM(J39,Y39) -> 0 | H39: =F39-G39 -> 176800 | K39: 26.57 | M39: =IF($J39>0,IF($L39<$K39,$K39,$L39),0) -> 0 | N39: =(M39*$N$4) -> 0 | O39: =(N39+M39)*$O$4 -> 0 | P39: =(N39+M39+O39)*$P$4 -> 0 | Q39: =(M39+N39+O39+P39)*$Q$4 -> 0 | R39: =SUM(M39:Q39) -> 0 | S39: =(R39-Q39)*$S$4 -> 0 | T39: =SUM(R39:S39) -> 0 | U39: =R39*J39 -> 0 | V39: =S39*J39 -> 0 | W39: =T39*J39 -> 0 | AA39: =IF($Y39>0,$Z39,0) -> 0 | AB39: =(AA39*$AB$4) -> 0 | AC39: =(AA39+AB39)*$AC$4 -> 0 | AE39: =SUM(AA39:AD39) -> 0 | AF39: =$AF$4*(AC39+AA39+AB39) -> 0 | AG39: =SUM(AE39:AF39) -> 0 | AH39: =AE39*Y39 -> 0 | AI39: =AF39*Y39 -> 0 | AJ39: =AG39*Y39 -> 0 | AO39: =IFERROR(SUM(U39,AH39)/G39,"") | AP39: =IFERROR(SUM(V39,AI39)/G39,"") | AQ39: =SUM(AO39:AP39) -> 0
A40: Total Package Fielding (TPF) and De-processing | B40: 020 | C40: Heavy Equipment Mechanic | E40: OCONUS | F40: 201011 | G40: =SUM(J40,Y40) -> 0 | H40: =F40-G40 -> 201011 | K40: 31.25 | M40: =IF($J40>0,IF($L40<$K40,$K40,$L40),0) -> 0 | N40: =(M40*$N$4) -> 0 | O40: =(N40+M40)*$O$4 -> 0 | P40: =(N40+M40+O40)*$P$4 -> 0 | Q40: =(M40+N40+O40+P40)*$Q$4 -> 0 | R40: =SUM(M40:Q40) -> 0 | S40: =(R40-Q40)*$S$4 -> 0 | T40: =SUM(R40:S40) -> 0 | U40: =R40*J40 -> 0 | V40: =S40*J40 -> 0 | W40: =T40*J40 -> 0 | AA40: =IF($Y40>0,$Z40,0) -> 0 | AB40: =(AA40*$AB$4) -> 0 | AC40: =(AA40+AB40)*$AC$4 -> 0 | AE40: =SUM(AA40:AD40) -> 0 | AF40: =$AF$4*(AC40+AA40+AB40) -> 0 | AG40: =SUM(AE40:AF40) -> 0 | AH40: =AE40*Y40 -> 0 | AI40: =AF40*Y40 -> 0 | AJ40: =AG40*Y40 -> 0 | AO40: =IFERROR(SUM(U40,AH40)/G40,"") | AP40: =IFERROR(SUM(V40,AI40)/G40,"") | AQ40: =SUM(AO40:AP40) -> 0
...

Sheet Ordering Period 2
A1: Ordering Period 2:
A2: Ordering Period 2 Labor Categories & Hours | J2: Prime Contractor CPFF Labor | W2: Subcontractor Labor | AM2: Composite FBLR (Prime & Sub)
A3: Service | B3: ID | C3: Labor Category | D3: Reference | E3: Location | F3: Req. Hours | G3: Prop Hours. | H3: Delta (Req. - Prop.) | J3: Prime Hours | K3: Direct Labor (Calculation) | L3: Fringe Benefit | M3: Labor OH | N3: G&A | O3: FCCOM | P3: Cost | Q3: Fee | R3: FBLR | S3: Total Cost | T3: Total Fee | U3: Total Price | W3: Sub Hours | X3: Sub FBLR | Y3: Sub FBLR (Calculation) | Z3: Prime OH | AA3: Prime G&A | AB3: Prime FCCOM | AC3: Cost | AD3: Prime Fee | AE3: FBLR (Inclusive of All Prime Adders) | AF3: Total Cost | AG3: Total Fee | AH3: Total Price | AI3: Name of Subcontractor(s) | AJ3: Blended Sub FBLR (Y/N) | AK3: Billing Nomenclature | AM3: CPFF
A4: CONUS | AM4: Cost | AN4: Fee | AO4: Total
