Workbook

Sheet Subcontractor Instructions
A1: INSTRUCTIONS TO SUBCONTRACTORS
A3: General
A4: 1 | B4: The subcontractor shall complete this Government Format Pricing Model (GFPM-Subs).
A5: 2 | B5: All proposed direct labor rates shall be in line with justifying data (historical/incurred costs, salary survey, BLS OES etc.) for each identified locality.
A6: 3 | B6: The subcontractor GFPM will be utilized for each subcontractor to show its compliance with providing a full labor buildup, per labor category and to ensure compliance with the Government provided floor rates.
A7: "Subcontractor Labor Build" Tab
A8: 1 | B8: All subcontractors must provide the subcontractor GFPM to the prime offeror for submittal to the Government as part of the prime offeror proposal OR each subcontractor must submit this file directly to the Government.
A9: 2 | B9: Offeror input is required in all applicable cells highlighted in yellow.
A10: 3 | B10: The "Labor Categories & Hours" table (columns A - F) contain all of the performance locations and labor categories that the USG anticipates to be necessary for completion of this effort. Offerors shall input the proposed number of hours in column F that will be completed by the subcontractor for each applicable labor category being performed by the subcontractor.
A11: 4 | B11: In the "Subcontractor Labor Build" table (columns H-T), subcontractors are required to submit fully burdened labor rates for each of the labor categories that the subcontractor is performing (Column Q). Subcontractors shall insert all of the cost elements (direct labor, fringe benefit costs, labor overhead costs, general & administrative cost, profit/fee etc.) that make up all of the fully burdened labor rates proposed (Columns I - P). If necessary, subcontractors may submit additional cost data in it's own format to further justify the proposed single elements of the prime labor costs.
A12: 5 | B12: Offerors shall insert direct labor rates in Ordering Period 1 for the applicable labor categories (I5 - I28) and and in Ordering Period 4 for the applicable labor categories (I108 - I115). Note: Per section L of the RFP, the proposed direct labor rates must meet or exceed the USG floor rates referenced in Ordering Period 1 (H5 - H28) and in Ordering Period 4 (H108 - H115).
A13: 6 | B13: In the event a subcontractor proposes a direct labor rate below the floor rate in error, the subcontractor GFPM corrects this error by utilizing the floor rate (as calculated by the pre-populated formula in column J) to compute the subcontractor costs that contribute to the subcontractor proposed FBLR in columns K - P.
A14: 7 | B14: Profit / fee formulas in column P restrict subcontractors from proposing negative profit/fee percentages.
A15: 8 | B15: Particular cells are locked and cannot be edited. Cells highlighted in yellow can be modified to fit a subcontractors accounting methods, however, the Government has included pre-populated formulas if applicable.
A16: 9 | B16: The FBLR proposed in column Q should be consistent with the FBLR provided to the prime for the primes submittal of its proposal.
A17: "Escalation" Tab
A18: 1 | B18: This tab provides the data for the labor escalation rates which apply to all option periods of performance tabs.
A19: 2 | B19: Per section L of the RFP, for evaluation purposes only, this solicitation has set a minimum escalation for each period of performance. Subcontractors may choose to increase this rate in column C of the escalation tab, but shall not propose an escalation rate which is below the USG minimum.
A20: "DBA Insurance" Tab
A21: 1 | B21: Subcontractors shall demonstrate on the DBA Tab of the GFPM-Subs how the estimated DBA Insurance Amount was calculated, if applicable.
A22: 2 | B22: DBA Insurance shall not be included in any FBLRs and may not have indirect expense or fee added to it.
A23: 3 | B23: Subcontractors shall provide a copy of the DBA Insurance quote, if applicable.
A24: "Sub FBLR & DBA Summary" Tab
A25: 1 | B25: To promote consistency between subcontractor files and prime offeror files, the Government has provided a FBLR & DBA Summary tab within the Subcontractor GFPM for the subcontractor to be able to more easily transfer its proposed FBLRs and DBA Insurance cost totals for each option period, to the prime offeror for the prime offeror to include in its proposal.
A26: 2 | B26: The Hours and FBLRs (columns F & G) are automatically populated in this tab as they are pulled directly from the 'Subcontractor Labor Build' tab.
A27: 3 | B27: The DBA Insurance costs must be manually input by the Subcontractors into the yellow cells, if applicable.

Sheet Subcontractor Labor Build
A1: Ordering Period 1:
A2: Ordering Period 1 Labor Categories & Hours
A3: Service | B3: ID | C3: Labor Category | D3: Reference | E3: Location | F3: Hours | H3: (Floor Rate) | I3: Direct Labor (Proposed) | J3: Direct Labor (Calculation) | K3: Fringe Benefit | L3: Labor OH 1 | M3: G&A | N3: FCCOM | O3: Cost | P3: Fee | Q3: FBLR | R3: Total Cost | S3: Total Fee | T3: Total Price
A4: CONUS
A5: Program Management | B5: 001 | C5: Project Management Specialist | D5: Section H.3.1.11 | E5: CONUS | H5: 42.46 | J5: =IF($I5<$H5,$H5,$I5) -> 42.46 | K5: =(J5*$K$4) -> 0 | L5: =(K5+J5)*$L$4 -> 0 | M5: =(K5+J5+L5)*$M$4 -> 0 | N5: =(J5+K5+L5+M5)*$N$4 -> 0 | O5: =SUM(J5:N5) -> 42.46 | P5: =IF($P$4<0,"N/A",$P$4*(J5+K5+L5+M5)) -> 0 | Q5: =SUM(O5:P5) -> 42.46 | R5: =O5*F5 -> 0 | S5: =P5*F5 -> 0 | T5: =Q5*F5 -> 0
A6: Field Service Representative (FSR) | B6: 002 | C6: Field Service Representative | D6: Section H.3.1.9 | E6: CONUS | H6: 29.76 | J6: =IF($I6<$H6,$H6,$I6) -> 29.76 | K6: =(J6*$K$4) -> 0 | L6: =(K6+J6)*$L$4 -> 0 | M6: =(K6+J6+L6)*$M$4 -> 0 | N6: =(J6+K6+L6+M6)*$N$4 -> 0 | O6: =SUM(J6:N6) -> 29.76 | P6: =IF($P$4<0,"N/A",$P$4*(J6+K6+L6+M6)) -> 0 | Q6: =SUM(O6:P6) -> 29.76 | R6: =O6*F6 -> 0 | S6: =P6*F6 -> 0 | T6: =Q6*F6 -> 0
A7: General Maintenance | B7: 003 | C7: Heavy Equipment Mechanic | D7: Section H.3.1.3 | E7: CONUS | H7: 29.76 | J7: =IF($I7<$H7,$H7,$I7) -> 29.76 | K7: =(J7*$K$4) -> 0 | L7: =(K7+J7)*$L$4 -> 0 | M7: =(K7+J7+L7)*$M$4 -> 0 | N7: =(J7+K7+L7+M7)*$N$4 -> 0 | O7: =SUM(J7:N7) -> 29.76 | P7: =IF($P$4<0,"N/A",$P$4*(J7+K7+L7+M7)) -> 0 | Q7: =SUM(O7:P7) -> 29.76 | R7: =O7*F7 -> 0 | S7: =P7*F7 -> 0 | T7: =Q7*F7 -> 0
A8: Modified Work Orders (MWO) | B8: 004 | C8: Field Service Representative | D8: Section H.3.1.9 | E8: CONUS | H8: 29.76 | J8: =IF($I8<$H8,$H8,$I8) -> 29.76 | K8: =(J8*$K$4) -> 0 | L8: =(K8+J8)*$L$4 -> 0 | M8: =(K8+J8+L8)*$M$4 -> 0 | N8: =(J8+K8+L8+M8)*$N$4 -> 0 | O8: =SUM(J8:N8) -> 29.76 | P8: =IF($P$4<0,"N/A",$P$4*(J8+K8+L8+M8)) -> 0 | Q8: =SUM(O8:P8) -> 29.76 | R8: =O8*F8 -> 0 | S8: =P8*F8 -> 0 | T8: =Q8*F8 -> 0
B9: 005 | C9: Modified Work Orders (MWO) | D9: Section H.3.1.6 | E9: CONUS | H9: 29.76 | J9: =IF($I9<$H9,$H9,$I9) -> 29.76 | K9: =(J9*$K$4) -> 0 | L9: =(K9+J9)*$L$4 -> 0 | M9: =(K9+J9+L9)*$M$4 -> 0 | N9: =(J9+K9+L9+M9)*$N$4 -> 0 | O9: =SUM(J9:N9) -> 29.76 | P9: =IF($P$4<0,"N/A",$P$4*(J9+K9+L9+M9)) -> 0 | Q9: =SUM(O9:P9) -> 29.76 | R9: =O9*F9 -> 0 | S9: =P9*F9 -> 0 | T9: =Q9*F9 -> 0
B10: 006 | C10: Quality Assurance | D10: Section H.3.1.10 | E10: CONUS | H10: 29.76 | J10: =IF($I10<$H10,$H10,$I10) -> 29.76 | K10: =(J10*$K$4) -> 0 | L10: =(K10+J10)*$L$4 -> 0 | M10: =(K10+J10+L10)*$M$4 -> 0 | N10: =(J10+K10+L10+M10)*$N$4 -> 0 | O10: =SUM(J10:N10) -> 29.76 | P10: =IF($P$4<0,"N/A",$P$4*(J10+K10+L10+M10)) -> 0 | Q10: =SUM(O10:P10) -> 29.76 | R10: =O10*F10 -> 0 | S10: =P10*F10 -> 0 | T10: =Q10*F10 -> 0
B11: 007 | C11: Software | D11: Section H.3.1.5 | E11: CONUS | H11: 29.76 | J11: =IF($I11<$H11,$H11,$I11) -> 29.76 | K11: =(J11*$K$4) -> 0 | L11: =(K11+J11)*$L$4 -> 0 | M11: =(K11+J11+L11)*$M$4 -> 0 | N11: =(J11+K11+L11+M11)*$N$4 -> 0 | O11: =SUM(J11:N11) -> 29.76 | P11: =IF($P$4<0,"N/A",$P$4*(J11+K11+L11+M11)) -> 0 | Q11: =SUM(O11:P11) -> 29.76 | R11: =O11*F11 -> 0 | S11: =P11*F11 -> 0 | T11: =Q11*F11 -> 0
B12: 008 | C12: Welder | D12: Section H.3.1.4 | E12: CONUS | H12: 23.57 | J12: =IF($I12<$H12,$H12,$I12) -> 23.57 | K12: =(J12*$K$4) -> 0 | L12: =(K12+J12)*$L$4 -> 0 | M12: =(K12+J12+L12)*$M$4 -> 0 | N12: =(J12+K12+L12+M12)*$N$4 -> 0 | O12: =SUM(J12:N12) -> 23.57 | P12: =IF($P$4<0,"N/A",$P$4*(J12+K12+L12+M12)) -> 0 | Q12: =SUM(O12:P12) -> 23.57 | R12: =O12*F12 -> 0 | S12: =P12*F12 -> 0 | T12: =Q12*F12 -> 0
A13: New Equipment Training (NET) | B13: 009 | C13: Instructor Supervisor | D13: Section H.3.1.7 | E13: CONUS | H13: 25.3 | J13: =IF($I13<$H13,$H13,$I13) -> 25.3 | K13: =(J13*$K$4) -> 0 | L13: =(K13+J13)*$L$4 -> 0 | M13: =(K13+J13+L13)*$M$4 -> 0 | N13: =(J13+K13+L13+M13)*$N$4 -> 0 | O13: =SUM(J13:N13) -> 25.3 | P13: =IF($P$4<0,"N/A",$P$4*(J13+K13+L13+M13)) -> 0 | Q13: =SUM(O13:P13) -> 25.3 | R13: =O13*F13 -> 0 | S13: =P13*F13 -> 0 | T13: =Q13*F13 -> 0
B14: 010 | C14: Instructor | D14: Section H.3.1.8 | E14: CONUS | H14: 25.3 | J14: =IF($I14<$H14,$H14,$I14) -> 25.3 | K14: =(J14*$K$4) -> 0 | L14: =(K14+J14)*$L$4 -> 0 | M14: =(K14+J14+L14)*$M$4 -> 0 | N14: =(J14+K14+L14+M14)*$N$4 -> 0 | O14: =SUM(J14:N14) -> 25.3 | P14: =IF($P$4<0,"N/A",$P$4*(J14+K14+L14+M14)) -> 0 | Q14: =SUM(O14:P14) -> 25.3 | R14: =O14*F14 -> 0 | S14: =P14*F14 -> 0 | T14: =Q14*F14 -> 0
A15: Total Package Fielding (TPF) and De-processing | B15: 011 | C15: Heavy Equipment Mechanic | D15: Section H.3.1.3 | E15: CONUS | H15: 29.76 | J15: =IF($I15<$H15,$H15,$I15) -> 29.76 | K15: =(J15*$K$4) -> 0 | L15: =(K15+J15)*$L$4 -> 0 | M15: =(K15+J15+L15)*$M$4 -> 0 | N15: =(J15+K15+L15+M15)*$N$4 -> 0 | O15: =SUM(J15:N15) -> 29.76 | P15: =IF($P$4<0,"N/A",$P$4*(J15+K15+L15+M15)) -> 0 | Q15: =SUM(O15:P15) -> 29.76 | R15: =O15*F15 -> 0 | S15: =P15*F15 -> 0 | T15: =Q15*F15 -> 0
B16: 012 | C16: Material Handling Specialist | D16: Section H.3.1.2 | E16: CONUS | H16: 25.91 | J16: =IF($I16<$H16,$H16,$I16) -> 25.91 | K16: =(J16*$K$4) -> 0 | L16: =(K16+J16)*$L$4 -> 0 | M16: =(K16+J16+L16)*$M$4 -> 0 | N16: =(J16+K16+L16+M16)*$N$4 -> 0 | O16: =SUM(J16:N16) -> 25.91 | P16: =IF($P$4<0,"N/A",$P$4*(J16+K16+L16+M16)) -> 0 | Q16: =SUM(O16:P16) -> 25.91 | R16: =O16*F16 -> 0 | S16: =P16*F16 -> 0 | T16: =Q16*F16 -> 0
B17: 013 | C17: Quality Assurance | D17: Section H.3.1.10 | E17: CONUS | H17: 29.76 | J17: =IF($I17<$H17,$H17,$I17) -> 29.76 | K17: =(J17*$K$4) -> 0 | L17: =(K17+J17)*$L$4 -> 0 | M17: =(K17+J17+L17)*$M$4 -> 0 | N17: =(J17+K17+L17+M17)*$N$4 -> 0 | O17: =SUM(J17:N17) -> 29.76 | P17: =IF($P$4<0,"N/A",$P$4*(J17+K17+L17+M17)) -> 0 | Q17: =SUM(O17:P17) -> 29.76 | R17: =O17*F17 -> 0 | S17: =P17*F17 -> 0 | T17: =Q17*F17 -> 0
B18: 014 | C18: Supply/Procurement Specialist | D18: Section H.3.1.1 | E18: CONUS | H18: 33.8 | J18: =IF($I18<$H18,$H18,$I18) -> 33.8 | K18: =(J18*$K$4) -> 0 | L18: =(K18+J18)*$L$4 -> 0 | M18: =(K18+J18+L18)*$M$4 -> 0 | N18: =(J18+K18+L18+M18)*$N$4 -> 0 | O18: =SUM(J18:N18) -> 33.8 | P18: =IF($P$4<0,"N/A",$P$4*(J18+K18+L18+M18)) -> 0 | Q18: =SUM(O18:P18) -> 33.8 | R18: =O18*F18 -> 0 | S18: =P18*F18 -> 0 | T18: =Q18*F18 -> 0
B19: 015 | C19: Welder | D19: Section H.3.1.4 | E19: CONUS | H19: 23.57 | J19: =IF($I19<$H19,$H19,$I19) -> 23.57 | K19: =(J19*$K$4) -> 0 | L19: =(K19+J19)*$L$4 -> 0 | M19: =(K19+J19+L19)*$M$4 -> 0 | N19: =(J19+K19+L19+M19)*$N$4 -> 0 | O19: =SUM(J19:N19) -> 23.57 | P19: =IF($P$4<0,"N/A",$P$4*(J19+K19+L19+M19)) -> 0 | Q19: =SUM(O19:P19) -> 23.57 | R19: =O19*F19 -> 0 | S19: =P19*F19 -> 0 | T19: =Q19*F19 -> 0
A20: OCONUS
A21: Field Service Representative (FSR) | B21: 016 | C21: Field Service Representative | E21: OCONUS | H21: 31.25 | J21: =IF($I21<$H21,$H21,$I21) -> 31.25 | K21: =(J21*$K$4) -> 0 | L21: =(K21+J21)*$L$4 -> 0 | M21: =(K21+J21+L21)*$M$4 -> 0 | N21: =(J21+K21+L21+M21)*$N$4 -> 0 | O21: =SUM(J21:N21) -> 31.25 | P21: =IF($P$4<0,"N/A",$P$4*(J21+K21+L21+M21)) -> 0 | Q21: =SUM(O21:P21) -> 31.25 | R21: =O21*F21 -> 0 | S21: =P21*F21 -> 0 | T21: =Q21*F21 -> 0
A22: General Maintenance | B22: 017 | C22: Heavy Equipment Mechanic | E22: OCONUS | H22: 31.25 | J22: =IF($I22<$H22,$H22,$I22) -> 31.25 | K22: =(J22*$K$4) -> 0 | L22: =(K22+J22)*$L$4 -> 0 | M22: =(K22+J22+L22)*$M$4 -> 0 | N22: =(J22+K22+L22+M22)*$N$4 -> 0 | O22: =SUM(J22:N22) -> 31.25 | P22: =IF($P$4<0,"N/A",$P$4*(J22+K22+L22+M22)) -> 0 | Q22: =SUM(O22:P22) -> 31.25 | R22: =O22*F22 -> 0 | S22: =P22*F22 -> 0 | T22: =Q22*F22 -> 0
A23: New Equipment Training (NET) | B23: 018 | C23: Instructor Supervisor | E23: OCONUS | H23: 26.57 | J23: =IF($I23<$H23,$H23,$I23) -> 26.57 | K23: =(J23*$K$4) -> 0 | L23: =(K23+J23)*$L$4 -> 0 | M23: =(K23+J23+L23)*$M$4 -> 0 | N23: =(J23+K23+L23+M23)*$N$4 -> 0 | O23: =SUM(J23:N23) -> 26.57 | P23: =IF($P$4<0,"N/A",$P$4*(J23+K23+L23+M23)) -> 0 | Q23: =SUM(O23:P23) -> 26.57 | R23: =O23*F23 -> 0 | S23: =P23*F23 -> 0 | T23: =Q23*F23 -> 0
B24: 019 | C24: Instructor | E24: OCONUS | H24: 26.57 | J24: =IF($I24<$H24,$H24,$I24) -> 26.57 | K24: =(J24*$K$4) -> 0 | L24: =(K24+J24)*$L$4 -> 0 | M24: =(K24+J24+L24)*$M$4 -> 0 | N24: =(J24+K24+L24+M24)*$N$4 -> 0 | O24: =SUM(J24:N24) -> 26.57 | P24: =IF($P$4<0,"N/A",$P$4*(J24+K24+L24+M24)) -> 0 | Q24: =SUM(O24:P24) -> 26.57 | R24: =O24*F24 -> 0 | S24: =P24*F24 -> 0 | T24: =Q24*F24 -> 0
A25: Total Package Fielding (TPF) and De-processing | B25: 020 | C25: Heavy Equipment Mechanic | E25: OCONUS | H25: 31.25 | J25: =IF($I25<$H25,$H25,$I25) -> 31.25 | K25: =(J25*$K$4) -> 0 | L25: =(K25+J25)*$L$4 -> 0 | M25: =(K25+J25+L25)*$M$4 -> 0 | N25: =(J25+K25+L25+M25)*$N$4 -> 0 | O25: =SUM(J25:N25) -> 31.25 | P25: =IF($P$4<0,"N/A",$P$4*(J25+K25+L25+M25)) -> 0 | Q25: =SUM(O25:P25) -> 31.25 | R25: =O25*F25 -> 0 | S25: =P25*F25 -> 0 | T25: =Q25*F25 -> 0
B26: 021 | C26: Material Handling Specialist | E26: OCONUS | H26: 27.21 | J26: =IF($I26<$H26,$H26,$I26) -> 27.21 | K26: =(J26*$K$4) -> 0 | L26: =(K26+J26)*$L$4 -> 0 | M26: =(K26+J26+L26)*$M$4 -> 0 | N26: =(J26+K26+L26+M26)*$N$4 -> 0 | O26: =SUM(J26:N26) -> 27.21 | P26: =IF($P$4<0,"N/A",$P$4*(J26+K26+L26+M26)) -> 0 | Q26: =SUM(O26:P26) -> 27.21 | R26: =O26*F26 -> 0 | S26: =P26*F26 -> 0 | T26: =Q26*F26 -> 0
B27: 022 | C27: Quality Assurance | E27: OCONUS | H27: 31.25 | J27: =IF($I27<$H27,$H27,$I27) -> 31.25 | K27: =(J27*$K$4) -> 0 | L27: =(K27+J27)*$L$4 -> 0 | M27: =(K27+J27+L27)*$M$4 -> 0 | N27: =(J27+K27+L27+M27)*$N$4 -> 0 | O27: =SUM(J27:N27) -> 31.25 | P27: =IF($P$4<0,"N/A",$P$4*(J27+K27+L27+M27)) -> 0 | Q27: =SUM(O27:P27) -> 31.25 | R27: =O27*F27 -> 0 | S27: =P27*F27 -> 0 | T27: =Q27*F27 -> 0
B28: 023 | C28: Supply/Procurement Specialist | E28: OCONUS | H28: 35.49 | J28: =IF($I28<$H28,$H28,$I28) -> 35.49 | K28: =(J28*$K$4) -> 0 | L28: =(K28+J28)*$L$4 -> 0 | M28: =(K28+J28+L28)*$M$4 -> 0 | N28: =(J28+K28+L28+M28)*$N$4 -> 0 | O28: =SUM(J28:N28) -> 35.49 | P28: =IF($P$4<0,"N/A",$P$4*(J28+K28+L28+M28)) -> 0 | Q28: =SUM(O28:P28) -> 35.49 | R28: =O28*F28 -> 0 | S28: =P28*F28 -> 0 | T28: =Q28*F28 -> 0
A29: Ordering Period 2:
A30: Ordering Period 2 Labor Categories & Hours
A31: Service | B31: ID | C31: Labor Category | D31: Reference | E31: Location | F31: Hours | H31: (Floor Rate) | I31: Direct Labor (Proposed) | J31: Direct Labor (Calculation) | K31: Fringe Benefit | L31: Labor OH 1 | M31: G&A | N31: FCCOM | O31: Cost | P31: Fee | Q31: FBLR | R31: Total Cost | S31: Total Fee | T31: Total Price
A32: CONUS
A33: Program Management | B33: 001 | C33: Project Management Specialist | D33: Section H.3.1.11 | E33: CONUS | H33: =H5+(H5*Escalation!$D$2) -> 43.81872 | I33: =I5+(I5*Escalation!$D$2) -> 0 | J33: =IF($I33<$H33,$H33,$I33) -> 43.81872 | K33: =(J33*$K$4) -> 0 | L33: =(K33+J33)*$L$4 -> 0 | M33: =(K33+J33+L33)*$M$4 -> 0 | N33: =(J33+K33+L33+M33)*$N$4 -> 0 | O33: =SUM(J33:N33) -> 43.81872 | P33: =IF($P$4<0,"N/A",$P$4*(J33+K33+L33+M33)) -> 0 | Q33: =SUM(O33:P33) -> 43.81872 | R33: =O33*F33 -> 0 | S33: =P33*F33 -> 0 | T33: =Q33*F33 -> 0
A34: Field Service Representative (FSR) | B34: 002 | C34: Field Service Representative | D34: Section H.3.1.9 | E34: CONUS | H34: =H6+(H6*Escalation!$D$2) -> 30.71232 | I34: =I6+(I6*Escalation!$D$2) -> 0 | J34: =IF($I34<$H34,$H34,$I34) -> 30.71232 | K34: =(J34*$K$4) -> 0 | L34: =(K34+J34)*$L$4 -> 0 | M34: =(K34+J34+L34)*$M$4 -> 0 | N34: =(J34+K34+L34+M34)*$N$4 -> 0 | O34: =SUM(J34:N34) -> 30.71232 | P34: =IF($P$4<0,"N/A",$P$4*(J34+K34+L34+M34)) -> 0 | Q34: =SUM(O34:P34) -> 30.71232 | R34: =O34*F34 -> 0 | S34: =P34*F34 -> 0 | T34: =Q34*F34 -> 0
A35: General Maintenance | B35: 003 | C35: Heavy Equipment Mechanic | D35: Section H.3.1.3 | E35: CONUS | H35: =H7+(H7*Escalation!$D$2) -> 30.71232 | I35: =I7+(I7*Escalation!$D$2) -> 0 | J35: =IF($I35<$H35,$H35,$I35) -> 30.71232 | K35: =(J35*$K$4) -> 0 | L35: =(K35+J35)*$L$4 -> 0 | M35: =(K35+J35+L35)*$M$4 -> 0 | N35: =(J35+K35+L35+M35)*$N$4 -> 0 | O35: =SUM(J35:N35) -> 30.71232 | P35: =IF($P$4<0,"N/A",$P$4*(J35+K35+L35+M35)) -> 0 | Q35: =SUM(O35:P35) -> 30.71232 | R35: =O35*F35 -> 0 | S35: =P35*F35 -> 0 | T35: =Q35*F35 -> 0
A36: Modified Work Orders (MWO) | B36: 004 | C36: Field Service Representative | D36: Section H.3.1.9 | E36: CONUS | H36: =H8+(H8*Escalation!$D$2) -> 30.71232 | I36: =I8+(I8*Escalation!$D$2) -> 0 | J36: =IF($I36<$H36,$H36,$I36) -> 30.71232 | K36: =(J36*$K$4) -> 0 | L36: =(K36+J36)*$L$4 -> 0 | M36: =(K36+J36+L36)*$M$4 -> 0 | N36: =(J36+K36+L36+M36)*$N$4 -> 0 | O36: =SUM(J36:N36) -> 30.71232 | P36: =IF($P$4<0,"N/A",$P$4*(J36+K36+L36+M36)) -> 0 | Q36: =SUM(O36:P36) -> 30.71232 | R36: =O36*F36 -> 0 | S36: =P36*F36 -> 0 | T36: =Q36*F36 -> 0
B37: 005 | C37: Modified Work Orders (MWO) | D37: Section H.3.1.6 | E37: CONUS | H37: =H9+(H9*Escalation!$D$2) -> 30.71232 | I37: =I9+(I9*Escalation!$D$2) -> 0 | J37: =IF($I37<$H37,$H37,$I37) -> 30.71232 | K37: =(J37*$K$4) -> 0 | L37: =(K37+J37)*$L$4 -> 0 | M37: =(K37+J37+L37)*$M$4 -> 0 | N37: =(J37+K37+L37+M37)*$N$4 -> 0 | O37: =SUM(J37:N37) -> 30.71232 | P37: =IF($P$4<0,"N/A",$P$4*(J37+K37+L37+M37)) -> 0 | Q37: =SUM(O37:P37) -> 30.71232 | R37: =O37*F37 -> 0 | S37: =P37*F37 -> 0 | T37: =Q37*F37 -> 0
B38: 006 | C38: Quality Assurance | D38: Section H.3.1.10 | E38: CONUS | H38: =H10+(H10*Escalation!$D$2) -> 30.71232 | I38: =I10+(I10*Escalation!$D$2) -> 0 | J38: =IF($I38<$H38,$H38,$I38) -> 30.71232 | K38: =(J38*$K$4) -> 0 | L38: =(K38+J38)*$L$4 -> 0 | M38: =(K38+J38+L38)*$M$4 -> 0 | N38: =(J38+K38+L38+M38)*$N$4 -> 0 | O38: =SUM(J38:N38) -> 30.71232 | P38: =IF($P$4<0,"N/A",$P$4*(J38+K38+L38+M38)) -> 0 | Q38: =SUM(O38:P38) -> 30.71232 | R38: =O38*F38 -> 0 | S38: =P38*F38 -> 0 | T38: =Q38*F38 -> 0
B39: 007 | C39: Software | D39: Section H.3.1.5 | E39: CONUS | H39: =H11+(H11*Escalation!$D$2) -> 30.71232 | I39: =I11+(I11*Escalation!$D$2) -> 0 | J39: =IF($I39<$H39,$H39,$I39) -> 30.71232 | K39: =(J39*$K$4) -> 0 | L39: =(K39+J39)*$L$4 -> 0 | M39: =(K39+J39+L39)*$M$4 -> 0 | N39: =(J39+K39+L39+M39)*$N$4 -> 0 | O39: =SUM(J39:N39) -> 30.71232 | P39: =IF($P$4<0,"N/A",$P$4*(J39+K39+L39+M39)) -> 0 | Q39: =SUM(O39:P39) -> 30.71232 | R39: =O39*F39 -> 0 | S39: =P39*F39 -> 0 | T39: =Q39*F39 -> 0
B40: 008 | C40: Welder | D40: Section H.3.1.4 | E40: CONUS | H40: =H12+(H12*Escalation!$D$2) -> 24.32424 | I40: =I12+(I12*Escalation!$D$2) -> 0 | J40: =IF($I40<$H40,$H40,$I40) -> 24.32424 | K40: =(J40*$K$4) -> 0 | L40: =(K40+J40)*$L$4 -> 0 | M40: =(K40+J40+L40)*$M$4 -> 0 | N40: =(J40+K40+L40+M40)*$N$4 -> 0 | O40: =SUM(J40:N40) -> 24.32424 | P40: =IF($P$4<0,"N/A",$P$4*(J40+K40+L40+M40)) -> 0 | Q40: =SUM(O40:P40) -> 24.32424 | R40: =O40*F40 -> 0 | S40: =P40*F40 -> 0 | T40: =Q40*F40 -> 0
...

Sheet Escalation
A1: POP | B1: Minimum Escalation | C1: Proposed Escalation | D1: Calculated Escalation
A2: Ordering Period 2 | B2: 0.032 | D2: =IF($C2<$B2,$B2,$C2) -> 0.032
A3: Ordering Period 3 | B3: 0.027 | D3: =IF($C3<$B3,$B3,$C3) -> 0.027
A4: Ordering Period 4 | B4: 0.027 | D4: =IF($C4<$B4,$B4,$C4) -> 0.027
A5: Ordering Period 5 | B5: 0.027 | D5: =IF($C5<$B5,$B5,$C5) -> 0.027

Sheet Sub FBLR & DBA Summary
A1: Service | B1: ID | C1: Labor Category | D1: Reference | E1: Location | F1: Hours | G1: SUB FBLR
A2: Ordering Period 1
A3: CONUS
A4: Program Management | B4: 001 | C4: Project Management Specialist | D4: Section H.3.1.11 | E4: CONUS | F4: ='Subcontractor Labor Build'!F5 -> 0 | G4: ='Subcontractor Labor Build'!Q5 -> 42.46
A5: Field Service Representative (FSR) | B5: 002 | C5: Field Service Representative | D5: Section H.3.1.9 | E5: CONUS | F5: ='Subcontractor Labor Build'!F6 -> 0 | G5: ='Subcontractor Labor Build'!Q6 -> 29.76
A6: General Maintenance | B6: 003 | C6: Heavy Equipment Mechanic | D6: Section H.3.1.3 | E6: CONUS | F6: ='Subcontractor Labor Build'!F7 -> 0 | G6: ='Subcontractor Labor Build'!Q7 -> 29.76
A7: Modified Work Orders (MWO) | B7: 004 | C7: Field Service Representative | D7: Section H.3.1.9 | E7: CONUS | F7: ='Subcontractor Labor Build'!F8 -> 0 | G7: ='Subcontractor Labor Build'!Q8 -> 29.76
B8: 005 | C8: Modified Work Orders (MWO) | D8: Section H.3.1.6 | E8: CONUS | F8: ='Subcontractor Labor Build'!F9 -> 0 | G8: ='Subcontractor Labor Build'!Q9 -> 29.76
B9: 006 | C9: Quality Assurance | D9: Section H.3.1.10 | E9: CONUS | F9: ='Subcontractor Labor Build'!F10 -> 0 | G9: ='Subcontractor Labor Build'!Q10 -> 29.76 | K9: DBA Insurance Totals
B10: 007 | C10: Software | D10: Section H.3.1.5 | E10: CONUS | F10: ='Subcontractor Labor Build'!F11 -> 0 | G10: ='Subcontractor Labor Build'!Q11 -> 29.76
B11: 008 | C11: Welder | D11: Section H.3.1.4 | E11: CONUS | F11: ='Subcontractor Labor Build'!F12 -> 0 | G11: ='Subcontractor Labor Build'!Q12 -> 23.57 | K11: Base - DBA Total | M11: 0
A12: New Equipment Training (NET) | B12: 009 | C12: Instructor Supervisor | D12: Section H.3.1.7 | E12: CONUS | F12: ='Subcontractor Labor Build'!F13 -> 0 | G12: ='Subcontractor Labor Build'!Q13 -> 25.3 | K12: Option 1 - DBA Total | M12: 0
B13: 010 | C13: Instructor | D13: Section H.3.1.8 | E13: CONUS | F13: ='Subcontractor Labor Build'!F14 -> 0 | G13: ='Subcontractor Labor Build'!Q14 -> 25.3 | K13: Option 2 - DBA Total | M13: 0
A14: Total Package Fielding (TPF) and De-processing | B14: 011 | C14: Heavy Equipment Mechanic | D14: Section H.3.1.3 | E14: CONUS | F14: ='Subcontractor Labor Build'!F15 -> 0 | G14: ='Subcontractor Labor Build'!Q15 -> 29.76 | K14: Option 3 - DBA Total | M14: 0
B15: 012 | C15: Material Handling Specialist | D15: Section H.3.1.2 | E15: CONUS | F15: ='Subcontractor Labor Build'!F16 -> 0 | G15: ='Subcontractor Labor Build'!Q16 -> 25.91 | K15: Option 4 - DBA Total | M15: 0
B16: 013 | C16: Quality Assurance | D16: Section H.3.1.10 | E16: CONUS | F16: ='Subcontractor Labor Build'!F17 -> 0 | G16: ='Subcontractor Labor Build'!Q17 -> 29.76 | K16: Dash 8 - DBA Total | M16: =M15*0.5 -> 0
B17: 014 | C17: Supply/Procurement Specialist | D17: Section H.3.1.1 | E17: CONUS | F17: ='Subcontractor Labor Build'!F18 -> 0 | G17: ='Subcontractor Labor Build'!Q18 -> 33.8
B18: 015 | C18: Welder | D18: Section H.3.1.4 | E18: CONUS | F18: ='Subcontractor Labor Build'!F19 -> 0 | G18: ='Subcontractor Labor Build'!Q19 -> 23.57 | K18: Total Subcontractor DBA | M18: =M11+M12+M13+M14+M15+M16 -> 0
A19: OCONUS
A20: Field Service Representative (FSR) | B20: 016 | C20: Field Service Representative | E20: OCONUS | F20: ='Subcontractor Labor Build'!F21 -> 0 | G20: ='Subcontractor Labor Build'!Q21 -> 31.25
A21: General Maintenance | B21: 017 | C21: Heavy Equipment Mechanic | E21: OCONUS | F21: ='Subcontractor Labor Build'!F22 -> 0 | G21: ='Subcontractor Labor Build'!Q22 -> 31.25
A22: New Equipment Training (NET) | B22: 018 | C22: Instructor Supervisor | E22: OCONUS | F22: ='Subcontractor Labor Build'!F23 -> 0 | G22: ='Subcontractor Labor Build'!Q23 -> 26.57
B23: 019 | C23: Instructor | E23: OCONUS | F23: ='Subcontractor Labor Build'!F24 -> 0 | G23: ='Subcontractor Labor Build'!Q24 -> 26.57
A24: Total Package Fielding (TPF) and De-processing | B24: 020 | C24: Heavy Equipment Mechanic | E24: OCONUS | F24: ='Subcontractor Labor Build'!F25 -> 0 | G24: ='Subcontractor Labor Build'!Q25 -> 31.25
B25: 021 | C25: Material Handling Specialist | E25: OCONUS | F25: ='Subcontractor Labor Build'!F26 -> 0 | G25: ='Subcontractor Labor Build'!Q26 -> 27.21
B26: 022 | C26: Quality Assurance | E26: OCONUS | F26: ='Subcontractor Labor Build'!F27 -> 0 | G26: ='Subcontractor Labor Build'!Q27 -> 31.25
B27: 023 | C27: Supply/Procurement Specialist | E27: OCONUS | F27: ='Subcontractor Labor Build'!F28 -> 0 | G27: ='Subcontractor Labor Build'!Q28 -> 35.49
A28: Ordering Period 2
A29: CONUS
A30: Program Management | B30: 001 | C30: Project Management Specialist | D30: Section H.3.1.11 | E30: CONUS | F30: ='Subcontractor Labor Build'!F33 -> 0 | G30: ='Subcontractor Labor Build'!Q33 -> 43.81872
A31: Field Service Representative (FSR) | B31: 002 | C31: Field Service Representative | D31: Section H.3.1.9 | E31: CONUS | F31: ='Subcontractor Labor Build'!F34 -> 0 | G31: ='Subcontractor Labor Build'!Q34 -> 30.71232
A32: General Maintenance | B32: 003 | C32: Heavy Equipment Mechanic | D32: Section H.3.1.3 | E32: CONUS | F32: ='Subcontractor Labor Build'!F35 -> 0 | G32: ='Subcontractor Labor Build'!Q35 -> 30.71232
A33: Modified Work Orders (MWO) | B33: 004 | C33: Field Service Representative | D33: Section H.3.1.9 | E33: CONUS | F33: ='Subcontractor Labor Build'!F36 -> 0 | G33: ='Subcontractor Labor Build'!Q36 -> 30.71232
B34: 005 | C34: Modified Work Orders (MWO) | D34: Section H.3.1.6 | E34: CONUS | F34: ='Subcontractor Labor Build'!F37 -> 0 | G34: ='Subcontractor Labor Build'!Q37 -> 30.71232
B35: 006 | C35: Quality Assurance | D35: Section H.3.1.10 | E35: CONUS | F35: ='Subcontractor Labor Build'!F38 -> 0 | G35: ='Subcontractor Labor Build'!Q38 -> 30.71232
B36: 007 | C36: Software | D36: Section H.3.1.5 | E36: CONUS | F36: ='Subcontractor Labor Build'!F39 -> 0 | G36: ='Subcontractor Labor Build'!Q39 -> 30.71232
B37: 008 | C37: Welder | D37: Section H.3.1.4 | E37: CONUS | F37: ='Subcontractor Labor Build'!F40 -> 0 | G37: ='Subcontractor Labor Build'!Q40 -> 24.32424
A38: New Equipment Training (NET) | B38: 009 | C38: Instructor Supervisor | D38: Section H.3.1.7 | E38: CONUS | F38: ='Subcontractor Labor Build'!F41 -> 0 | G38: ='Subcontractor Labor Build'!Q41 -> 26.1096
B39: 010 | C39: Instructor | D39: Section H.3.1.8 | E39: CONUS | F39: ='Subcontractor Labor Build'!F42 -> 0 | G39: ='Subcontractor Labor Build'!Q42 -> 26.1096
A40: Total Package Fielding (TPF) and De-processing | B40: 011 | C40: Heavy Equipment Mechanic | D40: Section H.3.1.3 | E40: CONUS | F40: ='Subcontractor Labor Build'!F43 -> 0 | G40: ='Subcontractor Labor Build'!Q43 -> 30.71232
...

Sheet DBA Insurance
A1: Subcontractors shall use this tab to demonstrate how the estimated DBA Insurance costs were calculated, if applicable.
