Workbook
Name A4AV5percent: #REF!
Name Kanto10percent: #REF!
Name Kanto23percent: #REF!
Name KantoAV5percent: #REF!
Name KantoAverage: #REF!
Name KantoU: #REF!
Name U412percent: #REF!
Name U423percent: #REF!
Name U4average: #REF!
Name Upper4: #REF!

Sheet Sheet1
A1: GT | B1: =SUM(B2,B3) -> 8411
A2: Point | B2: 6811
A3: Distance | B3: 1600 | E3: 0.045
A4: Ammo | B4: 543 | C4: 29 | D4: 0.064
A5: Dangerous | C5: 228 | D5: 0.027
A6: Sensitive | C6: 119 | D6: 0.018
A7: Hazard | C7: 106 | D7: 0.018
A8: sen/hazard | C8: 61
A11: G4
A12: Cancel | B12: 5000 | D12: Demurrage | E12: 25
A13: same day | B13: 32 | D13: winter | E13: 14
D14: Midnight | E14: 5
A16: Reefer | B16: 2540
A19: OSOW | B19: 970 | C19: 181
A20: SGDYND | B20: 20 | C20: 18 | D20: 14 | E20: =SUM(C20:D20) -> 32
B21: 30 | C21: 18 | D21: 25 | E21: =SUM(C21:D21) -> 43
B22: 36 | C22: 14 | D22: 9 | E22: =SUM(C22:D22) -> 23
E23: =SUM(E20:E22) -> 98
A25: SGDFuji | C25: 20 | D25: 24 | E25: =SUM(C25:D25) -> 44
C26: 11 | E26: =SUM(C26:D26) -> 11
C27: 16 | D27: 11 | E27: =SUM(C27:D27) -> 27
A31: Forklift | B31: 100 | C31: 91
A32: 7 | C32: 38
A33: Crane | B33: 80 | C33: 68
A34: 25 | C34: 55
A35: 50 | C35: 13

Sheet A. General
A1: EXHIBIT AA: GENERAL TRUCKING FAMILY PRICING SCHEDULE (BASE YEAR 0001) | N1: EXHIBIT AB: GENERAL TRUCKING FAMILY PRICING SCHEDULE (BASE YEAR 1001) | AA1: EXHIBIT AC: GENERAL TRUCKING FAMILY PRICING SCHEDULE (BASE YEAR 2001) | AN1: EXHIBIT AD: GENERAL TRUCKING FAMILY PRICING SCHEDULE (BASE YEAR 3001) | BA1: EXHIBIT AE: GENERAL TRUCKING FAMILY PRICING SCHEDULE (BASE YEAR 4001)
A2: POINT-TO-POINT ROUTES (IAW PWS 3.4.1.): All listed unit prices shall be one-way rates per truckload of general freight. If proposing under the Mainland portion of the General Trucking family, offerors shall provide proposed unit prices for all listed Items. | N2: POINT-TO-POINT ROUTES (IAW PWS 3.4.1.): All listed unit prices shall be one-way rates per truckload of general freight. If proposing under the Mainland portion of the General Trucking family, offerors shall provide proposed unit prices for all listed Items. | AA2: POINT-TO-POINT ROUTES (IAW PWS 3.4.1.): All listed unit prices shall be one-way rates per truckload of general freight. If proposing under the Mainland portion of the General Trucking family, offerors shall provide proposed unit prices for all listed Items. | AN2: POINT-TO-POINT ROUTES (IAW PWS 3.4.1.): All listed unit prices shall be one-way rates per truckload of general freight. If proposing under the Mainland portion of the General Trucking family, offerors shall provide proposed unit prices for all listed Items. | BA2: POINT-TO-POINT ROUTES (IAW PWS 3.4.1.): All listed unit prices shall be one-way rates per truckload of general freight. If proposing under the Mainland portion of the General Trucking family, offerors shall provide proposed unit prices for all listed Items.
A3: Item No. | B3: Description | H3: Est. Qty | I3: Unit | K3: Unit Price | M3: Est. Total | N3: Item No. | O3: Description | U3: Est. Qty | V3: Unit | X3: Unit Price | Z3: Est. Total | AA3: Item No. | AB3: Description | AH3: Est. Qty | AI3: Unit | AK3: Unit Price | AM3: Est. Total | AN3: Item No. | AO3: Description | AU3: Est. Qty | AV3: Unit | AX3: Unit Price | AZ3: Est. Total | BA3: Item No. | BB3: Description | BH3: Est. Qty | BI3: Unit | BK3: Unit Price | BM3: Est. Total
B4: Between | C4: Sagami General Depot | O4: Between | P4: Sagami General Depot | AB4: Between | AC4: Sagami General Depot | AO4: Between | AP4: Sagami General Depot | BB4: Between | BC4: Sagami General Depot
B5: and | C5: US Fleet Activities, Yokosuka (52km) | O5: and | P5: US Fleet Activities, Yokosuka (52km) | AB5: and | AC5: US Fleet Activities, Yokosuka (52km) | AO5: and | AP5: US Fleet Activities, Yokosuka (52km) | BB5: and | BC5: US Fleet Activities, Yokosuka (52km)
A6: AA01 | C6: Medium/Large Truck | H6: 959 | I6: EA | J6: ¥ | L6: ¥ | M6: =H6*K6 -> 0 | N6: AB01 | P6: Medium/Large Truck | U6: 959 | V6: EA | W6: ¥ | Y6: ¥ | Z6: =U6*X6 -> 0 | AA6: AC01 | AC6: Medium/Large Truck | AH6: 959 | AI6: EA | AJ6: ¥ | AL6: ¥ | AM6: =AH6*AK6 -> 0 | AN6: AD01 | AP6: Medium/Large Truck | AU6: 959 | AV6: EA | AW6: ¥ | AY6: ¥ | AZ6: =AU6*AX6 -> 0 | BA6: AE01 | BC6: Medium/Large Truck | BH6: 959 | BI6: EA | BJ6: ¥ | BL6: ¥ | BM6: =BH6*BK6 -> 0
B7: Between | C7: Sagami General Depot | O7: Between | P7: Sagami General Depot | AB7: Between | AC7: Sagami General Depot | AO7: Between | AP7: Sagami General Depot | BB7: Between | BC7: Sagami General Depot
B8: and | C8: Yokota Air Base (24km) | O8: and | P8: Yokota Air Base (24km) | AB8: and | AC8: Yokota Air Base (24km) | AO8: and | AP8: Yokota Air Base (24km) | BB8: and | BC8: Yokota Air Base (24km)
A9: AA02 | C9: Medium/Large Truck | H9: 818 | I9: EA | J9: ¥ | L9: ¥ | M9: =H9*K9 -> 0 | N9: AB02 | P9: Medium/Large Truck | U9: 818 | V9: EA | W9: ¥ | Y9: ¥ | Z9: =U9*X9 -> 0 | AA9: AC02 | AC9: Medium/Large Truck | AH9: 818 | AI9: EA | AJ9: ¥ | AL9: ¥ | AM9: =AH9*AK9 -> 0 | AN9: AD02 | AP9: Medium/Large Truck | AU9: 818 | AV9: EA | AW9: ¥ | AY9: ¥ | AZ9: =AU9*AX9 -> 0 | BA9: AE02 | BC9: Medium/Large Truck | BH9: 818 | BI9: EA | BJ9: ¥ | BL9: ¥ | BM9: =BH9*BK9 -> 0
B10: Between | C10: Sagami General Depot | O10: Between | P10: Sagami General Depot | AB10: Between | AC10: Sagami General Depot | AO10: Between | AP10: Sagami General Depot | BB10: Between | BC10: Sagami General Depot
B11: and | C11: USN Air Facility, Atsugi (20km) | O11: and | P11: USN Air Facility, Atsugi (20km) | AB11: and | AC11: USN Air Facility, Atsugi (20km) | AO11: and | AP11: USN Air Facility, Atsugi (20km) | BB11: and | BC11: USN Air Facility, Atsugi (20km)
A12: AA03 | C12: Medium/Large Truck | H12: 348 | I12: EA | J12: ¥ | L12: ¥ | M12: =H12*K12 -> 0 | N12: AB03 | P12: Medium/Large Truck | U12: 348 | V12: EA | W12: ¥ | Y12: ¥ | Z12: =U12*X12 -> 0 | AA12: AC03 | AC12: Medium/Large Truck | AH12: 348 | AI12: EA | AJ12: ¥ | AL12: ¥ | AM12: =AH12*AK12 -> 0 | AN12: AD03 | AP12: Medium/Large Truck | AU12: 348 | AV12: EA | AW12: ¥ | AY12: ¥ | AZ12: =AU12*AX12 -> 0 | BA12: AE03 | BC12: Medium/Large Truck | BH12: 348 | BI12: EA | BJ12: ¥ | BL12: ¥ | BM12: =BH12*BK12 -> 0
B13: Between | C13: Sagami General Depot | O13: Between | P13: Sagami General Depot | AB13: Between | AC13: Sagami General Depot | AO13: Between | AP13: Sagami General Depot | BB13: Between | BC13: Sagami General Depot
B14: and | C14: Sagamihara Family Housing Area or Camp Zama, or Camp Zama via Sagamihara Housing Area or vice versa (10km/12km/15km/17km) | O14: and | P14: Sagamihara Family Housing Area or Camp Zama, or Camp Zama via Sagamihara Housing Area or vice versa (10km/12km/15km/17km) | AB14: and | AC14: Sagamihara Family Housing Area or Camp Zama, or Camp Zama via Sagamihara Housing Area or vice versa (10km/12km/15km/17km) | AO14: and | AP14: Sagamihara Family Housing Area or Camp Zama, or Camp Zama via Sagamihara Housing Area or vice versa (10km/12km/15km/17km) | BB14: and | BC14: Sagamihara Family Housing Area or Camp Zama, or Camp Zama via Sagamihara Housing Area or vice versa (10km/12km/15km/17km)
A15: AA04 | C15: Medium/Large Truck | H15: 294 | I15: EA | J15: ¥ | L15: ¥ | M15: =H15*K15 -> 0 | N15: AB04 | P15: Medium/Large Truck | U15: 294 | V15: EA | W15: ¥ | Y15: ¥ | Z15: =U15*X15 -> 0 | AA15: AC04 | AC15: Medium/Large Truck | AH15: 294 | AI15: EA | AJ15: ¥ | AL15: ¥ | AM15: =AH15*AK15 -> 0 | AN15: AD04 | AP15: Medium/Large Truck | AU15: 294 | AV15: EA | AW15: ¥ | AY15: ¥ | AZ15: =AU15*AX15 -> 0 | BA15: AE04 | BC15: Medium/Large Truck | BH15: 294 | BI15: EA | BJ15: ¥ | BL15: ¥ | BM15: =BH15*BK15 -> 0
B16: Between | C16: Sagami General Depot | O16: Between | P16: Sagami General Depot | AB16: Between | AC16: Sagami General Depot | AO16: Between | AP16: Sagami General Depot | BB16: Between | BC16: Sagami General Depot
B17: and | C17: USMC Air Station, Iwakuni (830km) | O17: and | P17: USMC Air Station, Iwakuni (830km) | AB17: and | AC17: USMC Air Station, Iwakuni (830km) | AO17: and | AP17: USMC Air Station, Iwakuni (830km) | BB17: and | BC17: USMC Air Station, Iwakuni (830km)
A18: AA05 | C18: Medium/Large Truck | H18: 27 | I18: EA | J18: ¥ | L18: ¥ | M18: =H18*K18 -> 0 | N18: AB05 | P18: Medium/Large Truck | U18: 27 | V18: EA | W18: ¥ | Y18: ¥ | Z18: =U18*X18 -> 0 | AA18: AC05 | AC18: Medium/Large Truck | AH18: 27 | AI18: EA | AJ18: ¥ | AL18: ¥ | AM18: =AH18*AK18 -> 0 | AN18: AD05 | AP18: Medium/Large Truck | AU18: 27 | AV18: EA | AW18: ¥ | AY18: ¥ | AZ18: =AU18*AX18 -> 0 | BA18: AE05 | BC18: Medium/Large Truck | BH18: 27 | BI18: EA | BJ18: ¥ | BL18: ¥ | BM18: =BH18*BK18 -> 0
B19: Between | C19: US Fleet Activities, Yokosuka | O19: Between | P19: US Fleet Activities, Yokosuka | AB19: Between | AC19: US Fleet Activities, Yokosuka | AO19: Between | AP19: US Fleet Activities, Yokosuka | BB19: Between | BC19: US Fleet Activities, Yokosuka
B20: and | C20: USN Air Facility, Atsugi (38km) | O20: and | P20: USN Air Facility, Atsugi (38km) | AB20: and | AC20: USN Air Facility, Atsugi (38km) | AO20: and | AP20: USN Air Facility, Atsugi (38km) | BB20: and | BC20: USN Air Facility, Atsugi (38km)
A21: AA06 | C21: Medium/Large Truck | H21: 358 | I21: EA | J21: ¥ | L21: ¥ | M21: =H21*K21 -> 0 | N21: AB06 | P21: Medium/Large Truck | U21: 358 | V21: EA | W21: ¥ | Y21: ¥ | Z21: =U21*X21 -> 0 | AA21: AC06 | AC21: Medium/Large Truck | AH21: 358 | AI21: EA | AJ21: ¥ | AL21: ¥ | AM21: =AH21*AK21 -> 0 | AN21: AD06 | AP21: Medium/Large Truck | AU21: 358 | AV21: EA | AW21: ¥ | AY21: ¥ | AZ21: =AU21*AX21 -> 0 | BA21: AE06 | BC21: Medium/Large Truck | BH21: 358 | BI21: EA | BJ21: ¥ | BL21: ¥ | BM21: =BH21*BK21 -> 0
B22: Between | C22: US Fleet Activities, Yokosuka or USN Air Facility, Atsugi | O22: Between | P22: US Fleet Activities, Yokosuka or USN Air Facility, Atsugi | AB22: Between | AC22: US Fleet Activities, Yokosuka or USN Air Facility, Atsugi | AO22: Between | AP22: US Fleet Activities, Yokosuka or USN Air Facility, Atsugi | BB22: Between | BC22: US Fleet Activities, Yokosuka or USN Air Facility, Atsugi
B23: and | C23: US Fleet Activities, Sasebo (1,206km/1159km) | O23: and | P23: US Fleet Activities, Sasebo (1,206km/1159km) | AB23: and | AC23: US Fleet Activities, Sasebo (1,206km/1159km) | AO23: and | AP23: US Fleet Activities, Sasebo (1,206km/1159km) | BB23: and | BC23: US Fleet Activities, Sasebo (1,206km/1159km)
A24: AA07 | C24: Medium/Large Truck | H24: 931 | I24: EA | J24: ¥ | L24: ¥ | M24: =H24*K24 -> 0 | N24: AB07 | P24: Medium/Large Truck | U24: 931 | V24: EA | W24: ¥ | Y24: ¥ | Z24: =U24*X24 -> 0 | AA24: AC07 | AC24: Medium/Large Truck | AH24: 931 | AI24: EA | AJ24: ¥ | AL24: ¥ | AM24: =AH24*AK24 -> 0 | AN24: AD07 | AP24: Medium/Large Truck | AU24: 931 | AV24: EA | AW24: ¥ | AY24: ¥ | AZ24: =AU24*AX24 -> 0 | BA24: AE07 | BC24: Medium/Large Truck | BH24: 931 | BI24: EA | BJ24: ¥ | BL24: ¥ | BM24: =BH24*BK24 -> 0
B25: Between | C25: US Fleet Activities, Yokosuka via Yokota | O25: Between | P25: US Fleet Activities, Yokosuka via Yokota | AB25: Between | AC25: US Fleet Activities, Yokosuka via Yokota | AO25: Between | AP25: US Fleet Activities, Yokosuka via Yokota | BB25: Between | BC25: US Fleet Activities, Yokosuka via Yokota
B26: and | C26: US Fleet Activities, Sasebo (1,273km) | O26: and | P26: US Fleet Activities, Sasebo (1,273km) | AB26: and | AC26: US Fleet Activities, Sasebo (1,273km) | AO26: and | AP26: US Fleet Activities, Sasebo (1,273km) | BB26: and | BC26: US Fleet Activities, Sasebo (1,273km)
A27: AA08 | C27: Medium/Large Truck | H27: 103 | I27: EA | J27: ¥ | L27: ¥ | M27: =H27*K27 -> 0 | N27: AB08 | P27: Medium/Large Truck | U27: 103 | V27: EA | W27: ¥ | Y27: ¥ | Z27: =U27*X27 -> 0 | AA27: AC08 | AC27: Medium/Large Truck | AH27: 103 | AI27: EA | AJ27: ¥ | AL27: ¥ | AM27: =AH27*AK27 -> 0 | AN27: AD08 | AP27: Medium/Large Truck | AU27: 103 | AV27: EA | AW27: ¥ | AY27: ¥ | AZ27: =AU27*AX27 -> 0 | BA27: AE08 | BC27: Medium/Large Truck | BH27: 103 | BI27: EA | BJ27: ¥ | BL27: ¥ | BM27: =BH27*BK27 -> 0
B28: Between | C28: US Fleet Activities, Yokosuka or USN Air Facility, Atsugi | O28: Between | P28: US Fleet Activities, Yokosuka or USN Air Facility, Atsugi | AB28: Between | AC28: US Fleet Activities, Yokosuka or USN Air Facility, Atsugi | AO28: Between | AP28: US Fleet Activities, Yokosuka or USN Air Facility, Atsugi | BB28: Between | BC28: US Fleet Activities, Yokosuka or USN Air Facility, Atsugi
B29: and | C29: USMC Air Station, Iwakuni (858km/816km) | O29: and | P29: USMC Air Station, Iwakuni (858km/816km) | AB29: and | AC29: USMC Air Station, Iwakuni (858km/816km) | AO29: and | AP29: USMC Air Station, Iwakuni (858km/816km) | BB29: and | BC29: USMC Air Station, Iwakuni (858km/816km)
A30: AA09 | C30: Medium/Large Truck | H30: 514 | I30: EA | J30: ¥ | L30: ¥ | M30: =H30*K30 -> 0 | N30: AB09 | P30: Medium/Large Truck | U30: 514 | V30: EA | W30: ¥ | Y30: ¥ | Z30: =U30*X30 -> 0 | AA30: AC09 | AC30: Medium/Large Truck | AH30: 514 | AI30: EA | AJ30: ¥ | AL30: ¥ | AM30: =AH30*AK30 -> 0 | AN30: AD09 | AP30: Medium/Large Truck | AU30: 514 | AV30: EA | AW30: ¥ | AY30: ¥ | AZ30: =AU30*AX30 -> 0 | BA30: AE09 | BC30: Medium/Large Truck | BH30: 514 | BI30: EA | BJ30: ¥ | BL30: ¥ | BM30: =BH30*BK30 -> 0
B31: Between | C31: US Fleet Activities, Yokosuka or USN Air Facility, Atsugi | O31: Between | P31: US Fleet Activities, Yokosuka or USN Air Facility, Atsugi | AB31: Between | AC31: US Fleet Activities, Yokosuka or USN Air Facility, Atsugi | AO31: Between | AP31: US Fleet Activities, Yokosuka or USN Air Facility, Atsugi | BB31: Between | BC31: US Fleet Activities, Yokosuka or USN Air Facility, Atsugi
B32: and | C32: Misawa Air base (740km/731km) | O32: and | P32: Misawa Air base (740km/731km) | AB32: and | AC32: Misawa Air base (740km/731km) | AO32: and | AP32: Misawa Air base (740km/731km) | BB32: and | BC32: Misawa Air base (740km/731km)
A33: AA10 | C33: Medium/Large Truck | H33: 331 | I33: EA | J33: ¥ | L33: ¥ | M33: =H33*K33 -> 0 | N33: AB10 | P33: Medium/Large Truck | U33: 331 | V33: EA | W33: ¥ | Y33: ¥ | Z33: =U33*X33 -> 0 | AA33: AC10 | AC33: Medium/Large Truck | AH33: 331 | AI33: EA | AJ33: ¥ | AL33: ¥ | AM33: =AH33*AK33 -> 0 | AN33: AD10 | AP33: Medium/Large Truck | AU33: 331 | AV33: EA | AW33: ¥ | AY33: ¥ | AZ33: =AU33*AX33 -> 0 | BA33: AE10 | BC33: Medium/Large Truck | BH33: 331 | BI33: EA | BJ33: ¥ | BL33: ¥ | BM33: =BH33*BK33 -> 0
B34: Between | C34: US Fleet Activities, Yokosuka | O34: Between | P34: US Fleet Activities, Yokosuka | AB34: Between | AC34: US Fleet Activities, Yokosuka | AO34: Between | AP34: US Fleet Activities, Yokosuka | BB34: Between | BC34: US Fleet Activities, Yokosuka
B35: and | C35: Yokota Air Base (75km) | O35: and | P35: Yokota Air Base (75km) | AB35: and | AC35: Yokota Air Base (75km) | AO35: and | AP35: Yokota Air Base (75km) | BB35: and | BC35: Yokota Air Base (75km)
A36: AA11 | C36: Medium/Large Truck | H36: 1315 | I36: EA | J36: ¥ | L36: ¥ | M36: =H36*K36 -> 0 | N36: AB11 | P36: Medium/Large Truck | U36: 1315 | V36: EA | W36: ¥ | Y36: ¥ | Z36: =U36*X36 -> 0 | AA36: AC11 | AC36: Medium/Large Truck | AH36: 1315 | AI36: EA | AJ36: ¥ | AL36: ¥ | AM36: =AH36*AK36 -> 0 | AN36: AD11 | AP36: Medium/Large Truck | AU36: 1315 | AV36: EA | AW36: ¥ | AY36: ¥ | AZ36: =AU36*AX36 -> 0 | BA36: AE11 | BC36: Medium/Large Truck | BH36: 1315 | BI36: EA | BJ36: ¥ | BL36: ¥ | BM36: =BH36*BK36 -> 0
B37: Between | C37: US Fleet Activities, Yokosuka or USN Air Facility, Atsugi | O37: Between | P37: US Fleet Activities, Yokosuka or USN Air Facility, Atsugi | AB37: Between | AC37: US Fleet Activities, Yokosuka or USN Air Facility, Atsugi | AO37: Between | AP37: US Fleet Activities, Yokosuka or USN Air Facility, Atsugi | BB37: Between | BC37: US Fleet Activities, Yokosuka or USN Air Facility, Atsugi
B38: and | C38: DET Camp Kisarazu (70kn) | O38: and | P38: DET Camp Kisarazu (70kn) | AB38: and | AC38: DET Camp Kisarazu (70kn) | AO38: and | AP38: DET Camp Kisarazu (70kn) | BB38: and | BC38: DET Camp Kisarazu (70kn)
A39: AA12 | C39: Medium/Large Truck | H39: 44 | I39: EA | J39: ¥ | L39: ¥ | M39: =H39*K39 -> 0 | N39: AB12 | P39: Medium/Large Truck | U39: 44 | V39: EA | W39: ¥ | Y39: ¥ | Z39: =U39*X39 -> 0 | AA39: AC12 | AC39: Medium/Large Truck | AH39: 44 | AI39: EA | AJ39: ¥ | AL39: ¥ | AM39: =AH39*AK39 -> 0 | AN39: AD12 | AP39: Medium/Large Truck | AU39: 44 | AV39: EA | AW39: ¥ | AY39: ¥ | AZ39: =AU39*AX39 -> 0 | BA39: AE12 | BC39: Medium/Large Truck | BH39: 44 | BI39: EA | BJ39: ¥ | BL39: ¥ | BM39: =BH39*BK39 -> 0
B40: Between | C40: Yokota Air Base | O40: Between | P40: Yokota Air Base | AB40: Between | AC40: Yokota Air Base | AO40: Between | AP40: Yokota Air Base | BB40: Between | BC40: Yokota Air Base
...

Sheet B. Reefer
A1: EXHIBIT BA: REEFER TRUCKING FAMILY PRICING SCHEDULE (BASE YEAR 0002) | N1: EXHIBIT BB: REEFER TRUCKING FAMILY PRICING SCHEDULE (BASE YEAR 1002) | AA1: EXHIBIT BC: REEFER TRUCKING FAMILY PRICING SCHEDULE (BASE YEAR 2002) | AN1: EXHIBIT BD: REEFER TRUCKING FAMILY PRICING SCHEDULE (BASE YEAR 3002) | BA1: EXHIBIT BE: REEFER TRUCKING FAMILY PRICING SCHEDULE (BASE YEAR 4002)
A2: POINT-TO-POINT ROUTES (IAW PWS 3.4.1.): All listed unit prices shall be one-way rates per truckload of temparature-controlled freight. If proposing under the Mainland portion of the Reefer Trucking family, offerors shall provide proposed unit prices for all listed Items. | N2: POINT-TO-POINT ROUTES (IAW PWS 3.4.1.): All listed unit prices shall be one-way rates per truckload of temparature-controlled freight. If proposing under the Mainland portion of the Reefer Trucking family, offerors shall provide proposed unit prices for all listed Items. | AA2: POINT-TO-POINT ROUTES (IAW PWS 3.4.1.): All listed unit prices shall be one-way rates per truckload of temparature-controlled freight. If proposing under the Mainland portion of the Reefer Trucking family, offerors shall provide proposed unit prices for all listed Items. | AN2: POINT-TO-POINT ROUTES (IAW PWS 3.4.1.): All listed unit prices shall be one-way rates per truckload of temparature-controlled freight. If proposing under the Mainland portion of the Reefer Trucking family, offerors shall provide proposed unit prices for all listed Items. | BA2: POINT-TO-POINT ROUTES (IAW PWS 3.4.1.): All listed unit prices shall be one-way rates per truckload of temparature-controlled freight. If proposing under the Mainland portion of the Reefer Trucking family, offerors shall provide proposed unit prices for all listed Items.
A3: Item No. | B3: Description | H3: Est. Qty | I3: Unit | K3: Unit Price | M3: Est. Total | N3: Item No. | O3: Description | U3: Est. Qty | V3: Unit | X3: Unit Price | Z3: Est. Total | AA3: Item No. | AB3: Description | AH3: Est. Qty | AI3: Unit | AK3: Unit Price | AM3: Est. Total | AN3: Item No. | AO3: Description | AU3: Est. Qty | AV3: Unit | AX3: Unit Price | AZ3: Est. Total | BA3: Item No. | BB3: Description | BH3: Est. Qty | BI3: Unit | BK3: Unit Price | BM3: Est. Total
B4: Between | C4: Sagami General Depot | O4: Between | P4: Sagami General Depot | AB4: Between | AC4: Sagami General Depot | AO4: Between | AP4: Sagami General Depot | BB4: Between | BC4: Sagami General Depot
B5: and | C5: US Fleet Activities, Yokosuka (52km) | O5: and | P5: US Fleet Activities, Yokosuka (52km) | AB5: and | AC5: US Fleet Activities, Yokosuka (52km) | AO5: and | AP5: US Fleet Activities, Yokosuka (52km) | BB5: and | BC5: US Fleet Activities, Yokosuka (52km)
A6: BA01 | C6: Medium/Large Truck | H6: 360 | I6: EA | J6: ¥ | L6: ¥ | M6: =H6*K6 -> 0 | N6: BB01 | P6: Medium/Large Truck | U6: 360 | V6: EA | W6: ¥ | Y6: ¥ | Z6: =U6*X6 -> 0 | AA6: BC01 | AC6: Medium/Large Truck | AH6: 360 | AI6: EA | AJ6: ¥ | AL6: ¥ | AM6: =AH6*AK6 -> 0 | AN6: BD01 | AP6: Medium/Large Truck | AU6: 360 | AV6: EA | AW6: ¥ | AY6: ¥ | AZ6: =AU6*AX6 -> 0 | BA6: BE01 | BC6: Medium/Large Truck | BH6: 360 | BI6: EA | BJ6: ¥ | BL6: ¥ | BM6: =BH6*BK6 -> 0
B7: Between | C7: Sagami General Depot | O7: Between | P7: Sagami General Depot | AB7: Between | AC7: Sagami General Depot | AO7: Between | AP7: Sagami General Depot | BB7: Between | BC7: Sagami General Depot
B8: and | C8: Yokota Air Base (24km) | O8: and | P8: Yokota Air Base (24km) | AB8: and | AC8: Yokota Air Base (24km) | AO8: and | AP8: Yokota Air Base (24km) | BB8: and | BC8: Yokota Air Base (24km)
A9: BA02 | C9: Medium/Large Truck | H9: 350 | I9: EA | J9: ¥ | L9: ¥ | M9: =H9*K9 -> 0 | N9: BB02 | P9: Medium/Large Truck | U9: 350 | V9: EA | W9: ¥ | Y9: ¥ | Z9: =U9*X9 -> 0 | AA9: BC02 | AC9: Medium/Large Truck | AH9: 350 | AI9: EA | AJ9: ¥ | AL9: ¥ | AM9: =AH9*AK9 -> 0 | AN9: BD02 | AP9: Medium/Large Truck | AU9: 350 | AV9: EA | AW9: ¥ | AY9: ¥ | AZ9: =AU9*AX9 -> 0 | BA9: BE02 | BC9: Medium/Large Truck | BH9: 350 | BI9: EA | BJ9: ¥ | BL9: ¥ | BM9: =BH9*BK9 -> 0
B10: Between | C10: Sagami General Depot | O10: Between | P10: Sagami General Depot | AB10: Between | AC10: Sagami General Depot | AO10: Between | AP10: Sagami General Depot | BB10: Between | BC10: Sagami General Depot
B11: and | C11: USN Air Facility, Atsugi (20km) | O11: and | P11: USN Air Facility, Atsugi (20km) | AB11: and | AC11: USN Air Facility, Atsugi (20km) | AO11: and | AP11: USN Air Facility, Atsugi (20km) | BB11: and | BC11: USN Air Facility, Atsugi (20km)
A12: BA03 | C12: Medium/Large Truck | H12: 320 | I12: EA | J12: ¥ | L12: ¥ | M12: =H12*K12 -> 0 | N12: BB03 | P12: Medium/Large Truck | U12: 320 | V12: EA | W12: ¥ | Y12: ¥ | Z12: =U12*X12 -> 0 | AA12: BC03 | AC12: Medium/Large Truck | AH12: 320 | AI12: EA | AJ12: ¥ | AL12: ¥ | AM12: =AH12*AK12 -> 0 | AN12: BD03 | AP12: Medium/Large Truck | AU12: 320 | AV12: EA | AW12: ¥ | AY12: ¥ | AZ12: =AU12*AX12 -> 0 | BA12: BE03 | BC12: Medium/Large Truck | BH12: 320 | BI12: EA | BJ12: ¥ | BL12: ¥ | BM12: =BH12*BK12 -> 0
B13: Between | C13: Sagami General Depot | O13: Between | P13: Sagami General Depot | AB13: Between | AC13: Sagami General Depot | AO13: Between | AP13: Sagami General Depot | BB13: Between | BC13: Sagami General Depot
B14: and | C14: Sagamihara Family Housing Area or Camp Zama, or Camp Zama via Sagamihara Housing Area or vice versa (10km/12km/15km/17km) | O14: and | P14: Sagamihara Family Housing Area or Camp Zama, or Camp Zama via Sagamihara Housing Area or vice versa (10km/12km/15km/17km) | AB14: and | AC14: Sagamihara Family Housing Area or Camp Zama, or Camp Zama via Sagamihara Housing Area or vice versa (10km/12km/15km/17km) | AO14: and | AP14: Sagamihara Family Housing Area or Camp Zama, or Camp Zama via Sagamihara Housing Area or vice versa (10km/12km/15km/17km) | BB14: and | BC14: Sagamihara Family Housing Area or Camp Zama, or Camp Zama via Sagamihara Housing Area or vice versa (10km/12km/15km/17km)
A15: BA04 | C15: Medium/Large Truck | H15: 320 | I15: EA | J15: ¥ | L15: ¥ | M15: =H15*K15 -> 0 | N15: BB04 | P15: Medium/Large Truck | U15: 320 | V15: EA | W15: ¥ | Y15: ¥ | Z15: =U15*X15 -> 0 | AA15: BC04 | AC15: Medium/Large Truck | AH15: 320 | AI15: EA | AJ15: ¥ | AL15: ¥ | AM15: =AH15*AK15 -> 0 | AN15: BD04 | AP15: Medium/Large Truck | AU15: 320 | AV15: EA | AW15: ¥ | AY15: ¥ | AZ15: =AU15*AX15 -> 0 | BA15: BE04 | BC15: Medium/Large Truck | BH15: 320 | BI15: EA | BJ15: ¥ | BL15: ¥ | BM15: =BH15*BK15 -> 0
B16: Between | C16: Sagami General Depot | O16: Between | P16: Sagami General Depot | AB16: Between | AC16: Sagami General Depot | AO16: Between | AP16: Sagami General Depot | BB16: Between | BC16: Sagami General Depot
B17: and | C17: USMC Air Station, Iwakuni (830km) | O17: and | P17: USMC Air Station, Iwakuni (830km) | AB17: and | AC17: USMC Air Station, Iwakuni (830km) | AO17: and | AP17: USMC Air Station, Iwakuni (830km) | BB17: and | BC17: USMC Air Station, Iwakuni (830km)
A18: BA05 | C18: Medium/Large Truck | H18: 170 | I18: EA | J18: ¥ | L18: ¥ | M18: =H18*K18 -> 0 | N18: BB05 | P18: Medium/Large Truck | U18: 170 | V18: EA | W18: ¥ | Y18: ¥ | Z18: =U18*X18 -> 0 | AA18: BC05 | AC18: Medium/Large Truck | AH18: 170 | AI18: EA | AJ18: ¥ | AL18: ¥ | AM18: =AH18*AK18 -> 0 | AN18: BD05 | AP18: Medium/Large Truck | AU18: 170 | AV18: EA | AW18: ¥ | AY18: ¥ | AZ18: =AU18*AX18 -> 0 | BA18: BE05 | BC18: Medium/Large Truck | BH18: 170 | BI18: EA | BJ18: ¥ | BL18: ¥ | BM18: =BH18*BK18 -> 0
B19: Between | C19: Sagami General Depot | O19: Between | P19: Sagami General Depot | AB19: Between | AC19: Sagami General Depot | AO19: Between | AP19: Sagami General Depot | BB19: Between | BC19: Sagami General Depot
B20: and | C20: Misawa Air base (725km) | O20: and | P20: Misawa Air base (725km) | AB20: and | AC20: Misawa Air base (725km) | AO20: and | AP20: Misawa Air base (725km) | BB20: and | BC20: Misawa Air base (725km)
A21: BA06 | C21: Medium/Large Truck | H21: 10 | I21: EA | J21: ¥ | L21: ¥ | M21: =H21*K21 -> 0 | N21: BB06 | P21: Medium/Large Truck | U21: 10 | V21: EA | W21: ¥ | Y21: ¥ | Z21: =U21*X21 -> 0 | AA21: BC06 | AC21: Medium/Large Truck | AH21: 10 | AI21: EA | AJ21: ¥ | AL21: ¥ | AM21: =AH21*AK21 -> 0 | AN21: BD06 | AP21: Medium/Large Truck | AU21: 10 | AV21: EA | AW21: ¥ | AY21: ¥ | AZ21: =AU21*AX21 -> 0 | BA21: BE06 | BC21: Medium/Large Truck | BH21: 10 | BI21: EA | BJ21: ¥ | BL21: ¥ | BM21: =BH21*BK21 -> 0
B22: Between | C22: USMC Air Station, Iwakuni | O22: Between | P22: USMC Air Station, Iwakuni | AB22: Between | AC22: USMC Air Station, Iwakuni | AO22: Between | AP22: USMC Air Station, Iwakuni | BB22: Between | BC22: USMC Air Station, Iwakuni
B23: and | C23: Kure Pier No. 6 (72km) | O23: and | P23: Kure Pier No. 6 (72km) | AB23: and | AC23: Kure Pier No. 6 (72km) | AO23: and | AP23: Kure Pier No. 6 (72km) | BB23: and | BC23: Kure Pier No. 6 (72km)
A24: BA07 | C24: Medium/Large Truck | H24: 52 | I24: EA | J24: ¥ | L24: ¥ | M24: =H24*K24 -> 0 | N24: BB07 | P24: Medium/Large Truck | U24: 52 | V24: EA | W24: ¥ | Y24: ¥ | Z24: =U24*X24 -> 0 | AA24: BC07 | AC24: Medium/Large Truck | AH24: 52 | AI24: EA | AJ24: ¥ | AL24: ¥ | AM24: =AH24*AK24 -> 0 | AN24: BD07 | AP24: Medium/Large Truck | AU24: 52 | AV24: EA | AW24: ¥ | AY24: ¥ | AZ24: =AU24*AX24 -> 0 | BA24: BE07 | BC24: Medium/Large Truck | BH24: 52 | BI24: EA | BJ24: ¥ | BL24: ¥ | BM24: =BH24*BK24 -> 0
B25: Between | C25: USMC Air Station, Iwakuni | O25: Between | P25: USMC Air Station, Iwakuni | AB25: Between | AC25: USMC Air Station, Iwakuni | AO25: Between | AP25: USMC Air Station, Iwakuni | BB25: Between | BC25: USMC Air Station, Iwakuni
B26: and | C26: US Fleet Activities, Sasebo (352km) or Hario Village (350km) | O26: and | P26: US Fleet Activities, Sasebo (352km) or Hario Village (350km) | AB26: and | AC26: US Fleet Activities, Sasebo (352km) or Hario Village (350km) | AO26: and | AP26: US Fleet Activities, Sasebo (352km) or Hario Village (350km) | BB26: and | BC26: US Fleet Activities, Sasebo (352km) or Hario Village (350km)
A27: BA08 | C27: Medium/Large Truck | H27: 245 | I27: EA | J27: ¥ | L27: ¥ | M27: =H27*K27 -> 0 | N27: BB08 | P27: Medium/Large Truck | U27: 245 | V27: EA | W27: ¥ | Y27: ¥ | Z27: =U27*X27 -> 0 | AA27: BC08 | AC27: Medium/Large Truck | AH27: 245 | AI27: EA | AJ27: ¥ | AL27: ¥ | AM27: =AH27*AK27 -> 0 | AN27: BD08 | AP27: Medium/Large Truck | AU27: 245 | AV27: EA | AW27: ¥ | AY27: ¥ | AZ27: =AU27*AX27 -> 0 | BA27: BE08 | BC27: Medium/Large Truck | BH27: 245 | BI27: EA | BJ27: ¥ | BL27: ¥ | BM27: =BH27*BK27 -> 0
B28: Between | C28: Yokohama North Dock | O28: Between | P28: Yokohama North Dock | AB28: Between | AC28: Yokohama North Dock | AO28: Between | AP28: Yokohama North Dock | BB28: Between | BC28: Yokohama North Dock
B29: and | C29: US Fleet Activities, Sasebo (1,187km) | O29: and | P29: US Fleet Activities, Sasebo (1,187km) | AB29: and | AC29: US Fleet Activities, Sasebo (1,187km) | AO29: and | AP29: US Fleet Activities, Sasebo (1,187km) | BB29: and | BC29: US Fleet Activities, Sasebo (1,187km)
A30: BA09 | C30: Medium/Large Truck | H30: 52 | I30: EA | J30: ¥ | L30: ¥ | M30: =H30*K30 -> 0 | N30: BB09 | P30: Medium/Large Truck | U30: 52 | V30: EA | W30: ¥ | Y30: ¥ | Z30: =U30*X30 -> 0 | AA30: BC09 | AC30: Medium/Large Truck | AH30: 52 | AI30: EA | AJ30: ¥ | AL30: ¥ | AM30: =AH30*AK30 -> 0 | AN30: BD09 | AP30: Medium/Large Truck | AU30: 52 | AV30: EA | AW30: ¥ | AY30: ¥ | AZ30: =AU30*AX30 -> 0 | BA30: BE09 | BC30: Medium/Large Truck | BH30: 52 | BI30: EA | BJ30: ¥ | BL30: ¥ | BM30: =BH30*BK30 -> 0
B31: Between | C31: US Fleet Activities, Yokosuka | O31: Between | P31: US Fleet Activities, Yokosuka | AB31: Between | AC31: US Fleet Activities, Yokosuka | AO31: Between | AP31: US Fleet Activities, Yokosuka | BB31: Between | BC31: US Fleet Activities, Yokosuka
B32: and | C32: US Fleet Activities, Sasebo (1,206km) | O32: and | P32: US Fleet Activities, Sasebo (1,206km) | AB32: and | AC32: US Fleet Activities, Sasebo (1,206km) | AO32: and | AP32: US Fleet Activities, Sasebo (1,206km) | BB32: and | BC32: US Fleet Activities, Sasebo (1,206km)
A33: BA10 | C33: Medium/Large Truck | H33: 50 | I33: EA | J33: ¥ | L33: ¥ | M33: =H33*K33 -> 0 | N33: BB10 | P33: Medium/Large Truck | U33: 50 | V33: EA | W33: ¥ | Y33: ¥ | Z33: =U33*X33 -> 0 | AA33: BC10 | AC33: Medium/Large Truck | AH33: 50 | AI33: EA | AJ33: ¥ | AL33: ¥ | AM33: =AH33*AK33 -> 0 | AN33: BD10 | AP33: Medium/Large Truck | AU33: 50 | AV33: EA | AW33: ¥ | AY33: ¥ | AZ33: =AU33*AX33 -> 0 | BA33: BE10 | BC33: Medium/Large Truck | BH33: 50 | BI33: EA | BJ33: ¥ | BL33: ¥ | BM33: =BH33*BK33 -> 0
A34: BA11 thru BA15 | C34: Reserved | H34: Reserved | N34: BB11 thru BB15 | P34: Reserved | U34: Reserved | AA34: BC11 thru BC15 | AC34: Reserved | AH34: Reserved | AN34: BD11 thru BD15 | AP34: Reserved | AU34: Reserved | BA34: BE11 thru BE15 | BC34: Reserved | BH34: Reserved
A35: ① ESTIMATED TOTAL AMOUNT FOR POINT-TO-POINT ROUTE: | L35: ¥ | M35: =SUM(M5:M33) -> 0 | N35: ① ESTIMATED TOTAL AMOUNT FOR POINT-TO-POINT ROUTE: | Y35: ¥ | Z35: =SUM(Z5:Z33) -> 0 | AA35: ① ESTIMATED TOTAL AMOUNT FOR POINT-TO-POINT ROUTE: | AL35: ¥ | AM35: =SUM(AM5:AM33) -> 0 | AN35: ① ESTIMATED TOTAL AMOUNT FOR POINT-TO-POINT ROUTE: | AY35: ¥ | AZ35: =SUM(AZ5:AZ33) -> 0 | BA35: ① ESTIMATED TOTAL AMOUNT FOR POINT-TO-POINT ROUTE: | BL35: ¥ | BM35: =SUM(BM5:BM33) -> 0
A36: MAINLAND DISTANCE RATE TABLE (IAW nationwide industiry standards and GOJ guidelines; see PWS 3.4.2.): All listed unit prices shall be one-way rates per truckload of temparature-controlled freight. (Min. Chargeable Distance: 10km) If proposing under the Mainland portion of the Reefer Trucking family, offerors shall provide proposed distance rates for all listed distances. | N36: MAINLAND DISTANCE RATE TABLE (IAW nationwide industiry standards and GOJ guidelines; see PWS 3.4.2.): All listed unit prices shall be one-way rates per truckload of temparature-controlled freight. (Min. Chargeable Distance: 10km) If proposing under the Mainland portion of the Reefer Trucking family, offerors shall provide proposed distance rates for all listed distances. | AA36: MAINLAND DISTANCE RATE TABLE (IAW nationwide industiry standards and GOJ guidelines; see PWS 3.4.2.): All listed unit prices shall be one-way rates per truckload of temparature-controlled freight. (Min. Chargeable Distance: 10km) If proposing under the Mainland portion of the Reefer Trucking family, offerors shall provide proposed distance rates for all listed distances. | AN36: MAINLAND DISTANCE RATE TABLE (IAW nationwide industiry standards and GOJ guidelines; see PWS 3.4.2.): All listed unit prices shall be one-way rates per truckload of temparature-controlled freight. (Min. Chargeable Distance: 10km) If proposing under the Mainland portion of the Reefer Trucking family, offerors shall provide proposed distance rates for all listed distances. | BA36: MAINLAND DISTANCE RATE TABLE (IAW nationwide industiry standards and GOJ guidelines; see PWS 3.4.2.): All listed unit prices shall be one-way rates per truckload of temparature-controlled freight. (Min. Chargeable Distance: 10km) If proposing under the Mainland portion of the Reefer Trucking family, offerors shall provide proposed distance rates for all listed distances.
A37: All listed unit prices shall be one-way rates per truckload of general freight. (Min. Chargeable Distance: 10km) | B37: Description | H37: Est. Qty | I37: Unit | N37: Item No. | O37: Description | U37: Est. Qty | V37: Unit | AA37: Item No. | AB37: Description | AH37: Est. Qty | AI37: Unit | AN37: Item No. | AO37: Description | AU37: Est. Qty | AV37: Unit | BA37: Item No. | BB37: Description | BH37: Est. Qty | BI37: Unit
A38: BA16 | B38: Distance Rates for Refeer Transportation Service in Mainland | H38: 20 | I38: EA | N38: BB16 | O38: Distance Rates for Refeer Transportation Service in Mainland | U38: 20 | V38: EA | AA38: BC16 | AB38: Distance Rates for Refeer Transportation Service in Mainland | AH38: 20 | AI38: EA | AN38: BD16 | AO38: Distance Rates for Refeer Transportation Service in Mainland | AU38: 20 | AV38: EA | BA38: BE16 | BB38: Distance Rates for Refeer Transportation Service in Mainland | BH38: 20 | BI38: EA
H39: One-Way | J39: Truck Type | U39: One-Way | W39: Truck Type | AH39: One-Way | AJ39: Truck Type | AU39: One-Way | AW39: Truck Type | BH39: One-Way | BJ39: Truck Type
H40: Distance (km) | J40: Medium/Large Truck | U40: Distance (km) | W40: Medium/Large Truck | AH40: Distance (km) | AJ40: Medium/Large Truck | AU40: Distance (km) | AW40: Medium/Large Truck | BH40: Distance (km) | BJ40: Medium/Large Truck
...

Sheet C. OSOW
A1: EXHIBIT CA: OVERSIZED OVERWEIGHT FAMILY PRICING SCHEDULE (BASE YEAR 0003) | P1: EXHIBIT CB: OVERSIZED OVERWEIGHT FAMILY PRICING SCHEDULE (BASE YEAR 1003) | AE1: EXHIBIT CC: OVERSIZED OVERWEIGHT FAMILY PRICING SCHEDULE (BASE YEAR 2003) | AT1: EXHIBIT CD: OVERSIZED OVERWEIGHT FAMILY PRICING SCHEDULE (BASE YEAR 3003) | BI1: EXHIBIT CE: OVERSIZED OVERWEIGHT FAMILY PRICING SCHEDULE (BASE YEAR 4003)
A2: POINT-TO-POINT ROUTES (IAW PWS 3.4.1.): All listed unit prices shall be one-way rates per truckload of OSOW freight. If proposing under the Mainland portion of the OSOW family, offerors shall provide proposed unit prices for all listed Items. | P2: POINT-TO-POINT ROUTES (IAW PWS 3.4.1.): All listed unit prices shall be one-way rates per truckload of OSOW freight. If proposing under the Mainland portion of the OSOW family, offerors shall provide proposed unit prices for all listed Items. | AE2: POINT-TO-POINT ROUTES (IAW PWS 3.4.1.): All listed unit prices shall be one-way rates per truckload of OSOW freight. If proposing under the Mainland portion of the OSOW family, offerors shall provide proposed unit prices for all listed Items. | AT2: POINT-TO-POINT ROUTES (IAW PWS 3.4.1.): All listed unit prices shall be one-way rates per truckload of OSOW freight. If proposing under the Mainland portion of the OSOW family, offerors shall provide proposed unit prices for all listed Items. | BI2: POINT-TO-POINT ROUTES (IAW PWS 3.4.1.): All listed unit prices shall be one-way rates per truckload of OSOW freight. If proposing under the Mainland portion of the OSOW family, offerors shall provide proposed unit prices for all listed Items.
A3: Item No. | C3: Description | H3: Est. Qty | I3: Unit | K3: Unit Price | N3: Est. Total | P3: Item No. | R3: Description | W3: Est. Qty | X3: Unit | Z3: Unit Price | AC3: Est. Total | AE3: Item No. | AG3: Description | AL3: Est. Qty | AM3: Unit | AO3: Unit Price | AR3: Est. Total | AT3: Item No. | AV3: Description | BA3: Est. Qty | BB3: Unit | BD3: Unit Price | BG3: Est. Total | BI3: Item No. | BK3: Description | BP3: Est. Qty | BQ3: Unit | BS3: Unit Price | BV3: Est. Total
A4: CA01 | B4: Between | C4: Sagami General Depot | P4: CB01 | Q4: Between | R4: Sagami General Depot | AE4: CC01 | AF4: Between | AG4: Sagami General Depot | AT4: CD01 | AU4: Between | AV4: Sagami General Depot | BI4: CE01 | BJ4: Between | BK4: Sagami General Depot
B5: and | C5: Yokohama North Dock or Honmoku Futo or Minami Honmoku Futo (32km/35km/38km) | Q5: and | R5: Yokohama North Dock or Honmoku Futo or Minami Honmoku Futo (32km/35km/38km) | AF5: and | AG5: Yokohama North Dock or Honmoku Futo or Minami Honmoku Futo (32km/35km/38km) | AU5: and | AV5: Yokohama North Dock or Honmoku Futo or Minami Honmoku Futo (32km/35km/38km) | BJ5: and | BK5: Yokohama North Dock or Honmoku Futo or Minami Honmoku Futo (32km/35km/38km)
A6: CA01A | C6: Up to 20-ton capacity Low-bed Semitrailer | H6: 35 | I6: EA | J6: ¥ | M6: ¥ | N6: =H6*K6 -> 0 | P6: CB01A | R6: Up to 20-ton capacity Low-bed Semitrailer | W6: 35 | X6: EA | Y6: ¥ | AB6: ¥ | AC6: =W6*Z6 -> 0 | AE6: CC01A | AG6: Up to 20-ton capacity Low-bed Semitrailer | AL6: 35 | AM6: EA | AN6: ¥ | AQ6: ¥ | AR6: =AL6*AO6 -> 0 | AT6: CD01A | AV6: Up to 20-ton capacity Low-bed Semitrailer | BA6: 35 | BB6: EA | BC6: ¥ | BF6: ¥ | BG6: =BA6*BD6 -> 0 | BI6: CE01A | BK6: Up to 20-ton capacity Low-bed Semitrailer | BP6: 35 | BQ6: EA | BR6: ¥ | BU6: ¥ | BV6: =BP6*BS6 -> 0
A7: CA01B | C7: Up to 26-ton capacity Low-bed Semitrailer | H7: 35 | I7: EA | J7: ¥ | M7: ¥ | N7: =H7*K7 -> 0 | P7: CB01B | R7: Up to 26-ton capacity Low-bed Semitrailer | W7: 35 | X7: EA | Y7: ¥ | AB7: ¥ | AC7: =W7*Z7 -> 0 | AE7: CC01B | AG7: Up to 26-ton capacity Low-bed Semitrailer | AL7: 35 | AM7: EA | AN7: ¥ | AQ7: ¥ | AR7: =AL7*AO7 -> 0 | AT7: CD01B | AV7: Up to 26-ton capacity Low-bed Semitrailer | BA7: 35 | BB7: EA | BC7: ¥ | BF7: ¥ | BG7: =BA7*BD7 -> 0 | BI7: CE01B | BK7: Up to 26-ton capacity Low-bed Semitrailer | BP7: 35 | BQ7: EA | BR7: ¥ | BU7: ¥ | BV7: =BP7*BS7 -> 0
A8: CA01C | C8: Up to 30-ton capacity Low-bed Semitrailer | H8: 45 | I8: EA | J8: ¥ | M8: ¥ | N8: =H8*K8 -> 0 | P8: CB01C | R8: Up to 30-ton capacity Low-bed Semitrailer | W8: 45 | X8: EA | Y8: ¥ | AB8: ¥ | AC8: =W8*Z8 -> 0 | AE8: CC01C | AG8: Up to 30-ton capacity Low-bed Semitrailer | AL8: 45 | AM8: EA | AN8: ¥ | AQ8: ¥ | AR8: =AL8*AO8 -> 0 | AT8: CD01C | AV8: Up to 30-ton capacity Low-bed Semitrailer | BA8: 45 | BB8: EA | BC8: ¥ | BF8: ¥ | BG8: =BA8*BD8 -> 0 | BI8: CE01C | BK8: Up to 30-ton capacity Low-bed Semitrailer | BP8: 45 | BQ8: EA | BR8: ¥ | BU8: ¥ | BV8: =BP8*BS8 -> 0
A9: CA01D | C9: Up to 36-ton capacity Low-bed Semitrailer | H9: 25 | I9: EA | J9: ¥ | M9: ¥ | N9: =H9*K9 -> 0 | P9: CB01D | R9: Up to 36-ton capacity Low-bed Semitrailer | W9: 25 | X9: EA | Y9: ¥ | AB9: ¥ | AC9: =W9*Z9 -> 0 | AE9: CC01D | AG9: Up to 36-ton capacity Low-bed Semitrailer | AL9: 25 | AM9: EA | AN9: ¥ | AQ9: ¥ | AR9: =AL9*AO9 -> 0 | AT9: CD01D | AV9: Up to 36-ton capacity Low-bed Semitrailer | BA9: 25 | BB9: EA | BC9: ¥ | BF9: ¥ | BG9: =BA9*BD9 -> 0 | BI9: CE01D | BK9: Up to 36-ton capacity Low-bed Semitrailer | BP9: 25 | BQ9: EA | BR9: ¥ | BU9: ¥ | BV9: =BP9*BS9 -> 0
A10: CA02 | B10: Between | C10: Yokohama North Dock | P10: CB02 | Q10: Between | R10: Yokohama North Dock | AE10: CC02 | AF10: Between | AG10: Yokohama North Dock | AT10: CD02 | AU10: Between | AV10: Yokohama North Dock | BI10: CE02 | BJ10: Between | BK10: Yokohama North Dock
B11: and | C11: Combined Arms Training Center, Camp Fuji (94km) | Q11: and | R11: Combined Arms Training Center, Camp Fuji (94km) | AF11: and | AG11: Combined Arms Training Center, Camp Fuji (94km) | AU11: and | AV11: Combined Arms Training Center, Camp Fuji (94km) | BJ11: and | BK11: Combined Arms Training Center, Camp Fuji (94km)
A12: CA02A | C12: Up to 20-ton capacity Low-bed Semitrailer | H12: 44 | I12: EA | J12: ¥ | M12: ¥ | N12: =H12*K12 -> 0 | P12: CB02A | R12: Up to 20-ton capacity Low-bed Semitrailer | W12: 44 | X12: EA | Y12: ¥ | AB12: ¥ | AC12: =W12*Z12 -> 0 | AE12: CC02A | AG12: Up to 20-ton capacity Low-bed Semitrailer | AL12: 44 | AM12: EA | AN12: ¥ | AQ12: ¥ | AR12: =AL12*AO12 -> 0 | AT12: CD02A | AV12: Up to 20-ton capacity Low-bed Semitrailer | BA12: 44 | BB12: EA | BC12: ¥ | BF12: ¥ | BG12: =BA12*BD12 -> 0 | BI12: CE02A | BK12: Up to 20-ton capacity Low-bed Semitrailer | BP12: 44 | BQ12: EA | BR12: ¥ | BU12: ¥ | BV12: =BP12*BS12 -> 0
A13: CA02B | C13: Up to 26-ton capacity Low-bed Semitrailer | H13: 44 | I13: EA | J13: ¥ | M13: ¥ | N13: =H13*K13 -> 0 | P13: CB02B | R13: Up to 26-ton capacity Low-bed Semitrailer | W13: 44 | X13: EA | Y13: ¥ | AB13: ¥ | AC13: =W13*Z13 -> 0 | AE13: CC02B | AG13: Up to 26-ton capacity Low-bed Semitrailer | AL13: 44 | AM13: EA | AN13: ¥ | AQ13: ¥ | AR13: =AL13*AO13 -> 0 | AT13: CD02B | AV13: Up to 26-ton capacity Low-bed Semitrailer | BA13: 44 | BB13: EA | BC13: ¥ | BF13: ¥ | BG13: =BA13*BD13 -> 0 | BI13: CE02B | BK13: Up to 26-ton capacity Low-bed Semitrailer | BP13: 44 | BQ13: EA | BR13: ¥ | BU13: ¥ | BV13: =BP13*BS13 -> 0
A14: CA02C | C14: Up to 30-ton capacity Low-bed Semitrailer | H14: 11 | I14: EA | J14: ¥ | M14: ¥ | N14: =H14*K14 -> 0 | P14: CB02C | R14: Up to 30-ton capacity Low-bed Semitrailer | W14: 11 | X14: EA | Y14: ¥ | AB14: ¥ | AC14: =W14*Z14 -> 0 | AE14: CC02C | AG14: Up to 30-ton capacity Low-bed Semitrailer | AL14: 11 | AM14: EA | AN14: ¥ | AQ14: ¥ | AR14: =AL14*AO14 -> 0 | AT14: CD02C | AV14: Up to 30-ton capacity Low-bed Semitrailer | BA14: 11 | BB14: EA | BC14: ¥ | BF14: ¥ | BG14: =BA14*BD14 -> 0 | BI14: CE02C | BK14: Up to 30-ton capacity Low-bed Semitrailer | BP14: 11 | BQ14: EA | BR14: ¥ | BU14: ¥ | BV14: =BP14*BS14 -> 0
A15: CA02D | C15: Up to 36-ton capacity Low-bed Semitrailer | H15: 27 | I15: EA | J15: ¥ | M15: ¥ | N15: =H15*K15 -> 0 | P15: CB02D | R15: Up to 36-ton capacity Low-bed Semitrailer | W15: 27 | X15: EA | Y15: ¥ | AB15: ¥ | AC15: =W15*Z15 -> 0 | AE15: CC02D | AG15: Up to 36-ton capacity Low-bed Semitrailer | AL15: 27 | AM15: EA | AN15: ¥ | AQ15: ¥ | AR15: =AL15*AO15 -> 0 | AT15: CD02D | AV15: Up to 36-ton capacity Low-bed Semitrailer | BA15: 27 | BB15: EA | BC15: ¥ | BF15: ¥ | BG15: =BA15*BD15 -> 0 | BI15: CE02D | BK15: Up to 36-ton capacity Low-bed Semitrailer | BP15: 27 | BQ15: EA | BR15: ¥ | BU15: ¥ | BV15: =BP15*BS15 -> 0
A16: CA03 thru CA04 | C16: Reserved | H16: Reserved | P16: CB03 thru CB04 | R16: Reserved | W16: Reserved | AE16: CCA03 thru CC04 | AG16: Reserved | AL16: Reserved | AT16: CD03 thru CD04 | AV16: Reserved | BA16: Reserved | BI16: CE03 thru CE04 | BK16: Reserved | BP16: Reserved
A17: ① ESTIMATED TOTAL AMOUNT FOR POINT-TO-POINT ROUTE: | N17: ¥ | O17: =SUM(N6:O15) -> 0 | P17: ① ESTIMATED TOTAL AMOUNT FOR POINT-TO-POINT ROUTE: | AC17: ¥ | AD17: =SUM(AC6:AD15) -> 0 | AE17: ① ESTIMATED TOTAL AMOUNT FOR POINT-TO-POINT ROUTE: | AR17: ¥ | AS17: =SUM(AR6:AS15) -> 0 | AT17: ① ESTIMATED TOTAL AMOUNT FOR POINT-TO-POINT ROUTE: | BG17: ¥ | BH17: =SUM(BG6:BH15) -> 0 | BI17: ① ESTIMATED TOTAL AMOUNT FOR POINT-TO-POINT ROUTE: | BV17: ¥ | BW17: =SUM(BV6:BW15) -> 0
A18: MAINLAND DISTANCE RATE TABLE (IAW nationwide industiry standards and GOJ guidelines; see PWS 3.4.2.): All listed unit prices shall be one-way rates per truckload of OSOW freight. (Min. Chargeable Distance: 10km) If proposing under the Mainland portion of the OSOW family, offerors shall provide proposed distance rates for all listed truck types and distances. | P18: MAINLAND DISTANCE RATE TABLE (IAW nationwide industiry standards and GOJ guidelines; see PWS 3.4.2.): All listed unit prices shall be one-way rates per truckload of OSOW freight. (Min. Chargeable Distance: 10km) If proposing under the Mainland portion of the OSOW family, offerors shall provide proposed distance rates for all listed truck types and distances. | AE18: MAINLAND DISTANCE RATE TABLE (IAW nationwide industiry standards and GOJ guidelines; see PWS 3.4.2.): All listed unit prices shall be one-way rates per truckload of OSOW freight. (Min. Chargeable Distance: 10km) If proposing under the Mainland portion of the OSOW family, offerors shall provide proposed distance rates for all listed truck types and distances. | AT18: MAINLAND DISTANCE RATE TABLE (IAW nationwide industiry standards and GOJ guidelines; see PWS 3.4.2.): All listed unit prices shall be one-way rates per truckload of OSOW freight. (Min. Chargeable Distance: 10km) If proposing under the Mainland portion of the OSOW family, offerors shall provide proposed distance rates for all listed truck types and distances. | BI18: MAINLAND DISTANCE RATE TABLE (IAW nationwide industiry standards and GOJ guidelines; see PWS 3.4.2.): All listed unit prices shall be one-way rates per truckload of OSOW freight. (Min. Chargeable Distance: 10km) If proposing under the Mainland portion of the OSOW family, offerors shall provide proposed distance rates for all listed truck types and distances.
A19: Item No. | C19: Description | H19: Est. Qty | I19: Unit | P19: Item No. | R19: Description | W19: Est. Qty | X19: Unit | AE19: Item No. | AG19: Description | AL19: Est. Qty | AM19: Unit | AT19: Item No. | AV19: Description | BA19: Est. Qty | BB19: Unit | BI19: Item No. | BK19: Description | BP19: Est. Qty | BQ19: Unit
A20: CA05 | B20: Distance Rates for All Areas excluding Okinawa | H20: 800 | I20: EA | P20: CB05 | Q20: Distance Rates for All Areas excluding Okinawa | W20: 800 | X20: EA | AE20: CC05 | AF20: Distance Rates for All Areas excluding Okinawa | AL20: 800 | AM20: EA | AT20: CD05 | AU20: Distance Rates for All Areas excluding Okinawa | BA20: 800 | BB20: EA | BI20: CE05 | BJ20: Distance Rates for All Areas excluding Okinawa | BP20: 800 | BQ20: EA
H21: One-Way | I21: Truck Type | W21: One-Way | X21: Truck Type | AL21: One-Way | AM21: Truck Type | BA21: One-Way | BB21: Truck Type | BP21: One-Way | BQ21: Truck Type
H22: Distance (km) | I22: 20-ton | J22: 26-ton | L22: 30-ton | N22: 36-ton | O22: Self-Loader | W22: Distance (km) | X22: 20-ton | Y22: 26-ton | AA22: 30-ton | AC22: 36-ton | AD22: Self-Loader | AL22: Distance (km) | AM22: 20-ton | AN22: 26-ton | AP22: 30-ton | AR22: 36-ton | AS22: Self-Loader | BA22: Distance (km) | BB22: 20-ton | BC22: 26-ton | BE22: 30-ton | BG22: 36-ton | BH22: Self-Loader | BP22: Distance (km) | BQ22: 20-ton | BR22: 26-ton | BT22: 30-ton | BV22: 36-ton | BW22: Self-Loader
H23: 10 | W23: 10 | AL23: 10 | BA23: 10 | BP23: 10
H24: 20 | W24: 20 | AL24: 20 | BA24: 20 | BP24: 20
H25: 30 | W25: 30 | AL25: 30 | BA25: 30 | BP25: 30
H26: 40 | W26: 40 | AL26: 40 | BA26: 40 | BP26: 40
H27: 50 | W27: 50 | AL27: 50 | BA27: 50 | BP27: 50
H28: 60 | W28: 60 | AL28: 60 | BA28: 60 | BP28: 60
H29: 70 | W29: 70 | AL29: 70 | BA29: 70 | BP29: 70
H30: 80 | W30: 80 | AL30: 80 | BA30: 80 | BP30: 80
H31: 90 | W31: 90 | AL31: 90 | BA31: 90 | BP31: 90
H32: 100 | W32: 100 | AL32: 100 | BA32: 100 | BP32: 100
H33: 110 | W33: 110 | AL33: 110 | BA33: 110 | BP33: 110
H34: 120 | W34: 120 | AL34: 120 | BA34: 120 | BP34: 120
... H42: 200 | W42: 200 | AL42: 200 | BA42: 200 | BP42: 200
H43: Over 200 km through 500 km: Per 20 km Increment | W43: Over 200 km through 500 km: Per 20 km Increment | AL43: Over 200 km through 500 km: Per 20 km Increment | BA43: Over 200 km through 500 km: Per 20 km Increment | BP43: Over 200 km through 500 km: Per 20 km Increment
H44: Over 500 km: Per 50 km Increment | W44: Over 500 km: Per 50 km Increment | AL44: Over 500 km: Per 50 km Increment | BA44: Over 500 km: Per 50 km Increment | BP44: Over 500 km: Per 50 km Increment
A45: ② ESTIMATED TOTAL AMOUNT FOR STANDARD TABLE: | N45: ¥ | O45: =SUM(I23:O44) -> 0 | P45: ② ESTIMATED TOTAL AMOUNT FOR STANDARD TABLE: | AC45: ¥ | AD45: =SUM(X23:AD44) -> 0 | AE45: ② ESTIMATED TOTAL AMOUNT FOR STANDARD TABLE: | AR45: ¥ | AS45: =SUM(AM23:AS44) -> 0 | AT45: ② ESTIMATED TOTAL AMOUNT FOR STANDARD TABLE: | BG45: ¥ | BH45: =SUM(BB23:BH44) -> 0 | BI45: ② ESTIMATED TOTAL AMOUNT FOR STANDARD TABLE: | BV45: ¥ | BW45: =SUM(BQ23:BW44) -> 0
A46: OKINAWA DISTANCE RATE TABLE (IAW nationwide industiry standards and GOJ guidelines; see PWS 3.4.2.): All listed unit prices shall be one-way rates per truckload of OSOW freight. (Min. Chargeable Distance: 5km) If proposing under the Okinawa portion of the OSOW family, offerors shall provide proposed distance rates for all listed truck types and distances. | P46: OKINAWA DISTANCE RATE TABLE (IAW nationwide industiry standards and GOJ guidelines; see PWS 3.4.2.): All listed unit prices shall be one-way rates per truckload of OSOW freight. (Min. Chargeable Distance: 5km) If proposing under the Okinawa portion of the OSOW family, offerors shall provide proposed distance rates for all listed truck types and distances. | AE46: OKINAWA DISTANCE RATE TABLE (IAW nationwide industiry standards and GOJ guidelines; see PWS 3.4.2.): All listed unit prices shall be one-way rates per truckload of OSOW freight. (Min. Chargeable Distance: 5km) If proposing under the Okinawa portion of the OSOW family, offerors shall provide proposed distance rates for all listed truck types and distances. | AT46: OKINAWA DISTANCE RATE TABLE (IAW nationwide industiry standards and GOJ guidelines; see PWS 3.4.2.): All listed unit prices shall be one-way rates per truckload of OSOW freight. (Min. Chargeable Distance: 5km) If proposing under the Okinawa portion of the OSOW family, offerors shall provide proposed distance rates for all listed truck types and distances. | BI46: OKINAWA DISTANCE RATE TABLE (IAW nationwide industiry standards and GOJ guidelines; see PWS 3.4.2.): All listed unit prices shall be one-way rates per truckload of OSOW freight. (Min. Chargeable Distance: 5km) If proposing under the Okinawa portion of the OSOW family, offerors shall provide proposed distance rates for all listed truck types and distances.
A47: Item No. | C47: Description | H47: Est. Qty | I47: Unit | P47: Item No. | R47: Description | W47: Est. Qty | X47: Unit | AE47: Item No. | AG47: Description | AL47: Est. Qty | AM47: Unit | AT47: Item No. | AV47: Description | BA47: Est. Qty | BB47: Unit | BI47: Item No. | BK47: Description | BP47: Est. Qty | BQ47: Unit
...

Sheet D. ISO
A1: EXHIBIT DA: ISO CONTAINER TRUCKING FAMILY PRICING SCHEDULE (BASE YEAR 0004) | N1: EXHIBIT DB: ISO CONTAINER TRUCKING FAMILY PRICING SCHEDULE (BASE YEAR 1004) | AA1: EXHIBIT DC: ISO CONTAINER TRUCKING FAMILY PRICING SCHEDULE (BASE YEAR 2004) | AN1: EXHIBIT DD: ISO CONTAINER TRUCKING FAMILY PRICING SCHEDULE (BASE YEAR 3004) | BA1: EXHIBIT DE: ISO CONTAINER TRUCKING FAMILY PRICING SCHEDULE (BASE YEAR 4004)
A2: POINT-TO-POINT ROUTES (IAW PWS 3.4.1.): All listed unit prices shall be one-way rates per truckload of general freight. If proposing under the Mainland portion of the ISO Contrainer family, offerors shall provide proposed unit prices for all listed Items. | N2: POINT-TO-POINT ROUTES (IAW PWS 3.4.1.): All listed unit prices shall be one-way rates per truckload of general freight. If proposing under the Mainland portion of the ISO Contrainer family, offerors shall provide proposed unit prices for all listed Items. | AA2: POINT-TO-POINT ROUTES (IAW PWS 3.4.1.): All listed unit prices shall be one-way rates per truckload of general freight. If proposing under the Mainland portion of the ISO Contrainer family, offerors shall provide proposed unit prices for all listed Items. | AN2: POINT-TO-POINT ROUTES (IAW PWS 3.4.1.): All listed unit prices shall be one-way rates per truckload of general freight. If proposing under the Mainland portion of the ISO Contrainer family, offerors shall provide proposed unit prices for all listed Items. | BA2: POINT-TO-POINT ROUTES (IAW PWS 3.4.1.): All listed unit prices shall be one-way rates per truckload of general freight. If proposing under the Mainland portion of the ISO Contrainer family, offerors shall provide proposed unit prices for all listed Items.
A3: Item No. | B3: Description | H3: Est. Qty | I3: Unit | K3: Unit Price | M3: Est. Total | N3: Item No. | O3: Description | U3: Est. Qty | V3: Unit | X3: Unit Price | Z3: Est. Total | AA3: Item No. | AB3: Description | AH3: Est. Qty | AI3: Unit | AK3: Unit Price | AM3: Est. Total | AN3: Item No. | AO3: Description | AU3: Est. Qty | AV3: Unit | AX3: Unit Price | AZ3: Est. Total | BA3: Item No. | BB3: Description | BH3: Est. Qty | BI3: Unit | BK3: Unit Price | BM3: Est. Total
A4: DA01 | B4: Between | C4: Hiro Ammunition Depot | N4: DB01 | O4: Between | P4: Hiro Ammunition Depot | AA4: DC01 | AB4: Between | AC4: Hiro Ammunition Depot | AN4: DD01 | AO4: Between | AP4: Hiro Ammunition Depot | BA4: DE01 | BB4: Between | BC4: Hiro Ammunition Depot
B5: and | C5: Kawakami Ammunition Depot (37km) | O5: and | P5: Kawakami Ammunition Depot (37km) | AB5: and | AC5: Kawakami Ammunition Depot (37km) | AO5: and | AP5: Kawakami Ammunition Depot (37km) | BB5: and | BC5: Kawakami Ammunition Depot (37km)
A6: DA01A | C6: Transportation of 20' ISO Container | H6: 110 | I6: EA | J6: ¥ | L6: ¥ | M6: =H6*K6 -> 0 | N6: DB01A | P6: Transportation of 20' ISO Container | U6: 110 | V6: EA | W6: ¥ | Y6: ¥ | Z6: =U6*X6 -> 0 | AA6: DC01A | AC6: Transportation of 20' ISO Container | AH6: 110 | AI6: EA | AJ6: ¥ | AL6: ¥ | AM6: =AH6*AK6 -> 0 | AN6: DD01A | AP6: Transportation of 20' ISO Container | AU6: 110 | AV6: EA | AW6: ¥ | AY6: ¥ | AZ6: =AU6*AX6 -> 0 | BA6: DE01A | BC6: Transportation of 20' ISO Container | BH6: 110 | BI6: EA | BJ6: ¥ | BL6: ¥ | BM6: =BH6*BK6 -> 0
A7: DA01B | C7: Transportation of 40' ISO Container | H7: 10 | I7: EA | J7: ¥ | L7: ¥ | M7: =H7*K7 -> 0 | N7: DB01B | P7: Transportation of 40' ISO Container | U7: 10 | V7: EA | W7: ¥ | Y7: ¥ | Z7: =U7*X7 -> 0 | AA7: DC01B | AC7: Transportation of 40' ISO Container | AH7: 10 | AI7: EA | AJ7: ¥ | AL7: ¥ | AM7: =AH7*AK7 -> 0 | AN7: DD01B | AP7: Transportation of 40' ISO Container | AU7: 10 | AV7: EA | AW7: ¥ | AY7: ¥ | AZ7: =AU7*AX7 -> 0 | BA7: DE01B | BC7: Transportation of 40' ISO Container | BH7: 10 | BI7: EA | BJ7: ¥ | BL7: ¥ | BM7: =BH7*BK7 -> 0
A8: DA02 thru DA03 | C8: Reserved | H8: Reserved | N8: DB02 thru DB03 | P8: Reserved | U8: Reserved | AA8: DC02 thru DC03 | AC8: Reserved | AH8: Reserved | AN8: DD02 thru DD03 | AP8: Reserved | AU8: Reserved | BA8: DE02 thru DE03 | BC8: Reserved | BH8: Reserved
A9: ① ESTIMATED TOTAL AMOUNT FOR POINT-TO-POINT ROUTE: | L9: ¥ | M9: =SUM(M5:M7) -> 0 | N9: ① ESTIMATED TOTAL AMOUNT FOR POINT-TO-POINT ROUTE: | Y9: ¥ | Z9: =SUM(Z5:Z7) -> 0 | AA9: ① ESTIMATED TOTAL AMOUNT FOR POINT-TO-POINT ROUTE: | AL9: ¥ | AM9: =SUM(AM5:AM7) -> 0 | AN9: ① ESTIMATED TOTAL AMOUNT FOR POINT-TO-POINT ROUTE: | AY9: ¥ | AZ9: =SUM(AZ5:AZ7) -> 0 | BA9: ① ESTIMATED TOTAL AMOUNT FOR POINT-TO-POINT ROUTE: | BL9: ¥ | BM9: =SUM(BM5:BM7) -> 0
A10: MAINLAND DISTANCE RATE TABLE (IAW nationwide industiry standards and GOJ guidelines; see PWS 3.4.2.): All listed unit prices shall be one-way rates per truckload of general freight. (Min. Chargeable Distance: 10km) If proposing under the Mainland portion, offerors shall provide proposed distance rates for all listed truck types and distances. | N10: MAINLAND DISTANCE RATE TABLE (IAW nationwide industiry standards and GOJ guidelines; see PWS 3.4.2.): All listed unit prices shall be one-way rates per truckload of general freight. (Min. Chargeable Distance: 10km) If proposing under the Mainland portion, offerors shall provide proposed distance rates for all listed truck types and distances. | AA10: MAINLAND DISTANCE RATE TABLE (IAW nationwide industiry standards and GOJ guidelines; see PWS 3.4.2.): All listed unit prices shall be one-way rates per truckload of general freight. (Min. Chargeable Distance: 10km) If proposing under the Mainland portion, offerors shall provide proposed distance rates for all listed truck types and distances. | AN10: MAINLAND DISTANCE RATE TABLE (IAW nationwide industiry standards and GOJ guidelines; see PWS 3.4.2.): All listed unit prices shall be one-way rates per truckload of general freight. (Min. Chargeable Distance: 10km) If proposing under the Mainland portion, offerors shall provide proposed distance rates for all listed truck types and distances. | BA10: MAINLAND DISTANCE RATE TABLE (IAW nationwide industiry standards and GOJ guidelines; see PWS 3.4.2.): All listed unit prices shall be one-way rates per truckload of general freight. (Min. Chargeable Distance: 10km) If proposing under the Mainland portion, offerors shall provide proposed distance rates for all listed truck types and distances.
A11: Item No. | B11: Description | H11: Est. Qty | I11: Unit | N11: Item No. | O11: Description | U11: Est. Qty | V11: Unit | AA11: Item No. | AB11: Description | AH11: Est. Qty | AI11: Unit | AN11: Item No. | AO11: Description | AU11: Est. Qty | AV11: Unit | BA11: Item No. | BB11: Description | BH11: Est. Qty | BI11: Unit
A12: DA04 | B12: Distance Rates for All Areas excluding Okinawa | H12: 250 | I12: EA | N12: DB04 | O12: Distance Rates for All Areas excluding Okinawa | U12: 250 | V12: EA | AA12: DC04 | AB12: Distance Rates for All Areas excluding Okinawa | AH12: 250 | AI12: EA | AN12: DD04 | AO12: Distance Rates for All Areas excluding Okinawa | AU12: 250 | AV12: EA | BA12: DE04 | BB12: Distance Rates for All Areas excluding Okinawa | BH12: 250 | BI12: EA
H13: One-Way | J13: Container Size | U13: One-Way | W13: Container Size | AH13: One-Way | AJ13: Container Size | AU13: One-Way | AW13: Container Size | BH13: One-Way | BJ13: Container Size
H14: Distance (km) | J14: 20ft | L14: 40ft | U14: Distance (km) | W14: 20ft | Y14: 40ft | AH14: Distance (km) | AJ14: 20ft | AL14: 40ft | AU14: Distance (km) | AW14: 20ft | AY14: 40ft | BH14: Distance (km) | BJ14: 20ft | BL14: 40ft
H15: 10 | U15: 10 | AH15: 10 | AU15: 10 | BH15: 10
H16: 20 | U16: 20 | AH16: 20 | AU16: 20 | BH16: 20
H17: 30 | U17: 30 | AH17: 30 | AU17: 30 | BH17: 30
H18: 40 | U18: 40 | AH18: 40 | AU18: 40 | BH18: 40
H19: 50 | U19: 50 | AH19: 50 | AU19: 50 | BH19: 50
H20: 60 | U20: 60 | AH20: 60 | AU20: 60 | BH20: 60
H21: 70 | U21: 70 | AH21: 70 | AU21: 70 | BH21: 70
H22: 80 | U22: 80 | AH22: 80 | AU22: 80 | BH22: 80
H23: 90 | U23: 90 | AH23: 90 | AU23: 90 | BH23: 90
H24: 100 | U24: 100 | AH24: 100 | AU24: 100 | BH24: 100
H25: 110 | U25: 110 | AH25: 110 | AU25: 110 | BH25: 110
H26: 120 | U26: 120 | AH26: 120 | AU26: 120 | BH26: 120
... H34: 200 | U34: 200 | AH34: 200 | AU34: 200 | BH34: 200
H35: Over 200 km through 500 km: Per 20 km Increment | U35: Over 200 km through 500 km: Per 20 km Increment | AH35: Over 200 km through 500 km: Per 20 km Increment | AU35: Over 200 km through 500 km: Per 20 km Increment | BH35: Over 200 km through 500 km: Per 20 km Increment
H36: Over 500 km: Per 50 km Increment | U36: Over 500 km: Per 50 km Increment | AH36: Over 500 km: Per 50 km Increment | AU36: Over 500 km: Per 50 km Increment | BH36: Over 500 km: Per 50 km Increment
A37: ② ESTIMATED TOTAL AMOUNT FOR STANDARD TABLE: | L37: ¥ | M37: =SUM(J15:M36) -> 0 | N37: ② ESTIMATED TOTAL AMOUNT FOR STANDARD TABLE: | Y37: ¥ | Z37: =SUM(W15:Z36) -> 0 | AA37: ② ESTIMATED TOTAL AMOUNT FOR STANDARD TABLE: | AL37: ¥ | AM37: =SUM(AJ15:AM36) -> 0 | AN37: ② ESTIMATED TOTAL AMOUNT FOR STANDARD TABLE: | AY37: ¥ | AZ37: =SUM(AW15:AZ36) -> 0 | BA37: ② ESTIMATED TOTAL AMOUNT FOR STANDARD TABLE: | BL37: ¥ | BM37: =SUM(BJ15:BM36) -> 0
