Workbook

Sheet RFQ
A1: USAG YONGSAN-CASEY, Bldg 2849, Appliances | R1: Housing | S1: GSA
A2: # | B2: Qty | C2: FID Para. | D2: FID Item Code / Description | E2: Vendor Quoted | F2: Product Line Quoted | G2: Model Quoted | H2: =IF(R1="Housing","Nominal Dimensions For Information Only Provide dimensions in Inches","HIDE THESE COLUMNS") -> Nominal Dimensions For Information Only Provide dimensions in Inches | K2: =IF(S1="GSA","GSA Contract Number OR Open Market","Hide this column") -> GSA Contract Number OR Open Market | N2: =IF(S1="GSA","GSA Contract Unit Cost") -> GSA Contract Unit Cost | O2: =IF(S1="GSA","GSA Contract Total Cost","Hide this column") -> GSA Contract Total Cost | P2: HNC Unit Cost | Q2: HNC Total Cost | R2: EDC-I: Hide these columns before submitting file. Select correct entries in the boxes above. These columns shows open market costs and difference from GSA
H3: =IF($R$1="Admin","","W") -> W | I3: H | J3: D | R3: Open Market | S3: GSA vs HNC
A4: 1 | B4: 100 | C4: 8.2.a | D4: AP03: Refrigerator Freezer, 10 cu.ft. | O4: =SUM($N4*$B4) -> 0 | Q4: =SUM($P4*$B4) -> 0 | R4: =IF(LEFT($K4,2)="OP",$Q4,0) -> 0 | S4: =IF($S$1="SAM","",IF(N4="","",P4-N4))
A5: 2 | B5: 10 | C5: 8.3.a | D5: AP04: Refrigerator Freezer, 18-19.5 cu.ft. | O5: =SUM($N5*$B5) -> 0 | Q5: =SUM($P5*$B5) -> 0 | R5: =IF(LEFT($K5,2)="OP",$Q5,0) -> 0 | S5: =IF($S$1="SAM","",IF(N5="","",P5-N5))
A6: 3 | B6: 150 | C6: 8.7 | D6: AP16: Top Load Washing Machine | O6: =SUM($N6*$B6) -> 0 | Q6: =SUM($P6*$B6) -> 0 | R6: =IF(LEFT($K6,2)="OP",$Q6,0) -> 0 | S6: =IF($S$1="SAM","",IF(N6="","",P6-N6))
A7: 4 | B7: 130 | C7: 8.8.a | D7: AP18: Electric Dryer | O7: =SUM($N7*$B7) -> 0 | Q7: =SUM($P7*$B7) -> 0 | R7: =IF(LEFT($K7,2)="OP",$Q7,0) -> 0 | S7: =IF($S$1="SAM","",IF(N7="","",P7-N7))
A8: Furniture Subtotals: | G8: =IF(S1="GSA","Open Market:","") -> Open Market: | L8: =IF(S1="GSA",R8,"") -> 0 | N8: GSA Cost: | O8: =SUM(O4:O7) -> 0 | P8: =SUM(P4:P7) -> 0 | Q8: =SUM(Q4:Q7) -> 0 | R8: =SUM(R4:R7) -> 0
A9: =IF(S1="GSA","Please note, if one or more of the boxes above are in amber or red, please refer to RFQ, Sect. J, Instruction to Quoters for requirements for Open Market items.","") -> Please note, if one or more of the boxes above are in amber or red, please refer to RFQ, Sect. J, Instruction to Quoters for requirements for Open Market items. | R9: Open Market Total above
A10: Installation & Shipping:
A11: Shipping (CONUS)
A12: Commercial Shipping (OCONUS) | C12: Offload only
A13: Tariffs
A14: Offload Only | R14: Housing
A15: GRAND TOTAL: | Q15: =SUM(Q8:Q14) -> 0
A16: Do not alter any formulas in shaded cells
A17: If part of an item is on GSA Contract and part is open market, Vendor shall provide a description, model, and cost of open market item(s) on the same line as the GSA item. | R17: SAM
A18: GSA Contract Unit Cost is the cost provided on GSA schedule per item. HNC Unit Cost is the cost provided to HNC per item. | R18: GSA

Sheet Tech Eval HNC USE ONLY
A1: =IF(RFQ!D4="",0,RFQ!A4) -> 1 | B1: =IF(C1=0,0,"FID "&RFQ!C4) -> FID 8.2.a | C1: =RFQ!D4 -> AP03: Refrigerator Freezer, 10 cu.ft.
A2: Vendor Quoted: | C2: =RFQ!E4 -> 0
A3: Product Line Quoted: | C3: =RFQ!F4 -> 0
A4: Model Quoted: | C4: =RFQ!G4 -> 0
A5: GSA # or Open Market: | C5: =RFQ!K4 -> 0
A6: Warranty:
A7: 1st Review HNC:
A8: 1st Review Vendor:
A9: 2nd Review HNC:
A10: 2nd Review Vendor:
A11: 3rd Review HNC:
A12: 3rd Review Vendor:
A13: 4th Review HNC:
A14: 4th Review Vendor:
A15: =IF(RFQ!D5="",0,RFQ!A5) -> 2 | B15: =IF(C15=0,0,"FID "&RFQ!C5) -> FID 8.3.a | C15: =RFQ!D5 -> AP04: Refrigerator Freezer, 18-19.5 cu.ft.
A16: Vendor Quoted: | C16: =RFQ!E5 -> 0
A17: Product Line Quoted: | C17: =RFQ!F5 -> 0
A18: Model Quoted: | C18: =RFQ!G5 -> 0
A19: GSA # or Open Market: | C19: =RFQ!K5 -> 0
A20: Warranty:
A21: 1st Review HNC:
A22: 1st Review Vendor:
A23: 2nd Review HNC:
A24: 2nd Review Vendor:
A25: 3rd Review HNC:
A26: 3rd Review Vendor:
A27: 4th Review HNC:
A28: 4th Review Vendor:
A29: =IF(RFQ!D6="",0,RFQ!A6) -> 3 | B29: =IF(C29=0,0,"FID "&RFQ!C6) -> FID 8.7 | C29: =RFQ!D6 -> AP16: Top Load Washing Machine
A30: Vendor Quoted: | C30: =RFQ!E6 -> 0
A31: Product Line Quoted: | C31: =RFQ!F6 -> 0
A32: Model Quoted: | C32: =RFQ!G6 -> 0
A33: GSA # or Open Market: | C33: =RFQ!K6 -> 0
A34: Warranty:
A35: 1st Review HNC:
A36: 1st Review Vendor:
A37: 2nd Review HNC:
A38: 2nd Review Vendor:
A39: 3rd Review HNC:
A40: 3rd Review Vendor:
...

Sheet Instructions
A1: ATTACHMENT 1 TEMPLATE - 06/06/25
A2: Preparation of the Attachment 1 prior to RFQ If there are multiple buildings, see instructions below.
A3: 1 | B3: In the A column, Select SAM buy or GSA buy. If SAM buy, Hide the two columns that are purple at the top and hide the last two rows of notes at the bottom that refer to GSA. | D3: Types of Delivery
A4: 2 | B4: In the FID, Highlight the entire Table of Contents and Copy. | D4: Installation of furniture - to include any GFP in the SOW, if applicable | E4: Vendor Install all items on Att 1. GFP is Government Furnished Products (usually items in warehouse).
A5: 3 | B5: In the Prep Tab (in this form), highlight upper left cell and Paste by right clicking on your mouse and using the second Paste option (Match Destination Formatting (M)). | D5: Shipping (CONUS) Note 1 | E5: Shipping in the continental US
A6: 4 | B6: In the Prep Tab, Delete Column C. | D6: Commercial Shipping (OCONUS) | E6: Commercial shipping to locations outside of the continental US.
A7: 5 | B7: In the Prep Tab, Delete all rows that you do not want in the Attachment 1 (extra lines, titles, "Not Used"). Keep only items you want listed in the Attachment 1. | D7: Secure Shipping (CONUS/OCONUS) - Refer to SOW | E7: For projects that have security requirements like locked and sealed containers, potentially SCIFs, NOCs, Ops Centers, etc.
A8: 6 | B8: In the Prep Tab, Highlight text and Copy into columns D & E of the RFQ tab by clicking on cell F4 and Paste by right clicking on your mouse and using the second Paste option (Values (V)). NOTE: Only copy FID paragraph number & Item Code and Description into RFQ tab. | D8: Electrical Work- Hardwire all items as noted in the FID to the Facility | E8: Electrical Work - This is used if there are items to be hardwired. All items should be noted in the FID.
A9: 7 | B9: Ensure that the FID Paragraph numbers are correct and that the zero didn't drop off. For example, verify whether the paragraph is 2.10 instead of 2.1. If you can't add the "0" to the end, Format the column as Text. | D9: Oversight of Delivery | E9: Warehouse workers offload product and a representative for the Vendor is present to oversee.
A10: 8 | B10: Add title to the Att 1 and turn black - it will automatically populate on the Locations matrix. | D10: Offload Only | E10: This is unloaded by the delivery driver.
A11: 9 | B11: In the Locations matrix (right side of the Att 1), adjust row heights and then indicate quantities for each item under each room (Row T-CU). Once completed, Hide all unused columns and rows, indicated by purple boxes, up to the green cells. NOTE: Enter quantities in the Locations area only. | D11: Removal and Disposal of Existing Furniture | E11: Vendor is responsible for removal of the old furnishings and to dispose of them.
A12: 10 | B12: Hide Column A when the form is complete. (A contains the formula for the OPEN MARKET TOTAL). | D12: Removal of Existing Furniture and Moving to Designated Location | E12: Vendor is responsible for removal of the old furnishings and to moving it to another building.
A13: 11 | B13: Keep the Installation and Shipping that pertain to your order and turn the text black. Hide Installation & Shipping lines not needed. NOTE: Types of Delivery are defined in the table on the right of this page.
A14: 12 | B14: Hide all extra rows down to Furniture Subtotals.
A15: 13 | B15: Hide all tabs except RFQ. Right click on the tab and click Hide.
A16: 14 | B16: Save spreadsheet.
A18: Preparation of the Attachment 1 prior to RFQ for projects with multiple buildings | D18: Tech Review "Warranty" blank comment examples are:
A19: 1 | B19: Perform the instructions 1-8 above "Preparation of the Attachment 1 prior to RFQ" . | D19: N/A
A20: 2 | B20: File Save As for each additional building. | D20: Provide a warranty for this item.
A21: 3 | B21: Complete steps 9-14 under "Preparation of the Attachment 1 prior to RFQ" for all buildings. | D21: Warranty was provided but does not meet the FID requirement.
D22: Warranty provided and acceptable.
A23: Inserting More Rows into RFQ Tab
A24: 1 | B24: To insert more rows in the RFQ tab (there are 80 rows available in the template): A. Highlight row 84 and move your cursor down how ever many rows are needed. B. Right click and select Insert. C. Highlight row 84 and Copy to all the new blank rows. NOTE: MAKE SURE SUBTOTALS AND TOTALS ARE INCLUSIVE OF NEW ROWS!
A25: 2 | B25: To insert a row in the middle of the RFQ tab: A. Highlight the row below where you need the new row, right click, and select Insert. B. Look at the "#" to determine which numbers the new row is between and Copy the "#", "Qty", "Unit", "GSA Contract Total Cost", and "HNC Total Cost" cells from the row above. C. Then Copy the "#" cell you just pasted into the "#" cell in the row below to fix the row numbering. D. Then, enter the "FID Para." and "Item Code & Description" information. E. Enter the quantities in the appropriate rooms/areas. F. Then, in the Tech Eval tab, Insert 14 rows and copy the data from the 14 rows above into these new cells. G. Change the formulas in the top 2 rows of the rows you just copied by comparing the formulas from 14 cells above and 14 cells below to determine what number needs to be changed in the formula. I. Check to ensure everything copied and the line numbering is correct on both tabs.
A26: 3 | B26: To delete a row in the middle of the RFQ tab: A. Highlight the row to delete and delete. B. Highlight the "#" cell above the first row with "##". C. Paste the copied "#" cell into the first "#" cell with "##". Then you will need to go to the Tech Eval tab and Delete the 14 lines for the item that was removed. (Easily identified by "#REF").
A28: Inserting more Columns into Locations area
A29: 1 | B29: If you need to insert more columns in the Locations matrix (there are 80 columns in the template), highlight the green column and move your cursor to how many columns you need to add. Right click and select "Insert". Then Highlight the last column and Copy into the new columns.
A31: Printing (optional)
A32: 1 | B32: To print the Attachment 1, go to "VIEW" tab, select "Custom Views", and highlight "attach1" and click show. Then go to FILE/PRINT. It is set up to print landscape on 8.5 x 11 paper.
A33: 2 | B33: To print the Locations, go to "VIEW" tab, select "Custom Views", and highlight "locations" and click show. Then go to FILE/PRINT. It is set up to print landscape on 8.5 x 11 paper.
A35: Preparation of Tech Eval after quotes are received back from Vendors
A36: 1 | B36: A. Copy the "Tech Eval HNC USE ONLY" columns A-C, all rows that are blue (prior to the first purple cells) into Att 8 Document (Word) prior to starting the Tech Eval. B. Title the Document "1st TR - Vendor - Project Name.docx" for the Tech Eval. Each item will have a "block" of 14 rows, to allow for multiple rounds of tech evals. When dealing with a specific item, please remember there are 14 rows to copy. NOTE: DO NOT COMPLETE THE TECH REVIEW IN THE ATT 1 TEMPLATE.
A37: 2 | B37: To add more lines to the RFQ Tab: A. When lines are added to the RFQ tab you must also insert more rows in the Tech Eval tab. B. Highlight the 14 rows that reflect the tech eval block for the item directly above. C. Copy those onto the end, or in whatever location is required, repeat for each new item. D. Hand change the 7 formulas that pull data from the RFQ tab. They are in the first 5 lines of the item block. The 2 digit cell numbers will need to be changed to 85. The next one will be changed to 86 and so forth.
A38: 3 | B38: To delete lines from the RFQ Tab: A. If lines are deleted from the RFQ Tab, you will need to delete rows in the Tech Eval tab. B. The item block in the Tech Eval tab will have the #REF! error. If you come across a block that is not needed, either Delete or Hide those 14 rows.
A40: Preparation of an Revision / MOD
A41: 1 | B41: A. "Save As" the Att 1 file and add REV 00-00-0000 (date) to the title and the file name. B. To update the Att 1 for a change of product manually highlight cells in yellow that need changing (modifying). C. For a change in quantity, this includes the quantity on the Locations matrix, the total quantity for the item on the Locations matrix, and the quantity on the RFQ table, Highlight the yellow cell(s) at the bottom of the Locations matrix and use Format Paint to update the cells above. NOTE: Tan lines cannot be changed to yellow the normal way.

Sheet Prep Tab
