Workbook

Sheet Instructions
A2: Use the information from the prefilled division sheets below to complete the 50 Divisions Cost Estimate CSI* Format tool to build your proposal. The information from the prefilled division sheets may not be all inclusive. The contractor is allowed to include any missing items from each division and is allowed to fill in other divisions that are not listed in the prefilled division sheets. If there is a disagreement with the prefilled division sheets, the contractor should not delete the element(s), but instead leave it blank and then include their suggested element(s) at the bottom of that division tab. Please note that on the summary page there is a place to fill in overhead and profit percentages for both the prime and the subcontractor that will self-populate the summary page and all the division tabs. Exceptions: (1) if each subcontractor has a different overhead and profit rates than the percentage placed on the summary page, an adjustment will have to be made to that specific division page. The spreadsheet will still calculate correctly. (2) If the prime is self-performing the work for that division then the profit and overhead will need to be zeroed for that particular division, because the primes overhead and profit is already captured on the summary page.
A3: The ktr is required to complete the areas marked "Fill Here" in the summary tab. The rest of the information in the summary tab will automatically tabulate from the individual division tabs except for the few exceptions listed above.
A4: Divisions 1, 2, and 3 show sample inputs to illustrate how the spreadsheet works.
A8: * CSI = Construction Specifications Institute

Sheet Summary
A1: CONSTRUCTION COST ESTIMATE | C1: Date:
D2: Fill Here
A3: COMPANY
A4: Fill Here
A7: PROJECT
A8: Fill Here
A9: LOCATION | C9: PROJECT NO. | D9: Fill Here
A10: EGLIN AIR FORCE BASE, FLORIDA
A11: DIVISION | B11: DESCRIPTION | C11: % by Division | D11: Division Total
A13: DIVISION 01 | B13: GENERAL REQUIREMENTS | C13: =SUM(D13/D60) -> 0.28748024 | D13: ='Div1'!H$46 -> 50
A14: DIVISION 02 | B14: EXISTING CONDITIONS | C14: =SUM(D14/D60) -> 0.34195774 | D14: ='Div2'!H46 -> 59.475
A15: DIVISION 03 | B15: CONCRETE WORK | C15: =SUM(D15/D60) -> 0.37056202 | D15: ='Div3'!H$46 -> 64.45 | F15: FILL IN AS REQUIRED (this will link to the entire document)
A16: DIVISION 04 | B16: MASONRY | C16: =SUM(D16/D60) -> 0 | D16: ='Div4'!H$46 -> 0
A17: DIVISION 05 | B17: METALS | C17: =SUM(D17/D60) -> 0 | D17: ='Div5'!H$46 -> 0
A18: DIVISION 06 | B18: WOOD, PLASTICS AND COMPOSITES | C18: =SUM(D18/D60) -> 0 | D18: ='Div6'!H$46 -> 0 | F18: GC Overhead | G18: 0.1
A19: DIVISION 07 | B19: THERMAL AND MOISTURE PROTECTION | C19: =SUM(D19/D60) -> 0 | D19: ='Div7'!H$46 -> 0 | F19: GC Profit | G19: 0.15
A20: DIVISION 08 | B20: OPENINGS | C20: =SUM(D20/D60) -> 0 | D20: ='Div8'!H$46 -> 0 | F20: Sub Overhead | G20: 0.05
A21: DIVISION 09 | B21: FINISHES | C21: =SUM(D21/D60) -> 0 | D21: ='Div9'!H$46 -> 0 | F21: Sub Profit | G21: 0.11
A22: DIVISION 10 | B22: SPECIALTIES | C22: =SUM(D22/D60) -> 0 | D22: ='Div10'!H$46 -> 0 | F22: Sales Tax | G22: 0.06
A23: DIVISION 11 | B23: EQUIPMENT | C23: =SUM(D23/D60) -> 0 | D23: ='Div11'!H$46 -> 0 | F23: Risk/Bonding | G23: 0.02
A24: DIVISION 12 | B24: FURNISHINGS | C24: =SUM(D24/D$60) -> 0 | D24: ='Div12'!H$46 -> 0
A25: DIVISION 13 | B25: SPECIAL CONSTRUCTION | C25: =SUM(D25/D$60) -> 0 | D25: ='Div13'!H$46 -> 0 | F25: This spreadsheet contains many formulas... please save a copy prior to editting in case you make a mistake. All shaded areas are either linked or contain formulas
A26: DIVISION 14 | B26: CONVEYING EQUIPMENT | C26: =SUM(D26/D$60) -> 0 | D26: ='Div14'!H$46 -> 0
A27: DIVISION 15 | B27: RESERVED | C27: =SUM(D27/D$60) -> 0 | D27: ='Div15'!H$46 -> 0
A28: DIVISION 16 | B28: RESERVED | C28: =SUM(D28/D$60) -> 0 | D28: ='Div16'!H$47 -> 0
A29: DIVISION 20 | B29: RESERVED | C29: =SUM(D29/D$60) -> 0 | D29: ='Div20'!H$47 -> 0
A30: DIVISION 21 | B30: FIRE SUPRESSION | C30: =SUM(D30/D$60) -> 0 | D30: ='Div21'!H$46 -> 0
A31: DIVISION 22 | B31: PLUMBING | C31: =SUM(D31/D$60) -> 0 | D31: ='Div22'!H$46 -> 0
A32: DIVISION 23 | B32: HEATING, VENTILATING AND A/C | C32: =SUM(D32/D$60) -> 0 | D32: ='Div23'!H$46 -> 0
A33: DIVISION 24 | B33: RESERVED | C33: =SUM(D33/D$60) -> 0 | D33: ='Div24'!H$46 -> 0
A34: DIVISION 25 | B34: INTEGRATED AUTOMATION | C34: =SUM(D34/D$60) -> 0 | D34: ='Div25'!H$46 -> 0
A35: DIVISION 26 | B35: ELECTRICAL | C35: =SUM(D35/D$60) -> 0 | D35: ='Div26'!H$46 -> 0
A36: DIVISION 27 | B36: COMMUNICATIONS | C36: =SUM(D36/D$60) -> 0 | D36: ='Div27'!H$46 -> 0
A37: DIVISION 28 | B37: ELECTRONIC SAFETY AND SECURITY | C37: =SUM(D37/D$60) -> 0 | D37: ='Div28'!H$46 -> 0
A38: DIVISION 29 | B38: RESERVED | C38: =SUM(D38/D$60) -> 0 | D38: ='Div29'!H$46 -> 0
A39: DIVISION 30 | B39: RESERVED | C39: =SUM(D39/D$60) -> 0 | D39: ='Div30'!H$46 -> 0
A40: DIVISION 31 | B40: EARTHWORK | C40: =SUM(D40/D$60) -> 0 | D40: ='Div31'!H$46 -> 0
A41: DIVISION 32 | B41: EXTERIOR IMPROVEMENTS | C41: =SUM(D41/D$60) -> 0 | D41: ='Div32'!H$46 -> 0
A42: DIVISION 33 | B42: UTILITIES | C42: =SUM(D42/D$60) -> 0 | D42: ='Div33'!H$46 -> 0
A43: DIVISION 34 | B43: TRANSPORTATION | C43: =SUM(D43/D$60) -> 0 | D43: ='Div34'!H$46 -> 0
...

Sheet Div1
A1: CONSTRUCTION COST ESTIMATE | D1: DATE
D2: =Summary!D2 -> Fill Here
A3: PROJECT | F3: BASIS FOR ESTIMATE
A4: =Summary!A8 -> Fill Here | F4: CODE A (No design completed)
A5: LOCATION | F5: CODE B (Preliminary design)
A6: EGLIN AIR FORCE BASE, FLORIDA | F6: CODE C (Final design)
A7: COMPANY | C7: PROJECT NO. | F7: OTHER (Specify)
A8: =Summary!A4 -> Fill Here | C8: =Summary!D9 -> Fill Here
A9: DRAWING NO. | B9: ESTIMATOR | F9: CHECKED BY
B11: QUANTITY | D11: LABOR | F11: MATERIAL
A12: ITEM DESCRIPTION | B12: NO. UNITS | C12: UNIT MEAS. | D12: PER UNIT | E12: TOTAL | F12: PER UNIT | G12: TOTAL | H12: TOTAL COST
A13: =Summary!B13 -> GENERAL REQUIREMENTS
E14: =B14*D14 -> 0 | G14: =B14*F14 -> 0 | H14: =E14+G14 -> 0
E15: =B15*D15 -> 0 | G15: =B15*F15 -> 0 | H15: =E15+G15 -> 0
A16: Sample Input | B16: 2 | E16: =B16*D16 -> 0 | F16: 10 | G16: =B16*F16 -> 20 | H16: =E16+G16 -> 20
A17: Sample Input | B17: 3 | C17: 1 | D17: 10 | E17: =B17*D17 -> 30 | G17: =B17*F17 -> 0 | H17: =E17+G17 -> 30
E18: =B18*D18 -> 0 | G18: =B18*F18 -> 0 | H18: =E18+G18 -> 0
E20: =B20*D20 -> 0 | G20: =B20*F20 -> 0 | H20: =E20+G20 -> 0
E21: =B21*D21 -> 0 | G21: =B21*F21 -> 0 | H21: =E21+G21 -> 0
E22: =B22*D22 -> 0 | G22: =B22*F22 -> 0 | H22: =E22+G22 -> 0
E23: =B23*D23 -> 0 | G23: =B23*F23 -> 0 | H23: =E23+G23 -> 0
E24: =B24*D24 -> 0 | G24: =B24*F24 -> 0 | H24: =E24+G24 -> 0
E25: =B25*D25 -> 0 | G25: =B25*F25 -> 0 | H25: =E25+G25 -> 0
E26: =B26*D26 -> 0 | G26: =B26*F26 -> 0 | H26: =E26+G26 -> 0
E27: =B27*D27 -> 0 | G27: =B27*F27 -> 0 | H27: =E27+G27 -> 0
E28: =B28*D28 -> 0 | G28: =B28*F28 -> 0 | H28: =E28+G28 -> 0
E29: =B29*D29 -> 0 | G29: =B29*F29 -> 0 | H29: =E29+G29 -> 0
E30: =B30*D30 -> 0 | G30: =B30*F30 -> 0 | H30: =E30+G30 -> 0
... E40: =B40*D40 -> 0 | G40: =B40*F40 -> 0 | H40: =E40+G40 -> 0
A41: TOTAL LABOR/MATERIALS | E41: =SUM(E14:E40) -> 30 | G41: =SUM(G14:G40) -> 20
A42: SUBTOTAL | H42: =SUM(H14:H41) -> 50
A43: Sub-Contractor's Overhead | G43: 0 | H43: =SUM(H42*G43) -> 0
A44: Sub-Contractor's Profit | G44: 0 | H44: =SUM(H42+H43)*G44 -> 0
A45: FL State Sales Tax | G45: 0 | H45: =SUM(G41*G45) -> 0
A46: TOTAL | H46: =SUM(H42:H45) -> 50

Sheet Div2
A1: CONSTRUCTION COST ESTIMATE | D1: DATE
D2: =Summary!D2 -> Fill Here
A3: PROJECT | F3: BASIS FOR ESTIMATE
A4: =Summary!A8 -> Fill Here | F4: CODE A (No design completed)
A5: LOCATION | F5: CODE B (Preliminary design)
A6: EGLIN AIR FORCE BASE, FLORIDA | F6: CODE C (Final design)
A7: COMPANY | C7: PROJECT NO. | F7: OTHER (Specify)
A8: =Summary!A4 -> Fill Here | C8: =Summary!D9 -> Fill Here
A9: DRAWING NO. | B9: ESTIMATOR | F9: CHECKED BY
B11: QUANTITY | D11: LABOR | F11: MATERIAL
A12: ITEM DESCRIPTION | B12: NO. UNITS | C12: UNIT MEAS. | D12: PER UNIT | E12: TOTAL | F12: PER UNIT | G12: TOTAL | H12: TOTAL COST
A13: =Summary!B14 -> EXISTING CONDITIONS
E14: =B14*D14 -> 0 | G14: =B14*F14 -> 0 | H14: =E14+G14 -> 0
E15: =B15*D15 -> 0 | G15: =B15*F15 -> 0 | H15: =E15+G15 -> 0
A16: Sample Input | B16: 2 | E16: =B16*D16 -> 0 | F16: 10 | G16: =B16*F16 -> 20 | H16: =E16+G16 -> 20
A17: Sample Input | B17: 3 | D17: 10 | E17: =B17*D17 -> 30 | G17: =B17*F17 -> 0 | H17: =E17+G17 -> 30
E18: =B18*D18 -> 0 | G18: =B18*F18 -> 0 | H18: =E18+G18 -> 0
E19: =B19*D19 -> 0 | G19: =B19*F19 -> 0 | H19: =E19+G19 -> 0
E20: =B20*D20 -> 0 | G20: =B20*F20 -> 0 | H20: =E20+G20 -> 0
E21: =B21*D21 -> 0 | G21: =B21*F21 -> 0 | H21: =E21+G21 -> 0
E22: =B22*D22 -> 0 | G22: =B22*F22 -> 0 | H22: =E22+G22 -> 0
E23: =B23*D23 -> 0 | G23: =B23*F23 -> 0 | H23: =E23+G23 -> 0
E24: =B24*D24 -> 0 | G24: =B24*F24 -> 0 | H24: =E24+G24 -> 0
E25: =B25*D25 -> 0 | G25: =B25*F25 -> 0 | H25: =E25+G25 -> 0
E26: =B26*D26 -> 0 | G26: =B26*F26 -> 0 | H26: =E26+G27 -> 0
E27: =B27*D27 -> 0 | G27: =B27*F27 -> 0 | H27: =E27+G28 -> 0
E28: =B28*D28 -> 0 | G28: =B28*F28 -> 0 | H28: =E28+G28 -> 0
E29: =B29*D29 -> 0 | G29: =B29*F29 -> 0 | H29: =E29+G29 -> 0
E30: =B30*D30 -> 0 | G30: =B30*F30 -> 0 | H30: =E30+G30 -> 0
E31: =B31*D31 -> 0 | G31: =B31*F31 -> 0 | H31: =E31+G31 -> 0
E32: =B32*D32 -> 0 | G32: =B32*F32 -> 0 | H32: =E32+G32 -> 0
E33: =B33*D33 -> 0 | G33: =B33*F33 -> 0 | H33: =E33+G33 -> 0
E34: =B34*D34 -> 0 | G34: =B34*F34 -> 0 | H34: =E34+G34 -> 0
E35: =B35*D35 -> 0 | G35: =B35*F35 -> 0 | H35: =E35+G35 -> 0
E36: =B36*D36 -> 0 | G36: =B36*F36 -> 0 | H36: =E36+G36 -> 0
E37: =B37*D37 -> 0 | G37: =B37*F37 -> 0 | H37: =E37+G37 -> 0
E38: =B38*D38 -> 0 | G38: =B38*F38 -> 0 | H38: =E38+G38 -> 0
E39: =B39*D39 -> 0 | G39: =B39*F39 -> 0 | H39: =E39+G39 -> 0
E40: =B40*D40 -> 0 | G40: =B40*F40 -> 0 | H40: =E40+G40 -> 0
A41: TOTAL LABOR/MATERIALS | E41: =SUM(E14:E40) -> 30 | G41: =SUM(G14:G40) -> 20
...

Sheet Div3
A1: CONSTRUCTION COST ESTIMATE | D1: DATE
D2: =Summary!D2 -> Fill Here
A3: PROJECT | F3: BASIS FOR ESTIMATE
A4: =Summary!A8 -> Fill Here | F4: CODE A (No design completed)
A5: LOCATION | F5: CODE B (Preliminary design)
A6: EGLIN AIR FORCE BASE, FLORIDA | F6: CODE C (Final design)
A7: COMPANY | C7: PROJECT NO. | F7: OTHER (Specify)
A8: =Summary!A4 -> Fill Here | C8: =Summary!D9 -> Fill Here
A9: DRAWING NO. | B9: ESTIMATOR | F9: CHECKED BY
B11: QUANTITY | D11: LABOR | F11: MATERIAL
A12: ITEM DESCRIPTION | B12: NO. UNITS | C12: UNIT MEAS. | D12: PER UNIT | E12: TOTAL | F12: PER UNIT | G12: TOTAL | H12: TOTAL COST
A13: =Summary!B15 -> CONCRETE WORK
E14: =B14*D14 -> 0 | G14: =B14*F14 -> 0 | H14: =E14+G14 -> 0
E15: =B15*D15 -> 0 | G15: =B15*F15 -> 0 | H15: =E15+G15 -> 0
A16: Sample Input | B16: 2 | E16: =B16*D16 -> 0 | F16: 10 | G16: =B16*F16 -> 20 | H16: =E16+G16 -> 20
A17: Sample Input | B17: 3 | D17: 10 | E17: =B17*D17 -> 30 | G17: =B17*F17 -> 0 | H17: =E17+G17 -> 30
E18: =B18*D18 -> 0 | G18: =B18*F18 -> 0 | H18: =E18+G18 -> 0
E19: =B19*D19 -> 0 | G19: =B19*F19 -> 0 | H19: =E19+G19 -> 0
E20: =B20*D20 -> 0 | G20: =B20*F20 -> 0 | H20: =E20+G20 -> 0
E21: =B21*D21 -> 0 | G21: =B21*F21 -> 0 | H21: =E21+G21 -> 0
E22: =B22*D22 -> 0 | G22: =B22*F22 -> 0 | H22: =E22+G22 -> 0
E23: =B23*D23 -> 0 | G23: =B23*F23 -> 0 | H23: =E23+G23 -> 0
E24: =B24*D24 -> 0 | G24: =B24*F24 -> 0 | H24: =E24+G24 -> 0
E25: =B25*D25 -> 0 | G25: =B25*F25 -> 0 | H25: =E25+G25 -> 0
E26: =B26*D26 -> 0 | G26: =B26*F26 -> 0 | H26: =E26+G26 -> 0
E27: =B27*D27 -> 0 | G27: =B27*F27 -> 0 | H27: =E27+G27 -> 0
E28: =B28*D28 -> 0 | G28: =B28*F28 -> 0 | H28: =E28+G28 -> 0
E29: =B29*D29 -> 0 | G29: =B29*F29 -> 0 | H29: =E29+G29 -> 0
... E40: =B40*D40 -> 0 | G40: =B40*F40 -> 0 | H40: =E40+G40 -> 0
A41: TOTAL LABOR/MATERIALS | E41: =SUM(E14:E40) -> 30 | G41: =SUM(G14:G40) -> 20
A42: SUBTOTAL | H42: =E41+G41 -> 50
A43: Sub-Contractor's Overhead | G43: 0.1 | H43: =SUM(H42*G43) -> 5
A44: Sub-Contractor's Profit | G44: 0.15 | H44: =SUM(H42+H43)*G44 -> 8.25
A45: FL State Sales Tax | G45: =Summary!G22 -> 0.06 | H45: =SUM(G41*G45) -> 1.2
A46: TOTAL | H46: =SUM(H42:H45) -> 64.45

Sheet Div4
A1: CONSTRUCTION COST ESTIMATE | D1: DATE
D2: =Summary!D2 -> Fill Here
A3: PROJECT | F3: BASIS FOR ESTIMATE
A4: =Summary!A8 -> Fill Here | F4: CODE A (No design completed)
A5: LOCATION | F5: CODE B (Preliminary design)
A6: EGLIN AIR FORCE BASE, FLORIDA | F6: CODE C (Final design)
A7: COMPANY | C7: PROJECT NO. | F7: OTHER (Specify)
A8: =Summary!A4 -> Fill Here | C8: =Summary!D9 -> Fill Here
A9: DRAWING NO. | B9: ESTIMATOR | F9: CHECKED BY
B11: QUANTITY | D11: LABOR | F11: MATERIAL
A12: ITEM DESCRIPTION | B12: NO. UNITS | C12: UNIT MEAS. | D12: PER UNIT | E12: TOTAL | F12: PER UNIT | G12: TOTAL | H12: TOTAL COST
A13: =Summary!B16 -> MASONRY
E14: =B14*D14 -> 0 | G14: =B14*F14 -> 0 | H14: =E14+G14 -> 0
E15: =B15*D15 -> 0 | G15: =B15*F15 -> 0 | H15: =E15+G15 -> 0
E16: =B16*D16 -> 0 | G16: =B16*F16 -> 0 | H16: =E16+G16 -> 0
E17: =B17*D17 -> 0 | G17: =B17*F17 -> 0 | H17: =E17+G17 -> 0
E18: =B18*D18 -> 0 | G18: =B18*F18 -> 0 | H18: =E18+G18 -> 0
E19: =B19*D19 -> 0 | G19: =B19*F19 -> 0 | H19: =E19+G19 -> 0
E20: =B20*D20 -> 0 | G20: =B20*F20 -> 0 | H20: =E20+G20 -> 0
E21: =B21*D21 -> 0 | G21: =B21*F21 -> 0 | H21: =E21+G21 -> 0
E22: =B22*D22 -> 0 | G22: =B22*F22 -> 0 | H22: =E22+G22 -> 0
E23: =B23*D23 -> 0 | G23: =B23*F23 -> 0 | H23: =E23+G23 -> 0
E24: =B24*D24 -> 0 | G24: =B24*F24 -> 0 | H24: =E24+G24 -> 0
E25: =B25*D25 -> 0 | G25: =B25*F25 -> 0 | H25: =E25+G25 -> 0
... E40: =B40*D40 -> 0 | G40: =B40*F40 -> 0 | H40: =E40+G40 -> 0
A41: TOTAL LABOR/MATERIALS | E41: =SUM(E14:E40) -> 0 | G41: =SUM(G14:G40) -> 0
A42: SUBTOTAL | H42: =SUM(H14:H40) -> 0
A43: Sub-Contractor's Overhead | G43: =Summary!G20 -> 0.05 | H43: =SUM(H42*G43) -> 0
A44: Sub-Contractor's Profit | G44: =Summary!G21 -> 0.11 | H44: =SUM(H42+H43)*G44 -> 0
A45: FL State Sales Tax | G45: =Summary!G22 -> 0.06 | H45: =SUM(G41*G45) -> 0
A46: TOTAL | H46: =SUM(H42:H45) -> 0

Sheet Div5
A1: CONSTRUCTION COST ESTIMATE | D1: DATE
D2: =Summary!D2 -> Fill Here
A3: PROJECT | F3: BASIS FOR ESTIMATE
A4: =Summary!A8 -> Fill Here | F4: CODE A (No design completed)
A5: LOCATION | F5: CODE B (Preliminary design)
A6: EGLIN AIR FORCE BASE, FLORIDA | F6: CODE C (Final design)
A7: COMPANY | C7: PROJECT NO. | F7: OTHER (Specify)
A8: =Summary!A4 -> Fill Here | C8: =Summary!D9 -> Fill Here
A9: DRAWING NO. | B9: ESTIMATOR | F9: CHECKED BY
B11: QUANTITY | D11: LABOR | F11: MATERIAL
A12: ITEM DESCRIPTION | B12: NO. UNITS | C12: UNIT MEAS. | D12: PER UNIT | E12: TOTAL | F12: PER UNIT | G12: TOTAL | H12: TOTAL COST
A13: =Summary!B17 -> METALS
E14: =B14*D14 -> 0 | G14: =B14*F14 -> 0 | H14: =E14+G14 -> 0
E15: =B15*D15 -> 0 | G15: =B15*F15 -> 0 | H15: =E15+G15 -> 0
E16: =B16*D16 -> 0 | G16: =B16*F16 -> 0 | H16: =E16+G16 -> 0
E17: =B17*D17 -> 0 | G17: =B17*F17 -> 0 | H17: =E17+G17 -> 0
E18: =B18*D18 -> 0 | G18: =B18*F18 -> 0 | H18: =E18+G18 -> 0
E19: =B19*D19 -> 0 | G19: =B19*F19 -> 0 | H19: =E19+G19 -> 0
E20: =B20*D20 -> 0 | G20: =B20*F20 -> 0 | H20: =E20+G20 -> 0
E21: =B21*D21 -> 0 | G21: =B21*F21 -> 0 | H21: =E21+G21 -> 0
E22: =B22*D22 -> 0 | G22: =B22*F22 -> 0 | H22: =E22+G22 -> 0
E23: =B23*D23 -> 0 | G23: =B23*F23 -> 0 | H23: =E23+G23 -> 0
E24: =B24*D24 -> 0 | G24: =B24*F24 -> 0 | H24: =E24+G24 -> 0
E25: =B25*D25 -> 0 | G25: =B25*F25 -> 0 | H25: =E25+G25 -> 0
... E40: =B40*D40 -> 0 | G40: =B40*F40 -> 0 | H40: =E40+G40 -> 0
A41: TOTAL LABOR/MATERIALS | E41: =SUM(E14:E40) -> 0 | G41: =SUM(G14:G40) -> 0
A42: SUBTOTAL | H42: =SUM(H14:H40) -> 0
A43: Sub-Contractor's Overhead | G43: =Summary!G20 -> 0.05 | H43: =SUM(H42*G43) -> 0
A44: Sub-Contractor's Profit | G44: =Summary!G21 -> 0.11 | H44: =SUM(H42+H43)*G44 -> 0
A45: FL State Sales Tax | G45: =Summary!G22 -> 0.06 | H45: =SUM(G41*G45) -> 0
A46: TOTAL | H46: =SUM(H42:H45) -> 0

Sheet Div6
A1: CONSTRUCTION COST ESTIMATE | D1: DATE
D2: =Summary!D2 -> Fill Here
A3: PROJECT | F3: BASIS FOR ESTIMATE
A4: =Summary!A8 -> Fill Here | F4: CODE A (No design completed)
A5: LOCATION | F5: CODE B (Preliminary design)
A6: EGLIN AIR FORCE BASE, FLORIDA | F6: CODE C (Final design)
A7: COMPANY | C7: PROJECT NO. | F7: OTHER (Specify)
A8: =Summary!A4 -> Fill Here | C8: =Summary!D9 -> Fill Here
A9: DRAWING NO. | B9: ESTIMATOR | F9: CHECKED BY
B11: QUANTITY | D11: LABOR | F11: MATERIAL
A12: ITEM DESCRIPTION | B12: NO. UNITS | C12: UNIT MEAS. | D12: PER UNIT | E12: TOTAL | F12: PER UNIT | G12: TOTAL | H12: TOTAL COST
A13: =Summary!B18 -> WOOD, PLASTICS AND COMPOSITES
E14: =B14*D14 -> 0 | G14: =B14*F14 -> 0 | H14: =E14+G14 -> 0
E15: =B15*D15 -> 0 | G15: =B15*F15 -> 0 | H15: =E15+G15 -> 0
E16: =B16*D16 -> 0 | G16: =B16*F16 -> 0 | H16: =E16+G16 -> 0
E17: =B17*D17 -> 0 | G17: =B17*F17 -> 0 | H17: =E17+G17 -> 0
E18: =B18*D18 -> 0 | G18: =B18*F18 -> 0 | H18: =E18+G18 -> 0
E19: =B19*D19 -> 0 | G19: =B19*F19 -> 0 | H19: =E19+G19 -> 0
E20: =B20*D20 -> 0 | G20: =B20*F20 -> 0 | H20: =E20+G20 -> 0
E21: =B21*D21 -> 0 | G21: =B21*F21 -> 0 | H21: =E21+G21 -> 0
E22: =B22*D22 -> 0 | G22: =B22*F22 -> 0 | H22: =E22+G22 -> 0
E23: =B23*D23 -> 0 | G23: =B23*F23 -> 0 | H23: =E23+G23 -> 0
E24: =B24*D24 -> 0 | G24: =B24*F24 -> 0 | H24: =E24+G24 -> 0
E25: =B25*D25 -> 0 | G25: =B25*F25 -> 0 | H25: =E25+G25 -> 0
... E40: =B40*D40 -> 0 | G40: =B40*F40 -> 0 | H40: =E40+G40 -> 0
A41: TOTAL LABOR/MATERIALS | E41: =SUM(E14:E39) -> 0 | G41: =SUM(G14:G39) -> 0
A42: SUBTOTAL | H42: =SUM(E41:G41) -> 0
A43: Sub-Contractor's Overhead | G43: =Summary!G20 -> 0.05 | H43: =SUM(H42*G43) -> 0
A44: Sub-Contractor's Profit | G44: =Summary!G21 -> 0.11 | H44: =SUM(H42+H43)*G44 -> 0
A45: FL State Sales Tax | G45: =Summary!G22 -> 0.06 | H45: =SUM(G41*G45) -> 0
A46: TOTAL | H46: =SUM(H42:H45) -> 0

Sheet Div7
A1: CONSTRUCTION COST ESTIMATE | D1: DATE
D2: =Summary!D2 -> Fill Here
A3: PROJECT | F3: BASIS FOR ESTIMATE
A4: =Summary!A8 -> Fill Here | F4: CODE A (No design completed)
A5: LOCATION | F5: CODE B (Preliminary design)
A6: EGLIN AIR FORCE BASE, FLORIDA | F6: CODE C (Final design)
A7: COMPANY | C7: PROJECT NO. | F7: OTHER (Specify)
A8: =Summary!A4 -> Fill Here | C8: =Summary!D9 -> Fill Here
A9: DRAWING NO. | B9: ESTIMATOR | F9: CHECKED BY
B11: QUANTITY | D11: LABOR | F11: MATERIAL
A12: ITEM DESCRIPTION | B12: NO. UNITS | C12: UNIT MEAS. | D12: PER UNIT | E12: TOTAL | F12: PER UNIT | G12: TOTAL | H12: TOTAL COST
A13: =Summary!B19 -> THERMAL AND MOISTURE PROTECTION
E14: =B14*D14 -> 0 | G14: =B14*F14 -> 0 | H14: =E14+G14 -> 0
E15: =B15*D15 -> 0 | G15: =B15*F15 -> 0 | H15: =E15+G15 -> 0
E16: =B16*D16 -> 0 | G16: =B16*F16 -> 0 | H16: =E16+G16 -> 0
E17: =B17*D17 -> 0 | G17: =B17*F17 -> 0 | H17: =E17+G17 -> 0
E18: =B18*D18 -> 0 | G18: =B18*F18 -> 0 | H18: =E18+G18 -> 0
E19: =B19*D19 -> 0 | G19: =B19*F19 -> 0 | H19: =E19+G19 -> 0
E20: =B20*D20 -> 0 | G20: =B20*F20 -> 0 | H20: =E20+G20 -> 0
E21: =B21*D21 -> 0 | G21: =B21*F21 -> 0 | H21: =E21+G21 -> 0
E22: =B22*D22 -> 0 | G22: =B22*F22 -> 0 | H22: =E22+G22 -> 0
E23: =B23*D23 -> 0 | G23: =B23*F23 -> 0 | H23: =E23+G23 -> 0
E24: =B24*D24 -> 0 | G24: =B24*F24 -> 0 | H24: =E24+G24 -> 0
E25: =B25*D25 -> 0 | G25: =B25*F25 -> 0 | H25: =E25+G25 -> 0
... E40: =B40*D40 -> 0 | G40: =B40*F40 -> 0 | H40: =E40+G40 -> 0
A41: TOTAL LABOR/MATERIALS | E41: =SUM(E14:E40) -> 0 | G41: =SUM(G14:G40) -> 0
A42: SUBTOTAL | H42: =E41+G41 -> 0
A43: Sub-Contractor's Overhead | G43: =Summary!G20 -> 0.05 | H43: =SUM(H42*G43) -> 0
A44: Sub-Contractor's Profit | G44: =Summary!G21 -> 0.11 | H44: =SUM(H42+H43)*G44 -> 0
A45: FL State Sales Tax | G45: =Summary!G22 -> 0.06 | H45: =SUM(G41*G45) -> 0
A46: TOTAL | H46: =SUM(H42:H45) -> 0

Sheet Div8
A1: CONSTRUCTION COST ESTIMATE | D1: DATE
D2: =Summary!D2 -> Fill Here
A3: PROJECT | F3: BASIS FOR ESTIMATE
A4: =Summary!A8 -> Fill Here | F4: CODE A (No design completed)
A5: LOCATION | F5: CODE B (Preliminary design)
A6: EGLIN AIR FORCE BASE, FLORIDA | F6: CODE C (Final design)
A7: COMPANY | C7: PROJECT NO. | F7: OTHER (Specify)
A8: =Summary!A4 -> Fill Here | C8: =Summary!D9 -> Fill Here
A9: DRAWING NO. | B9: ESTIMATOR | F9: CHECKED BY
B11: QUANTITY | D11: LABOR | F11: MATERIAL
A12: ITEM DESCRIPTION | B12: NO. UNITS | C12: UNIT MEAS. | D12: PER UNIT | E12: TOTAL | F12: PER UNIT | G12: TOTAL | H12: TOTAL COST
A13: =Summary!B20 -> OPENINGS
E14: =B14*D14 -> 0 | G14: =B14*F14 -> 0 | H14: =E14+G14 -> 0
E15: =B15*D15 -> 0 | G15: =B15*F15 -> 0 | H15: =E15+G15 -> 0
E16: =B16*D16 -> 0 | G16: =B16*F16 -> 0 | H16: =E16+G16 -> 0
E17: =B17*D17 -> 0 | G17: =B17*F17 -> 0 | H17: =E17+G17 -> 0
E18: =B18*D18 -> 0 | G18: =B18*F18 -> 0 | H18: =E18+G18 -> 0
E19: =B19*D19 -> 0 | G19: =B19*F19 -> 0 | H19: =E19+G19 -> 0
E20: =B20*D20 -> 0 | G20: =B20*F20 -> 0 | H20: =E20+G20 -> 0
E21: =B21*D21 -> 0 | G21: =B21*F21 -> 0 | H21: =E21+G21 -> 0
E22: =B22*D22 -> 0 | G22: =B22*F22 -> 0 | H22: =E22+G22 -> 0
E23: =B23*D23 -> 0 | G23: =B23*F23 -> 0 | H23: =E23+G23 -> 0
E24: =B24*D24 -> 0 | G24: =B24*F24 -> 0 | H24: =E24+G24 -> 0
E25: =B25*D25 -> 0 | G25: =B25*F25 -> 0 | H25: =E25+G25 -> 0
... E40: =B40*D40 -> 0 | G40: =B40*F40 -> 0 | H40: =E40+G40 -> 0
A41: TOTAL LABOR/MATERIALS | E41: =SUM(E14:E40) -> 0 | G41: =SUM(G14:G40) -> 0
A42: SUBTOTAL | H42: =E41+G41 -> 0
A43: Sub-Contractor's Overhead | G43: =Summary!G20 -> 0.05 | H43: =SUM(H42*G43) -> 0
A44: Sub-Contractor's Profit | G44: =Summary!G21 -> 0.11 | H44: =SUM(H42+H43)*G44 -> 0
A45: FL State Sales Tax | G45: =Summary!G22 -> 0.06 | H45: =SUM(G41*G45) -> 0
A46: TOTAL | H46: =SUM(H42:H45) -> 0

Sheet Div9
A1: CONSTRUCTION COST ESTIMATE | D1: DATE
D2: =Summary!D2 -> Fill Here
A3: PROJECT | F3: BASIS FOR ESTIMATE
A4: =Summary!A8 -> Fill Here | F4: CODE A (No design completed)
A5: LOCATION | F5: CODE B (Preliminary design)
A6: EGLIN AIR FORCE BASE, FLORIDA | F6: CODE C (Final design)
A7: COMPANY | C7: PROJECT NO. | F7: OTHER (Specify)
A8: =Summary!A4 -> Fill Here | C8: =Summary!D9 -> Fill Here
A9: DRAWING NO. | B9: ESTIMATOR | F9: CHECKED BY
B11: QUANTITY | D11: LABOR | F11: MATERIAL
A12: ITEM DESCRIPTION | B12: NO. UNITS | C12: UNIT MEAS. | D12: PER UNIT | E12: TOTAL | F12: PER UNIT | G12: TOTAL | H12: TOTAL COST
A13: =Summary!B21 -> FINISHES
E14: =B14*D14 -> 0 | G14: =B14*F14 -> 0 | H14: =E14+G14 -> 0
E15: =B15*D15 -> 0 | G15: =B15*F15 -> 0 | H15: =E15+G15 -> 0
E16: =B16*D16 -> 0 | G16: =B16*F16 -> 0 | H16: =E16+G16 -> 0
E17: =B17*D17 -> 0 | G17: =B17*F17 -> 0 | H17: =E17+G17 -> 0
E18: =B18*D18 -> 0 | G18: =B18*F18 -> 0 | H18: =E18+G18 -> 0
E19: =B19*D19 -> 0 | G19: =B19*F19 -> 0 | H19: =E19+G19 -> 0
E20: =B20*D20 -> 0 | G20: =B20*F20 -> 0 | H20: =E20+G20 -> 0
E21: =B21*D21 -> 0 | G21: =B21*F21 -> 0 | H21: =E21+G21 -> 0
E22: =B22*D22 -> 0 | G22: =B22*F22 -> 0 | H22: =E22+G22 -> 0
E23: =B23*D23 -> 0 | G23: =B23*F23 -> 0 | H23: =E23+G23 -> 0
E24: =B24*D24 -> 0 | G24: =B24*F24 -> 0 | H24: =E24+G24 -> 0
E25: =B25*D25 -> 0 | G25: =B25*F25 -> 0 | H25: =E25+G25 -> 0
... E40: =B40*D40 -> 0 | G40: =B40*F40 -> 0 | H40: =E40+G40 -> 0
A41: TOTAL LABOR/MATERIALS | E41: =SUM(E14:E40) -> 0 | G41: =SUM(G14:G40) -> 0
A42: SUBTOTAL | H42: =SUM(H14:H40) -> 0
A43: Sub-Contractor's Overhead | G43: =Summary!G20 -> 0.05 | H43: =SUM(H42*G43) -> 0
A44: Sub-Contractor's Profit | G44: =Summary!G21 -> 0.11 | H44: =SUM(H42+H43)*G44 -> 0
A45: FL State Sales Tax | G45: =Summary!G22 -> 0.06 | H45: =SUM(G41*G45) -> 0
A46: TOTAL | H46: =SUM(H42:H45) -> 0

Sheet Div10
A1: CONSTRUCTION COST ESTIMATE | D1: DATE
D2: =Summary!D2 -> Fill Here
A3: PROJECT | F3: BASIS FOR ESTIMATE
A4: =Summary!A8 -> Fill Here | F4: CODE A (No design completed)
A5: LOCATION | F5: CODE B (Preliminary design)
A6: EGLIN AIR FORCE BASE, FLORIDA | F6: CODE C (Final design)
A7: COMPANY | C7: PROJECT NO. | F7: OTHER (Specify)
A8: =Summary!A4 -> Fill Here | C8: =Summary!D9 -> Fill Here
A9: DRAWING NO. | B9: ESTIMATOR | F9: CHECKED BY
B11: QUANTITY | D11: LABOR | F11: MATERIAL
A12: ITEM DESCRIPTION | B12: NO. UNITS | C12: UNIT MEAS. | D12: PER UNIT | E12: TOTAL | F12: PER UNIT | G12: TOTAL | H12: TOTAL COST
A13: =Summary!B22 -> SPECIALTIES
E14: =B14*D14 -> 0 | G14: =B14*F14 -> 0 | H14: =E14+G14 -> 0
E15: =B15*D15 -> 0 | G15: =B15*F15 -> 0 | H15: =E15+G15 -> 0
E16: =B16*D16 -> 0 | G16: =B16*F16 -> 0 | H16: =E16+G16 -> 0
E17: =B17*D17 -> 0 | G17: =B17*F17 -> 0 | H17: =E17+G17 -> 0
E18: =B18*D18 -> 0 | G18: =B18*F18 -> 0 | H18: =E18+G18 -> 0
E19: =B19*D19 -> 0 | G19: =B19*F19 -> 0 | H19: =E19+G19 -> 0
E20: =B20*D20 -> 0 | G20: =B20*F20 -> 0 | H20: =E20+G20 -> 0
E21: =B21*D21 -> 0 | G21: =B21*F21 -> 0 | H21: =E21+G21 -> 0
E22: =B22*D22 -> 0 | G22: =B22*F22 -> 0 | H22: =E22+G22 -> 0
E23: =B23*D23 -> 0 | G23: =B23*F23 -> 0 | H23: =E23+G23 -> 0
E24: =B24*D24 -> 0 | G24: =B24*F24 -> 0 | H24: =E24+G24 -> 0
E25: =B25*D25 -> 0 | G25: =B25*F25 -> 0 | H25: =E25+G25 -> 0
... E40: =B40*D40 -> 0 | G40: =B40*F40 -> 0 | H40: =E40+G40 -> 0
A41: TOTAL LABOR/MATERIALS | E41: =SUM(E14:E40) -> 0 | G41: =SUM(G14:G40) -> 0
A42: SUBTOTAL | H42: =SUM(H14:H40) -> 0
A43: Sub-Contractor's Overhead | G43: =Summary!G20 -> 0.05 | H43: =SUM(H42*G43) -> 0
A44: Sub-Contractor's Profit | G44: =Summary!G21 -> 0.11 | H44: =SUM(H42+H43)*G44 -> 0
A45: FL State Sales Tax | G45: =Summary!G22 -> 0.06 | H45: =SUM(G41*G45) -> 0
A46: TOTAL | H46: =SUM(H42:H45) -> 0

Sheet Div11
A1: CONSTRUCTION COST ESTIMATE | D1: DATE
D2: =Summary!D2 -> Fill Here
A3: PROJECT | F3: BASIS FOR ESTIMATE
A4: =Summary!A8 -> Fill Here | F4: CODE A (No design completed)
A5: LOCATION | F5: CODE B (Preliminary design)
A6: EGLIN AIR FORCE BASE, FLORIDA | F6: CODE C (Final design)
A7: COMPANY | C7: PROJECT NO. | F7: OTHER (Specify)
A8: =Summary!A4 -> Fill Here | C8: =Summary!D9 -> Fill Here
A9: DRAWING NO. | B9: ESTIMATOR | F9: CHECKED BY
B11: QUANTITY | D11: LABOR | F11: MATERIAL
A12: ITEM DESCRIPTION | B12: NO. UNITS | C12: UNIT MEAS. | D12: PER UNIT | E12: TOTAL | F12: PER UNIT | G12: TOTAL | H12: TOTAL COST
A13: =Summary!B23 -> EQUIPMENT
E14: =B14*D14 -> 0 | G14: =B14*F14 -> 0 | H14: =E14+G14 -> 0
E15: =B15*D15 -> 0 | G15: =B15*F15 -> 0 | H15: =E15+G15 -> 0
E16: =B16*D16 -> 0 | G16: =B16*F16 -> 0 | H16: =E16+G16 -> 0
E17: =B17*D17 -> 0 | G17: =B17*F17 -> 0 | H17: =E17+G17 -> 0
E18: =B18*D18 -> 0 | G18: =B18*F18 -> 0 | H18: =E18+G18 -> 0
E19: =B19*D19 -> 0 | G19: =B19*F19 -> 0 | H19: =E19+G19 -> 0
E20: =B20*D20 -> 0 | G20: =B20*F20 -> 0 | H20: =E20+G20 -> 0
E21: =B21*D21 -> 0 | G21: =B21*F21 -> 0 | H21: =E21+G21 -> 0
E22: =B22*D22 -> 0 | G22: =B22*F22 -> 0 | H22: =E22+G22 -> 0
E23: =B23*D23 -> 0 | G23: =B23*F23 -> 0 | H23: =E23+G23 -> 0
E24: =B24*D24 -> 0 | G24: =B24*F24 -> 0 | H24: =E24+G24 -> 0
E25: =B25*D25 -> 0 | G25: =B25*F25 -> 0 | H25: =E25+G25 -> 0
... E40: =B40*D40 -> 0 | G40: =B40*F40 -> 0 | H40: =E40+G40 -> 0
A41: TOTAL LABOR/MATERIALS | E41: =SUM(E14:E39) -> 0 | G41: =SUM(G14:G39) -> 0
A42: SUBTOTAL | H42: =SUM(E41:G41) -> 0
A43: Sub-Contractor's Overhead | G43: =Summary!G20 -> 0.05 | H43: =SUM(H42*G43) -> 0
A44: Sub-Contractor's Profit | G44: =Summary!G21 -> 0.11 | H44: =SUM(H42+H43)*G44 -> 0
A45: FL State Sales Tax | G45: =Summary!G22 -> 0.06 | H45: =SUM(G41*G45) -> 0
A46: TOTAL | H46: =SUM(H42:H45) -> 0

Sheet Div12
A1: CONSTRUCTION COST ESTIMATE | D1: DATE
D2: =Summary!D2 -> Fill Here
A3: PROJECT | F3: BASIS FOR ESTIMATE
A4: =Summary!A8 -> Fill Here | F4: CODE A (No design completed)
A5: LOCATION | F5: CODE B (Preliminary design)
A6: EGLIN AIR FORCE BASE, FLORIDA | F6: CODE C (Final design)
A7: COMPANY | C7: PROJECT NO. | F7: OTHER (Specify)
A8: =Summary!A4 -> Fill Here | C8: =Summary!D9 -> Fill Here
A9: DRAWING NO. | B9: ESTIMATOR | F9: CHECKED BY
B11: QUANTITY | D11: LABOR | F11: MATERIAL
A12: ITEM DESCRIPTION | B12: NO. UNITS | C12: UNIT MEAS. | D12: PER UNIT | E12: TOTAL | F12: PER UNIT | G12: TOTAL | H12: TOTAL COST
A13: =Summary!B24 -> FURNISHINGS
E14: =B14*D14 -> 0 | G14: =B14*F14 -> 0 | H14: =E14+G14 -> 0
E15: =B15*D15 -> 0 | G15: =B15*F15 -> 0 | H15: =E15+G15 -> 0
E16: =B16*D16 -> 0 | G16: =B16*F16 -> 0 | H16: =E16+G16 -> 0
E17: =B17*D17 -> 0 | G17: =B17*F17 -> 0 | H17: =E17+G17 -> 0
E18: =B18*D18 -> 0 | G18: =B18*F18 -> 0 | H18: =E18+G18 -> 0
E19: =B19*D19 -> 0 | G19: =B19*F19 -> 0 | H19: =E19+G19 -> 0
E20: =B20*D20 -> 0 | G20: =B20*F20 -> 0 | H20: =E20+G20 -> 0
E21: =B21*D21 -> 0 | G21: =B21*F21 -> 0 | H21: =E21+G21 -> 0
E22: =B22*D22 -> 0 | G22: =B22*F22 -> 0 | H22: =E22+G22 -> 0
E23: =B23*D23 -> 0 | G23: =B23*F23 -> 0 | H23: =E23+G23 -> 0
E24: =B24*D24 -> 0 | G24: =B24*F24 -> 0 | H24: =E24+G24 -> 0
E25: =B25*D25 -> 0 | G25: =B25*F25 -> 0 | H25: =E25+G25 -> 0
... E40: =B40*D40 -> 0 | G40: =B40*F40 -> 0 | H40: =E40+G40 -> 0
A41: TOTAL LABOR/MATERIALS | E41: =SUM(E14:E40) -> 0 | G41: =SUM(G14:G40) -> 0
A42: SUBTOTAL | H42: =E41+G41 -> 0
A43: Sub-Contractor's Overhead | G43: =Summary!G20 -> 0.05 | H43: =SUM(H42*G43) -> 0
A44: Sub-Contractor's Profit | G44: =Summary!G21 -> 0.11 | H44: =SUM(H42+H43)*G44 -> 0
A45: FL State Sales Tax | G45: =Summary!G22 -> 0.06 | H45: =SUM(G41*G45) -> 0
A46: TOTAL | H46: =SUM(H42:H45) -> 0

Sheet Div13
A1: CONSTRUCTION COST ESTIMATE | D1: DATE
D2: =Summary!D2 -> Fill Here
A3: PROJECT | F3: BASIS FOR ESTIMATE
A4: =Summary!A8 -> Fill Here | F4: CODE A (No design completed)
A5: LOCATION | F5: CODE B (Preliminary design)
A6: EGLIN AIR FORCE BASE, FLORIDA | F6: CODE C (Final design)
A7: COMPANY | C7: PROJECT NO. | F7: OTHER (Specify)
A8: =Summary!A4 -> Fill Here | C8: =Summary!D9 -> Fill Here
A9: DRAWING NO. | B9: ESTIMATOR | F9: CHECKED BY
B11: QUANTITY | D11: LABOR | F11: MATERIAL
A12: ITEM DESCRIPTION | B12: NO. UNITS | C12: UNIT MEAS. | D12: PER UNIT | E12: TOTAL | F12: PER UNIT | G12: TOTAL | H12: TOTAL COST
A13: =Summary!B25 -> SPECIAL CONSTRUCTION
E14: =B14*D14 -> 0 | G14: =B14*F14 -> 0 | H14: =E14+G14 -> 0
E15: =B15*D15 -> 0 | G15: =B15*F15 -> 0 | H15: =E15+G15 -> 0
E16: =B16*D16 -> 0 | G16: =B16*F16 -> 0 | H16: =E16+G16 -> 0
E17: =B17*D17 -> 0 | G17: =B17*F17 -> 0 | H17: =E17+G17 -> 0
E18: =B18*D18 -> 0 | G18: =B18*F18 -> 0 | H18: =E18+G18 -> 0
E19: =B19*D19 -> 0 | G19: =B19*F19 -> 0 | H19: =E19+G19 -> 0
E20: =B20*D20 -> 0 | G20: =B20*F20 -> 0 | H20: =E20+G20 -> 0
E21: =B21*D21 -> 0 | G21: =B21*F21 -> 0 | H21: =E21+G21 -> 0
E22: =B22*D22 -> 0 | G22: =B22*F22 -> 0 | H22: =E22+G22 -> 0
E23: =B23*D23 -> 0 | G23: =B23*F23 -> 0 | H23: =E23+G23 -> 0
E24: =B24*D24 -> 0 | G24: =B24*F24 -> 0 | H24: =E24+G24 -> 0
E25: =B25*D25 -> 0 | G25: =B25*F25 -> 0 | H25: =E25+G25 -> 0
... E33: =B33*D33 -> 0 | G33: =B33*F33 -> 0 | H33: =E33+G33 -> 0
E34: =B34*D34 -> 0 | G34: =B34*F34 -> 0 | H34: =E35+G34 -> 0
E35: =B35*D35 -> 0
E36: =B36*D36 -> 0 | G36: =B36*F36 -> 0 | H36: =E36+G36 -> 0
E37: =B37*D37 -> 0 | G37: =B37*F37 -> 0 | H37: =E37+G37 -> 0
E38: =B38*D38 -> 0 | G38: =B38*F38 -> 0 | H38: =E38+G38 -> 0
E39: =B39*D39 -> 0 | G39: =B39*F39 -> 0 | H39: =E39+G39 -> 0
E40: =B40*D40 -> 0 | G40: =B40*F40 -> 0 | H40: =E40+G40 -> 0
A41: TOTAL LABOR/MATERIALS | E41: =SUM(E14:E40) -> 0 | G41: =SUM(G14:G40) -> 0
A42: SUBTOTAL | H42: =E41+G41 -> 0
A43: Sub-Contractor's Overhead | G43: =Summary!G20 -> 0.05 | H43: =SUM(H42*G43) -> 0
A44: Sub-Contractor's Profit | G44: =Summary!G21 -> 0.11 | H44: =SUM(H42+H43)*G44 -> 0
A45: FL State Sales Tax | G45: =Summary!G22 -> 0.06 | H45: =SUM(G41*G45) -> 0
A46: TOTAL | H46: =SUM(H42:H45) -> 0

Sheet Div14
A1: CONSTRUCTION COST ESTIMATE | D1: DATE
D2: =Summary!D2 -> Fill Here
A3: PROJECT | F3: BASIS FOR ESTIMATE
A4: =Summary!A8 -> Fill Here | F4: CODE A (No design completed)
A5: LOCATION | F5: CODE B (Preliminary design)
A6: EGLIN AIR FORCE BASE, FLORIDA | F6: CODE C (Final design)
A7: COMPANY | C7: PROJECT NO. | F7: OTHER (Specify)
A8: =Summary!A4 -> Fill Here | C8: =Summary!D9 -> Fill Here
A9: DRAWING NO. | B9: ESTIMATOR | F9: CHECKED BY
B11: QUANTITY | D11: LABOR | F11: MATERIAL
A12: ITEM DESCRIPTION | B12: NO. UNITS | C12: UNIT MEAS. | D12: PER UNIT | E12: TOTAL | F12: PER UNIT | G12: TOTAL | H12: TOTAL COST
A13: =Summary!B26 -> CONVEYING EQUIPMENT
E14: =B14*D14 -> 0 | G14: =B14*F14 -> 0 | H14: =E14+G14 -> 0
E15: =B15*D15 -> 0 | G15: =B15*F15 -> 0 | H15: =E15+G15 -> 0
E16: =B16*D16 -> 0 | G16: =B16*F16 -> 0 | H16: =E16+G16 -> 0
E17: =B17*D17 -> 0 | G17: =B17*F17 -> 0 | H17: =E17+G17 -> 0
E18: =B18*D18 -> 0 | G18: =B18*F18 -> 0 | H18: =E18+G18 -> 0
E19: =B19*D19 -> 0 | G19: =B19*F19 -> 0 | H19: =E19+G19 -> 0
E20: =B20*D20 -> 0 | G20: =B20*F20 -> 0 | H20: =E20+G20 -> 0
E21: =B21*D21 -> 0 | G21: =B21*F21 -> 0 | H21: =E21+G21 -> 0
E22: =B22*D22 -> 0 | G22: =B22*F22 -> 0 | H22: =E22+G22 -> 0
E23: =B23*D23 -> 0 | G23: =B23*F23 -> 0 | H23: =E23+G23 -> 0
E24: =B24*D24 -> 0 | G24: =B24*F24 -> 0 | H24: =E24+G24 -> 0
E25: =B25*D25 -> 0 | G25: =B25*F25 -> 0 | H25: =E25+G25 -> 0
... E40: =B40*D40 -> 0 | G40: =B40*F40 -> 0 | H40: =E40+G40 -> 0
A41: TOTAL LABOR/MATERIALS | E41: =SUM(E14:E40) -> 0 | G41: =SUM(G14:G40) -> 0
A42: SUBTOTAL | H42: =SUM(H14:H40) -> 0
A43: Sub-Contractor's Overhead | G43: =Summary!G20 -> 0.05 | H43: =SUM(H42*G43) -> 0
A44: Sub-Contractor's Profit | G44: =Summary!G21 -> 0.11 | H44: =SUM(H42+H43)*G44 -> 0
A45: FL State Sales Tax | G45: =Summary!G22 -> 0.06 | H45: =SUM(G41*G45) -> 0
A46: TOTAL | H46: =SUM(H42:H45) -> 0

Sheet Div15
A1: CONSTRUCTION COST ESTIMATE | D1: DATE
D2: =Summary!D2 -> Fill Here
A3: PROJECT | F3: BASIS FOR ESTIMATE
A4: =Summary!A8 -> Fill Here | F4: CODE A (No design completed)
A5: LOCATION | F5: CODE B (Preliminary design)
A6: EGLIN AIR FORCE BASE, FLORIDA | F6: CODE C (Final design)
A7: COMPANY | C7: PROJECT NO. | F7: OTHER (Specify)
A8: =Summary!A4 -> Fill Here | C8: =Summary!D9 -> Fill Here
A9: DRAWING NO. | B9: ESTIMATOR | F9: CHECKED BY
B11: QUANTITY | D11: LABOR | F11: MATERIAL
A12: ITEM DESCRIPTION | B12: NO. UNITS | C12: UNIT MEAS. | D12: PER UNIT | E12: TOTAL | F12: PER UNIT | G12: TOTAL | H12: TOTAL COST
A13: =Summary!B27 -> RESERVED
E14: =B14*D14 -> 0 | G14: =B14*F14 -> 0 | H14: =E14+G14 -> 0
E15: =B15*D15 -> 0 | G15: =B15*F15 -> 0 | H15: =E15+G15 -> 0
E16: =B16*D16 -> 0 | G16: =B16*F16 -> 0 | H16: =E16+G16 -> 0
E17: =B17*D17 -> 0 | G17: =B17*F17 -> 0 | H17: =E17+G17 -> 0
E18: =B18*D18 -> 0 | G18: =B18*F18 -> 0 | H18: =E18+G18 -> 0
E19: =B19*D19 -> 0 | G19: =B19*F19 -> 0 | H19: =E19+G19 -> 0
E20: =B20*D20 -> 0 | G20: =B20*F20 -> 0 | H20: =E20+G20 -> 0
E21: =B21*D21 -> 0 | G21: =B21*F21 -> 0 | H21: =E21+G21 -> 0
E22: =B22*D22 -> 0 | G22: =B22*F22 -> 0 | H22: =E22+G22 -> 0
E23: =B23*D23 -> 0 | G23: =B23*F23 -> 0 | H23: =E23+G23 -> 0
E24: =B24*D24 -> 0 | G24: =B24*F24 -> 0 | H24: =E24+G24 -> 0
E25: =B25*D25 -> 0 | G25: =B25*F25 -> 0 | H25: =E25+G25 -> 0
... E40: =B40*D40 -> 0 | G40: =B40*F40 -> 0 | H40: =E40+G40 -> 0
A41: TOTAL LABOR/MATERIALS | E41: =SUM(E14:E40) -> 0 | G41: =SUM(G14:G40) -> 0
A42: SUBTOTAL | H42: =SUM(H14:H40) -> 0
A43: Sub-Contractor's Overhead | G43: =Summary!G20 -> 0.05 | H43: =SUM(H42*G43) -> 0
A44: Sub-Contractor's Profit | G44: =Summary!G21 -> 0.11 | H44: =SUM(H42+H43)*G44 -> 0
A45: FL State Sales Tax | G45: =Summary!G22 -> 0.06 | H45: =SUM(G41*G45) -> 0
A46: TOTAL | H46: =SUM(H42:H45) -> 0

Sheet Div16
A1: CONSTRUCTION COST ESTIMATE | D1: DATE
D2: =Summary!D2 -> Fill Here
A3: PROJECT | F3: BASIS FOR ESTIMATE
A4: =Summary!A8 -> Fill Here | F4: CODE A (No design completed)
A5: LOCATION | F5: CODE B (Preliminary design)
A6: EGLIN AIR FORCE BASE, FLORIDA | F6: CODE C (Final design)
A7: COMPANY | C7: PROJECT NO. | F7: OTHER (Specify)
A8: =Summary!A4 -> Fill Here | C8: =Summary!D9 -> Fill Here
A9: DRAWING NO. | B9: ESTIMATOR | F9: CHECKED BY
B11: QUANTITY | D11: LABOR | F11: MATERIAL
A12: ITEM DESCRIPTION | B12: NO. UNITS | C12: UNIT MEAS. | D12: PER UNIT | E12: TOTAL | F12: PER UNIT | G12: TOTAL | H12: TOTAL COST
A13: =Summary!B27 -> RESERVED
E14: =B14*D14 -> 0 | G14: =B14*F14 -> 0 | H14: =E14+G14 -> 0
E15: =B15*D15 -> 0 | G15: =B15*F15 -> 0 | H15: =E15+G15 -> 0
E16: =B16*D16 -> 0 | G16: =B16*F16 -> 0 | H16: =E16+G16 -> 0
E17: =B17*D17 -> 0 | G17: =B17*F17 -> 0 | H17: =E17+G17 -> 0
E18: =B18*D18 -> 0 | G18: =B18*F18 -> 0 | H18: =E18+G18 -> 0
E19: =B19*D19 -> 0 | G19: =B19*F19 -> 0 | H19: =E19+G19 -> 0
E20: =B20*D20 -> 0 | G20: =B20*F20 -> 0 | H20: =E20+G20 -> 0
E21: =B21*D21 -> 0 | G21: =B21*F21 -> 0 | H21: =E21+G21 -> 0
E22: =B22*D22 -> 0 | G22: =B22*F22 -> 0 | H22: =E22+G22 -> 0
E23: =B23*D23 -> 0 | G23: =B23*F23 -> 0 | H23: =E23+G23 -> 0
E24: =B24*D24 -> 0 | G24: =B24*F24 -> 0 | H24: =E24+G24 -> 0
E25: =B25*D25 -> 0 | G25: =B25*F25 -> 0 | H25: =E25+G25 -> 0
... E40: =B40*D40 -> 0 | G40: =B40*F40 -> 0 | H40: =E40+G40 -> 0
A41: TOTAL LABOR/MATERIALS | E41: =SUM(E14:E39) -> 0 | G41: =SUM(G14:G39) -> 0
A42: SUBTOTAL | H42: =SUM(E41:G41) -> 0
A43: Sub-Contractor's Overhead | G43: =Summary!G20 -> 0.05 | H43: =SUM(H42*G43) -> 0
A44: Sub-Contractor's Profit | G44: =Summary!G21 -> 0.11 | H44: =SUM(H42+H43)*G44 -> 0
A45: FL State Sales Tax | G45: =Summary!G22 -> 0.06 | H45: =SUM(G41*G45) -> 0
A46: TOTAL | H46: =SUM(H42:H45) -> 0

Sheet Div20
A1: CONSTRUCTION COST ESTIMATE | D1: DATE
D2: =Summary!D2 -> Fill Here
A3: PROJECT | F3: BASIS FOR ESTIMATE
A4: =Summary!A8 -> Fill Here | F4: CODE A (No design completed)
A5: LOCATION | F5: CODE B (Preliminary design)
A6: EGLIN AIR FORCE BASE, FLORIDA | F6: CODE C (Final design)
A7: COMPANY | C7: PROJECT NO. | F7: OTHER (Specify)
A8: =Summary!A4 -> Fill Here | C8: =Summary!D9 -> Fill Here
A9: DRAWING NO. | B9: ESTIMATOR | F9: CHECKED BY
B11: QUANTITY | D11: LABOR | F11: MATERIAL
A12: ITEM DESCRIPTION | B12: NO. UNITS | C12: UNIT MEAS. | D12: PER UNIT | E12: TOTAL | F12: PER UNIT | G12: TOTAL | H12: TOTAL COST
A13: =Summary!B28 -> RESERVED
E14: =B14*D14 -> 0 | G14: =B14*F14 -> 0 | H14: =E14+G14 -> 0
E15: =B15*D15 -> 0 | G15: =B15*F15 -> 0 | H15: =E15+G15 -> 0
E16: =B16*D16 -> 0 | G16: =B16*F16 -> 0 | H16: =E16+G16 -> 0
E17: =B17*D17 -> 0 | G17: =B17*F17 -> 0 | H17: =E17+G17 -> 0
E18: =B18*D18 -> 0 | G18: =B18*F18 -> 0 | H18: =E18+G18 -> 0
E19: =B19*D19 -> 0 | G19: =B19*F19 -> 0 | H19: =E19+G19 -> 0
E20: =B20*D20 -> 0 | G20: =B20*F20 -> 0 | H20: =E20+G20 -> 0
E21: =B21*D21 -> 0 | G21: =B21*F21 -> 0 | H21: =E21+G21 -> 0
E22: =B22*D22 -> 0 | G22: =B22*F22 -> 0 | H22: =E22+G22 -> 0
E23: =B23*D23 -> 0 | G23: =B23*F23 -> 0 | H23: =E23+G23 -> 0
E24: =B24*D24 -> 0 | G24: =B24*F24 -> 0 | H24: =E24+G24 -> 0
E25: =B25*D25 -> 0 | G25: =B25*F25 -> 0 | H25: =E25+G25 -> 0
... E40: =B40*D40 -> 0 | G40: =B40*F40 -> 0 | H40: =E40+G40 -> 0
A41: TOTAL LABOR/MATERIALS | E41: =SUM(E14:E40) -> 0 | G41: =SUM(G14:G40) -> 0
A42: SUBTOTAL | H42: =E41+G41 -> 0
A43: Sub-Contractor's Overhead | G43: =Summary!G20 -> 0.05 | H43: =SUM(H42*G43) -> 0
A44: Sub-Contractor's Profit | G44: =Summary!G21 -> 0.11 | H44: =SUM(H42+H43)*G44 -> 0
A45: FL State Sales Tax | G45: =Summary!G22 -> 0.06 | H45: =SUM(G41*G45) -> 0
A46: TOTAL | H46: =SUM(H42:H45) -> 0

Sheet Div21
A1: CONSTRUCTION COST ESTIMATE | D1: DATE
D2: =Summary!D2 -> Fill Here
A3: PROJECT | F3: BASIS FOR ESTIMATE
A4: =Summary!A8 -> Fill Here | F4: CODE A (No design completed)
A5: LOCATION | F5: CODE B (Preliminary design)
A6: EGLIN AIR FORCE BASE, FLORIDA | F6: CODE C (Final design)
A7: COMPANY | C7: PROJECT NO. | F7: OTHER (Specify)
A8: =Summary!A4 -> Fill Here | C8: =Summary!D9 -> Fill Here
A9: DRAWING NO. | B9: ESTIMATOR | F9: CHECKED BY
B11: QUANTITY | D11: LABOR | F11: MATERIAL
A12: ITEM DESCRIPTION | B12: NO. UNITS | C12: UNIT MEAS. | D12: PER UNIT | E12: TOTAL | F12: PER UNIT | G12: TOTAL | H12: TOTAL COST
A13: =Summary!B30 -> FIRE SUPRESSION
E14: =B14*D14 -> 0 | G14: =B14*F14 -> 0 | H14: =E14+G14 -> 0
E15: =B15*D15 -> 0 | G15: =B15*F15 -> 0 | H15: =E15+G15 -> 0
E16: =B16*D16 -> 0 | G16: =B16*F16 -> 0 | H16: =E16+G16 -> 0
E17: =B17*D17 -> 0 | G17: =B17*F17 -> 0 | H17: =E17+G17 -> 0
E18: =B18*D18 -> 0 | G18: =B18*F18 -> 0 | H18: =E18+G18 -> 0
E19: =B19*D19 -> 0 | G19: =B19*F19 -> 0 | H19: =E19+G19 -> 0
E20: =B20*D20 -> 0 | G20: =B20*F20 -> 0 | H20: =E20+G20 -> 0
E21: =B21*D21 -> 0 | G21: =B21*F21 -> 0 | H21: =E21+G21 -> 0
E22: =B22*D22 -> 0 | G22: =B22*F22 -> 0 | H22: =E22+G22 -> 0
E23: =B23*D23 -> 0 | G23: =B23*F23 -> 0 | H23: =E23+G23 -> 0
E24: =B24*D24 -> 0 | G24: =B24*F24 -> 0 | H24: =E24+G24 -> 0
E25: =B25*D25 -> 0 | G25: =B25*F25 -> 0 | H25: =E25+G25 -> 0
... E40: =B40*D40 -> 0 | G40: =B40*F40 -> 0 | H40: =E40+G40 -> 0
A41: TOTAL LABOR/MATERIALS | E41: =SUM(E14:E40) -> 0 | G41: =SUM(G14:G40) -> 0
A42: SUBTOTAL | H42: =E41+G41 -> 0
A43: Sub-Contractor's Overhead | G43: =Summary!G20 -> 0.05 | H43: =SUM(H42*G43) -> 0
A44: Sub-Contractor's Profit | G44: =Summary!G21 -> 0.11 | H44: =SUM(H42+H43)*G44 -> 0
A45: FL State Sales Tax | G45: =Summary!G22 -> 0.06 | H45: =SUM(G41*G45) -> 0
A46: TOTAL | H46: =SUM(H42:H45) -> 0

Sheet Div22
A1: CONSTRUCTION COST ESTIMATE | D1: DATE
D2: =Summary!D2 -> Fill Here
A3: PROJECT | F3: BASIS FOR ESTIMATE
A4: =Summary!A8 -> Fill Here | F4: CODE A (No design completed)
A5: LOCATION | F5: CODE B (Preliminary design)
A6: EGLIN AIR FORCE BASE, FLORIDA | F6: CODE C (Final design)
A7: COMPANY | C7: PROJECT NO. | F7: OTHER (Specify)
A8: =Summary!A4 -> Fill Here | C8: =Summary!D9 -> Fill Here
A9: DRAWING NO. | B9: ESTIMATOR | F9: CHECKED BY
B11: QUANTITY | D11: LABOR | F11: MATERIAL
A12: ITEM DESCRIPTION | B12: NO. UNITS | C12: UNIT MEAS. | D12: PER UNIT | E12: TOTAL | F12: PER UNIT | G12: TOTAL | H12: TOTAL COST
A13: =Summary!B31 -> PLUMBING
E14: =B14*D14 -> 0 | G14: =B14*F14 -> 0 | H14: =E14+G14 -> 0
E15: =B15*D15 -> 0 | G15: =B15*F15 -> 0 | H15: =E15+G15 -> 0
E16: =B16*D16 -> 0 | G16: =B16*F16 -> 0 | H16: =E16+G16 -> 0
E17: =B17*D17 -> 0 | G17: =B17*F17 -> 0 | H17: =E17+G17 -> 0
E18: =B18*D18 -> 0 | G18: =B18*F18 -> 0 | H18: =E18+G18 -> 0
E19: =B19*D19 -> 0 | G19: =B19*F19 -> 0 | H19: =E19+G19 -> 0
E20: =B20*D20 -> 0 | G20: =B20*F20 -> 0 | H20: =E20+G20 -> 0
E21: =B21*D21 -> 0 | G21: =B21*F21 -> 0 | H21: =E21+G21 -> 0
E22: =B22*D22 -> 0 | G22: =B22*F22 -> 0 | H22: =E22+G22 -> 0
E23: =B23*D23 -> 0 | G23: =B23*F23 -> 0 | H23: =E23+G23 -> 0
E24: =B24*D24 -> 0 | G24: =B24*F24 -> 0 | H24: =E24+G24 -> 0
E25: =B25*D25 -> 0 | G25: =B25*F25 -> 0 | H25: =E25+G25 -> 0
... E40: =B40*D40 -> 0 | G40: =B40*F40 -> 0 | H40: =E40+G40 -> 0
A41: TOTAL LABOR/MATERIALS | E41: =SUM(E14:E40) -> 0 | G41: =SUM(G14:G40) -> 0
A42: SUBTOTAL | H42: =SUM(H14:H40) -> 0
A43: Sub-Contractor's Overhead | G43: =Summary!G20 -> 0.05 | H43: =SUM(H42*G43) -> 0
A44: Sub-Contractor's Profit | G44: =Summary!G21 -> 0.11 | H44: =SUM(H42+H43)*G44 -> 0
A45: FL State Sales Tax | G45: =Summary!G22 -> 0.06 | H45: =SUM(G41*G45) -> 0
A46: TOTAL | H46: =SUM(H42:H45) -> 0

Sheet Div23
A1: CONSTRUCTION COST ESTIMATE | D1: DATE
D2: =Summary!D2 -> Fill Here
A3: PROJECT | F3: BASIS FOR ESTIMATE
A4: =Summary!A8 -> Fill Here | F4: CODE A (No design completed)
A5: LOCATION | F5: CODE B (Preliminary design)
A6: EGLIN AIR FORCE BASE, FLORIDA | F6: CODE C (Final design)
A7: COMPANY | C7: PROJECT NO. | F7: OTHER (Specify)
A8: =Summary!A4 -> Fill Here | C8: =Summary!D9 -> Fill Here
A9: DRAWING NO. | B9: ESTIMATOR | F9: CHECKED BY
B11: QUANTITY | D11: LABOR | F11: MATERIAL
A12: ITEM DESCRIPTION | B12: NO. UNITS | C12: UNIT MEAS. | D12: PER UNIT | E12: TOTAL | F12: PER UNIT | G12: TOTAL | H12: TOTAL COST
A13: =Summary!B32 -> HEATING, VENTILATING AND A/C
E14: =B14*D14 -> 0 | G14: =B14*F14 -> 0 | H14: =E14+G14 -> 0
E15: =B15*D15 -> 0 | G15: =B15*F15 -> 0 | H15: =E15+G15 -> 0
E16: =B16*D16 -> 0 | G16: =B16*F16 -> 0 | H16: =E16+G16 -> 0
E17: =B17*D17 -> 0 | G17: =B17*F17 -> 0 | H17: =E17+G17 -> 0
E18: =B18*D18 -> 0 | G18: =B18*F18 -> 0 | H18: =E18+G18 -> 0
E19: =B19*D19 -> 0 | G19: =B19*F19 -> 0 | H19: =E19+G19 -> 0
E20: =B20*D20 -> 0 | G20: =B20*F20 -> 0 | H20: =E20+G20 -> 0
E21: =B21*D21 -> 0 | G21: =B21*F21 -> 0 | H21: =E21+G21 -> 0
E22: =B22*D22 -> 0 | G22: =B22*F22 -> 0 | H22: =E22+G22 -> 0
E23: =B23*D23 -> 0 | G23: =B23*F23 -> 0 | H23: =E23+G23 -> 0
E24: =B24*D24 -> 0 | G24: =B24*F24 -> 0 | H24: =E24+G24 -> 0
E25: =B25*D25 -> 0 | G25: =B25*F25 -> 0 | H25: =E25+G25 -> 0
... E40: =B40*D40 -> 0 | G40: =B40*F40 -> 0 | H40: =E40+G40 -> 0
A41: TOTAL LABOR/MATERIALS | E41: =SUM(E14:E40) -> 0 | G41: =SUM(G14:G40) -> 0
A42: SUBTOTAL | H42: =SUM(H14:H40) -> 0
A43: Sub-Contractor's Overhead | G43: =Summary!G20 -> 0.05 | H43: =SUM(H42*G43) -> 0
A44: Sub-Contractor's Profit | G44: =Summary!G21 -> 0.11 | H44: =SUM(H42+H43)*G44 -> 0
A45: FL State Sales Tax | G45: =Summary!G22 -> 0.06 | H45: =SUM(G41*G45) -> 0
A46: TOTAL | H46: =SUM(H42:H45) -> 0

Sheet Div24
A1: CONSTRUCTION COST ESTIMATE | D1: DATE
D2: =Summary!D2 -> Fill Here
A3: PROJECT | F3: BASIS FOR ESTIMATE
A4: =Summary!A8 -> Fill Here | F4: CODE A (No design completed)
A5: LOCATION | F5: CODE B (Preliminary design)
A6: EGLIN AIR FORCE BASE, FLORIDA | F6: CODE C (Final design)
A7: COMPANY | C7: PROJECT NO. | F7: OTHER (Specify)
A8: =Summary!A4 -> Fill Here | C8: =Summary!D9 -> Fill Here
A9: DRAWING NO. | B9: ESTIMATOR | F9: CHECKED BY
B11: QUANTITY | D11: LABOR | F11: MATERIAL
A12: ITEM DESCRIPTION | B12: NO. UNITS | C12: UNIT MEAS. | D12: PER UNIT | E12: TOTAL | F12: PER UNIT | G12: TOTAL | H12: TOTAL COST
A13: =Summary!B33 -> RESERVED
E14: =B14*D14 -> 0 | G14: =B14*F14 -> 0 | H14: =E14+G14 -> 0
E15: =B15*D15 -> 0 | G15: =B15*F15 -> 0 | H15: =E15+G15 -> 0
E16: =B16*D16 -> 0 | G16: =B16*F16 -> 0 | H16: =E16+G16 -> 0
E17: =B17*D17 -> 0 | G17: =B17*F17 -> 0 | H17: =E17+G17 -> 0
E18: =B18*D18 -> 0 | G18: =B18*F18 -> 0 | H18: =E18+G18 -> 0
E19: =B19*D19 -> 0 | G19: =B19*F19 -> 0 | H19: =E19+G19 -> 0
E20: =B20*D20 -> 0 | G20: =B20*F20 -> 0 | H20: =E20+G20 -> 0
E21: =B21*D21 -> 0 | G21: =B21*F21 -> 0 | H21: =E21+G21 -> 0
E22: =B22*D22 -> 0 | G22: =B22*F22 -> 0 | H22: =E22+G22 -> 0
E23: =B23*D23 -> 0 | G23: =B23*F23 -> 0 | H23: =E23+G23 -> 0
E24: =B24*D24 -> 0 | G24: =B24*F24 -> 0 | H24: =E24+G24 -> 0
E25: =B25*D25 -> 0 | G25: =B25*F25 -> 0 | H25: =E25+G25 -> 0
... E40: =B40*D40 -> 0 | G40: =B40*F40 -> 0 | H40: =E40+G40 -> 0
A41: TOTAL LABOR/MATERIALS | E41: =SUM(E14:E40) -> 0 | G41: =SUM(G14:G40) -> 0
A42: SUBTOTAL | H42: =SUM(H14:H40) -> 0
A43: Sub-Contractor's Overhead | G43: =Summary!G20 -> 0.05 | H43: =SUM(H42*G43) -> 0
A44: Sub-Contractor's Profit | G44: =Summary!G21 -> 0.11 | H44: =SUM(H42+H43)*G44 -> 0
A45: FL State Sales Tax | G45: =Summary!G22 -> 0.06 | H45: =SUM(G41*G45) -> 0
A46: TOTAL | H46: =SUM(H42:H45) -> 0

Sheet Div25
A1: CONSTRUCTION COST ESTIMATE | D1: DATE
D2: =Summary!D2 -> Fill Here
A3: PROJECT | F3: BASIS FOR ESTIMATE
A4: =Summary!A8 -> Fill Here | F4: CODE A (No design completed)
A5: LOCATION | F5: CODE B (Preliminary design)
A6: EGLIN AIR FORCE BASE, FLORIDA | F6: CODE C (Final design)
A7: COMPANY | C7: PROJECT NO. | F7: OTHER (Specify)
A8: =Summary!A4 -> Fill Here | C8: =Summary!D9 -> Fill Here
A9: DRAWING NO. | B9: ESTIMATOR | F9: CHECKED BY
B11: QUANTITY | D11: LABOR | F11: MATERIAL
A12: ITEM DESCRIPTION | B12: NO. UNITS | C12: UNIT MEAS. | D12: PER UNIT | E12: TOTAL | F12: PER UNIT | G12: TOTAL | H12: TOTAL COST
A13: =Summary!B34 -> INTEGRATED AUTOMATION
E14: =B14*D14 -> 0 | G14: =B14*F14 -> 0 | H14: =E14+G14 -> 0
E15: =B15*D15 -> 0 | G15: =B15*F15 -> 0 | H15: =E15+G15 -> 0
E16: =B16*D16 -> 0 | G16: =B16*F16 -> 0 | H16: =E16+G16 -> 0
E17: =B17*D17 -> 0 | G17: =B17*F17 -> 0 | H17: =E17+G17 -> 0
E18: =B18*D18 -> 0 | G18: =B18*F18 -> 0 | H18: =E18+G18 -> 0
E19: =B19*D19 -> 0 | G19: =B19*F19 -> 0 | H19: =E19+G19 -> 0
E20: =B20*D20 -> 0 | G20: =B20*F20 -> 0 | H20: =E20+G20 -> 0
E21: =B21*D21 -> 0 | G21: =B21*F21 -> 0 | H21: =E21+G21 -> 0
E22: =B22*D22 -> 0 | G22: =B22*F22 -> 0 | H22: =E22+G22 -> 0
E23: =B23*D23 -> 0 | G23: =B23*F23 -> 0 | H23: =E23+G23 -> 0
E24: =B24*D24 -> 0 | G24: =B24*F24 -> 0 | H24: =E24+G24 -> 0
E25: =B25*D25 -> 0 | G25: =B25*F25 -> 0 | H25: =E25+G25 -> 0
... E40: =B40*D40 -> 0 | G40: =B40*F40 -> 0 | H40: =E40+G40 -> 0
A41: TOTAL LABOR/MATERIALS | E41: =SUM(E14:E40) -> 0 | G41: =SUM(G14:G40) -> 0
A42: SUBTOTAL | H42: =SUM(H14:H40) -> 0
A43: Sub-Contractor's Overhead | G43: =Summary!G20 -> 0.05 | H43: =SUM(H42*G43) -> 0
A44: Sub-Contractor's Profit | G44: =Summary!G21 -> 0.11 | H44: =SUM(H42+H43)*G44 -> 0
A45: FL State Sales Tax | G45: =Summary!G22 -> 0.06 | H45: =SUM(G41*G45) -> 0
A46: TOTAL | H46: =SUM(H42:H45) -> 0

Sheet Div26
A1: CONSTRUCTION COST ESTIMATE | D1: DATE
D2: =Summary!D2 -> Fill Here
A3: PROJECT | F3: BASIS FOR ESTIMATE
A4: =Summary!A8 -> Fill Here | F4: CODE A (No design completed)
A5: LOCATION | F5: CODE B (Preliminary design)
A6: EGLIN AIR FORCE BASE, FLORIDA | F6: CODE C (Final design)
A7: COMPANY | C7: PROJECT NO. | F7: OTHER (Specify)
A8: =Summary!A4 -> Fill Here | C8: =Summary!D9 -> Fill Here
A9: DRAWING NO. | B9: ESTIMATOR | F9: CHECKED BY
B11: QUANTITY | D11: LABOR | F11: MATERIAL
A12: ITEM DESCRIPTION | B12: NO. UNITS | C12: UNIT MEAS. | D12: PER UNIT | E12: TOTAL | F12: PER UNIT | G12: TOTAL | H12: TOTAL COST
A13: =Summary!B35 -> ELECTRICAL
E14: =B14*D14 -> 0 | G14: =B14*F14 -> 0 | H14: =E14+G14 -> 0
E15: =B15*D15 -> 0 | G15: =B15*F15 -> 0 | H15: =E15+G15 -> 0
E16: =B16*D16 -> 0 | G16: =B16*F16 -> 0 | H16: =E16+G16 -> 0
E17: =B17*D17 -> 0 | G17: =B17*F17 -> 0 | H17: =E17+G17 -> 0
E18: =B18*D18 -> 0 | G18: =B18*F18 -> 0 | H18: =E18+G18 -> 0
E19: =B19*D19 -> 0 | G19: =B19*F19 -> 0 | H19: =E19+G19 -> 0
E20: =B20*D20 -> 0 | G20: =B20*F20 -> 0 | H20: =E20+G20 -> 0
E21: =B21*D21 -> 0 | G21: =B21*F21 -> 0 | H21: =E21+G21 -> 0
E22: =B22*D22 -> 0 | G22: =B22*F22 -> 0 | H22: =E22+G22 -> 0
E23: =B23*D23 -> 0 | G23: =B23*F23 -> 0 | H23: =E23+G23 -> 0
E24: =B24*D24 -> 0 | G24: =B24*F24 -> 0 | H24: =E24+G24 -> 0
E25: =B25*D25 -> 0 | G25: =B25*F25 -> 0 | H25: =E25+G25 -> 0
... E40: =B40*D40 -> 0 | G40: =B40*F40 -> 0 | H40: =E40+G40 -> 0
A41: TOTAL LABOR/MATERIALS | E41: =SUM(E14:E39) -> 0 | G41: =SUM(G14:G39) -> 0
A42: SUBTOTAL | H42: =SUM(E41:G41) -> 0
A43: Sub-Contractor's Overhead | G43: =Summary!G20 -> 0.05 | H43: =SUM(H42*G43) -> 0
A44: Sub-Contractor's Profit | G44: =Summary!G21 -> 0.11 | H44: =SUM(H42+H43)*G44 -> 0
A45: FL State Sales Tax | G45: =Summary!G22 -> 0.06 | H45: =SUM(G41*G45) -> 0
A46: TOTAL | H46: =SUM(H42:H45) -> 0

Sheet Div27
A1: CONSTRUCTION COST ESTIMATE | D1: DATE
D2: =Summary!D2 -> Fill Here
A3: PROJECT | F3: BASIS FOR ESTIMATE
A4: =Summary!A8 -> Fill Here | F4: CODE A (No design completed)
A5: LOCATION | F5: CODE B (Preliminary design)
A6: EGLIN AIR FORCE BASE, FLORIDA | F6: CODE C (Final design)
A7: COMPANY | C7: PROJECT NO. | F7: OTHER (Specify)
A8: =Summary!A4 -> Fill Here | C8: =Summary!D9 -> Fill Here
A9: DRAWING NO. | B9: ESTIMATOR | F9: CHECKED BY
B11: QUANTITY | D11: LABOR | F11: MATERIAL
A12: ITEM DESCRIPTION | B12: NO. UNITS | C12: UNIT MEAS. | D12: PER UNIT | E12: TOTAL | F12: PER UNIT | G12: TOTAL | H12: TOTAL COST
A13: =Summary!B36 -> COMMUNICATIONS
E14: =B14*D14 -> 0 | G14: =B14*F14 -> 0 | H14: =E14+G14 -> 0
E15: =B15*D15 -> 0 | G15: =B15*F15 -> 0 | H15: =E15+G15 -> 0
E16: =B16*D16 -> 0 | G16: =B16*F16 -> 0 | H16: =E16+G16 -> 0
E17: =B17*D17 -> 0 | G17: =B17*F17 -> 0 | H17: =E17+G17 -> 0
E18: =B18*D18 -> 0 | G18: =B18*F18 -> 0 | H18: =E18+G18 -> 0
E19: =B19*D19 -> 0 | G19: =B19*F19 -> 0 | H19: =E19+G19 -> 0
E20: =B20*D20 -> 0 | G20: =B20*F20 -> 0 | H20: =E20+G20 -> 0
E21: =B21*D21 -> 0 | G21: =B21*F21 -> 0 | H21: =E21+G21 -> 0
E22: =B22*D22 -> 0 | G22: =B22*F22 -> 0 | H22: =E22+G22 -> 0
E23: =B23*D23 -> 0 | G23: =B23*F23 -> 0 | H23: =E23+G23 -> 0
E24: =B24*D24 -> 0 | G24: =B24*F24 -> 0 | H24: =E24+G24 -> 0
E25: =B25*D25 -> 0 | G25: =B25*F25 -> 0 | H25: =E25+G25 -> 0
... E40: =B40*D40 -> 0 | G40: =B40*F40 -> 0 | H40: =E40+G40 -> 0
A41: TOTAL LABOR/MATERIALS | E41: =SUM(E14:E40) -> 0 | G41: =SUM(G14:G40) -> 0
A42: SUBTOTAL | H42: =E41+G41 -> 0
A43: Sub-Contractor's Overhead | G43: =Summary!G20 -> 0.05 | H43: =SUM(H42*G43) -> 0
A44: Sub-Contractor's Profit | G44: =Summary!G21 -> 0.11 | H44: =SUM(H42+H43)*G44 -> 0
A45: FL State Sales Tax | G45: =Summary!G22 -> 0.06 | H45: =SUM(G41*G45) -> 0
A46: TOTAL | H46: =SUM(H42:H45) -> 0

Sheet Div28
A1: CONSTRUCTION COST ESTIMATE | D1: DATE
D2: =Summary!D2 -> Fill Here
A3: PROJECT | F3: BASIS FOR ESTIMATE
A4: =Summary!A8 -> Fill Here | F4: CODE A (No design completed)
A5: LOCATION | F5: CODE B (Preliminary design)
A6: EGLIN AIR FORCE BASE, FLORIDA | F6: CODE C (Final design)
A7: COMPANY | C7: PROJECT NO. | F7: OTHER (Specify)
A8: =Summary!A4 -> Fill Here | C8: =Summary!D9 -> Fill Here
A9: DRAWING NO. | B9: ESTIMATOR | F9: CHECKED BY
B11: QUANTITY | D11: LABOR | F11: MATERIAL
A12: ITEM DESCRIPTION | B12: NO. UNITS | C12: UNIT MEAS. | D12: PER UNIT | E12: TOTAL | F12: PER UNIT | G12: TOTAL | H12: TOTAL COST
A13: =Summary!B37 -> ELECTRONIC SAFETY AND SECURITY
E14: =B14*D14 -> 0 | G14: =B14*F14 -> 0 | H14: =E14+G14 -> 0
E15: =B15*D15 -> 0 | G15: =B15*F15 -> 0 | H15: =E15+G15 -> 0
E16: =B16*D16 -> 0 | G16: =B16*F16 -> 0 | H16: =E16+G16 -> 0
E17: =B17*D17 -> 0 | G17: =B17*F17 -> 0 | H17: =E17+G17 -> 0
E18: =B18*D18 -> 0 | G18: =B18*F18 -> 0 | H18: =E18+G18 -> 0
E19: =B19*D19 -> 0 | G19: =B19*F19 -> 0 | H19: =E19+G19 -> 0
E20: =B20*D20 -> 0 | G20: =B20*F20 -> 0 | H20: =E20+G20 -> 0
E21: =B21*D21 -> 0 | G21: =B21*F21 -> 0 | H21: =E21+G21 -> 0
E22: =B22*D22 -> 0 | G22: =B22*F22 -> 0 | H22: =E22+G22 -> 0
E23: =B23*D23 -> 0 | G23: =B23*F23 -> 0 | H23: =E23+G23 -> 0
E24: =B24*D24 -> 0 | G24: =B24*F24 -> 0 | H24: =E24+G24 -> 0
E25: =B25*D25 -> 0 | G25: =B25*F25 -> 0 | H25: =E25+G25 -> 0
... E40: =B40*D40 -> 0 | G40: =B40*F40 -> 0 | H40: =E40+G40 -> 0
A41: TOTAL LABOR/MATERIALS | E41: =SUM(E14:E40) -> 0 | G41: =SUM(G14:G40) -> 0
A42: SUBTOTAL | H42: =E41+G41 -> 0
A43: Sub-Contractor's Overhead | G43: =Summary!G20 -> 0.05 | H43: =SUM(H42*G43) -> 0
A44: Sub-Contractor's Profit | G44: =Summary!G21 -> 0.11 | H44: =SUM(H42+H43)*G44 -> 0
A45: FL State Sales Tax | G45: =Summary!G22 -> 0.06 | H45: =SUM(G41*G45) -> 0
A46: TOTAL | H46: =SUM(H42:H45) -> 0

Sheet Div29
A1: CONSTRUCTION COST ESTIMATE | D1: DATE
D2: =Summary!D2 -> Fill Here
A3: PROJECT | F3: BASIS FOR ESTIMATE
A4: =Summary!A8 -> Fill Here | F4: CODE A (No design completed)
A5: LOCATION | F5: CODE B (Preliminary design)
A6: EGLIN AIR FORCE BASE, FLORIDA | F6: CODE C (Final design)
A7: COMPANY | C7: PROJECT NO. | F7: OTHER (Specify)
A8: =Summary!A4 -> Fill Here | C8: =Summary!D9 -> Fill Here
A9: DRAWING NO. | B9: ESTIMATOR | F9: CHECKED BY
B11: QUANTITY | D11: LABOR | F11: MATERIAL
A12: ITEM DESCRIPTION | B12: NO. UNITS | C12: UNIT MEAS. | D12: PER UNIT | E12: TOTAL | F12: PER UNIT | G12: TOTAL | H12: TOTAL COST
A13: =Summary!B38 -> RESERVED
E14: =B14*D14 -> 0 | G14: =B14*F14 -> 0 | H14: =E14+G14 -> 0
E15: =B15*D15 -> 0 | G15: =B15*F15 -> 0 | H15: =E15+G15 -> 0
E16: =B16*D16 -> 0 | G16: =B16*F16 -> 0 | H16: =E16+G16 -> 0
E17: =B17*D17 -> 0 | G17: =B17*F17 -> 0 | H17: =E17+G17 -> 0
E18: =B18*D18 -> 0 | G18: =B18*F18 -> 0 | H18: =E18+G18 -> 0
E19: =B19*D19 -> 0 | G19: =B19*F19 -> 0 | H19: =E19+G19 -> 0
E20: =B20*D20 -> 0 | G20: =B20*F20 -> 0 | H20: =E20+G20 -> 0
E21: =B21*D21 -> 0 | G21: =B21*F21 -> 0 | H21: =E21+G21 -> 0
E22: =B22*D22 -> 0 | G22: =B22*F22 -> 0 | H22: =E22+G22 -> 0
E23: =B23*D23 -> 0 | G23: =B23*F23 -> 0 | H23: =E23+G23 -> 0
E24: =B24*D24 -> 0 | G24: =B24*F24 -> 0 | H24: =E24+G24 -> 0
E25: =B25*D25 -> 0 | G25: =B25*F25 -> 0 | H25: =E25+G25 -> 0
... E40: =B40*D40 -> 0 | G40: =B40*F40 -> 0 | H40: =E40+G40 -> 0
A41: TOTAL LABOR/MATERIALS | E41: =SUM(E14:E40) -> 0 | G41: =SUM(G14:G40) -> 0
A42: SUBTOTAL | H42: =SUM(H14:H40) -> 0
A43: Sub-Contractor's Overhead | G43: =Summary!G20 -> 0.05 | H43: =SUM(H42*G43) -> 0
A44: Sub-Contractor's Profit | G44: =Summary!G21 -> 0.11 | H44: =SUM(H42+H43)*G44 -> 0
A45: FL State Sales Tax | G45: =Summary!G22 -> 0.06 | H45: =SUM(G41*G45) -> 0
A46: TOTAL | H46: =SUM(H42:H45) -> 0

Sheet Div30
A1: CONSTRUCTION COST ESTIMATE | D1: DATE
D2: =Summary!D2 -> Fill Here
A3: PROJECT | F3: BASIS FOR ESTIMATE
A4: =Summary!A8 -> Fill Here | F4: CODE A (No design completed)
A5: LOCATION | F5: CODE B (Preliminary design)
A6: EGLIN AIR FORCE BASE, FLORIDA | F6: CODE C (Final design)
A7: COMPANY | C7: PROJECT NO. | F7: OTHER (Specify)
A8: =Summary!A4 -> Fill Here | C8: =Summary!D9 -> Fill Here
A9: DRAWING NO. | B9: ESTIMATOR | F9: CHECKED BY
B11: QUANTITY | D11: LABOR | F11: MATERIAL
A12: ITEM DESCRIPTION | B12: NO. UNITS | C12: UNIT MEAS. | D12: PER UNIT | E12: TOTAL | F12: PER UNIT | G12: TOTAL | H12: TOTAL COST
A13: =Summary!B39 -> RESERVED
E14: =B14*D14 -> 0 | G14: =B14*F14 -> 0 | H14: =E14+G14 -> 0
E15: =B15*D15 -> 0 | G15: =B15*F15 -> 0 | H15: =E15+G15 -> 0
E16: =B16*D16 -> 0 | G16: =B16*F16 -> 0 | H16: =E16+G16 -> 0
E17: =B17*D17 -> 0 | G17: =B17*F17 -> 0 | H17: =E17+G17 -> 0
E18: =B18*D18 -> 0 | G18: =B18*F18 -> 0 | H18: =E18+G18 -> 0
E19: =B19*D19 -> 0 | G19: =B19*F19 -> 0 | H19: =E19+G19 -> 0
E20: =B20*D20 -> 0 | G20: =B20*F20 -> 0 | H20: =E20+G20 -> 0
E21: =B21*D21 -> 0 | G21: =B21*F21 -> 0 | H21: =E21+G21 -> 0
E22: =B22*D22 -> 0 | G22: =B22*F22 -> 0 | H22: =E22+G22 -> 0
E23: =B23*D23 -> 0 | G23: =B23*F23 -> 0 | H23: =E23+G23 -> 0
E24: =B24*D24 -> 0 | G24: =B24*F24 -> 0 | H24: =E24+G24 -> 0
E25: =B25*D25 -> 0 | G25: =B25*F25 -> 0 | H25: =E25+G25 -> 0
... E40: =B40*D40 -> 0 | G40: =B40*F40 -> 0 | H40: =E40+G40 -> 0
A41: TOTAL LABOR/MATERIALS | E41: =SUM(E14:E40) -> 0 | G41: =SUM(G14:G40) -> 0
A42: SUBTOTAL | H42: =SUM(H14:H40) -> 0
A43: Sub-Contractor's Overhead | G43: =Summary!G20 -> 0.05 | H43: =SUM(H42*G43) -> 0
A44: Sub-Contractor's Profit | G44: =Summary!G21 -> 0.11 | H44: =SUM(H42+H43)*G44 -> 0
A45: FL State Sales Tax | G45: =Summary!G22 -> 0.06 | H45: =SUM(G41*G45) -> 0
A46: TOTAL | H46: =SUM(H42:H45) -> 0

Sheet Div31
A1: CONSTRUCTION COST ESTIMATE | D1: DATE
D2: =Summary!D2 -> Fill Here
A3: PROJECT | F3: BASIS FOR ESTIMATE
A4: =Summary!A8 -> Fill Here | F4: CODE A (No design completed)
A5: LOCATION | F5: CODE B (Preliminary design)
A6: EGLIN AIR FORCE BASE, FLORIDA | F6: CODE C (Final design)
A7: COMPANY | C7: PROJECT NO. | F7: OTHER (Specify)
A8: =Summary!A4 -> Fill Here | C8: =Summary!D9 -> Fill Here
A9: DRAWING NO. | B9: ESTIMATOR | F9: CHECKED BY
B11: QUANTITY | D11: LABOR | F11: MATERIAL
A12: ITEM DESCRIPTION | B12: NO. UNITS | C12: UNIT MEAS. | D12: PER UNIT | E12: TOTAL | F12: PER UNIT | G12: TOTAL | H12: TOTAL COST
A13: =Summary!B40 -> EARTHWORK
E14: =B14*D14 -> 0 | G14: =B14*F14 -> 0 | H14: =E14+G14 -> 0
E15: =B15*D15 -> 0 | G15: =B15*F15 -> 0 | H15: =E15+G15 -> 0
E16: =B16*D16 -> 0 | G16: =B16*F16 -> 0 | H16: =E16+G16 -> 0
E17: =B17*D17 -> 0 | G17: =B17*F17 -> 0 | H17: =E17+G17 -> 0
E18: =B18*D18 -> 0 | G18: =B18*F18 -> 0 | H18: =E18+G18 -> 0
E19: =B19*D19 -> 0 | G19: =B19*F19 -> 0 | H19: =E19+G19 -> 0
E20: =B20*D20 -> 0 | G20: =B20*F20 -> 0 | H20: =E20+G20 -> 0
E21: =B21*D21 -> 0 | G21: =B21*F21 -> 0 | H21: =E21+G21 -> 0
E22: =B22*D22 -> 0 | G22: =B22*F22 -> 0 | H22: =E22+G22 -> 0
E23: =B23*D23 -> 0 | G23: =B23*F23 -> 0 | H23: =E23+G23 -> 0
E24: =B24*D24 -> 0 | G24: =B24*F24 -> 0 | H24: =E24+G24 -> 0
E25: =B25*D25 -> 0 | G25: =B25*F25 -> 0 | H25: =E25+G25 -> 0
... E40: =B40*D40 -> 0 | G40: =B40*F40 -> 0 | H40: =E40+G40 -> 0
A41: TOTAL LABOR/MATERIALS | E41: =SUM(E14:E39) -> 0 | G41: =SUM(G14:G39) -> 0
A42: SUBTOTAL | H42: =SUM(E41:G41) -> 0
A43: Sub-Contractor's Overhead | G43: =Summary!G20 -> 0.05 | H43: =SUM(H42*G43) -> 0
A44: Sub-Contractor's Profit | G44: =Summary!G21 -> 0.11 | H44: =SUM(H42+H43)*G44 -> 0
A45: FL State Sales Tax | G45: =Summary!G22 -> 0.06 | H45: =SUM(G41*G45) -> 0
A46: TOTAL | H46: =SUM(H42:H45) -> 0

Sheet Div32
A1: CONSTRUCTION COST ESTIMATE | D1: DATE
D2: =Summary!D2 -> Fill Here
A3: PROJECT | F3: BASIS FOR ESTIMATE
A4: =Summary!A8 -> Fill Here | F4: CODE A (No design completed)
A5: LOCATION | F5: CODE B (Preliminary design)
A6: EGLIN AIR FORCE BASE, FLORIDA | F6: CODE C (Final design)
A7: COMPANY | C7: PROJECT NO. | F7: OTHER (Specify)
A8: =Summary!A4 -> Fill Here | C8: =Summary!D9 -> Fill Here
A9: DRAWING NO. | B9: ESTIMATOR | F9: CHECKED BY
B11: QUANTITY | D11: LABOR | F11: MATERIAL
A12: ITEM DESCRIPTION | B12: NO. UNITS | C12: UNIT MEAS. | D12: PER UNIT | E12: TOTAL | F12: PER UNIT | G12: TOTAL | H12: TOTAL COST
A13: =Summary!B41 -> EXTERIOR IMPROVEMENTS
E14: =B14*D14 -> 0 | G14: =B14*F14 -> 0 | H14: =E14+G14 -> 0
E15: =B15*D15 -> 0 | G15: =B15*F15 -> 0 | H15: =E15+G15 -> 0
