Workbook

Sheet Instructions
A1: Use the information from the provided prefilled division sheets to fill in the 50 Divisions Cost Estimate CSI Format tool to build your proposal. The information from the prefilled division sheets may not be all inclusive. The contractor is allowed to include any missing items from each division and is allowed to fill in other divisions that are not listed in the prefilled division sheets. If there is a disagreement with the prefilled division sheets, the contractor should not delete the element(s), but instead leave it blank and then include their suggested element(s) at the bottom of that division tab.
A2: The ktr is required to complete the areas marked "Fill Here" in the summary tab. The rest of the information in the summary tab will automatically tabulate from the individual division tabs.

Sheet CLIN Structure
A1: CLIN STRUCTURE
A2: CLIN | B2: Description | C2: Unit of Issue | D2: Unit Price | E2: Total Amount | F2: Anticipated PoP
A3: 0001 | B3: Design – All design costs shall be included on this CLIN and represent 100% design submittal | C3: Job | F3: 119 DAYS
A4: 0002 | B4: Build – All construction costs shall be included on this CLIN | C4: Job | F4: 272 DAYS

Sheet Summary
A1: CONSTRUCTION COST ESTIMATE | C1: Date:
D2: Fill Here
A3: COMPANY
A4: Fill Here
A7: PROJECT
A8: Upgrade HVAC B8640 | B8: FA282325R0012
A9: LOCATION | C9: PROJECT NO. | D9: FTFA 23VH26
A10: EGLIN AIR FORCE BASE, FLORIDA
A11: DIVISION | B11: DESCRIPTION | C11: % by Division | D11: Division Total
A13: DIVISION 01 | B13: GENERAL REQUIREMENTS | C13: =SUM(D13/D46) -> #DIV/0! | D13: ='Div1'!H$42 -> 0
A14: DIVISION 02 | B14: EXISTING CONDITIONS | C14: =SUM(D14/D46) -> #DIV/0! | D14: ='Div2'!H50 -> 0
A15: DIVISION 03 | B15: CONCRETE WORK | C15: =SUM(D15/D46) -> #DIV/0! | D15: ='Div3'!H$42 -> 0 | F15: FILL IN AS REQUIRED (this will link to the entire document)
A16: DIVISION 04 | B16: MASONRY | C16: =SUM(D16/D46) -> #DIV/0! | D16: ='Div4'!H43 -> 0
A17: DIVISION 05 | B17: METALS | C17: =SUM(D17/D46) -> #DIV/0! | D17: ='Div5'!H$43 -> 0
A18: DIVISION 06 | B18: WOOD, PLASTICS AND COMPOSITES | C18: =SUM(D18/D46) -> #DIV/0! | D18: ='Div6'!H$47 -> 0 | F18: GC Overhead | G18: 0
A19: DIVISION 07 | B19: THERMAL AND MOISTURE PROTECTION | C19: =SUM(D19/D46) -> #DIV/0! | D19: ='Div7'!H43 -> 0 | F19: GC Protit | G19: 0
A20: DIVISION 08 | B20: OPENINGS | C20: =SUM(D20/D46) -> #DIV/0! | D20: ='Div8'!H$47 -> 0 | F20: Sub Overhead | G20: 0
A21: DIVISION 09 | B21: FINISHES | C21: =SUM(D21/D46) -> #DIV/0! | D21: ='Div9'!H43 -> 0 | F21: Sub Profit | G21: 0
A22: DIVISION 10 | B22: SPECIALTIES | C22: =SUM(D22/D46) -> #DIV/0! | D22: ='Div10'!H42 -> 0 | F22: Sales Tax | G22: 0
A23: DIVISION 11 | B23: EQUIPMENT | C23: =SUM(D23/D46) -> #DIV/0! | D23: ='Div11'!H42 -> 0 | F23: Risk/Bonding | G23: 0
A24: DIVISION 12 | B24: FURNISHINGS | C24: =SUM(D24/D46) -> #DIV/0! | D24: ='Div12'!H43 -> 0
A25: DIVISION 13 | B25: SPECIAL CONSTRUCTION | C25: =SUM(D25/D46) -> #DIV/0! | D25: ='Div13'!H41 -> 0 | F25: This spreadsheet contains many formulas, please save a copy prior to editting in case you make a mistake. All shaded areas are either linked or contain formulas
A26: DIVISION 14 | B26: CONVEYING EQUIPMENT | C26: =SUM(D26/D46) -> #DIV/0! | D26: ='Div14'!H41 -> 0
A27: DIVISION 21 | B27: FIRE SUPRESSION | C27: =SUM(D27/D46) -> #DIV/0! | D27: ='Div21'!H40 -> 0
A28: DIVISION 22 | B28: PLUMBING | C28: =SUM(D28/D46) -> #DIV/0! | D28: ='Div22'!H50 -> 0
A29: DIVISION 23 | B29: HEATING, VENTILATING AND A/C | C29: =SUM(D29/D46) -> #DIV/0! | D29: ='Div23'!H37 -> 0
A30: DIVISION 25 | B30: INTEGRATED AUTOMATION | C30: =SUM(D30/D46) -> #DIV/0! | D30: ='Div25'!H37 -> 0
A31: DIVISION 26 | B31: ELECTRICAL | C31: =SUM(D31/D46) -> #DIV/0! | D31: ='Div26'!H56 -> 0
A32: DIVISION 27 | B32: COMMUNICATIONS | C32: =SUM(D32/D46) -> #DIV/0! | D32: ='Div27'!H39 -> 0
A33: DIVISION 28 | B33: ELECTRONIC SAFETY AND SECURITY | C33: =SUM(D33/D46) -> #DIV/0! | D33: ='Div28'!H38 -> 0
A34: DIVISION 31 | B34: EARTHWORK | C34: =SUM(D34/D46) -> #DIV/0! | D34: ='Div31'!H61 -> 0
A35: DIVISION 32 | B35: EXTERIOR IMPROVEMENTS | C35: =SUM(D35/D46) -> #DIV/0! | D35: ='Div32'!H35 -> 0
A36: DIVISION 33 | B36: UTILITIES | C36: =SUM(D36/D46) -> #DIV/0! | D36: ='Div33'!H31 -> 0
A37: DIVISION 34 | B37: TRANSPORTATION | C37: =SUM(D37/D46) -> #DIV/0! | D37: ='Div34'!H38 -> 0
A38: DIVISION 35 | B38: WATERWAYS AND MARINE CONSTRUCTION | C38: =SUM(D38/D46) -> #DIV/0! | D38: ='Div35'!H38 -> 0
A39: DIVISION 40 | B39: PROCESS INTEGRATION | C39: =SUM(D39/D46) -> #DIV/0! | D39: ='Div40'!H36 -> 0
A40: DIVISION 41 | B40: MATERIAL PROCESING AND HANDLING EQUIPMENT | C40: =SUM(D40/D46) -> #DIV/0! | D40: ='Div41'!H39 -> 0
A41: DIVISION 42 | B41: PROCESS HEATING, COOLING AND DRYING EQUIPMENT | C41: =SUM(D41/D46) -> #DIV/0! | D41: ='Div42'!H36 -> 0
A42: DIVISION 43 | B42: PROCESS GAS & LIQUID HANDLING, PURIFICATION AND STORAGE EQUIPMENT | C42: =SUM(D42/D46) -> #DIV/0! | D42: ='Div43'!H37 -> 0
A43: DIVISION 44 | B43: POLLUTION CONTROL EQUIPMENT | C43: =SUM(D43/D46) -> #DIV/0! | D43: ='Div44'!H36 -> 0
...

Sheet Div1
A1: CONSTRUCTION COST ESTIMATE | D1: DATE
D2: =Summary!D2 -> Fill Here
A3: PROJECT | F3: BASIS FOR ESTIMATE
A4: =Summary!A8 -> Upgrade HVAC B8640 | F4: CODE A (No design completed)
A5: LOCATION | F5: CODE B (Preliminary design)
A6: EGLIN AIR FORCE BASE, FLORIDA | F6: CODE C (Final design)
A7: COMPANY | C7: PROJECT NO. | F7: OTHER (Specify)
A8: =Summary!A4 -> Fill Here | D8: =Summary!D9 -> FTFA 23VH26
A9: DRAWING NO. | B9: ESTIMATOR | F9: CHECKED BY
B11: QUANTITY | D11: LABOR | F11: MATERIAL
A12: ITEM DESCRIPTION | B12: NO. UNITS | C12: UNIT MEAS. | D12: PER UNIT | E12: TOTAL | F12: PER UNIT | G12: TOTAL | H12: TOTAL COST
A13: =Summary!B13 -> GENERAL REQUIREMENTS
E14: =B14*D14 -> 0 | G14: =B14*F14 -> 0 | H14: =E14+G14 -> 0
E15: =B15*D15 -> 0 | G15: =B15*F15 -> 0 | H15: =E15+G15 -> 0
E16: =B16*D16 -> 0 | G16: =B16*F16 -> 0 | H16: =E16+G16 -> 0
E17: =B17*D17 -> 0 | G17: =B17*F17 -> 0 | H17: =E17+G17 -> 0
E18: =B18*D18 -> 0 | G18: =B18*F18 -> 0 | H18: =E18+G18 -> 0
E19: =B19*D19 -> 0 | G19: =B19*F19 -> 0 | H19: =E19+G19 -> 0
E20: =B20*D20 -> 0 | G20: =B20*F20 -> 0 | H20: =E20+G20 -> 0
E21: =B21*D21 -> 0 | G21: =B21*F21 -> 0 | H21: =E21+G21 -> 0
E22: =B22*D22 -> 0 | G22: =B22*F22 -> 0 | H22: =E22+G22 -> 0
E23: =B23*D23 -> 0 | G23: =B23*F23 -> 0 | H23: =E23+G23 -> 0
E24: =B24*D24 -> 0 | G24: =B24*F24 -> 0 | H24: =E24+G24 -> 0
E25: =B25*D25 -> 0 | G25: =B25*F25 -> 0 | H25: =E25+G25 -> 0
... E36: =B36*D36 -> 0 | G36: =B36*F36 -> 0 | H36: =E36+G36 -> 0
A37: TOTAL LABOR/MATERIALS | E37: =SUM(E14:E35) -> 0 | G37: =SUM(G14:G35) -> 0
A38: SUBTOTAL | H38: =SUM(E37:G37) -> 0
A39: Sub-Contractor's Overhead | G39: =Summary!G20 -> 0 | H39: =SUM(H38*G39) -> 0
A40: Sub-Contractor's Profit | G40: =Summary!G21 -> 0 | H40: =SUM(H38+H39)*G40 -> 0
A41: FL State Sales Tax | G41: =Summary!G22 -> 0 | H41: =SUM(G37*G41) -> 0
A42: TOTAL | H42: =SUM(H38:H41) -> 0

Sheet Div2
A1: CONSTRUCTION COST ESTIMATE | D1: DATE
D2: =Summary!D2 -> Fill Here
A3: PROJECT | F3: BASIS FOR ESTIMATE
A4: =Summary!A8 -> Upgrade HVAC B8640 | F4: CODE A (No design completed)
A5: LOCATION | F5: CODE B (Preliminary design)
A6: EGLIN AIR FORCE BASE, FLORIDA | F6: CODE C (Final design)
A7: COMPANY | C7: PROJECT NO. | F7: OTHER (Specify)
A8: =Summary!A4 -> Fill Here | D8: =Summary!D9 -> FTFA 23VH26
A9: DRAWING NO. | B9: ESTIMATOR | F9: CHECKED BY
B11: QUANTITY | D11: LABOR | F11: MATERIAL
A12: ITEM DESCRIPTION | B12: NO. UNITS | C12: UNIT MEAS. | D12: PER UNIT | E12: TOTAL | F12: PER UNIT | G12: TOTAL | H12: TOTAL COST
A13: =Summary!B14 -> EXISTING CONDITIONS
E14: =B14*D14 -> 0 | G14: =B14*F14 -> 0 | H14: =E14+G14 -> 0
E15: =B15*D15 -> 0 | G15: =B15*F15 -> 0 | H15: =E15+G15 -> 0
E16: =B16*D16 -> 0 | G16: =B16*F16 -> 0 | H16: =E16+G16 -> 0
E17: =B17*D17 -> 0 | G17: =B17*F17 -> 0 | H17: =E17+G17 -> 0
E18: =B18*D18 -> 0 | G18: =B18*F18 -> 0 | H18: =E18+G18 -> 0
E19: =B19*D19 -> 0 | G19: =B19*F19 -> 0 | H19: =E19+G19 -> 0
E20: =B20*D20 -> 0 | G20: =B20*F20 -> 0 | H20: =E20+G20 -> 0
E21: =B21*D21 -> 0 | G21: =B21*F21 -> 0 | H21: =E21+G21 -> 0
E22: =B22*D22 -> 0 | G22: =B22*F22 -> 0 | H22: =E22+G22 -> 0
E23: =B23*D23 -> 0 | G23: =B23*F23 -> 0 | H23: =E23+G23 -> 0
E24: =B24*D24 -> 0 | G24: =B24*F24 -> 0 | H24: =E24+G24 -> 0
E25: =B25*D25 -> 0 | G25: =B25*F25 -> 0 | H25: =E25+G25 -> 0
... E44: =B44*D44 -> 0 | G44: =B44*F44 -> 0 | H44: =E44+G44 -> 0
A45: TOTAL LABOR/MATERIALS | E45: =SUM(E14:E44) -> 0 | G45: =B45*F45 -> 0
A46: SUBTOTAL | H46: =E45+G45 -> 0
A47: Sub-Contractor's Overhead | G47: =Summary!G20 -> 0 | H47: =SUM(H46*G47) -> 0
A48: Sub-Contractor's Profit | G48: =Summary!G21 -> 0 | H48: =SUM(H46+H47)*G48 -> 0
A49: FL State Sales Tax | G49: =Summary!G22 -> 0 | H49: =SUM(G45*G49) -> 0
A50: TOTAL | H50: =SUM(H46:H49) -> 0

Sheet Div3
A1: CONSTRUCTION COST ESTIMATE | D1: DATE
D2: =Summary!D2 -> Fill Here
A3: PROJECT | F3: BASIS FOR ESTIMATE
A4: =Summary!A8 -> Upgrade HVAC B8640 | F4: CODE A (No design completed)
A5: LOCATION | F5: CODE B (Preliminary design)
A6: EGLIN AIR FORCE BASE, FLORIDA | F6: CODE C (Final design)
A7: COMPANY | C7: PROJECT NO. | F7: OTHER (Specify)
A8: =Summary!A4 -> Fill Here | D8: =Summary!D9 -> FTFA 23VH26
A9: DRAWING NO. | B9: ESTIMATOR | F9: CHECKED BY
B11: QUANTITY | D11: LABOR | F11: MATERIAL
A12: ITEM DESCRIPTION | B12: NO. UNITS | C12: UNIT MEAS. | D12: PER UNIT | E12: TOTAL | F12: PER UNIT | G12: TOTAL | H12: TOTAL COST
A13: =Summary!B15 -> CONCRETE WORK
E14: =B14*D14 -> 0 | G14: =B14*F14 -> 0 | H14: =E14+G14 -> 0
E15: =B15*D15 -> 0 | G15: =B15*F15 -> 0 | H15: =E15+G15 -> 0
E16: =B16*D16 -> 0 | G16: =B16*F16 -> 0 | H16: =E16+G16 -> 0
E17: =B17*D17 -> 0 | G17: =B17*F17 -> 0 | H17: =E17+G17 -> 0
E18: =B18*D18 -> 0 | G18: =B18*F18 -> 0 | H18: =E18+G18 -> 0
E19: =B19*D19 -> 0 | G19: =B19*F19 -> 0 | H19: =E19+G19 -> 0
E20: =B20*D20 -> 0 | G20: =B20*F20 -> 0 | H20: =E20+G20 -> 0
E21: =B21*D21 -> 0 | G21: =B21*F21 -> 0 | H21: =E21+G21 -> 0
E22: =B22*D22 -> 0 | G22: =B22*F22 -> 0 | H22: =E22+G22 -> 0
E23: =B23*D23 -> 0 | G23: =B23*F23 -> 0 | H23: =E23+G23 -> 0
E24: =B24*D24 -> 0 | G24: =B24*F24 -> 0 | H24: =E24+G24 -> 0
E25: =B25*D25 -> 0 | G25: =B25*F25 -> 0 | H25: =E25+G25 -> 0
... E36: =B36*D36 -> 0 | G36: =B36*F36 -> 0 | H36: =E36+G36 -> 0
A37: TOTAL LABOR/MATERIALS | E37: =SUM(E14:E36) -> 0 | G37: =SUM(G14:G36) -> 0
A38: SUBTOTAL | H38: =E37+G37 -> 0
A39: Sub-Contractor's Overhead | G39: =Summary!G20 -> 0 | H39: =SUM(H38*G39) -> 0
A40: Sub-Contractor's Profit | G40: =Summary!G21 -> 0 | H40: =SUM(H38+H39)*G40 -> 0
A41: FL State Sales Tax | G41: =Summary!G22 -> 0 | H41: =SUM(G37*G41) -> 0
A42: TOTAL | H42: =SUM(H38:H41) -> 0

Sheet Div4
A1: CONSTRUCTION COST ESTIMATE | D1: DATE
D2: =Summary!D2 -> Fill Here
A3: PROJECT | F3: BASIS FOR ESTIMATE
A4: =Summary!A8 -> Upgrade HVAC B8640 | F4: CODE A (No design completed)
A5: LOCATION | F5: CODE B (Preliminary design)
A6: EGLIN AIR FORCE BASE, FLORIDA | F6: CODE C (Final design)
A7: COMPANY | C7: PROJECT NO. | F7: OTHER (Specify)
A8: =Summary!A4 -> Fill Here | D8: =Summary!D9 -> FTFA 23VH26
A9: DRAWING NO. | B9: ESTIMATOR | F9: CHECKED BY
B11: QUANTITY | D11: LABOR | F11: MATERIAL
A12: ITEM DESCRIPTION | B12: NO. UNITS | C12: UNIT MEAS. | D12: PER UNIT | E12: TOTAL | F12: PER UNIT | G12: TOTAL | H12: TOTAL COST
A13: =Summary!B16 -> MASONRY
E14: =B14*D14 -> 0 | G14: =B14*F14 -> 0 | H14: =E14+G14 -> 0
E15: =B15*D15 -> 0 | G15: =B15*F15 -> 0 | H15: =E15+G15 -> 0
E16: =B16*D16 -> 0 | G16: =B16*F16 -> 0 | H16: =E16+G16 -> 0
E17: =B17*D17 -> 0 | G17: =B17*F17 -> 0 | H17: =E17+G17 -> 0
E18: =B18*D18 -> 0 | G18: =B18*F18 -> 0 | H18: =E18+G18 -> 0
E19: =B19*D19 -> 0 | G19: =B19*F19 -> 0 | H19: =E19+G19 -> 0
E20: =B20*D20 -> 0 | G20: =B20*F20 -> 0 | H20: =E20+G20 -> 0
E21: =B21*D21 -> 0 | G21: =B21*F21 -> 0 | H21: =E21+G21 -> 0
E22: =B22*D22 -> 0 | G22: =B22*F22 -> 0 | H22: =E22+G22 -> 0
E23: =B23*D23 -> 0 | G23: =B23*F23 -> 0 | H23: =E23+G23 -> 0
E24: =B24*D24 -> 0 | G24: =B24*F24 -> 0 | H24: =E24+G24 -> 0
E25: =B25*D25 -> 0 | G25: =B25*F25 -> 0 | H25: =E25+G25 -> 0
... E37: =B37*D37 -> 0 | G37: =B37*F37 -> 0 | H37: =E37+G37 -> 0
A38: TOTAL LABOR/MATERIALS | E38: =SUM(E14:E37) -> 0 | G38: =SUM(G14:G37) -> 0
A39: SUBTOTAL | H39: =SUM(H14:H37) -> 0
A40: Sub-Contractor's Overhead | G40: =Summary!G20 -> 0 | H40: =SUM(H39*G40) -> 0
A41: Sub-Contractor's Profit | G41: =Summary!G21 -> 0 | H41: =SUM(H39+H40)*G41 -> 0
A42: FL State Sales Tax | G42: =Summary!G22 -> 0 | H42: =SUM(G38*G42) -> 0
A43: TOTAL | H43: =SUM(H39:H42) -> 0

Sheet Div5
A1: CONSTRUCTION COST ESTIMATE | D1: DATE
D2: =Summary!D2 -> Fill Here
A3: PROJECT | F3: BASIS FOR ESTIMATE
A4: =Summary!A8 -> Upgrade HVAC B8640 | F4: CODE A (No design completed)
A5: LOCATION | F5: CODE B (Preliminary design)
A6: EGLIN AIR FORCE BASE, FLORIDA | F6: CODE C (Final design)
A7: COMPANY | C7: PROJECT NO. | F7: OTHER (Specify)
A8: =Summary!A4 -> Fill Here | C8: =Summary!D9 -> FTFA 23VH26
A9: DRAWING NO. | B9: ESTIMATOR | F9: CHECKED BY
B11: QUANTITY | D11: LABOR | F11: MATERIAL
A12: ITEM DESCRIPTION | B12: NO. UNITS | C12: UNIT MEAS. | D12: PER UNIT | E12: TOTAL | F12: PER UNIT | G12: TOTAL | H12: TOTAL COST
A13: =Summary!B17 -> METALS
E14: =B14*D14 -> 0 | G14: =B14*F14 -> 0 | H14: =E14+G14 -> 0
E15: =B15*D15 -> 0 | G15: =B15*F15 -> 0 | H15: =E15+G15 -> 0
E16: =B16*D16 -> 0 | G16: =B16*F16 -> 0 | H16: =E16+G16 -> 0
E17: =B17*D17 -> 0 | G17: =B17*F17 -> 0 | H17: =E17+G17 -> 0
E18: =B18*D18 -> 0 | G18: =B18*F18 -> 0 | H18: =E18+G18 -> 0
E19: =B19*D19 -> 0 | G19: =B19*F19 -> 0 | H19: =E19+G19 -> 0
E20: =B20*D20 -> 0 | G20: =B20*F20 -> 0 | H20: =E20+G20 -> 0
E21: =B21*D21 -> 0 | G21: =B21*F21 -> 0 | H21: =E21+G21 -> 0
E22: =B22*D22 -> 0 | G22: =B22*F22 -> 0 | H22: =E22+G22 -> 0
E23: =B23*D23 -> 0 | G23: =B23*F23 -> 0 | H23: =E23+G23 -> 0
E24: =B24*D24 -> 0 | G24: =B24*F24 -> 0 | H24: =E24+G24 -> 0
E25: =B25*D25 -> 0 | G25: =B25*F25 -> 0 | H25: =E25+G25 -> 0
... E37: =B37*D37 -> 0 | G37: =B37*F37 -> 0 | H37: =E37+G37 -> 0
A38: TOTAL LABOR/MATERIALS | E38: =SUM(E14:E37) -> 0 | G38: =SUM(G14:G37) -> 0
A39: SUBTOTAL | H39: =SUM(H14:H37) -> 0
A40: Sub-Contractor's Overhead | G40: =Summary!G20 -> 0 | H40: =SUM(H39*G40) -> 0
A41: Sub-Contractor's Profit | G41: =Summary!G21 -> 0 | H41: =SUM(H39+H40)*G41 -> 0
A42: FL State Sales Tax | G42: =Summary!G22 -> 0 | H42: =SUM(G38*G42) -> 0
A43: TOTAL | H43: =SUM(H39:H42) -> 0

Sheet Div6
A1: CONSTRUCTION COST ESTIMATE | D1: DATE
D2: =Summary!D2 -> Fill Here
A3: PROJECT | F3: BASIS FOR ESTIMATE
A4: =Summary!A8 -> Upgrade HVAC B8640 | F4: CODE A (No design completed)
A5: LOCATION | F5: CODE B (Preliminary design)
A6: EGLIN AIR FORCE BASE, FLORIDA | F6: CODE C (Final design)
A7: COMPANY | C7: PROJECT NO. | F7: OTHER (Specify)
A8: =Summary!A4 -> Fill Here | D8: =Summary!D9 -> FTFA 23VH26
A9: DRAWING NO. | B9: ESTIMATOR | F9: CHECKED BY
B11: QUANTITY | D11: LABOR | F11: MATERIAL
A12: ITEM DESCRIPTION | B12: NO. UNITS | C12: UNIT MEAS. | D12: PER UNIT | E12: TOTAL | F12: PER UNIT | G12: TOTAL | H12: TOTAL COST
A13: =Summary!B18 -> WOOD, PLASTICS AND COMPOSITES
E14: =B14*D14 -> 0 | G14: =B14*F14 -> 0 | H14: =E14+G14 -> 0
E15: =B15*D15 -> 0 | G15: =B15*F15 -> 0 | H15: =E15+G15 -> 0
E16: =B16*D16 -> 0 | G16: =B16*F16 -> 0 | H16: =E16+G16 -> 0
E17: =B17*D17 -> 0 | G17: =B17*F17 -> 0 | H17: =E17+G17 -> 0
E18: =B18*D18 -> 0 | G18: =B18*F18 -> 0 | H18: =E18+G18 -> 0
E19: =B19*D19 -> 0 | G19: =B19*F19 -> 0 | H19: =E19+G19 -> 0
E20: =B20*D20 -> 0 | G20: =B20*F20 -> 0 | H20: =E20+G20 -> 0
E21: =B21*D21 -> 0 | G21: =B21*F21 -> 0 | H21: =E21+G21 -> 0
E22: =B22*D22 -> 0 | G22: =B22*F22 -> 0 | H22: =E22+G22 -> 0
E23: =B23*D23 -> 0 | G23: =B23*F23 -> 0 | H23: =E23+G23 -> 0
E24: =B24*D24 -> 0 | G24: =B24*F24 -> 0 | H24: =E24+G24 -> 0
E25: =B25*D25 -> 0 | G25: =B25*F25 -> 0 | H25: =E25+G25 -> 0
... E41: =B41*D41 -> 0 | G41: =B41*F41 -> 0 | H41: =E41+G41 -> 0
A42: TOTAL LABOR/MATERIALS | E42: =SUM(E14:E40) -> 0 | G42: =SUM(G14:G40) -> 0
A43: SUBTOTAL | H43: =SUM(E42:G42) -> 0
A44: Sub-Contractor's Overhead | G44: =Summary!G20 -> 0 | H44: =SUM(H43*G44) -> 0
A45: Sub-Contractor's Profit | G45: =Summary!G21 -> 0 | H45: =SUM(H43+H44)*G45 -> 0
A46: FL State Sales Tax | G46: =Summary!G22 -> 0 | H46: =SUM(G42*G46) -> 0
A47: TOTAL | H47: =SUM(H43:H46) -> 0

Sheet Div7
A1: CONSTRUCTION COST ESTIMATE | D1: DATE
D2: =Summary!D2 -> Fill Here
A3: PROJECT | F3: BASIS FOR ESTIMATE
A4: =Summary!A8 -> Upgrade HVAC B8640 | F4: CODE A (No design completed)
A5: LOCATION | F5: CODE B (Preliminary design)
A6: EGLIN AIR FORCE BASE, FLORIDA | F6: CODE C (Final design)
A7: COMPANY | C7: PROJECT NO. | F7: OTHER (Specify)
A8: =Summary!A4 -> Fill Here | D8: =Summary!D9 -> FTFA 23VH26
A9: DRAWING NO. | B9: ESTIMATOR | F9: CHECKED BY
B11: QUANTITY | D11: LABOR | F11: MATERIAL
A12: ITEM DESCRIPTION | B12: NO. UNITS | C12: UNIT MEAS. | D12: PER UNIT | E12: TOTAL | F12: PER UNIT | G12: TOTAL | H12: TOTAL COST
A13: =Summary!B19 -> THERMAL AND MOISTURE PROTECTION
E14: =B14*D14 -> 0 | G14: =B14*F14 -> 0 | H14: =E14+G14 -> 0
E15: =B15*D15 -> 0 | G15: =B15*F15 -> 0 | H15: =E15+G15 -> 0
E16: =B16*D16 -> 0 | G16: =B16*F16 -> 0 | H16: =E16+G16 -> 0
E17: =B17*D17 -> 0 | G17: =B17*F17 -> 0 | H17: =E17+G17 -> 0
E18: =B18*D18 -> 0 | G18: =B18*F18 -> 0 | H18: =E18+G18 -> 0
E19: =B19*D19 -> 0 | G19: =B19*F19 -> 0 | H19: =E19+G19 -> 0
E20: =B20*D20 -> 0 | G20: =B20*F20 -> 0 | H20: =E20+G20 -> 0
E21: =B21*D21 -> 0 | G21: =B21*F21 -> 0 | H21: =E21+G21 -> 0
E22: =B22*D22 -> 0 | G22: =B22*F22 -> 0 | H22: =E22+G22 -> 0
E23: =B23*D23 -> 0 | G23: =B23*F23 -> 0 | H23: =E23+G23 -> 0
E24: =B24*D24 -> 0 | G24: =B24*F24 -> 0 | H24: =E24+G24 -> 0
E25: =B25*D25 -> 0 | G25: =B25*F25 -> 0 | H25: =E25+G25 -> 0
... E37: =B37*D37 -> 0 | G37: =B37*F37 -> 0 | H37: =E37+G37 -> 0
A38: TOTAL LABOR/MATERIALS | E38: =SUM(E14:E37) -> 0 | G38: =SUM(G14:G37) -> 0
A39: SUBTOTAL | H39: =E38+G38 -> 0
A40: Sub-Contractor's Overhead | G40: =Summary!G20 -> 0 | H40: =SUM(H39*G40) -> 0
A41: Sub-Contractor's Profit | G41: =Summary!G21 -> 0 | H41: =SUM(H39+H40)*G41 -> 0
A42: FL State Sales Tax | G42: =Summary!G22 -> 0 | H42: =SUM(G38*G42) -> 0
A43: TOTAL | H43: =SUM(H39:H42) -> 0

Sheet Div8
A1: CONSTRUCTION COST ESTIMATE | D1: DATE
D2: =Summary!D2 -> Fill Here
A3: PROJECT | F3: BASIS FOR ESTIMATE
A4: =Summary!A8 -> Upgrade HVAC B8640 | F4: CODE A (No design completed)
A5: LOCATION | F5: CODE B (Preliminary design)
A6: EGLIN AIR FORCE BASE, FLORIDA | F6: CODE C (Final design)
A7: COMPANY | C7: PROJECT NO. | F7: OTHER (Specify)
A8: =Summary!A4 -> Fill Here | D8: =Summary!D9 -> FTFA 23VH26
A9: DRAWING NO. | B9: ESTIMATOR | F9: CHECKED BY
B11: QUANTITY | D11: LABOR | F11: MATERIAL
A12: ITEM DESCRIPTION | B12: NO. UNITS | C12: UNIT MEAS. | D12: PER UNIT | E12: TOTAL | F12: PER UNIT | G12: TOTAL | H12: TOTAL COST
A13: =Summary!B20 -> OPENINGS
E14: =B14*D14 -> 0 | G14: =B14*F14 -> 0 | H14: =E14+G14 -> 0
E15: =B15*D15 -> 0 | G15: =B15*F15 -> 0 | H15: =E15+G15 -> 0
E16: =B16*D16 -> 0 | G16: =B16*F16 -> 0 | H16: =E16+G16 -> 0
E17: =B17*D17 -> 0 | G17: =B17*F17 -> 0 | H17: =E17+G17 -> 0
E18: =B18*D18 -> 0 | G18: =B18*F18 -> 0 | H18: =E18+G18 -> 0
E19: =B19*D19 -> 0 | G19: =B19*F19 -> 0 | H19: =E19+G19 -> 0
E20: =B20*D20 -> 0 | G20: =B20*F20 -> 0 | H20: =E20+G20 -> 0
E21: =B21*D21 -> 0 | G21: =B21*F21 -> 0 | H21: =E21+G21 -> 0
E22: =B22*D22 -> 0 | G22: =B22*F22 -> 0 | H22: =E22+G22 -> 0
E23: =B23*D23 -> 0 | G23: =B23*F23 -> 0 | H23: =E23+G23 -> 0
E24: =B24*D24 -> 0 | G24: =B24*F24 -> 0 | H24: =E24+G24 -> 0
E25: =B25*D25 -> 0 | G25: =B25*F25 -> 0 | H25: =E25+G25 -> 0
... E41: =B41*D41 -> 0 | G41: =B41*F41 -> 0 | H41: =E41+G41 -> 0
A42: TOTAL LABOR/MATERIALS | E42: =SUM(E14:E41) -> 0 | G42: =SUM(G14:G41) -> 0
A43: SUBTOTAL | H43: =E42+G42 -> 0
A44: Sub-Contractor's Overhead | G44: =Summary!G20 -> 0 | H44: =SUM(H43*G44) -> 0
A45: Sub-Contractor's Profit | G45: =Summary!G21 -> 0 | H45: =SUM(H43+H44)*G45 -> 0
A46: FL State Sales Tax | G46: =Summary!G22 -> 0 | H46: =SUM(G42*G46) -> 0
A47: TOTAL | H47: =SUM(H43:H46) -> 0

Sheet Div9
A1: CONSTRUCTION COST ESTIMATE | D1: DATE
D2: =Summary!D2 -> Fill Here
A3: PROJECT | F3: BASIS FOR ESTIMATE
A4: =Summary!A8 -> Upgrade HVAC B8640 | F4: CODE A (No design completed)
A5: LOCATION | F5: CODE B (Preliminary design)
A6: EGLIN AIR FORCE BASE, FLORIDA | F6: CODE C (Final design)
A7: COMPANY | C7: PROJECT NO. | F7: OTHER (Specify)
A8: =Summary!A4 -> Fill Here | C8: =Summary!D9 -> FTFA 23VH26
A9: DRAWING NO. | B9: ESTIMATOR | F9: CHECKED BY
B11: QUANTITY | D11: LABOR | F11: MATERIAL
A12: ITEM DESCRIPTION | B12: NO. UNITS | C12: UNIT MEAS. | D12: PER UNIT | E12: TOTAL | F12: PER UNIT | G12: TOTAL | H12: TOTAL COST
A13: =Summary!B21 -> FINISHES
E14: =B14*D14 -> 0 | G14: =B14*F14 -> 0 | H14: =E14+G14 -> 0
E15: =B15*D15 -> 0 | G15: =B15*F15 -> 0 | H15: =E15+G15 -> 0
E16: =B16*D16 -> 0 | G16: =B16*F16 -> 0 | H16: =E16+G16 -> 0
E17: =B17*D17 -> 0 | G17: =B17*F17 -> 0 | H17: =E17+G17 -> 0
E18: =B18*D18 -> 0 | G18: =B18*F18 -> 0 | H18: =E18+G18 -> 0
E19: =B19*D19 -> 0 | G19: =B19*F19 -> 0 | H19: =E19+G19 -> 0
E20: =B20*D20 -> 0 | G20: =B20*F20 -> 0 | H20: =E20+G20 -> 0
E21: =B21*D21 -> 0 | G21: =B21*F21 -> 0 | H21: =E21+G21 -> 0
E22: =B22*D22 -> 0 | G22: =B22*F22 -> 0 | H22: =E22+G22 -> 0
E23: =B23*D23 -> 0 | G23: =B23*F23 -> 0 | H23: =E23+G23 -> 0
E24: =B24*D24 -> 0 | G24: =B24*F24 -> 0 | H24: =E24+G24 -> 0
E25: =B25*D25 -> 0 | G25: =B25*F25 -> 0 | H25: =E25+G25 -> 0
... E37: =B37*D37 -> 0 | G37: =B37*F37 -> 0 | H37: =E37+G37 -> 0
A38: TOTAL LABOR/MATERIALS | E38: =SUM(E14:E37) -> 0 | G38: =SUM(G14:G37) -> 0
A39: SUBTOTAL | H39: =SUM(H14:H37) -> 0
A40: Sub-Contractor's Overhead | G40: =Summary!G20 -> 0 | H40: =SUM(H39*G40) -> 0
A41: Sub-Contractor's Profit | G41: =Summary!G21 -> 0 | H41: =SUM(H39+H40)*G41 -> 0
A42: FL State Sales Tax | G42: =Summary!G22 -> 0 | H42: =SUM(G38*G42) -> 0
A43: TOTAL | H43: =SUM(H39:H42) -> 0

Sheet Div10
A1: CONSTRUCTION COST ESTIMATE | D1: DATE
D2: =Summary!D2 -> Fill Here
A3: PROJECT | F3: BASIS FOR ESTIMATE
A4: =Summary!A8 -> Upgrade HVAC B8640 | F4: CODE A (No design completed)
A5: LOCATION | F5: CODE B (Preliminary design)
A6: EGLIN AIR FORCE BASE, FLORIDA | F6: CODE C (Final design)
A7: COMPANY | C7: PROJECT NO. | F7: OTHER (Specify)
A8: =Summary!A4 -> Fill Here | C8: =Summary!D9 -> FTFA 23VH26
A9: DRAWING NO. | B9: ESTIMATOR | F9: CHECKED BY
B11: QUANTITY | D11: LABOR | F11: MATERIAL
A12: ITEM DESCRIPTION | B12: NO. UNITS | C12: UNIT MEAS. | D12: PER UNIT | E12: TOTAL | F12: PER UNIT | G12: TOTAL | H12: TOTAL COST
A13: =Summary!B22 -> SPECIALTIES
E14: =B14*D14 -> 0 | G14: =B14*F14 -> 0 | H14: =E14+G14 -> 0
E15: =B15*D15 -> 0 | G15: =B15*F15 -> 0 | H15: =E15+G15 -> 0
E16: =B16*D16 -> 0 | G16: =B16*F16 -> 0 | H16: =E16+G16 -> 0
E17: =B17*D17 -> 0 | G17: =B17*F17 -> 0 | H17: =E17+G17 -> 0
E18: =B18*D18 -> 0 | G18: =B18*F18 -> 0 | H18: =E18+G18 -> 0
E19: =B19*D19 -> 0 | G19: =B19*F19 -> 0 | H19: =E19+G19 -> 0
E20: =B20*D20 -> 0 | G20: =B20*F20 -> 0 | H20: =E20+G20 -> 0
E21: =B21*D21 -> 0 | G21: =B21*F21 -> 0 | H21: =E21+G21 -> 0
E22: =B22*D22 -> 0 | G22: =B22*F22 -> 0 | H22: =E22+G22 -> 0
E23: =B23*D23 -> 0 | G23: =B23*F23 -> 0 | H23: =E23+G23 -> 0
E24: =B24*D24 -> 0 | G24: =B24*F24 -> 0 | H24: =E24+G24 -> 0
E25: =B25*D25 -> 0 | G25: =B25*F25 -> 0 | H25: =E25+G25 -> 0
... E36: =B36*D36 -> 0 | G36: =B36*F36 -> 0 | H36: =E36+G36 -> 0
A37: TOTAL LABOR/MATERIALS | E37: =SUM(E14:E36) -> 0 | G37: =SUM(G14:G36) -> 0
A38: SUBTOTAL | H38: =SUM(H14:H36) -> 0
A39: Sub-Contractor's Overhead | G39: =Summary!G20 -> 0 | H39: =SUM(H38*G39) -> 0
A40: Sub-Contractor's Profit | G40: =Summary!G21 -> 0 | H40: =SUM(H38+H39)*G40 -> 0
A41: FL State Sales Tax | G41: =Summary!G22 -> 0 | H41: =SUM(G37*G41) -> 0
A42: TOTAL | H42: =SUM(H38:H41) -> 0

Sheet Div11
A1: CONSTRUCTION COST ESTIMATE | D1: DATE
D2: =Summary!D2 -> Fill Here
A3: PROJECT | F3: BASIS FOR ESTIMATE
A4: =Summary!A8 -> Upgrade HVAC B8640 | F4: CODE A (No design completed)
A5: LOCATION | F5: CODE B (Preliminary design)
A6: EGLIN AIR FORCE BASE, FLORIDA | F6: CODE C (Final design)
A7: COMPANY | C7: PROJECT NO. | F7: OTHER (Specify)
A8: =Summary!A4 -> Fill Here | D8: =Summary!D9 -> FTFA 23VH26
A9: DRAWING NO. | B9: ESTIMATOR | F9: CHECKED BY
B11: QUANTITY | D11: LABOR | F11: MATERIAL
A12: ITEM DESCRIPTION | B12: NO. UNITS | C12: UNIT MEAS. | D12: PER UNIT | E12: TOTAL | F12: PER UNIT | G12: TOTAL | H12: TOTAL COST
A13: =Summary!B23 -> EQUIPMENT
E14: =B14*D14 -> 0 | G14: =B14*F14 -> 0 | H14: =E14+G14 -> 0
E15: =B15*D15 -> 0 | G15: =B15*F15 -> 0 | H15: =E15+G15 -> 0
E16: =B16*D16 -> 0 | G16: =B16*F16 -> 0 | H16: =E16+G16 -> 0
E17: =B17*D17 -> 0 | G17: =B17*F17 -> 0 | H17: =E17+G17 -> 0
E18: =B18*D18 -> 0 | G18: =B18*F18 -> 0 | H18: =E18+G18 -> 0
E19: =B19*D19 -> 0 | G19: =B19*F19 -> 0 | H19: =E19+G19 -> 0
E20: =B20*D20 -> 0 | G20: =B20*F20 -> 0 | H20: =E20+G20 -> 0
E21: =B21*D21 -> 0 | G21: =B21*F21 -> 0 | H21: =E21+G21 -> 0
E22: =B22*D22 -> 0 | G22: =B22*F22 -> 0 | H22: =E22+G22 -> 0
E23: =B23*D23 -> 0 | G23: =B23*F23 -> 0 | H23: =E23+G23 -> 0
E24: =B24*D24 -> 0 | G24: =B24*F24 -> 0 | H24: =E24+G24 -> 0
E25: =B25*D25 -> 0 | G25: =B25*F25 -> 0 | H25: =E25+G25 -> 0
... E36: =B36*D36 -> 0 | G36: =B36*F36 -> 0 | H36: =E36+G36 -> 0
A37: TOTAL LABOR/MATERIALS | E37: =SUM(E14:E35) -> 0 | G37: =SUM(G14:G35) -> 0
A38: SUBTOTAL | H38: =SUM(E37:G37) -> 0
A39: Sub-Contractor's Overhead | G39: =Summary!G20 -> 0 | H39: =SUM(H38*G39) -> 0
A40: Sub-Contractor's Profit | G40: =Summary!G21 -> 0 | H40: =SUM(H38+H39)*G40 -> 0
A41: FL State Sales Tax | G41: =Summary!G22 -> 0 | H41: =SUM(G37*G41) -> 0
A42: TOTAL | H42: =SUM(H38:H41) -> 0

Sheet Div12
A1: CONSTRUCTION COST ESTIMATE | D1: DATE
D2: =Summary!D2 -> Fill Here
A3: PROJECT | F3: BASIS FOR ESTIMATE
A4: =Summary!A8 -> Upgrade HVAC B8640 | F4: CODE A (No design completed)
A5: LOCATION | F5: CODE B (Preliminary design)
A6: EGLIN AIR FORCE BASE, FLORIDA | F6: CODE C (Final design)
A7: COMPANY | C7: PROJECT NO. | F7: OTHER (Specify)
A8: =Summary!A4 -> Fill Here | D8: =Summary!D9 -> FTFA 23VH26
A9: DRAWING NO. | B9: ESTIMATOR | F9: CHECKED BY
B11: QUANTITY | D11: LABOR | F11: MATERIAL
A12: ITEM DESCRIPTION | B12: NO. UNITS | C12: UNIT MEAS. | D12: PER UNIT | E12: TOTAL | F12: PER UNIT | G12: TOTAL | H12: TOTAL COST
A13: =Summary!B24 -> FURNISHINGS
E14: =B14*D14 -> 0 | G14: =B14*F14 -> 0 | H14: =E14+G14 -> 0
E15: =B15*D15 -> 0 | G15: =B15*F15 -> 0 | H15: =E15+G15 -> 0
E16: =B16*D16 -> 0 | G16: =B16*F16 -> 0 | H16: =E16+G16 -> 0
E17: =B17*D17 -> 0 | G17: =B17*F17 -> 0 | H17: =E17+G17 -> 0
E18: =B18*D18 -> 0 | G18: =B18*F18 -> 0 | H18: =E18+G18 -> 0
E19: =B19*D19 -> 0 | G19: =B19*F19 -> 0 | H19: =E19+G19 -> 0
E20: =B20*D20 -> 0 | G20: =B20*F20 -> 0 | H20: =E20+G20 -> 0
E21: =B21*D21 -> 0 | G21: =B21*F21 -> 0 | H21: =E21+G21 -> 0
E22: =B22*D22 -> 0 | G22: =B22*F22 -> 0 | H22: =E22+G22 -> 0
E23: =B23*D23 -> 0 | G23: =B23*F23 -> 0 | H23: =E23+G23 -> 0
E24: =B24*D24 -> 0 | G24: =B24*F24 -> 0 | H24: =E24+G24 -> 0
E25: =B25*D25 -> 0 | G25: =B25*F25 -> 0 | H25: =E25+G25 -> 0
... E37: =B37*D37 -> 0 | G37: =B37*F37 -> 0 | H37: =E37+G37 -> 0
A38: TOTAL LABOR/MATERIALS | E38: =SUM(E14:E37) -> 0 | G38: =SUM(G14:G37) -> 0
A39: SUBTOTAL | H39: =E38+G38 -> 0
A40: Sub-Contractor's Overhead | G40: =Summary!G20 -> 0 | H40: =SUM(H39*G40) -> 0
A41: Sub-Contractor's Profit | G41: =Summary!G21 -> 0 | H41: =SUM(H39+H40)*G41 -> 0
A42: FL State Sales Tax | G42: =Summary!G22 -> 0 | H42: =SUM(G38*G42) -> 0
A43: TOTAL | H43: =SUM(H39:H42) -> 0

Sheet Div13
A1: CONSTRUCTION COST ESTIMATE | D1: DATE
D2: =Summary!D2 -> Fill Here
A3: PROJECT | F3: BASIS FOR ESTIMATE
A4: =Summary!A8 -> Upgrade HVAC B8640 | F4: CODE A (No design completed)
A5: LOCATION | F5: CODE B (Preliminary design)
A6: EGLIN AIR FORCE BASE, FLORIDA | F6: CODE C (Final design)
A7: COMPANY | C7: PROJECT NO. | F7: OTHER (Specify)
A8: =Summary!A4 -> Fill Here | D8: =Summary!D9 -> FTFA 23VH26
A9: DRAWING NO. | B9: ESTIMATOR | F9: CHECKED BY
B11: QUANTITY | D11: LABOR | F11: MATERIAL
A12: ITEM DESCRIPTION | B12: NO. UNITS | C12: UNIT MEAS. | D12: PER UNIT | E12: TOTAL | F12: PER UNIT | G12: TOTAL | H12: TOTAL COST
A13: =Summary!B25 -> SPECIAL CONSTRUCTION
E14: =B14*D14 -> 0 | G14: =B14*F14 -> 0 | H14: =E14+G14 -> 0
E15: =B15*D15 -> 0 | G15: =B15*F15 -> 0 | H15: =E15+G15 -> 0
E16: =B16*D16 -> 0 | G16: =B16*F16 -> 0 | H16: =E16+G16 -> 0
E17: =B17*D17 -> 0 | G17: =B17*F17 -> 0 | H17: =E17+G17 -> 0
E18: =B18*D18 -> 0 | G18: =B18*F18 -> 0 | H18: =E18+G18 -> 0
E19: =B19*D19 -> 0 | G19: =B19*F19 -> 0 | H19: =E19+G19 -> 0
E20: =B20*D20 -> 0 | G20: =B20*F20 -> 0 | H20: =E20+G20 -> 0
E21: =B21*D21 -> 0 | G21: =B21*F21 -> 0 | H21: =E21+G21 -> 0
E22: =B22*D22 -> 0 | G22: =B22*F22 -> 0 | H22: =E22+G22 -> 0
E23: =B23*D23 -> 0 | G23: =B23*F23 -> 0 | H23: =E23+G23 -> 0
E24: =B24*D24 -> 0 | G24: =B24*F24 -> 0 | H24: =E24+G24 -> 0
E25: =B25*D25 -> 0 | G25: =B25*F25 -> 0 | H25: =E25+G25 -> 0
... E28: =B28*D28 -> 0 | G28: =B28*F28 -> 0 | H28: =E28+G28 -> 0
E29: =B29*D29 -> 0 | G29: =B29*F29 -> 0 | H29: =E30+G29 -> 0
E30: =B30*D30 -> 0
E31: =B31*D31 -> 0 | G31: =B31*F31 -> 0 | H31: =E31+G31 -> 0
E32: =B32*D32 -> 0 | G32: =B32*F32 -> 0 | H32: =E32+G32 -> 0
E33: =B33*D33 -> 0 | G33: =B33*F33 -> 0 | H33: =E33+G33 -> 0
E34: =B34*D34 -> 0 | G34: =B34*F34 -> 0 | H34: =E34+G34 -> 0
E35: =B35*D35 -> 0 | G35: =B35*F35 -> 0 | H35: =E35+G35 -> 0
A36: TOTAL LABOR/MATERIALS | E36: =SUM(E14:E35) -> 0 | G36: =SUM(G14:G35) -> 0
A37: SUBTOTAL | H37: =E36+G36 -> 0
A38: Sub-Contractor's Overhead | G38: =Summary!G20 -> 0 | H38: =SUM(H37*G38) -> 0
A39: Sub-Contractor's Profit | G39: =Summary!G21 -> 0 | H39: =SUM(H37+H38)*G39 -> 0
A40: FL State Sales Tax | G40: =Summary!G22 -> 0 | H40: =SUM(G36*G40) -> 0
A41: TOTAL | H41: =SUM(H37:H40) -> 0

Sheet Div14
A1: CONSTRUCTION COST ESTIMATE | D1: DATE
D2: =Summary!D2 -> Fill Here
A3: PROJECT | F3: BASIS FOR ESTIMATE
A4: =Summary!A8 -> Upgrade HVAC B8640 | F4: CODE A (No design completed)
A5: LOCATION | F5: CODE B (Preliminary design)
A6: EGLIN AIR FORCE BASE, FLORIDA | F6: CODE C (Final design)
A7: COMPANY | C7: PROJECT NO. | F7: OTHER (Specify)
A8: =Summary!A4 -> Fill Here | C8: =Summary!D9 -> FTFA 23VH26
A9: DRAWING NO. | B9: ESTIMATOR | F9: CHECKED BY
B11: QUANTITY | D11: LABOR | F11: MATERIAL
A12: ITEM DESCRIPTION | B12: NO. UNITS | C12: UNIT MEAS. | D12: PER UNIT | E12: TOTAL | F12: PER UNIT | G12: TOTAL | H12: TOTAL COST
A13: =Summary!B26 -> CONVEYING EQUIPMENT
E14: =B14*D14 -> 0 | G14: =B14*F14 -> 0 | H14: =E14+G14 -> 0
E15: =B15*D15 -> 0 | G15: =B15*F15 -> 0 | H15: =E15+G15 -> 0
E16: =B16*D16 -> 0 | G16: =B16*F16 -> 0 | H16: =E16+G16 -> 0
E17: =B17*D17 -> 0 | G17: =B17*F17 -> 0 | H17: =E17+G17 -> 0
E18: =B18*D18 -> 0 | G18: =B18*F18 -> 0 | H18: =E18+G18 -> 0
E19: =B19*D19 -> 0 | G19: =B19*F19 -> 0 | H19: =E19+G19 -> 0
E20: =B20*D20 -> 0 | G20: =B20*F20 -> 0 | H20: =E20+G20 -> 0
E21: =B21*D21 -> 0 | G21: =B21*F21 -> 0 | H21: =E21+G21 -> 0
E22: =B22*D22 -> 0 | G22: =B22*F22 -> 0 | H22: =E22+G22 -> 0
E23: =B23*D23 -> 0 | G23: =B23*F23 -> 0 | H23: =E23+G23 -> 0
E24: =B24*D24 -> 0 | G24: =B24*F24 -> 0 | H24: =E24+G24 -> 0
E25: =B25*D25 -> 0 | G25: =B25*F25 -> 0 | H25: =E25+G25 -> 0
... E35: =B35*D35 -> 0 | G35: =B35*F35 -> 0 | H35: =E35+G35 -> 0
A36: TOTAL LABOR/MATERIALS | E36: =SUM(E14:E35) -> 0 | G36: =SUM(G14:G35) -> 0
A37: SUBTOTAL | H37: =SUM(H14:H35) -> 0
A38: Sub-Contractor's Overhead | G38: =Summary!G20 -> 0 | H38: =SUM(H37*G38) -> 0
A39: Sub-Contractor's Profit | G39: =Summary!G21 -> 0 | H39: =SUM(H37+H38)*G39 -> 0
A40: FL State Sales Tax | G40: =Summary!G22 -> 0 | H40: =SUM(G36*G40) -> 0
A41: TOTAL | H41: =SUM(H37:H40) -> 0

Sheet Div21
A1: CONSTRUCTION COST ESTIMATE | D1: DATE
D2: =Summary!D2 -> Fill Here
A3: PROJECT | F3: BASIS FOR ESTIMATE
A4: =Summary!A8 -> Upgrade HVAC B8640 | F4: CODE A (No design completed)
A5: LOCATION | F5: CODE B (Preliminary design)
A6: EGLIN AIR FORCE BASE, FLORIDA | F6: CODE C (Final design)
A7: COMPANY | C7: PROJECT NO. | F7: OTHER (Specify)
A8: =Summary!A4 -> Fill Here | D8: =Summary!D9 -> FTFA 23VH26
A9: DRAWING NO. | B9: ESTIMATOR | F9: CHECKED BY
B11: QUANTITY | D11: LABOR | F11: MATERIAL
A12: ITEM DESCRIPTION | B12: NO. UNITS | C12: UNIT MEAS. | D12: PER UNIT | E12: TOTAL | F12: PER UNIT | G12: TOTAL | H12: TOTAL COST
A13: =Summary!B27 -> FIRE SUPRESSION
E14: =B14*D14 -> 0 | G14: =B14*F14 -> 0 | H14: =E14+G14 -> 0
E15: =B15*D15 -> 0 | G15: =B15*F15 -> 0 | H15: =E15+G15 -> 0
E16: =B16*D16 -> 0 | G16: =B16*F16 -> 0 | H16: =E16+G16 -> 0
E17: =B17*D17 -> 0 | G17: =B17*F17 -> 0 | H17: =E17+G17 -> 0
E18: =B18*D18 -> 0 | G18: =B18*F18 -> 0 | H18: =E18+G18 -> 0
E19: =B19*D19 -> 0 | G19: =B19*F19 -> 0 | H19: =E19+G19 -> 0
E20: =B20*D20 -> 0 | G20: =B20*F20 -> 0 | H20: =E20+G20 -> 0
E21: =B21*D21 -> 0 | G21: =B21*F21 -> 0 | H21: =E21+G21 -> 0
E22: =B22*D22 -> 0 | G22: =B22*F22 -> 0 | H22: =E22+G22 -> 0
E23: =B23*D23 -> 0 | G23: =B23*F23 -> 0 | H23: =E23+G23 -> 0
E24: =B24*D24 -> 0 | G24: =B24*F24 -> 0 | H24: =E24+G24 -> 0
E25: =B25*D25 -> 0 | G25: =B25*F25 -> 0 | H25: =E25+G25 -> 0
... E34: =B34*D34 -> 0 | G34: =B34*F34 -> 0 | H34: =E34+G34 -> 0
A35: TOTAL LABOR/MATERIALS | E35: =SUM(E14:E34) -> 0 | G35: =SUM(G14:G34) -> 0
A36: SUBTOTAL | H36: =E35+G35 -> 0
A37: Sub-Contractor's Overhead | G37: =Summary!G20 -> 0 | H37: =SUM(H36*G37) -> 0
A38: Sub-Contractor's Profit | G38: =Summary!G21 -> 0 | H38: =SUM(H36+H37)*G38 -> 0
A39: FL State Sales Tax | G39: =Summary!G22 -> 0 | H39: =SUM(G35*G39) -> 0
A40: TOTAL | H40: =SUM(H36:H39) -> 0

Sheet Div22
A1: CONSTRUCTION COST ESTIMATE | D1: DATE
D2: =Summary!D2 -> Fill Here
A3: PROJECT | F3: BASIS FOR ESTIMATE
A4: =Summary!A8 -> Upgrade HVAC B8640 | F4: CODE A (No design completed)
A5: LOCATION | F5: CODE B (Preliminary design)
A6: EGLIN AIR FORCE BASE, FLORIDA | F6: CODE C (Final design)
A7: COMPANY | C7: PROJECT NO. | F7: OTHER (Specify)
A8: =Summary!A4 -> Fill Here
A9: DRAWING NO. | B9: ESTIMATOR | F9: CHECKED BY
B11: QUANTITY | D11: LABOR | F11: MATERIAL
A12: ITEM DESCRIPTION | B12: NO. UNITS | C12: UNIT MEAS. | D12: PER UNIT | E12: TOTAL | F12: PER UNIT | G12: TOTAL | H12: TOTAL COST
A13: =Summary!B28 -> PLUMBING
E14: =B14*D14 -> 0 | G14: =B14*F14 -> 0 | H14: =E14+G14 -> 0
E15: =B15*D15 -> 0 | G15: =B15*F15 -> 0 | H15: =E15+G15 -> 0
E16: =B16*D16 -> 0 | G16: =B16*F16 -> 0 | H16: =E16+G16 -> 0
E17: =B17*D17 -> 0 | G17: =B17*F17 -> 0 | H17: =E17+G17 -> 0
E18: =B18*D18 -> 0 | G18: =B18*F18 -> 0 | H18: =E18+G18 -> 0
E19: =B19*D19 -> 0 | G19: =B19*F19 -> 0 | H19: =E19+G19 -> 0
E20: =B20*D20 -> 0 | G20: =B20*F20 -> 0 | H20: =E20+G20 -> 0
E21: =B21*D21 -> 0 | G21: =B21*F21 -> 0 | H21: =E21+G21 -> 0
E22: =B22*D22 -> 0 | G22: =B22*F22 -> 0 | H22: =E22+G22 -> 0
E23: =B23*D23 -> 0 | G23: =B23*F23 -> 0 | H23: =E23+G23 -> 0
E24: =B24*D24 -> 0 | G24: =B24*F24 -> 0 | H24: =E24+G24 -> 0
E25: =B25*D25 -> 0 | G25: =B25*F25 -> 0 | H25: =E25+G25 -> 0
... E44: =B44*D44 -> 0 | G44: =B44*F44 -> 0 | H44: =E44+G44 -> 0
A45: TOTAL LABOR/MATERIALS | E45: =SUM(E14:E44) -> 0 | G45: =SUM(G14:G44) -> 0
A46: SUBTOTAL | H46: =SUM(H14:H44) -> 0
A47: Sub-Contractor's Overhead | G47: =Summary!G20 -> 0 | H47: =SUM(H46*G47) -> 0
A48: Sub-Contractor's Profit | G48: =Summary!G21 -> 0 | H48: =SUM(H46+H47)*G48 -> 0
A49: FL State Sales Tax | G49: =Summary!G22 -> 0 | H49: =SUM(G45*G49) -> 0
A50: TOTAL | H50: =SUM(H46:H49) -> 0

Sheet Div23
A1: CONSTRUCTION COST ESTIMATE | D1: DATE
D2: =Summary!D2 -> Fill Here
A3: PROJECT | F3: BASIS FOR ESTIMATE
A4: =Summary!A8 -> Upgrade HVAC B8640 | F4: CODE A (No design completed)
A5: LOCATION | F5: CODE B (Preliminary design)
A6: EGLIN AIR FORCE BASE, FLORIDA | F6: CODE C (Final design)
A7: COMPANY | C7: PROJECT NO. | F7: OTHER (Specify)
A8: =Summary!A4 -> Fill Here
A9: DRAWING NO. | B9: ESTIMATOR | F9: CHECKED BY
B11: QUANTITY | D11: LABOR | F11: MATERIAL
A12: ITEM DESCRIPTION | B12: NO. UNITS | C12: UNIT MEAS. | D12: PER UNIT | E12: TOTAL | F12: PER UNIT | G12: TOTAL | H12: TOTAL COST
A13: =Summary!B29 -> HEATING, VENTILATING AND A/C
E14: =B14*D14 -> 0 | G14: =B14*F14 -> 0 | H14: =E14+G14 -> 0
E15: =B15*D15 -> 0 | G15: =B15*F15 -> 0 | H15: =E15+G15 -> 0
E16: =B16*D16 -> 0 | G16: =B16*F16 -> 0 | H16: =E16+G16 -> 0
E17: =B17*D17 -> 0 | G17: =B17*F17 -> 0 | H17: =E17+G17 -> 0
E18: =B18*D18 -> 0 | G18: =B18*F18 -> 0 | H18: =E18+G18 -> 0
E19: =B19*D19 -> 0 | G19: =B19*F19 -> 0 | H19: =E19+G19 -> 0
E20: =B20*D20 -> 0 | G20: =B20*F20 -> 0 | H20: =E20+G20 -> 0
E21: =B21*D21 -> 0 | G21: =B21*F21 -> 0 | H21: =E21+G21 -> 0
E22: =B22*D22 -> 0 | G22: =B22*F22 -> 0 | H22: =E22+G22 -> 0
E23: =B23*D23 -> 0 | G23: =B23*F23 -> 0 | H23: =E23+G23 -> 0
E24: =B24*D24 -> 0 | G24: =B24*F24 -> 0 | H24: =E24+G24 -> 0
E25: =B25*D25 -> 0 | G25: =B25*F25 -> 0 | H25: =E25+G25 -> 0
... E31: =B31*D31 -> 0 | G31: =B31*F31 -> 0 | H31: =E31+G31 -> 0
A32: TOTAL LABOR/MATERIALS | E32: =SUM(E14:E31) -> 0 | G32: =SUM(G14:G31) -> 0
A33: SUBTOTAL | H33: =SUM(H14:H31) -> 0
A34: Sub-Contractor's Overhead | G34: =Summary!G20 -> 0 | H34: =SUM(H33*G34) -> 0
A35: Sub-Contractor's Profit | G35: =Summary!G21 -> 0 | H35: =SUM(H33+H34)*G35 -> 0
A36: FL State Sales Tax | G36: =Summary!G22 -> 0 | H36: =SUM(G32*G36) -> 0
A37: TOTAL | H37: =SUM(H33:H36) -> 0

Sheet Div25
A1: CONSTRUCTION COST ESTIMATE | D1: DATE
D2: =Summary!D2 -> Fill Here
A3: PROJECT | F3: BASIS FOR ESTIMATE
A4: =Summary!A8 -> Upgrade HVAC B8640 | F4: CODE A (No design completed)
A5: LOCATION | F5: CODE B (Preliminary design)
A6: EGLIN AIR FORCE BASE, FLORIDA | F6: CODE C (Final design)
A7: COMPANY | C7: PROJECT NO. | F7: OTHER (Specify)
A8: =Summary!A4 -> Fill Here
A9: DRAWING NO. | B9: ESTIMATOR | F9: CHECKED BY
B11: QUANTITY | D11: LABOR | F11: MATERIAL
A12: ITEM DESCRIPTION | B12: NO. UNITS | C12: UNIT MEAS. | D12: PER UNIT | E12: TOTAL | F12: PER UNIT | G12: TOTAL | H12: TOTAL COST
A13: =Summary!B30 -> INTEGRATED AUTOMATION
E14: =B14*D14 -> 0 | G14: =B14*F14 -> 0 | H14: =E14+G14 -> 0
E15: =B15*D15 -> 0 | G15: =B15*F15 -> 0 | H15: =E15+G15 -> 0
E16: =B16*D16 -> 0 | G16: =B16*F16 -> 0 | H16: =E16+G16 -> 0
E17: =B17*D17 -> 0 | G17: =B17*F17 -> 0 | H17: =E17+G17 -> 0
E18: =B18*D18 -> 0 | G18: =B18*F18 -> 0 | H18: =E18+G18 -> 0
E19: =B19*D19 -> 0 | G19: =B19*F19 -> 0 | H19: =E19+G19 -> 0
E20: =B20*D20 -> 0 | G20: =B20*F20 -> 0 | H20: =E20+G20 -> 0
E21: =B21*D21 -> 0 | G21: =B21*F21 -> 0 | H21: =E21+G21 -> 0
E22: =B22*D22 -> 0 | G22: =B22*F22 -> 0 | H22: =E22+G22 -> 0
E23: =B23*D23 -> 0 | G23: =B23*F23 -> 0 | H23: =E23+G23 -> 0
E24: =B24*D24 -> 0 | G24: =B24*F24 -> 0 | H24: =E24+G24 -> 0
E25: =B25*D25 -> 0 | G25: =B25*F25 -> 0 | H25: =E25+G25 -> 0
... E31: =B31*D31 -> 0 | G31: =B31*F31 -> 0 | H31: =E31+G31 -> 0
A32: TOTAL LABOR/MATERIALS | E32: =SUM(E14:E31) -> 0 | G32: =SUM(G14:G31) -> 0
A33: SUBTOTAL | H33: =SUM(H14:H31) -> 0
A34: Sub-Contractor's Overhead | G34: =Summary!G20 -> 0 | H34: =SUM(H33*G34) -> 0
A35: Sub-Contractor's Profit | G35: =Summary!G21 -> 0 | H35: =SUM(H33+H34)*G35 -> 0
A36: FL State Sales Tax | G36: =Summary!G22 -> 0 | H36: =G36*G32 -> 0
A37: TOTAL | H37: =SUM(H33:H36) -> 0

Sheet Div26
A1: CONSTRUCTION COST ESTIMATE | D1: DATE
D2: =Summary!D2 -> Fill Here
A3: PROJECT | F3: BASIS FOR ESTIMATE
A4: =Summary!A8 -> Upgrade HVAC B8640 | F4: CODE A (No design completed)
A5: LOCATION | F5: CODE B (Preliminary design)
A6: EGLIN AIR FORCE BASE, FLORIDA | F6: CODE C (Final design)
A7: COMPANY | C7: PROJECT NO. | F7: OTHER (Specify)
A8: =Summary!A4 -> Fill Here | D8: =Summary!D9 -> FTFA 23VH26
A9: DRAWING NO. | B9: ESTIMATOR | F9: CHECKED BY
B11: QUANTITY | D11: LABOR | F11: MATERIAL
A12: ITEM DESCRIPTION | B12: NO. UNITS | C12: UNIT MEAS. | D12: PER UNIT | E12: TOTAL | F12: PER UNIT | G12: TOTAL | H12: TOTAL COST
A13: =Summary!B31 -> ELECTRICAL
E14: =B14*D14 -> 0 | G14: =B14*F14 -> 0 | H14: =E14+G14 -> 0
E15: =B15*D15 -> 0 | G15: =B15*F15 -> 0 | H15: =E15+G15 -> 0
E16: =B16*D16 -> 0 | G16: =B16*F16 -> 0 | H16: =E16+G16 -> 0
E17: =B17*D17 -> 0 | G17: =B17*F17 -> 0 | H17: =E17+G17 -> 0
E18: =B18*D18 -> 0 | G18: =B18*F18 -> 0 | H18: =E18+G18 -> 0
E19: =B19*D19 -> 0 | G19: =B19*F19 -> 0 | H19: =E19+G19 -> 0
E20: =B20*D20 -> 0 | G20: =B20*F20 -> 0 | H20: =E20+G20 -> 0
E21: =B21*D21 -> 0 | G21: =B21*F21 -> 0 | H21: =E21+G21 -> 0
E22: =B22*D22 -> 0 | G22: =B22*F22 -> 0 | H22: =E22+G22 -> 0
E23: =B23*D23 -> 0 | G23: =B23*F23 -> 0 | H23: =E23+G23 -> 0
E24: =B24*D24 -> 0 | G24: =B24*F24 -> 0 | H24: =E24+G24 -> 0
E25: =B25*D25 -> 0 | G25: =B25*F25 -> 0 | H25: =E25+G25 -> 0
... E50: =B50*D50 -> 0 | G50: =B50*F50 -> 0 | H50: =E50+G50 -> 0
A51: TOTAL LABOR/MATERIALS | E51: =SUM(E14:E36) -> 0 | G51: =SUM(G14:G36) -> 0
A52: SUBTOTAL | H52: =SUM(E51:G51) -> 0
A53: Sub-Contractor's Overhead | G53: =Summary!G20 -> 0 | H53: =SUM(H52*G53) -> 0
A54: Sub-Contractor's Profit | G54: =Summary!G21 -> 0 | H54: =SUM(H52+H53)*G54 -> 0
A55: FL State Sales Tax | G55: =Summary!G22 -> 0 | H55: =SUM(G51*G55) -> 0
A56: TOTAL | H56: =SUM(H52:H55) -> 0

Sheet Div27
A1: CONSTRUCTION COST ESTIMATE | D1: DATE
D2: =Summary!D2 -> Fill Here
A3: PROJECT | F3: BASIS FOR ESTIMATE
A4: =Summary!A8 -> Upgrade HVAC B8640 | F4: CODE A (No design completed)
A5: LOCATION | F5: CODE B (Preliminary design)
A6: EGLIN AIR FORCE BASE, FLORIDA | F6: CODE C (Final design)
A7: COMPANY | C7: PROJECT NO. | F7: OTHER (Specify)
A8: =Summary!A4 -> Fill Here | D8: =Summary!D9 -> FTFA 23VH26
A9: DRAWING NO. | B9: ESTIMATOR | F9: CHECKED BY
B11: QUANTITY | D11: LABOR | F11: MATERIAL
A12: ITEM DESCRIPTION | B12: NO. UNITS | C12: UNIT MEAS. | D12: PER UNIT | E12: TOTAL | F12: PER UNIT | G12: TOTAL | H12: TOTAL COST
A13: =Summary!B32 -> COMMUNICATIONS
E14: =B14*D14 -> 0 | G14: =B14*F14 -> 0 | H14: =E14+G14 -> 0
E15: =B15*D15 -> 0 | G15: =B15*F15 -> 0 | H15: =E15+G15 -> 0
E16: =B16*D16 -> 0 | G16: =B16*F16 -> 0 | H16: =E16+G16 -> 0
E17: =B17*D17 -> 0 | G17: =B17*F17 -> 0 | H17: =E17+G17 -> 0
E18: =B18*D18 -> 0 | G18: =B18*F18 -> 0 | H18: =E18+G18 -> 0
E19: =B19*D19 -> 0 | G19: =B19*F19 -> 0 | H19: =E19+G19 -> 0
E20: =B20*D20 -> 0 | G20: =B20*F20 -> 0 | H20: =E20+G20 -> 0
E21: =B21*D21 -> 0 | G21: =B21*F21 -> 0 | H21: =E21+G21 -> 0
E22: =B22*D22 -> 0 | G22: =B22*F22 -> 0 | H22: =E22+G22 -> 0
E23: =B23*D23 -> 0 | G23: =B23*F23 -> 0 | H23: =E23+G23 -> 0
E24: =B24*D24 -> 0 | G24: =B24*F24 -> 0 | H24: =E24+G24 -> 0
E25: =B25*D25 -> 0 | G25: =B25*F25 -> 0 | H25: =E25+G25 -> 0
... E33: =B33*D33 -> 0 | G33: =B33*F33 -> 0 | H33: =E33+G33 -> 0
A34: TOTAL LABOR/MATERIALS | E34: =SUM(E14:E33) -> 0 | G34: =SUM(G14:G33) -> 0
A35: SUBTOTAL | H35: =E34+G34 -> 0
A36: Sub-Contractor's Overhead | G36: =Summary!G20 -> 0 | H36: =SUM(H35*G36) -> 0
A37: Sub-Contractor's Profit | G37: =Summary!G21 -> 0 | H37: =SUM(H35+H36)*G37 -> 0
A38: FL State Sales Tax | G38: =Summary!G22 -> 0 | H38: =SUM(G34*G38) -> 0
A39: TOTAL | H39: =SUM(H35:H38) -> 0

Sheet Div28
A1: CONSTRUCTION COST ESTIMATE | D1: DATE
D2: =Summary!D2 -> Fill Here
A3: PROJECT | F3: BASIS FOR ESTIMATE
A4: =Summary!A8 -> Upgrade HVAC B8640 | F4: CODE A (No design completed)
A5: LOCATION | F5: CODE B (Preliminary design)
A6: EGLIN AIR FORCE BASE, FLORIDA | F6: CODE C (Final design)
A7: COMPANY | C7: PROJECT NO. | F7: OTHER (Specify)
A8: =Summary!A4 -> Fill Here | D8: =Summary!D9 -> FTFA 23VH26
A9: DRAWING NO. | B9: ESTIMATOR | F9: CHECKED BY
B11: QUANTITY | D11: LABOR | F11: MATERIAL
A12: ITEM DESCRIPTION | B12: NO. UNITS | C12: UNIT MEAS. | D12: PER UNIT | E12: TOTAL | F12: PER UNIT | G12: TOTAL | H12: TOTAL COST
A13: =Summary!B33 -> ELECTRONIC SAFETY AND SECURITY
E14: =B14*D14 -> 0 | G14: =B14*F14 -> 0 | H14: =E14+G14 -> 0
E15: =B15*D15 -> 0 | G15: =B15*F15 -> 0 | H15: =E15+G15 -> 0
E16: =B16*D16 -> 0 | G16: =B16*F16 -> 0 | H16: =E16+G16 -> 0
E17: =B17*D17 -> 0 | G17: =B17*F17 -> 0 | H17: =E17+G17 -> 0
E18: =B18*D18 -> 0 | G18: =B18*F18 -> 0 | H18: =E18+G18 -> 0
E19: =B19*D19 -> 0 | G19: =B19*F19 -> 0 | H19: =E19+G19 -> 0
E20: =B20*D20 -> 0 | G20: =B20*F20 -> 0 | H20: =E20+G20 -> 0
E21: =B21*D21 -> 0 | G21: =B21*F21 -> 0 | H21: =E21+G21 -> 0
E22: =B22*D22 -> 0 | G22: =B22*F22 -> 0 | H22: =E22+G22 -> 0
E23: =B23*D23 -> 0 | G23: =B23*F23 -> 0 | H23: =E23+G23 -> 0
E24: =B24*D24 -> 0 | G24: =B24*F24 -> 0 | H24: =E24+G24 -> 0
E25: =B25*D25 -> 0 | G25: =B25*F25 -> 0 | H25: =E25+G25 -> 0
... E32: =B32*D32 -> 0 | G32: =B32*F32 -> 0 | H32: =E32+G32 -> 0
A33: TOTAL LABOR/MATERIALS | E33: =SUM(E14:E32) -> 0 | G33: =SUM(G14:G32) -> 0
A34: SUBTOTAL | H34: =E33+G33 -> 0
A35: Sub-Contractor's Overhead | G35: =Summary!G20 -> 0 | H35: =SUM(H34*G35) -> 0
A36: Sub-Contractor's Profit | G36: =Summary!G21 -> 0 | H36: =SUM(H34+H35)*G36 -> 0
A37: FL State Sales Tax | G37: =Summary!G22 -> 0 | H37: =SUM(G33*G37) -> 0
A38: TOTAL | H38: =SUM(H34:H37) -> 0

Sheet Div31
A1: CONSTRUCTION COST ESTIMATE | D1: DATE
D2: =Summary!D2 -> Fill Here
A3: PROJECT | F3: BASIS FOR ESTIMATE
A4: =Summary!A8 -> Upgrade HVAC B8640 | F4: CODE A (No design completed)
A5: LOCATION | F5: CODE B (Preliminary design)
A6: EGLIN AIR FORCE BASE, FLORIDA | F6: CODE C (Final design)
A7: COMPANY | C7: PROJECT NO. | F7: OTHER (Specify)
A8: =Summary!A4 -> Fill Here | D8: =Summary!D9 -> FTFA 23VH26
A9: DRAWING NO. | B9: ESTIMATOR | F9: CHECKED BY
B11: QUANTITY | D11: LABOR | F11: MATERIAL
A12: ITEM DESCRIPTION | B12: NO. UNITS | C12: UNIT MEAS. | D12: PER UNIT | E12: TOTAL | F12: PER UNIT | G12: TOTAL | H12: TOTAL COST
A13: =Summary!B34 -> EARTHWORK
E14: =B14*D14 -> 0 | G14: =B14*F14 -> 0 | H14: =E14+G14 -> 0
E15: =B15*D15 -> 0 | G15: =B15*F15 -> 0 | H15: =E15+G15 -> 0
E16: =B16*D16 -> 0 | G16: =B16*F16 -> 0 | H16: =E16+G16 -> 0
E17: =B17*D17 -> 0 | G17: =B17*F17 -> 0 | H17: =E17+G17 -> 0
E18: =B18*D18 -> 0 | G18: =B18*F18 -> 0 | H18: =E18+G18 -> 0
E19: =B19*D19 -> 0 | G19: =B19*F19 -> 0 | H19: =E19+G19 -> 0
E20: =B20*D20 -> 0 | G20: =B20*F20 -> 0 | H20: =E20+G20 -> 0
E21: =B21*D21 -> 0 | G21: =B21*F21 -> 0 | H21: =E21+G21 -> 0
E22: =B22*D22 -> 0 | G22: =B22*F22 -> 0 | H22: =E22+G22 -> 0
E23: =B23*D23 -> 0 | G23: =B23*F23 -> 0 | H23: =E23+G23 -> 0
E24: =B24*D24 -> 0 | G24: =B24*F24 -> 0 | H24: =E24+G24 -> 0
E25: =B25*D25 -> 0 | G25: =B25*F25 -> 0 | H25: =E25+G25 -> 0
... E55: =B55*D55 -> 0 | G55: =B55*F55 -> 0 | H55: =E55+G55 -> 0
A56: TOTAL LABOR/MATERIALS | E56: =SUM(E14:E29) -> 0 | G56: =SUM(G14:G29) -> 0
A57: SUBTOTAL | H57: =SUM(E56:G56) -> 0
A58: Sub-Contractor's Overhead | G58: =Summary!G20 -> 0 | H58: =SUM(H57*G58) -> 0
A59: Sub-Contractor's Profit | G59: =Summary!G21 -> 0 | H59: =SUM(H57+H58)*G59 -> 0
A60: FL State Sales Tax | G60: =Summary!G22 -> 0 | H60: =SUM(G56*G60) -> 0
A61: TOTAL | H61: =SUM(H57:H60) -> 0

Sheet Div32
A1: CONSTRUCTION COST ESTIMATE | D1: DATE
D2: =Summary!D2 -> Fill Here
A3: PROJECT | F3: BASIS FOR ESTIMATE
A4: =Summary!A8 -> Upgrade HVAC B8640 | F4: CODE A (No design completed)
A5: LOCATION | F5: CODE B (Preliminary design)
A6: EGLIN AIR FORCE BASE, FLORIDA | F6: CODE C (Final design)
A7: COMPANY | C7: PROJECT NO. | F7: OTHER (Specify)
A8: =Summary!A4 -> Fill Here | D8: =Summary!D9 -> FTFA 23VH26
A9: DRAWING NO. | B9: ESTIMATOR | F9: CHECKED BY
B11: QUANTITY | D11: LABOR | F11: MATERIAL
A12: ITEM DESCRIPTION | B12: NO. UNITS | C12: UNIT MEAS. | D12: PER UNIT | E12: TOTAL | F12: PER UNIT | G12: TOTAL | H12: TOTAL COST
A13: =Summary!B35 -> EXTERIOR IMPROVEMENTS
E14: =B14*D14 -> 0 | G14: =B14*F14 -> 0 | H14: =E14+G14 -> 0
E15: =B15*D15 -> 0 | G15: =B15*F15 -> 0 | H15: =E15+G15 -> 0
E16: =B16*D16 -> 0 | G16: =B16*F16 -> 0 | H16: =E16+G16 -> 0
E17: =B17*D17 -> 0 | G17: =B17*F17 -> 0 | H17: =E17+G17 -> 0
E18: =B18*D18 -> 0 | G18: =B18*F18 -> 0 | H18: =E18+G18 -> 0
E19: =B19*D19 -> 0 | G19: =B19*F19 -> 0 | H19: =E19+G19 -> 0
E20: =B20*D20 -> 0 | G20: =B20*F20 -> 0 | H20: =E20+G20 -> 0
E21: =B21*D21 -> 0 | G21: =B21*F21 -> 0 | H21: =E21+G21 -> 0
E22: =B22*D22 -> 0 | G22: =B22*F22 -> 0 | H22: =E22+G22 -> 0
E23: =B23*D23 -> 0 | G23: =B23*F23 -> 0 | H23: =E23+G23 -> 0
E24: =B24*D24 -> 0 | G24: =B24*F24 -> 0 | H24: =E24+G24 -> 0
E25: =B25*D25 -> 0 | G25: =B25*F25 -> 0 | H25: =E25+G25 -> 0
... E29: =B29*D29 -> 0 | G29: =B29*F29 -> 0 | H29: =E29+G29 -> 0
A30: TOTAL LABOR/MATERIALS | E30: =SUM(E14:E29) -> 0 | G30: =SUM(G14:G29) -> 0
A31: SUBTOTAL | H31: =E30+G30 -> 0
A32: Sub-Contractor's Overhead | G32: =Summary!G20 -> 0 | H32: =SUM(H31*G32) -> 0
A33: Sub-Contractor's Profit | G33: =Summary!G21 -> 0 | H33: =SUM(H31+H32)*G33 -> 0
A34: FL State Sales Tax | G34: =Summary!G22 -> 0 | H34: =SUM(G30*G34) -> 0
A35: TOTAL | H35: =SUM(H31:H34) -> 0

Sheet Div33
A1: CONSTRUCTION COST ESTIMATE | D1: DATE
D2: =Summary!D2 -> Fill Here
A3: PROJECT | F3: BASIS FOR ESTIMATE
A4: =Summary!A8 -> Upgrade HVAC B8640 | F4: CODE A (No design completed)
A5: LOCATION | F5: CODE B (Preliminary design)
A6: EGLIN AIR FORCE BASE, FLORIDA | F6: CODE C (Final design)
A7: COMPANY | C7: PROJECT NO. | F7: OTHER (Specify)
A8: =Summary!A4 -> Fill Here | D8: =Summary!D9 -> FTFA 23VH26
A9: DRAWING NO. | B9: ESTIMATOR | F9: CHECKED BY
B11: QUANTITY | D11: LABOR | F11: MATERIAL
A12: ITEM DESCRIPTION | B12: NO. UNITS | C12: UNIT MEAS. | D12: PER UNIT | E12: TOTAL | F12: PER UNIT | G12: TOTAL | H12: TOTAL COST
A13: =Summary!B36 -> UTILITIES
E14: =B14*D14 -> 0 | G14: =B14*F14 -> 0 | H14: =E14+G14 -> 0
E15: =B15*D15 -> 0 | G15: =B15*F15 -> 0 | H15: =E15+G15 -> 0
E16: =B16*D16 -> 0 | G16: =B16*F16 -> 0 | H16: =E16+G16 -> 0
E17: =B17*D17 -> 0 | G17: =B17*F17 -> 0 | H17: =E17+G17 -> 0
E18: =B18*D18 -> 0 | G18: =B18*F18 -> 0 | H18: =E18+G18 -> 0
E19: =B19*D19 -> 0 | G19: =B19*F19 -> 0 | H19: =E19+G19 -> 0
E20: =B20*D20 -> 0 | G20: =B20*F20 -> 0 | H20: =E20+G20 -> 0
E21: =B21*D21 -> 0 | G21: =B21*F21 -> 0 | H21: =E21+G21 -> 0
E22: =B22*D22 -> 0 | G22: =B22*F22 -> 0 | H22: =E22+G22 -> 0
E23: =B23*D23 -> 0 | G23: =B23*F23 -> 0 | H23: =E23+G23 -> 0
E24: =B24*D24 -> 0 | G24: =B24*F24 -> 0 | H24: =E24+G24 -> 0
E25: =B25*D25 -> 0 | G25: =B25*F25 -> 0 | H25: =E25+G25 -> 0
A26: TOTAL LABOR/MATERIALS | E26: =SUM(E14:E25) -> 0 | G26: =SUM(G14:G25) -> 0
A27: SUBTOTAL | H27: =E26+G26 -> 0
A28: Sub-Contractor's Overhead | G28: =Summary!G20 -> 0 | H28: =SUM(H27*G28) -> 0
A29: Sub-Contractor's Profit | G29: =Summary!G21 -> 0 | H29: =SUM(H27+H28)*G29 -> 0
A30: FL State Sales Tax | G30: =Summary!G22 -> 0 | H30: =SUM(G26*G30) -> 0
A31: TOTAL | H31: =SUM(H27:H30) -> 0

Sheet Div34
A1: CONSTRUCTION COST ESTIMATE | D1: DATE
D2: =Summary!D2 -> Fill Here
A3: PROJECT | F3: BASIS FOR ESTIMATE
A4: =Summary!A8 -> Upgrade HVAC B8640 | F4: CODE A (No design completed)
A5: LOCATION | F5: CODE B (Preliminary design)
A6: EGLIN AIR FORCE BASE, FLORIDA | F6: CODE C (Final design)
A7: COMPANY | C7: PROJECT NO. | F7: OTHER (Specify)
A8: =Summary!A4 -> Fill Here
A9: DRAWING NO. | B9: ESTIMATOR | F9: CHECKED BY
B11: QUANTITY | D11: LABOR | F11: MATERIAL
A12: ITEM DESCRIPTION | B12: NO. UNITS | C12: UNIT MEAS. | D12: PER UNIT | E12: TOTAL | F12: PER UNIT | G12: TOTAL | H12: TOTAL COST
A13: =Summary!B37 -> TRANSPORTATION
E14: =B14*D14 -> 0 | G14: =B14*F14 -> 0 | H14: =E14+G14 -> 0
E15: =B15*D15 -> 0 | G15: =B15*F15 -> 0 | H15: =E15+G15 -> 0
E16: =B16*D16 -> 0 | G16: =B16*F16 -> 0 | H16: =E16+G16 -> 0
E17: =B17*D17 -> 0 | G17: =B17*F17 -> 0 | H17: =E17+G17 -> 0
E18: =B18*D18 -> 0 | G18: =B18*F18 -> 0 | H18: =E18+G18 -> 0
E19: =B19*D19 -> 0 | G19: =B19*F19 -> 0 | H19: =E19+G19 -> 0
E20: =B20*D20 -> 0 | G20: =B20*F20 -> 0 | H20: =E20+G20 -> 0
E21: =B21*D21 -> 0 | G21: =B21*F21 -> 0 | H21: =E21+G21 -> 0
E22: =B22*D22 -> 0 | G22: =B22*F22 -> 0 | H22: =E22+G22 -> 0
E23: =B23*D23 -> 0 | G23: =B23*F23 -> 0 | H23: =E23+G23 -> 0
E24: =B24*D24 -> 0 | G24: =B24*F24 -> 0 | H24: =E24+G24 -> 0
E25: =B25*D25 -> 0 | G25: =B25*F25 -> 0 | H25: =E25+G25 -> 0
... E32: =B32*D32 -> 0 | G32: =B32*F32 -> 0 | H32: =E32+G32 -> 0
A33: TOTAL LABOR/MATERIALS | E33: =SUM(E14:E32) -> 0 | G33: =SUM(G14:G32) -> 0
A34: SUBTOTAL | H34: =SUM(H14:H32) -> 0
A35: Sub-Contractor's Overhead | G35: =Summary!G20 -> 0 | H35: =SUM(H34*G35) -> 0
A36: Sub-Contractor's Profit | G36: =Summary!G21 -> 0 | H36: =SUM(H34+H35)*G36 -> 0
A37: FL State Sales Tax | G37: =Summary!G22 -> 0 | H37: =SUM(G33*G37) -> 0
A38: TOTAL | H38: =SUM(H34:H37) -> 0

Sheet Div35
A1: CONSTRUCTION COST ESTIMATE | D1: DATE
D2: =Summary!D2 -> Fill Here
A3: PROJECT | F3: BASIS FOR ESTIMATE
A4: =Summary!A8 -> Upgrade HVAC B8640 | F4: CODE A (No design completed)
A5: LOCATION | F5: CODE B (Preliminary design)
A6: EGLIN AIR FORCE BASE, FLORIDA | F6: CODE C (Final design)
A7: COMPANY | C7: PROJECT NO. | F7: OTHER (Specify)
A8: =Summary!A4 -> Fill Here
A9: DRAWING NO. | B9: ESTIMATOR | F9: CHECKED BY
B11: QUANTITY | D11: LABOR | F11: MATERIAL
A12: ITEM DESCRIPTION | B12: NO. UNITS | C12: UNIT MEAS. | D12: PER UNIT | E12: TOTAL | F12: PER UNIT | G12: TOTAL | H12: TOTAL COST
A13: =Summary!B38 -> WATERWAYS AND MARINE CONSTRUCTION
E14: =B14*D14 -> 0 | G14: =B14*F14 -> 0 | H14: =E14+G14 -> 0
E15: =B15*D15 -> 0 | G15: =B15*F15 -> 0 | H15: =E15+G15 -> 0
E16: =B16*D16 -> 0 | G16: =B16*F16 -> 0 | H16: =E16+G16 -> 0
E17: =B17*D17 -> 0 | G17: =B17*F17 -> 0 | H17: =E17+G17 -> 0
E18: =B18*D18 -> 0 | G18: =B18*F18 -> 0 | H18: =E18+G18 -> 0
E19: =B19*D19 -> 0 | G19: =B19*F19 -> 0 | H19: =E19+G19 -> 0
E20: =B20*D20 -> 0 | G20: =B20*F20 -> 0 | H20: =E20+G20 -> 0
E21: =B21*D21 -> 0 | G21: =B21*F21 -> 0 | H21: =E21+G21 -> 0
E22: =B22*D22 -> 0 | G22: =B22*F22 -> 0 | H22: =E22+G22 -> 0
E23: =B23*D23 -> 0 | G23: =B23*F23 -> 0 | H23: =E23+G23 -> 0
E24: =B24*D24 -> 0 | G24: =B24*F24 -> 0 | H24: =E24+G24 -> 0
E25: =B25*D25 -> 0 | G25: =B25*F25 -> 0 | H25: =E25+G25 -> 0
... E32: =B32*D32 -> 0 | G32: =B32*F32 -> 0 | H32: =E32+G32 -> 0
A33: TOTAL LABOR/MATERIALS | E33: =SUM(E14:E32) -> 0 | G33: =SUM(G14:G32) -> 0
A34: SUBTOTAL | H34: =SUM(H14:H32) -> 0
A35: Sub-Contractor's Overhead | G35: =Summary!G20 -> 0 | H35: =SUM(H34*G35) -> 0
A36: Sub-Contractor's Profit | G36: =Summary!G21 -> 0 | H36: =SUM(H34+H35)*G36 -> 0
A37: FL State Sales Tax | G37: =Summary!G22 -> 0 | H37: =SUM(G33*G37) -> 0
A38: TOTAL | H38: =SUM(H34:H37) -> 0

Sheet Div40
A1: CONSTRUCTION COST ESTIMATE | D1: DATE
D2: =Summary!D2 -> Fill Here
A3: PROJECT | F3: BASIS FOR ESTIMATE
A4: =Summary!A8 -> Upgrade HVAC B8640 | F4: CODE A (No design completed)
A5: LOCATION | F5: CODE B (Preliminary design)
A6: EGLIN AIR FORCE BASE, FLORIDA | F6: CODE C (Final design)
A7: COMPANY | C7: PROJECT NO. | F7: OTHER (Specify)
A8: =Summary!A4 -> Fill Here | D8: =Summary!D9 -> FTFA 23VH26
A9: DRAWING NO. | B9: ESTIMATOR | F9: CHECKED BY
B11: QUANTITY | D11: LABOR | F11: MATERIAL
A12: ITEM DESCRIPTION | B12: NO. UNITS | C12: UNIT MEAS. | D12: PER UNIT | E12: TOTAL | F12: PER UNIT | G12: TOTAL | H12: TOTAL COST
A13: =Summary!B40 -> MATERIAL PROCESING AND HANDLING EQUIPMENT
E14: =B14*D14 -> 0 | G14: =B14*F14 -> 0 | H14: =E14+G14 -> 0
E15: =B15*D15 -> 0 | G15: =B15*F15 -> 0 | H15: =E15+G15 -> 0
E16: =B16*D16 -> 0 | G16: =B16*F16 -> 0 | H16: =E16+G16 -> 0
E17: =B17*D17 -> 0 | G17: =B17*F17 -> 0 | H17: =E17+G17 -> 0
E18: =B18*D18 -> 0 | G18: =B18*F18 -> 0 | H18: =E18+G18 -> 0
E19: =B19*D19 -> 0 | G19: =B19*F19 -> 0 | H19: =E19+G19 -> 0
E20: =B20*D20 -> 0 | G20: =B20*F20 -> 0 | H20: =E20+G20 -> 0
E21: =B21*D21 -> 0 | G21: =B21*F21 -> 0 | H21: =E21+G21 -> 0
E22: =B22*D22 -> 0 | G22: =B22*F22 -> 0 | H22: =E22+G22 -> 0
E23: =B23*D23 -> 0 | G23: =B23*F23 -> 0 | H23: =E23+G23 -> 0
E24: =B24*D24 -> 0 | G24: =B24*F24 -> 0 | H24: =E24+G24 -> 0
E25: =B25*D25 -> 0 | G25: =B25*F25 -> 0 | H25: =E25+G25 -> 0
... E30: =B30*D30 -> 0 | G30: =B30*F30 -> 0 | H30: =E30+G30 -> 0
A31: TOTAL LABOR/MATERIALS | E31: =SUM(E14:E30) -> 0 | G31: =SUM(G14:G30) -> 0
A32: SUBTOTAL | H32: =E31+G31 -> 0
A33: Sub-Contractor's Overhead | G33: =Summary!G20 -> 0 | H33: =SUM(H32*G33) -> 0
A34: Sub-Contractor's Profit | G34: =Summary!G21 -> 0 | H34: =SUM(H32+H33)*G34 -> 0
A35: FL State Sales Tax | G35: =Summary!G22 -> 0 | H35: =SUM(G31*G35) -> 0
A36: TOTAL | H36: =SUM(H32:H35) -> 0

Sheet Div41
A1: CONSTRUCTION COST ESTIMATE | D1: DATE
D2: =Summary!D2 -> Fill Here
A3: PROJECT | F3: BASIS FOR ESTIMATE
A4: =Summary!A8 -> Upgrade HVAC B8640 | F4: CODE A (No design completed)
A5: LOCATION | F5: CODE B (Preliminary design)
A6: EGLIN AIR FORCE BASE, FLORIDA | F6: CODE C (Final design)
A7: COMPANY | C7: PROJECT NO. | F7: OTHER (Specify)
A8: =Summary!A4 -> Fill Here | D8: =Summary!D9 -> FTFA 23VH26
A9: DRAWING NO. | B9: ESTIMATOR | F9: CHECKED BY
B11: QUANTITY | D11: LABOR | F11: MATERIAL
A12: ITEM DESCRIPTION | B12: NO. UNITS | C12: UNIT MEAS. | D12: PER UNIT | E12: TOTAL | F12: PER UNIT | G12: TOTAL | H12: TOTAL COST
A13: =Summary!B40 -> MATERIAL PROCESING AND HANDLING EQUIPMENT
E14: =B14*D14 -> 0 | G14: =B14*F14 -> 0 | H14: =E14+G14 -> 0
E15: =B15*D15 -> 0 | G15: =B15*F15 -> 0 | H15: =E15+G15 -> 0
E16: =B16*D16 -> 0 | G16: =B16*F16 -> 0 | H16: =E16+G16 -> 0
E17: =B17*D17 -> 0 | G17: =B17*F17 -> 0 | H17: =E17+G17 -> 0
E18: =B18*D18 -> 0 | G18: =B18*F18 -> 0 | H18: =E18+G18 -> 0
E19: =B19*D19 -> 0 | G19: =B19*F19 -> 0 | H19: =E19+G19 -> 0
E20: =B20*D20 -> 0 | G20: =B20*F20 -> 0 | H20: =E20+G20 -> 0
E21: =B21*D21 -> 0 | G21: =B21*F21 -> 0 | H21: =E21+G21 -> 0
E22: =B22*D22 -> 0 | G22: =B22*F22 -> 0 | H22: =E22+G22 -> 0
E23: =B23*D23 -> 0 | G23: =B23*F23 -> 0 | H23: =E23+G23 -> 0
E24: =B24*D24 -> 0 | G24: =B24*F24 -> 0 | H24: =E24+G24 -> 0
E25: =B25*D25 -> 0 | G25: =B25*F25 -> 0 | H25: =E25+G25 -> 0
... E33: =B33*D33 -> 0 | G33: =B33*F33 -> 0 | H33: =E33+G33 -> 0
A34: TOTAL LABOR/MATERIALS | E34: =SUM(E14:E33) -> 0 | G34: =SUM(G14:G33) -> 0
A35: SUBTOTAL | H35: =E34+G34 -> 0
A36: Sub-Contractor's Overhead | G36: =Summary!G20 -> 0 | H36: =SUM(H35*G36) -> 0
A37: Sub-Contractor's Profit | G37: =Summary!G21 -> 0 | H37: =SUM(H35+H36)*G37 -> 0
A38: FL State Sales Tax | G38: =Summary!G22 -> 0 | H38: =SUM(G34*G38) -> 0
A39: TOTAL | H39: =SUM(H35:H38) -> 0

Sheet Div42
A1: CONSTRUCTION COST ESTIMATE | D1: DATE
D2: =Summary!D2 -> Fill Here
A3: PROJECT | F3: BASIS FOR ESTIMATE
A4: =Summary!A8 -> Upgrade HVAC B8640 | F4: CODE A (No design completed)
A5: LOCATION | F5: CODE B (Preliminary design)
A6: EGLIN AIR FORCE BASE, FLORIDA | F6: CODE C (Final design)
A7: COMPANY | C7: PROJECT NO. | F7: OTHER (Specify)
A8: =Summary!A4 -> Fill Here
A9: DRAWING NO. | B9: ESTIMATOR | F9: CHECKED BY
B11: QUANTITY | D11: LABOR | F11: MATERIAL
A12: ITEM DESCRIPTION | B12: NO. UNITS | C12: UNIT MEAS. | D12: PER UNIT | E12: TOTAL | F12: PER UNIT | G12: TOTAL | H12: TOTAL COST
A13: =Summary!B41 -> PROCESS HEATING, COOLING AND DRYING EQUIPMENT
E14: =B14*D14 -> 0 | G14: =B14*F14 -> 0 | H14: =E14+G14 -> 0
E15: =B15*D15 -> 0 | G15: =B15*F15 -> 0 | H15: =E15+G15 -> 0
E16: =B16*D16 -> 0 | G16: =B16*F16 -> 0 | H16: =E16+G16 -> 0
E17: =B17*D17 -> 0 | G17: =B17*F17 -> 0 | H17: =E17+G17 -> 0
E18: =B18*D18 -> 0 | G18: =B18*F18 -> 0 | H18: =E18+G18 -> 0
E19: =B19*D19 -> 0 | G19: =B19*F19 -> 0 | H19: =E19+G19 -> 0
E20: =B20*D20 -> 0 | G20: =B20*F20 -> 0 | H20: =E20+G20 -> 0
E21: =B21*D21 -> 0 | G21: =B21*F21 -> 0 | H21: =E21+G21 -> 0
E22: =B22*D22 -> 0 | G22: =B22*F22 -> 0 | H22: =E22+G22 -> 0
E23: =B23*D23 -> 0 | G23: =B23*F23 -> 0 | H23: =E23+G23 -> 0
E24: =B24*D24 -> 0 | G24: =B24*F24 -> 0 | H24: =E24+G24 -> 0
E25: =B25*D25 -> 0 | G25: =B25*F25 -> 0 | H25: =E25+G25 -> 0
... E30: =B30*D30 -> 0 | G30: =B30*F30 -> 0 | H30: =E30+G30 -> 0
A31: TOTAL LABOR/MATERIALS | E31: =SUM(E14:E30) -> 0 | G31: =SUM(G14:G30) -> 0
A32: SUBTOTAL | H32: =SUM(H14:H30) -> 0
A33: Sub-Contractor's Overhead | G33: =Summary!G20 -> 0 | H33: =SUM(H32*G33) -> 0
A34: Sub-Contractor's Profit | G34: =Summary!G21 -> 0 | H34: =SUM(H32+H33)*G34 -> 0
A35: FL State Sales Tax | G35: =Summary!G22 -> 0 | H35: =SUM(G31*G35) -> 0
A36: TOTAL | H36: =SUM(H32:H35) -> 0

Sheet Div43
A1: CONSTRUCTION COST ESTIMATE | D1: DATE
D2: =Summary!D2 -> Fill Here
A3: PROJECT | F3: BASIS FOR ESTIMATE
A4: =Summary!A8 -> Upgrade HVAC B8640 | F4: CODE A (No design completed)
A5: LOCATION | F5: CODE B (Preliminary design)
A6: EGLIN AIR FORCE BASE, FLORIDA | F6: CODE C (Final design)
A7: COMPANY | C7: PROJECT NO. | F7: OTHER (Specify)
A8: =Summary!A4 -> Fill Here
A9: DRAWING NO. | B9: ESTIMATOR | F9: CHECKED BY
