Workbook

Sheet Instructions
A1: ATTACHMENT 1 TEMPLATE - 06/06/25
A2: Preparation of the Attachment 1 prior to RFQ If there are multiple buildings, see instructions below.
A3: 1 | B3: In the A column, Select SAM buy or GSA buy. If SAM buy, Hide the two columns that are purple at the top and hide the last two rows of notes at the bottom that refer to GSA. | D3: Types of Delivery
A4: 2 | B4: In the FID, Highlight the entire Table of Contents and Copy. | D4: Installation of furniture - to include any GFP in the SOW, if applicable | E4: Vendor Install all items on Att 1. GFP is Government Furnished Products (usually items in warehouse).
A5: 3 | B5: In the Prep Tab (in this form), highlight upper left cell and Paste by right clicking on your mouse and using the second Paste option (Match Destination Formatting (M)). | D5: Shipping (CONUS) Note 1 | E5: Shipping in the continental US
A6: 4 | B6: In the Prep Tab, Delete Column C. | D6: Commercial Shipping (OCONUS) | E6: Commercial shipping to locations outside of the continental US.
A7: 5 | B7: In the Prep Tab, Delete all rows that you do not want in the Attachment 1 (extra lines, titles, "Not Used"). Keep only items you want listed in the Attachment 1. | D7: Secure Shipping (CONUS/OCONUS) - Refer to SOW | E7: For projects that have security requirements like locked and sealed containers, potentially SCIFs, NOCs, Ops Centers, etc.
A8: 6 | B8: In the Prep Tab, Highlight text and Copy into columns D & E of the RFQ tab by clicking on cell F4 and Paste by right clicking on your mouse and using the second Paste option (Values (V)). NOTE: Only copy FID paragraph number & Item Code and Description into RFQ tab. | D8: Electrical Work- Hardwire all items as noted in the FID to the Facility | E8: Electrical Work - This is used if there are items to be hardwired. All items should be noted in the FID.
A9: 7 | B9: Ensure that the FID Paragraph numbers are correct and that the zero didn't drop off. For example, verify whether the paragraph is 2.10 instead of 2.1. If you can't add the "0" to the end, Format the column as Text. | D9: Oversight of Delivery | E9: Warehouse workers offload product and a representative for the Vendor is present to oversee.
A10: 8 | B10: Add title to the Att 1 and turn black - it will automatically populate on the Locations matrix. | D10: Offload Only | E10: This is unloaded by the delivery driver.
A11: 9 | B11: In the Locations matrix (right side of the Att 1), adjust row heights and then indicate quantities for each item under each room (Row T-CU). Once completed, Hide all unused columns and rows, indicated by purple boxes, up to the green cells. NOTE: Enter quantities in the Locations area only. | D11: Removal and Disposal of Existing Furniture | E11: Vendor is responsible for removal of the old furnishings and to dispose of them.
A12: 10 | B12: Hide Column A when the form is complete. (A contains the formula for the OPEN MARKET TOTAL). | D12: Removal of Existing Furniture and Moving to Designated Location | E12: Vendor is responsible for removal of the old furnishings and to moving it to another building.
A13: 11 | B13: Keep the Installation and Shipping that pertain to your order and turn the text black. Hide Installation & Shipping lines not needed. NOTE: Types of Delivery are defined in the table on the right of this page.
A14: 12 | B14: Hide all extra rows down to Furniture Subtotals.
A15: 13 | B15: Hide all tabs except RFQ. Right click on the tab and click Hide.
A16: 14 | B16: Save spreadsheet.
A18: Preparation of the Attachment 1 prior to RFQ for projects with multiple buildings | D18: Tech Review "Warranty" blank comment examples are:
A19: 1 | B19: Perform the instructions 1-8 above "Preparation of the Attachment 1 prior to RFQ" . | D19: N/A
A20: 2 | B20: File Save As for each additional building. | D20: Provide a warranty for this item.
A21: 3 | B21: Complete steps 9-14 under "Preparation of the Attachment 1 prior to RFQ" for all buildings. | D21: Warranty was provided but does not meet the FID requirement.
D22: Warranty provided and acceptable.
A23: Inserting More Rows into RFQ Tab
A24: 1 | B24: To insert more rows in the RFQ tab (there are 80 rows available in the template): A. Highlight row 84 and move your cursor down how ever many rows are needed. B. Right click and select Insert. C. Highlight row 84 and Copy to all the new blank rows. NOTE: MAKE SURE SUBTOTALS AND TOTALS ARE INCLUSIVE OF NEW ROWS!
A25: 2 | B25: To insert a row in the middle of the RFQ tab: A. Highlight the row below where you need the new row, right click, and select Insert. B. Look at the "#" to determine which numbers the new row is between and Copy the "#", "Qty", "Unit", "GSA Contract Total Cost", and "HNC Total Cost" cells from the row above. C. Then Copy the "#" cell you just pasted into the "#" cell in the row below to fix the row numbering. D. Then, enter the "FID Para." and "Item Code & Description" information. E. Enter the quantities in the appropriate rooms/areas. F. Then, in the Tech Eval tab, Insert 14 rows and copy the data from the 14 rows above into these new cells. G. Change the formulas in the top 2 rows of the rows you just copied by comparing the formulas from 14 cells above and 14 cells below to determine what number needs to be changed in the formula. I. Check to ensure everything copied and the line numbering is correct on both tabs.
A26: 3 | B26: To delete a row in the middle of the RFQ tab: A. Highlight the row to delete and delete. B. Highlight the "#" cell above the first row with "##". C. Paste the copied "#" cell into the first "#" cell with "##". Then you will need to go to the Tech Eval tab and Delete the 14 lines for the item that was removed. (Easily identified by "#REF").
A28: Inserting more Columns into Locations area
A29: 1 | B29: If you need to insert more columns in the Locations matrix (there are 80 columns in the template), highlight the green column and move your cursor to how many columns you need to add. Right click and select "Insert". Then Highlight the last column and Copy into the new columns.
A31: Printing (optional)
A32: 1 | B32: To print the Attachment 1, go to "VIEW" tab, select "Custom Views", and highlight "attach1" and click show. Then go to FILE/PRINT. It is set up to print landscape on 8.5 x 11 paper.
A33: 2 | B33: To print the Locations, go to "VIEW" tab, select "Custom Views", and highlight "locations" and click show. Then go to FILE/PRINT. It is set up to print landscape on 8.5 x 11 paper.
A35: Preparation of Tech Eval after quotes are received back from Vendors
A36: 1 | B36: A. Copy the "Tech Eval HNC USE ONLY" columns A-C, all rows that are blue (prior to the first purple cells) into Att 8 Document (Word) prior to starting the Tech Eval. B. Title the Document "1st TR - Vendor - Project Name.docx" for the Tech Eval. Each item will have a "block" of 14 rows, to allow for multiple rounds of tech evals. When dealing with a specific item, please remember there are 14 rows to copy. NOTE: DO NOT COMPLETE THE TECH REVIEW IN THE ATT 1 TEMPLATE.
A37: 2 | B37: To add more lines to the RFQ Tab: A. When lines are added to the RFQ tab you must also insert more rows in the Tech Eval tab. B. Highlight the 14 rows that reflect the tech eval block for the item directly above. C. Copy those onto the end, or in whatever location is required, repeat for each new item. D. Hand change the 7 formulas that pull data from the RFQ tab. They are in the first 5 lines of the item block. The 2 digit cell numbers will need to be changed to 85. The next one will be changed to 86 and so forth.
A38: 3 | B38: To delete lines from the RFQ Tab: A. If lines are deleted from the RFQ Tab, you will need to delete rows in the Tech Eval tab. B. The item block in the Tech Eval tab will have the #REF! error. If you come across a block that is not needed, either Delete or Hide those 14 rows.
A40: Preparation of an Revision / MOD
A41: 1 | B41: A. "Save As" the Att 1 file and add REV 00-00-0000 (date) to the title and the file name. B. To update the Att 1 for a change of product manually highlight cells in yellow that need changing (modifying). C. For a change in quantity, this includes the quantity on the Locations matrix, the total quantity for the item on the Locations matrix, and the quantity on the RFQ table, Highlight the yellow cell(s) at the bottom of the Locations matrix and use Format Paint to update the cells above. NOTE: Tan lines cannot be changed to yellow the normal way.

Sheet Prep Tab
A1: 21.1 | B1: SN1/SN01: Industrial Storage Cabinet, Metal
A2: 21.2 | B2: SL2/SL02: Corrosive Safety Cabinet, Metal
A3: 22.1 | B3: SN2/SN02: Open Industrial Bulk Rack Storage Shelving, Metal Particleboard Decking
A4: 22.2 | B4: SS1/SS01: Open Industrial Bulk Rack Storage Shelving, Metal Particleboard Decking
A5: 22.3 | B5: SX1/SX01: Tool Storage Cabinet, Metal
A6: 22.4 | B6: SX2/SX02: Tool Storage Cabinet, Metal
A7: 22.5 | B7: SX3/SX03: Tool Storage Cabinet, Metal
A8: 22.6 | B8: EQ1/EQ01: Tool Storage Cabinet, Metal
A9: 22.7 | B9: TN1/TN01: Work Bench, Metal
A10: 22.8 | B10: TN2/TN02: Work Bench, Metal
A11: 22.9 | B11: TN3/TN03: Work Bench, Metal
A12: 22.10 | B12: TN4/TN04: Work Bench, Metal
... A14: 22.12 | B14: SX4/SX04: Heavy Duty Cart

Sheet RFQ
A1: Attachment #1 - Vandenberg Space Force Base, CA - Consolidated Maintenance Facility - Open Market | P1: Admin | Q1: SAM
A2: # | B2: Qty | C2: FID Para. | D2: FID Item Code / Description | E2: Vendor Quoted | F2: Product Line Quoted | G2: Model Quoted | H2: =IF(P1="Housing","Nominal Dimensions For Information Only Provide dimensions in Inches","HIDE THESE COLUMNS") -> HIDE THESE COLUMNS | K2: =IF(Q1="GSA","GSA Contract Number OR Open Market","Hide this column") -> Hide this column | L2: =IF(Q1="GSA","GSA Contract Unit Cost") -> FALSE | M2: =IF(Q1="GSA","GSA Contract Total Cost","Hide this column") -> Hide this column | N2: HNC Unit Cost | O2: HNC Total Cost | P2: EDC-I: Hide these columns before submitting file. Select correct entries in the boxes above. These columns shows open market costs and difference from GSA | S2: ="ITEM LOCATIONS"&" *** COMPLETED BY CEHNC *** "&A1 -> ITEM LOCATIONS *** COMPLETED BY CEHNC *** Attachment #1 - Vandenberg Space Force Base, CA - Consolidated Maintenance Facility - Open Market | V2: ROOM NAME/ TYPE/# | W2: 1110A STOR | X2: 1113 MOTHER'S ROOM | Y2: 1116 RECEIVING | Z2: 1122 T.O. Library | AA2: 1122A T.O. LIBRARY VAULT | AB2: 1125 SHARED BREAK ROOM | AC2: 1202 GRP/SEL | AD2: 1203 DEPUTY GRP/CC | AE2: 1204 GRP/CC | AF2: 1205 COFFEE/BREAK | AG2: 1206 TECH ADVISOR | AH2: 1207 VIP GUEST | AI2: 1209 1ST SGT | AJ2: 1210 PROTOCOL/PA | AK2: 1220 ORDERLY/MAIL ROOM | AL2: 1221 RESOURCE ADVISORS | AM2: 1222 SECURITY MANAGER | AN2: 1230 TMO OPEN OFFICE/ADMIN SUPPORT | AO2: 1231 UNIT SAFETY | AP2: 1232 WEAPONS SAFETY MANAGER | AQ2: 1233 NCOIC | AR2: 1234 NCOIC | AS2: 1235 NCOIC | AT2: 1237 STOR | AU2: 1238 PRODUCTION SUPERVISORS | AV2: 1239 OPS | AW2: 1240 CONFERENCE ROOM | AX2: 1241 MMOC | AY2: 1251 CONF ROOM | AZ2: 1252 SIPR | BA2: 1253 OPEN OFFICE/ADMIN SUPPORT/DISPATCH | BB2: 1254 FGO | BC2: 1255 CGO | BD2: 1256 CIVILIAN | BE2: 1257 B VAULT | BF2: 1258 A VAULT | BG2: 1259 STOR | BH2: 1259A SEC ELEC | BI2: 1260 OPEN OFFICE | BJ2: 1261 TOOL/CTKS/EQUIP CRIB | BK2: 1262 STOR | BL2: 1263 TRAINING ROOM | BM2: 1264 TSGT/NCOIC MCM | BN2: 1265 TSGT/NCOIC EMT | BO2: 1266 SGT/SECTION CHIEF | BP2: 1270 GUIDANCE VAULT | BQ2: 1271 OPEN OFFICE | BR2: 1272 GUIDANCE LAB | BS2: 1274 LEADS | BT2: 1275 SUPERVISOR | BU2: 1276 BRIEFING ROOM | BV2: 1280 TE LAB | BW2: 1280A CONFERENCE ROOM | BX2: 1281 TE OPEN OFFICE | BY2: 1282 PRIVATE OFFICE | BZ2: 1282A RESOURCES FLIGHT CC/CHIEF | CA2: 1290 OPEN OFFICE | CB2: 1291 SUPERVISOR/NCOIC | CC2: 1292 SECURE CONF. | CD2: 1293 LAB | CE2: 1300 VECH/ENVIRO OPEN OFFICE | CF2: 1301 LSS CONFERENCE ROOM | CG2: 1302 CONTRACT MANAGER | CH2: 1303 PROJECT MANAGER | CI2: 1304 TRAINING MANAGER | CJ2: 1305 TRAINING LEARNING CENTER | CK2: 1306 STOR | CL2: 1401 STOR | CM2: 1402 CAGED STOR | CN2: 1403 OPEN OFFICE | CO2: 1404 PRIVATE OFFICE | CP2: 1405 STOR | CQ2: 1410 OPEN OFFICE | CR2: 1411 MSGT/SECTION | CS2: 1413 MIXING ROOM | CT2: 1415 TOOL SHOP | CU2: 1416 BATTERY SHOP | CV2: 1417 PREL BAY | CW2: 1418 HAZMAT STOR | CX2: 1420 MAPS MAINTENANCE BAY - 3 | CY2: 1421 MAPS MAINTENANCE BAY - 2 | CZ2: 1422 MAPS MAINTENANCE BAY - 1 | DA2: 1423 QUALITY ASSURANCE WORK CENTER | DB2: 1424 QA CHIF | DC2: 1424B QA SUPERINTENDENT | DD2: 1425 EQUIPMENT STORAGE | DE2: 1427 WORKBENCH | DF2: 1500 MHT OPEN OFFICE | DG2: 1501 SUPERVISORS | DH2: 1503 MHT MAINTENANCE BAY - 1 | DI2: 1504 MHT MAINTENANCE BAY - 2 | DJ2: 1505 TOOL ROOM | DK2: 1510 MMT MAINTENANCE BAY | DL2: 1511 TOOL STORAGE | DM2: 1513 OPEN OFFICE | DN2: 1514 MSGT/NCOIC/TSGT/SSGT/SCHEDULER | DO2: 1515 TSGT/SITE SUPERVISOR | DP2: 1516 TSGT/SITE SUPERVISOR | DQ2: 1533 CLASSROOM | DR2: 1534 CLASSROOM | DS2: 1535 MX VIRTUAL DRIVER/TRAINER | DT2: 1536 VIRTUAL TRAINERS SUITE | DU2: 1538 FMS | DV2: 1540 EPM/PBACM | DW2: 1542 LF LC BATTERIES EMT | DX2: 2102 LARGE SHARED CONF RM | DY2: 2103 TEAM ROOM/BREAK ROOM | DZ2: 2114 MOTHER'S ROOM | EA2: 2120 OPEN OFFICE | EB2: 2122 SMALL CONF RM | EC2: 2123 LEADERSHIP/MANAGERS/MAJORS | ED2: 2124 LEADERSHIP/MANAGERS/MAJORS | EE2: 2125 LEADERSHIP/MANAGERS/MAJORS | EF2: 2126 LEADERSHIP/MANAGERS/MAJORS | EG2: 2127 LEADERSHIP/MANAGERS/MAJORS | EH2: 2128 LEADERSHIP/MANAGERS/MAJORS | EI2: 2130A FLTS DIRECTOR OF OPERATIONS | EJ2: 2130B FLTS SENIOR ENLISTED ADVISOR | EK2: 2131A FLTS COMMANDER | EL2: 2131B FLTS COFFEE & BREAK | EM2: 2132 OPEN OFFICE/SQ ADMIN | EN2: 2135 377 FTMMXS RECEPTION | EO2: 2136 377 FTMMXS COMMANDER | EP2: 2137 CSS | EQ2: 2138 377 FTMMXS ENLISTED ADVISOR | ER2: 2139 377 FTMMXS DIRECTOR OF OPERATIONS | ES2: 2140 CONTRACTOR SUPPORT AREA | ET2: 2141 OPEN OFFICE | EU2: 2150 ITIPS | EV2: 2152 ITIPS STORAGE | EW2: 2154 ITIPS OFFICE | EX2: 2158 SIPR SUITE | EY2: 2159 SECURE VAULT SPACE/SOFTWARE LAB | EZ2: 2160 COUNTDOWN PROCEDURES TRAINER | FA2: 2161 COUNTDOWN PROCEDURES TRAINER | FB2: 2162 ITIPS BRIEF/DEBRIEF | FC2: 2163 DATA ANALYSIS ROOM | FD2: 2164 ILCC CONFERENCE ROOM | FE2: 2165 ILCC 1 | FF2: 2166 ILCC 2 | FG2: 2167 LAUNCH MONITOR OBSERVATION 1 | FH2: 2168 LAUNCH MONITOR OBSERVATION 2 | FI2: 2170 COMPUTER SUPPORT | FJ2: 2171 CIVILIAN ADVISOR | FK2: 2172 DATA NCOIC | FL2: 2173 OFFICE | FM2: 2174 COMPUTER SYSTEM STORAGE | FN2: 2175 IMDS | FO2: 2181 OPEN OFFICE | FP2: 2182 MEETING RM | FQ2: 2183 MEETING RM | FR2: 2186 SUPERVISOR | FS2: 2187 SECURE COMM | FT2: 2188 SECURE ELEC
H3: =IF($P$1="Admin","","W") | I3: =IF($P$1="Admin","","D") | J3: =IF($P$1="Admin","","H") | P3: Open Market | Q3: GSA vs HNC | S3: # | T3: FID ¶ | U3: ITEM DESCRIPTION | V3: TOTALS
A4: =IF(B4>0,A3+1,A3) -> 1 | B4: =V4 -> 43 | C4: 21.1 | D4: SN1/SN01: Industrial Storage Cabinet, Metal | M4: =SUM($L4*$B4) -> 0 | O4: =SUM($N4*$B4) -> 0 | P4: =IF(LEFT($K4,2)="OP", $O4,0) -> 0 | Q4: =IF($Q$1="SAM","",IF(L4="","",N4-L4)) | S4: =IF(A4=0,"",A4) -> 1 | T4: =IF(C4="","",C4) -> 21.1 | U4: =IF(D4="","",D4) -> SN1/SN01: Industrial Storage Cabinet, Metal | V4: =SUM(AC4:GW4) -> 43 | BJ4: 2 | BK4: 3 | BP4: 5 | BR4: 5 | BV4: 1 | CT4: 4 | CU4: 3 | CV4: 3 | CW4: 3 | DE4: 4 | DJ4: 10
A5: =IF(B5>0,A4+1,A4) -> 2 | B5: =V5 -> 1 | C5: 21.2 | D5: SL2/SL02: Corrosive Safety Cabinet, Metal | M5: =SUM($L5*$B5) -> 0 | O5: =SUM($N5*$B5) -> 0 | P5: =IF(LEFT($K5,2)="OP", $O5,0) -> 0 | Q5: =IF($Q$1="SAM","",IF(L5="","",N5-L5)) | S5: =IF(A5=0,"",A5) -> 2 | T5: =IF(C5="","",C5) -> 21.2 | U5: =IF(D5="","",D5) -> SL2/SL02: Corrosive Safety Cabinet, Metal | V5: =SUM(AC5:GW5) -> 1 | CU5: 1
A6: =IF(B6>0,A5+1,A5) -> 3 | B6: =V6 -> 1 | C6: 22.1 | D6: SN2/SN02: Open Industrial Bulk Rack Storage Shelving, Metal Particleboard Decking | M6: =SUM($L6*$B6) -> 0 | O6: =SUM($N6*$B6) -> 0 | P6: =IF(LEFT($K6,2)="OP", $O6,0) -> 0 | Q6: =IF($Q$1="SAM","",IF(L6="","",N6-L6)) | S6: =IF(A6=0,"",A6) -> 3 | T6: =IF(C6="","",C6) -> 22.1 | U6: =IF(D6="","",D6) -> SN2/SN02: Open Industrial Bulk Rack Storage Shelving, Metal Particleboard Decking | V6: =SUM(AC6:GW6) -> 1 | BP6: 1
A7: =IF(B7>0,A6+1,A6) -> 4 | B7: =V7 -> 227 | C7: 22.2 | D7: SS1/SS01: Open Industrial Bulk Rack Storage Shelving, Metal Particleboard Decking | M7: =SUM($L7*$B7) -> 0 | O7: =SUM($N7*$B7) -> 0 | P7: =IF(LEFT($K7,2)="OP", $O7,0) -> 0 | Q7: =IF($Q$1="SAM","",IF(L7="","",N7-L7)) | S7: =IF(A7=0,"",A7) -> 4 | T7: =IF(C7="","",C7) -> 22.2 | U7: =IF(D7="","",D7) -> SS1/SS01: Open Industrial Bulk Rack Storage Shelving, Metal Particleboard Decking | V7: =SUM(W7:GW7) -> 227 | W7: 5 | Y7: 6 | Z7: 5 | AK7: 3 | AT7: 3 | BG7: 4 | BJ7: 3 | BK7: 2 | BP7: 5 | BV7: 3 | CK7: 4 | CL7: 6 | CM7: 41 | CP7: 14 | CT7: 2 | CU7: 8 | CW7: 3 | DD7: 29 | DE7: 25 | DJ7: 8 | DL7: 10 | EV7: 10 | FM7: 14 | FN7: 14
A8: =IF(B8>0,A7+1,A7) -> 5 | B8: =V8 -> 20 | C8: 22.3 | D8: SX1/SX01: Tool Storage Cabinet, Metal | M8: =SUM($L8*$B8) -> 0 | O8: =SUM($N8*$B8) -> 0 | P8: =IF(LEFT($K8,2)="OP", $O8,0) -> 0 | Q8: =IF($Q$1="SAM","",IF(L8="","",N8-L8)) | S8: =IF(A8=0,"",A8) -> 5 | T8: =IF(C8="","",C8) -> 22.3 | U8: =IF(D8="","",D8) -> SX1/SX01: Tool Storage Cabinet, Metal | V8: =SUM(AC8:GW8) -> 20 | CT8: 2 | CU8: 6 | CV8: 6 | DL8: 6
A9: =IF(B9>0,A8+1,A8) -> 6 | B9: =V9 -> 5 | C9: 22.4 | D9: SX2/SX02: Tool Storage Cabinet, Metal | M9: =SUM($L9*$B9) -> 0 | O9: =SUM($N9*$B9) -> 0 | P9: =IF(LEFT($K9,2)="OP", $O9,0) -> 0 | Q9: =IF($Q$1="SAM","",IF(L9="","",N9-L9)) | S9: =IF(A9=0,"",A9) -> 6 | T9: =IF(C9="","",C9) -> 22.4 | U9: =IF(D9="","",D9) -> SX2/SX02: Tool Storage Cabinet, Metal | V9: =SUM(AC9:GW9) -> 5 | CX9: 1 | CY9: 1 | CZ9: 1 | DH9: 1 | DI9: 1
A10: =IF(B10>0,A9+1,A9) -> 7 | B10: =V10 -> 5 | C10: 22.5 | D10: SX3/SX03: Tool Storage Cabinet, Metal | M10: =SUM($L10*$B10) -> 0 | O10: =SUM($N10*$B10) -> 0 | P10: =IF(LEFT($K10,2)="OP", $O10,0) -> 0 | Q10: =IF($Q$1="SAM","",IF(L10="","",N10-L10)) | S10: =IF(A10=0,"",A10) -> 7 | T10: =IF(C10="","",C10) -> 22.5 | U10: =IF(D10="","",D10) -> SX3/SX03: Tool Storage Cabinet, Metal | V10: =SUM(AC10:GW10) -> 5 | CX10: 1 | CY10: 1 | CZ10: 1 | DH10: 1 | DI10: 1
A11: =IF(B11>0,A10+1,A10) -> 8 | B11: =V11 -> 2 | C11: 22.6 | D11: EQ1/EQ01: Tool Storage Cabinet, Metal | M11: =SUM($L11*$B11) -> 0 | O11: =SUM($N11*$B11) -> 0 | P11: =IF(LEFT($K11,2)="OP", $O11,0) -> 0 | Q11: =IF($Q$1="SAM","",IF(L11="","",N11-L11)) | S11: =IF(A11=0,"",A11) -> 8 | T11: =IF(C11="","",C11) -> 22.6 | U11: =IF(D11="","",D11) -> EQ1/EQ01: Tool Storage Cabinet, Metal | V11: =SUM(AC11:GW11) -> 2 | BP11: 1 | BR11: 1
A12: =IF(B12>0,A11+1,A11) -> 9 | B12: =V12 -> 45 | C12: 22.7 | D12: TN1/TN01/TN2/TN02: Work Bench, Metal | M12: =SUM($L12*$B12) -> 0 | O12: =SUM($N12*$B12) -> 0 | P12: =IF(LEFT($K12,2)="OP", $O12,0) -> 0 | Q12: =IF($Q$1="SAM","",IF(L12="","",N12-L12)) | S12: =IF(A12=0,"",A12) -> 9 | T12: =IF(C12="","",C12) -> 22.7 | U12: =IF(D12="","",D12) -> TN1/TN01/TN2/TN02: Work Bench, Metal | V12: =SUM(AC12:GW12) -> 45 | BJ12: 1 | BP12: 2 | BR12: 2 | BV12: 2 | CD12: 6 | CS12: 1 | CT12: 1 | CU12: 2 | CV12: 2 | CW12: 1 | DE12: 5 | DL12: 1 | DS12: 3 | DT12: 3 | DU12: 3 | DV12: 8 | DW12: 2
A13: =IF(B13>0,A12+1,A12) -> 10 | B13: =V13 -> 10 | C13: 22.9 | D13: TN3/TN03/TN4/TN04: Work Bench, Metal | M13: =SUM($L13*$B13) -> 0 | O13: =SUM($N13*$B13) -> 0 | P13: =IF(LEFT($K13,2)="OP", $O13,0) -> 0 | Q13: =IF($Q$1="SAM","",IF(L13="","",N13-L13)) | S13: =IF(A13=0,"",A13) -> 10 | T13: =IF(C13="","",C13) -> 22.9 | U13: =IF(D13="","",D13) -> TN3/TN03/TN4/TN04: Work Bench, Metal | V13: =SUM(AC13:GW13) -> 10 | CD13: 10
A14: =IF(B14>0,A13+1,A13) -> 11 | B14: =V14 -> 1 | C14: 22.10 | D14: TN5/TN05: Work Bench, Metal | M14: =SUM($L14*$B14) -> 0 | O14: =SUM($N14*$B14) -> 0 | P14: =IF(LEFT($K14,2)="OP", $O14,0) -> 0 | Q14: =IF($Q$1="SAM","",IF(L14="","",N14-L14)) | S14: =IF(A14=0,"",A14) -> 11 | T14: =IF(C14="","",C14) -> 22.10 | U14: =IF(D14="","",D14) -> TN5/TN05: Work Bench, Metal | V14: =SUM(AC14:GW14) -> 1 | BR14: 1
A15: =IF(B15>0,A14+1,A14) -> 12 | B15: =V15 -> 13 | C15: 22.11 | D15: SL1/SL01: Double Tier Locker, Metal | M15: =SUM($L15*$B15) -> 0 | O15: =SUM($N15*$B15) -> 0 | P15: =IF(LEFT($K15,2)="OP", $O15,0) -> 0 | Q15: =IF($Q$1="SAM","",IF(L15="","",N15-L15)) | S15: =IF(A15=0,"",A15) -> 12 | T15: =IF(C15="","",C15) -> 22.11 | U15: =IF(D15="","",D15) -> SL1/SL01: Double Tier Locker, Metal | V15: =SUM(AC15:GW15) -> 13 | DL15: 13
A16: =IF(B16>0,A15+1,A15) -> 13 | B16: =V16 -> 1 | C16: 22.12 | D16: SX4/SX04: Heavy Duty Cart | M16: =SUM($L16*$B16) -> 0 | O16: =SUM($N16*$B16) -> 0 | P16: =IF(LEFT($K16,2)="OP", $O16,0) -> 0 | Q16: =IF($Q$1="SAM","",IF(L16="","",N16-L16)) | S16: =IF(A16=0,"",A16) -> 13 | T16: =IF(C16="","",C16) -> 22.12 | U16: =IF(D16="","",D16) -> SX4/SX04: Heavy Duty Cart | V16: =SUM(AC16:GW16) -> 1 | CT16: 1
A17: Furniture Subtotals: | G17: =IF(Q1="GSA","Open Market:","") | K17: =IF(Q1="GSA",P17,"") | L17: GSA Cost: | M17: =SUM(M4:M16) -> 0 | N17: HNC Cost: | O17: =SUM(O4:O16) -> 0 | P17: =SUM(P4:P16) -> 0
A18: =IF(Q1="GSA","Please note, if one or more of the boxes above are in amber or red, please refer to RFQ, Sect. J, Instruction to Quoters for requirements for Open Market items.","") | P18: Open Market Total above
A19: Installation & Shipping:
A20: Shipping (CONUS)
A21: Tariffs
A22: Installation - Includes new and existing items, if applicable, in accordance with SOW
A23: GRAND TOTAL: | O23: =SUM(O17:O22) -> 0
A24: Do not alter any formulas in shaded cells

Sheet Tech Eval HNC USE ONLY
A1: =IF(RFQ!D4="",0,RFQ!A4) -> 1 | B1: =IF(C1=0,0, "FID "&RFQ!C4) -> FID 21.1 | C1: =RFQ!D4 -> SN1/SN01: Industrial Storage Cabinet, Metal
A2: Vendor Quoted: | C2: =RFQ!E4 -> 0
A3: Product Line Quoted: | C3: =RFQ!F4 -> 0
A4: Model Quoted: | C4: =+RFQ!G4 -> 0
A5: GSA # or Open Market: | C5: =RFQ!K4 -> 0
A6: Warranty:
A7: 1st Review HNC:
A8: 1st Review Vendor:
A9: 2nd Review HNC:
A10: 2nd Review Vendor:
A11: 3rd Review HNC:
A12: 3rd Review Vendor:
A13: 4th Review HNC:
A14: 4th Review Vendor:
A15: =IF(RFQ!D5="",0,RFQ!A5) -> 2 | B15: =IF(C15=0,0, "FID "&RFQ!C5) -> FID 21.2 | C15: =RFQ!D5 -> SL2/SL02: Corrosive Safety Cabinet, Metal
A16: Vendor Quoted: | C16: =RFQ!E5 -> 0
A17: Product Line Quoted: | C17: =RFQ!F5 -> 0
A18: Model Quoted: | C18: =RFQ!G5 -> 0
A19: GSA # or Open Market: | C19: =RFQ!K5 -> 0
A20: Warranty:
A21: 1st Review HNC:
A22: 1st Review Vendor:
A23: 2nd Review HNC:
A24: 2nd Review Vendor:
A25: 3rd Review HNC:
A26: 3rd Review Vendor:
A27: 4th Review HNC:
A28: 4th Review Vendor:
A29: =IF(RFQ!D6="",0,RFQ!A6) -> 3 | B29: =IF(C29=0,0, "FID "&RFQ!C6) -> FID 22.1 | C29: =RFQ!D6 -> SN2/SN02: Open Industrial Bulk Rack Storage Shelving, Metal Particleboard Decking
A30: Vendor Quoted: | C30: =RFQ!E6 -> 0
A31: Product Line Quoted: | C31: =RFQ!F6 -> 0
A32: Model Quoted: | C32: =RFQ!G6 -> 0
A33: GSA # or Open Market: | C33: =RFQ!K6 -> 0
A34: Warranty:
A35: 1st Review HNC:
A36: 1st Review Vendor:
A37: 2nd Review HNC:
A38: 2nd Review Vendor:
A39: 3rd Review HNC:
A40: 3rd Review Vendor:
...
