Workbook

Sheet Summary
A1: Kitchen Exhaust Hood Cleaning
B3: Price Exhibit
A5: FY27 Ordering Period 1 Oct 26 - 30 Sep 27 | F5: ='FY27'!I61 -> 0
A6: FY28 Ordering Period 1 Oct 27 - 30 Sep 28 | F6: ='FY28'!I61 -> 0
A7: FY29 Ordering Period 1 Oct 28 - 30 Sep 29 | F7: ='FY29'!I61 -> 0
A8: FY30 Ordering Period 1 Oct 29 - 30 Sep 30 | F8: ='FY30'!I61 -> 0
A9: FY31 Ordering Period 1 Oct 30 - 30 Sep 31 | F9: ='FY31'!I61 -> 0
F11: =SUM(F5:F10) -> 0

Sheet FY27
A1: FY27 Ordering Period 1 Oct 26 - 30 Sep 27
A2: Item # | B2: Bldg | C2: Hood label # | D2: Description | E2: months | F2: Frequency | G2: Annual # of Cleanings | H2: Unit Price | I2: Total cost
B3: 61 | D3: Food Service
A4: A001 | B4: 61 | C4: 1 | D4: Steam kettle area L 9' x W 6' x H 2' (2 throats) Self washing unit | E4: May | F4: Annual | G4: 1 | I4: =SUM(G4*H4) -> 0
A5: A002 | B5: 61 | C5: 2 | D5: Steam kettle area L 9' x W 6' x H 2' (2 throats) Self washing unit | E5: May | F5: Annual | G5: 1 | I5: =SUM(G5*H5) -> 0
A6: A003 | B6: 61 | C6: 3 | D6: Bakery (fryer - donuts) L 9' X W 5' X H 3' (2 throats) Self washing unit | E6: May | F6: Annual | G6: 1 | I6: =SUM(G6*H6) -> 0
A7: A004 | B7: 61 | C7: 4 | D7: Oven in Bakery L 4' x W 2'4" x H 2'5" (1 throat) | E7: May | F7: Annual | G7: 1 | I7: =SUM(G7*H7) -> 0
B8: 195 | D8: Child Dev Center
A9: A005 | B9: 195 | C9: 1 | D9: Kitchen Stove top/Oven L 8' x W4' x H2' (1 throat) | E9: Dec | F9: Annual | G9: 1 | I9: =SUM(G9*H9) -> 0
B10: 204 | D10: TBD
A11: A006 | B11: 204 | C11: 1 | D11: TBD | E11: TBD | F11: TBD | G11: TBD
B12: 239 | D12: TBD
A13: A007 | B13: 239 | C13: 1 | D13: TBD | E13: TBD | F13: TBD | G13: TBD
A14: A008 | B14: 239 | C14: 2 | D14: TBD | E14: TBD | F14: TBD | G14: TBD
B15: 318 | D15: S. Bowling Lane
A16: A009 | B16: 318 | C16: 1 | D16: Fryer/Grill combo L 6' x W 4' x H 3' (1 throat) | E16: Jan/Apr/ Jul/Oct | F16: Every 3 months | G16: 4 | I16: =SUM(G16*H16) -> 0
D17: Lift Rental
B18: 740 | D18: MiniMall Food Court
A19: A010 | B19: 740 | C19: 1 | D19: Taco Bell Steamer L 3' x W 3' x H 1'4" (1 throat) | E19: Feb/May/ Aug/Nov | F19: Monthly | G19: 12 | I19: =SUM(G19*H19) -> 0
A20: A011 | B20: 740 | C20: 2 | D20: Panda Express L 21' x W 5' x H2' (1 Throat) | E20: Jan/Apr/ Jul/Oct | F20: Monthly | G20: 12 | I20: =SUM(G20*H20) -> 0
A21: A012 | B21: 740 | C21: 3 | D21: Panda Express L 21' x W 5' x H2' (1 Throat) | E21: Jan/Apr/ Jul/Oct | F21: Monthly | G21: 12 | I21: =SUM(G21*H21) -> 0
A22: A013 | B22: 740 | C22: 4 | D22: Popeye Chicken L 11' x W 2' x H 1' (1 throat) | E22: Jan through Dec | F22: Monthly | G22: 12 | I22: =SUM(G22*H22) -> 0
A23: A014 | B23: 740 | C23: 5 | D23: TBD | E23: TBD | F23: TBD | G23: TBD
B24: 805 | D24: Dining Hall
A25: A016 | B25: 805 | C25: 1 | D25: Serving Line Grill L 9 x W 5' x H 4' (1 throat) Water wash system | E25: Mar/Jun/ Sep/Dec | F25: Every 3 months | G25: 4 | I25: =SUM(G25*H25) -> 0
A26: A017 | B26: 805 | C26: 2 | D26: Serving Line Grill L 9 x W 5' x H 4' (1 throat) Water wash system | E26: Mar/Jun/ Sep/Dec | F26: Every 3 months | G26: 4 | I26: =SUM(G26*H26) -> 0
A27: A018 | B27: 805 | C27: 3 | D27: Serving Line Fryer/grill/B-B-Q combo L 10' x W 5' x H 4' (1 throat) Water wash system | E27: Jan through Dec | F27: monthly | G27: 12 | I27: =SUM(G27*H27) -> 0
A28: A019 | B28: 805 | C28: 4 | D28: Serving Line Fryer/grill/B-B-Q combo L 10' x W 5' x H 4' (1 throat) Water wash system | E28: Jan through Dec | F28: monthly | G28: 12 | I28: =SUM(G28*H28) -> 0
A29: A020 | B29: 805 | C29: 5 | D29: Kitchen Ovens/Till grill/Fryer L 26' x W 5' x H 4' (2 throats with 2 turbines) Water wash system | E29: Jan through Dec | F29: monthly | G29: 12 | I29: =SUM(G29*H29) -> 0
A30: A021 | B30: 805 | C30: 6 | D30: Kitchen Kettle pots L 20' x W 5' x H 4' (2 throats) Water wash system | E30: Jun/Dec | F30: Every 6 months | G30: 2 | I30: =SUM(G30*H30) -> 0
B31: 811 | D31: N. Bowling Lane
A32: A022 | B32: 811 | C32: 1 | D32: Grill/Fryer Combo L 10' x W 3' x H 2' (1 throat) | E32: Jan/Jul | F32: Every 6 months | G32: 2 | I32: =SUM(G32*H32) -> 0
B33: 1320 | D33: Dining Hall
A34: A023 | B34: 1320 | C34: 1 | D34: Serving Line Grill L 9 x W 5' x H 4' (1 throat) Water wash system | E34: Mar/Jun/ Sep/Dec | F34: Every 3 months | G34: 4 | I34: =SUM(G34*H34) -> 0
A35: A024 | B35: 1320 | C35: 2 | D35: Serving Line Grill L 9 x W 5' x H 4' (1 throat) Water wash system | E35: Mar/Jun/ Sep/Dec | F35: Every 3 months | G35: 4 | I35: =SUM(G35*H35) -> 0
A36: A025 | B36: 1320 | C36: 3 | D36: Serving Line Fryer/grill/B-B-Q combo L 10' x W 5' x H 4' (1 throat) Water wash system | E36: Jan through Dec | F36: monthly | G36: 12 | I36: =SUM(G36*H36) -> 0
A37: A026 | B37: 1320 | C37: 4 | D37: Serving Line Fryer/grill/B-B-Q combo L 10' x W 5' x H 4' (1 throat) Water wash system | E37: Jan through Dec | F37: monthly | G37: 12 | I37: =SUM(G37*H37) -> 0
A38: A027 | B38: 1320 | C38: 5 | D38: Kitchen Ovens/Till grill/Fryer L 26' x W 5' x H 4' (2 throats with 2 turbines) Water wash system | E38: Jan through Dec | F38: monthly | G38: 12 | I38: =SUM(G38*H38) -> 0
A39: A028 | B39: 1320 | C39: 6 | D39: Kitchen Kettle pots L 20' x W 5' x H 4' (2 throats) Water wash system | E39: Jun/Dec | F39: Every 6 months | G39: 2 | I39: =SUM(G39*H39) -> 0
B40: 1368 | D40: Dining Hall
...

Sheet FY28
A1: FY28 Ordering Period 1 Oct 27 - 30 Sep 28
A2: Item # | B2: Bldg | C2: Hood label # | D2: Description | E2: months | F2: Frequency | G2: Annual # of Cleanings | H2: Unit Price | I2: Total cost
B3: 61 | D3: Food Service
A4: B001 | B4: 61 | C4: 1 | D4: Steam kettle area L 9' x W 6' x H 2' (2 throats) Self washing unit | E4: May | F4: Annual | G4: 1 | I4: =SUM(G4*H4) -> 0
A5: B002 | B5: 61 | C5: 2 | D5: Steam kettle area L 9' x W 6' x H 2' (2 throats) Self washing unit | E5: May | F5: Annual | G5: 1 | I5: =SUM(G5*H5) -> 0
A6: B003 | B6: 61 | C6: 3 | D6: Bakery (fryer - donuts) L 9' X W 5' X H 3' (2 throats) Self washing unit | E6: May | F6: Annual | G6: 1 | I6: =SUM(G6*H6) -> 0
A7: B004 | B7: 61 | C7: 4 | D7: Oven in Bakery L 4' x W 2'4" x H 2'5" (1 throat) | E7: May | F7: Annual | G7: 1 | I7: =SUM(G7*H7) -> 0
B8: 195 | D8: Child Dev Center
A9: B005 | B9: 195 | C9: 1 | D9: Kitchen Stove top/Oven L 8' x W4' x H2' (1 throat) | E9: Dec | F9: Annual | G9: 1 | I9: =SUM(G9*H9) -> 0
B10: 204 | D10: TBD
A11: B006 | B11: 204 | C11: 1 | D11: TBD | E11: TBD | F11: TBD | G11: TBD
B12: 239 | D12: TBD
A13: B007 | B13: 239 | C13: 1 | D13: TBD | E13: TBD | F13: TBD | G13: TBD
A14: B008 | B14: 239 | C14: 2 | D14: TBD | E14: TBD | F14: TBD | G14: TBD
B15: 318 | D15: S. Bowling Lane
A16: B009 | B16: 318 | C16: 1 | D16: Fryer/Grill combo L 6' x W 4' x H 3' (1 throat) | E16: Jan/Apr/ Jul/Oct | F16: Every 3 months | G16: 4 | I16: =SUM(G16*H16) -> 0
D17: Lift Rental
B18: 740 | D18: MiniMall Food Court
A19: B010 | B19: 740 | C19: 1 | D19: Taco Bell Steamer L 3' x W 3' x H 1'4" (1 throat) | E19: Feb/May/ Aug/Nov | F19: Every 3 months | G19: 4 | I19: =SUM(G19*H19) -> 0
A20: B011 | B20: 740 | C20: 2 | D20: Panda Express L 21' x W 5' x H2' (1 Throat) | E20: Jan/Apr/ Jul/Oct | F20: Every 3 Months | G20: 4 | I20: =SUM(G20*H20) -> 0
A21: B012 | B21: 740 | C21: 3 | D21: Panda Express L 21' x W 5' x H2' (1 Throat) | E21: Jan/Apr/ Jul/Oct | F21: Every 3 Months | G21: 4 | I21: =SUM(G21*H21) -> 0
A22: B013 | B22: 740 | C22: 4 | D22: Popeye Chicken L 11' x W 2' x H 1' (1 throat) | E22: Jan through Dec | F22: monthly | G22: 12 | I22: =SUM(G22*H22) -> 0
A23: B014 | B23: 740 | C23: 5 | D23: TBD | E23: TBD | F23: TBD | G23: TBD
B24: 805 | D24: Dining Hall
A25: B016 | B25: 805 | C25: 1 | D25: Serving Line Grill L 9 x W 5' x H 4' (1 throat) Water wash system | E25: Mar/Jun/ Sep/Dec | F25: Every 3 months | G25: 4 | I25: =SUM(G25*H25) -> 0
A26: B017 | B26: 805 | C26: 2 | D26: Serving Line Grill L 9 x W 5' x H 4' (1 throat) Water wash system | E26: Mar/Jun/ Sep/Dec | F26: Every 3 months | G26: 4 | I26: =SUM(G26*H26) -> 0
A27: B018 | B27: 805 | C27: 3 | D27: Serving Line Fryer/grill/B-B-Q combo L 10' x W 5' x H 4' (1 throat) Water wash system | E27: Jan through Dec | F27: monthly | G27: 12 | I27: =SUM(G27*H27) -> 0
A28: B019 | B28: 805 | C28: 4 | D28: Serving Line Fryer/grill/B-B-Q combo L 10' x W 5' x H 4' (1 throat) Water wash system | E28: Jan through Dec | F28: monthly | G28: 12 | I28: =SUM(G28*H28) -> 0
A29: B020 | B29: 805 | C29: 5 | D29: Kitchen Ovens/Till grill/Fryer L 26' x W 5' x H 4' (2 throats with 2 turbines) Water wash system | E29: Jan through Dec | F29: monthly | G29: 12 | I29: =SUM(G29*H29) -> 0
A30: B021 | B30: 805 | C30: 6 | D30: Kitchen Kettle pots L 20' x W 5' x H 4' (2 throats) Water wash system | E30: Jun/Dec | F30: Every 6 months | G30: 2 | I30: =SUM(G30*H30) -> 0
B31: 811 | D31: N. Bowling Lane
A32: B022 | B32: 811 | C32: 1 | D32: Grill/Fryer Combo L 10' x W 3' x H 2' (1 throat) | E32: Jan/Jul | F32: Every 6 months | G32: 2 | I32: =SUM(G32*H32) -> 0
B33: 1320 | D33: Dining Hall
A34: B023 | B34: 1320 | C34: 1 | D34: Serving Line Grill L 9 x W 5' x H 4' (1 throat) Water wash system | E34: Mar/Jun/ Sep/Dec | F34: Every 3 months | G34: 4 | I34: =SUM(G34*H34) -> 0
A35: B024 | B35: 1320 | C35: 2 | D35: Serving Line Grill L 9 x W 5' x H 4' (1 throat) Water wash system | E35: Mar/Jun/ Sep/Dec | F35: Every 3 months | G35: 4 | I35: =SUM(G35*H35) -> 0
A36: B025 | B36: 1320 | C36: 3 | D36: Serving Line Fryer/grill/B-B-Q combo L 10' x W 5' x H 4' (1 throat) Water wash system | E36: Jan through Dec | F36: monthly | G36: 12 | I36: =SUM(G36*H36) -> 0
A37: B026 | B37: 1320 | C37: 4 | D37: Serving Line Fryer/grill/B-B-Q combo L 10' x W 5' x H 4' (1 throat) Water wash system | E37: Jan through Dec | F37: monthly | G37: 12 | I37: =SUM(G37*H37) -> 0
A38: B027 | B38: 1320 | C38: 5 | D38: Kitchen Ovens/Till grill/Fryer L 26' x W 5' x H 4' (2 throats with 2 turbines) Water wash system | E38: Jan through Dec | F38: monthly | G38: 12 | I38: =SUM(G38*H38) -> 0
A39: B028 | B39: 1320 | C39: 6 | D39: Kitchen Kettle pots L 20' x W 5' x H 4' (2 throats) Water wash system | E39: Jun/Dec | F39: Every 6 months | G39: 2 | I39: =SUM(G39*H39) -> 0
B40: 1368 | D40: Dining Hall
...

Sheet FY29
A1: FY29 Ordering Period 1 Oct 28 - 30 Sep 29
A2: Item # | B2: Bldg | C2: Hood label # | D2: Description | E2: months | F2: Frequency | G2: Annual # of Cleanings | H2: Unit Price | I2: Total cost
B3: 61 | D3: Food Service
A4: C001 | B4: 61 | C4: 1 | D4: Steam kettle area L 9' x W 6' x H 2' (2 throats) Self washing unit | E4: May | F4: Annual | G4: 1 | I4: =SUM(G4*H4) -> 0
A5: C002 | B5: 61 | C5: 2 | D5: Steam kettle area L 9' x W 6' x H 2' (2 throats) Self washing unit | E5: May | F5: Annual | G5: 1 | I5: =SUM(G5*H5) -> 0
A6: C003 | B6: 61 | C6: 3 | D6: Bakery (fryer - donuts) L 9' X W 5' X H 3' (2 throats) Self washing unit | E6: May | F6: Annual | G6: 1 | I6: =SUM(G6*H6) -> 0
A7: C004 | B7: 61 | C7: 4 | D7: Oven in Bakery L 4' x W 2'4" x H 2'5" (1 throat) | E7: May | F7: Annual | G7: 1 | I7: =SUM(G7*H7) -> 0
B8: 195 | D8: Child Dev Center
A9: C005 | B9: 195 | C9: 1 | D9: Kitchen Stove top/Oven L 8' x W4' x H2' (1 throat) | E9: Dec | F9: Annual | G9: 1 | I9: =SUM(G9*H9) -> 0
B10: 204 | D10: TBD
A11: C006 | B11: 204 | C11: 1 | D11: TBD | E11: TBD | F11: TBD | G11: TBD
B12: 239 | D12: TBD
A13: C007 | B13: 239 | C13: 1 | D13: TBD | E13: TBD | F13: TBD | G13: TBD
A14: C008 | B14: 239 | C14: 2 | D14: TBD | E14: TBD | F14: TBD | G14: TBD
B15: 318 | D15: S. Bowling Lane
A16: C009 | B16: 318 | C16: 1 | D16: Fryer/Grill combo L 6' x W 4' x H 3' (1 throat) | E16: Jan/Apr/ Jul/Oct | F16: Every 3 months | G16: 4 | I16: =SUM(G16*H16) -> 0
D17: Lift Rental
B18: 740 | D18: MiniMall Food Court
A19: C010 | B19: 740 | C19: 1 | D19: Taco Bell Steamer L 3' x W 3' x H 1'4" (1 throat) | E19: Feb/May/ Aug/Nov | F19: Every 3 months | G19: 4 | I19: =SUM(G19*H19) -> 0
A20: C011 | B20: 740 | C20: 2 | D20: Panda Express L 21' x W 5' x H2' (1 Throat) | E20: Jan/Apr/ Jul/Oct | F20: Every 3 Months | G20: 4 | I20: =SUM(G20*H20) -> 0
A21: C012 | B21: 740 | C21: 3 | D21: Panda Express L 21' x W 5' x H2' (1 Throat) | E21: Jan/Apr/ Jul/Oct | F21: Every 3 Months | G21: 4 | I21: =SUM(G21*H21) -> 0
A22: C013 | B22: 740 | C22: 4 | D22: Popeye Chicken L 11' x W 2' x H 1' (1 throat) | E22: Jan through Dec | F22: monthly | G22: 12 | I22: =SUM(G22*H22) -> 0
A23: C014 | B23: 740 | C23: 5 | D23: TBD | E23: TBD | F23: TBD | G23: TBD
B24: 805 | D24: Dining Hall
A25: C016 | B25: 805 | C25: 1 | D25: Serving Line Grill L 9 x W 5' x H 4' (1 throat) Water wash system | E25: Mar/Jun/ Sep/Dec | F25: Every 3 months | G25: 4 | I25: =SUM(G25*H25) -> 0
A26: C017 | B26: 805 | C26: 2 | D26: Serving Line Grill L 9 x W 5' x H 4' (1 throat) Water wash system | E26: Mar/Jun/ Sep/Dec | F26: Every 3 months | G26: 4 | I26: =SUM(G26*H26) -> 0
A27: C018 | B27: 805 | C27: 3 | D27: Serving Line Fryer/grill/B-B-Q combo L 10' x W 5' x H 4' (1 throat) Water wash system | E27: Jan through Dec | F27: monthly | G27: 12 | I27: =SUM(G27*H27) -> 0
A28: C019 | B28: 805 | C28: 4 | D28: Serving Line Fryer/grill/B-B-Q combo L 10' x W 5' x H 4' (1 throat) Water wash system | E28: Jan through Dec | F28: monthly | G28: 12 | I28: =SUM(G28*H28) -> 0
A29: C020 | B29: 805 | C29: 5 | D29: Kitchen Ovens/Till grill/Fryer L 26' x W 5' x H 4' (2 throats with 2 turbines) Water wash system | E29: Jan through Dec | F29: monthly | G29: 12 | I29: =SUM(G29*H29) -> 0
A30: C021 | B30: 805 | C30: 6 | D30: Kitchen Kettle pots L 20' x W 5' x H 4' (2 throats) Water wash system | E30: Jun/Dec | F30: Every 6 months | G30: 2 | I30: =SUM(G30*H30) -> 0
B31: 811 | D31: N. Bowling Lane
A32: C022 | B32: 811 | C32: 1 | D32: Grill/Fryer Combo L 10' x W 3' x H 2' (1 throat) | E32: Jan/Jul | F32: Every 6 months | G32: 2 | I32: =SUM(G32*H32) -> 0
B33: 1320 | D33: Dining Hall
A34: C023 | B34: 1320 | C34: 1 | D34: Serving Line Grill L 9 x W 5' x H 4' (1 throat) Water wash system | E34: Mar/Jun/ Sep/Dec | F34: Every 3 months | G34: 4 | I34: =SUM(G34*H34) -> 0
A35: C024 | B35: 1320 | C35: 2 | D35: Serving Line Grill L 9 x W 5' x H 4' (1 throat) Water wash system | E35: Mar/Jun/ Sep/Dec | F35: Every 3 months | G35: 4 | I35: =SUM(G35*H35) -> 0
A36: C025 | B36: 1320 | C36: 3 | D36: Serving Line Fryer/grill/B-B-Q combo L 10' x W 5' x H 4' (1 throat) Water wash system | E36: Jan through Dec | F36: monthly | G36: 12 | I36: =SUM(G36*H36) -> 0
A37: C026 | B37: 1320 | C37: 4 | D37: Serving Line Fryer/grill/B-B-Q combo L 10' x W 5' x H 4' (1 throat) Water wash system | E37: Jan through Dec | F37: monthly | G37: 12 | I37: =SUM(G37*H37) -> 0
A38: C027 | B38: 1320 | C38: 5 | D38: Kitchen Ovens/Till grill/Fryer L 26' x W 5' x H 4' (2 throats with 2 turbines) Water wash system | E38: Jan through Dec | F38: monthly | G38: 12 | I38: =SUM(G38*H38) -> 0
A39: C028 | B39: 1320 | C39: 6 | D39: Kitchen Kettle pots L 20' x W 5' x H 4' (2 throats) Water wash system | E39: Jun/Dec | F39: Every 6 months | G39: 2 | I39: =SUM(G39*H39) -> 0
B40: 1368 | D40: Dining Hall
...

Sheet FY30
A1: FY30 Ordering Period 1 Oct 29 - 30 Sep 30
A2: Item # | B2: Bldg | C2: Hood label # | D2: Description | E2: months | F2: Frequency | G2: Annual # of Cleanings | H2: Unit Price | I2: Total cost
B3: 61 | D3: Food Service
A4: D001 | B4: 61 | C4: 1 | D4: Steam kettle area L 9' x W 6' x H 2' (2 throats) Self washing unit | E4: May | F4: Annual | G4: 1 | I4: =SUM(G4*H4) -> 0
A5: D002 | B5: 61 | C5: 2 | D5: Steam kettle area L 9' x W 6' x H 2' (2 throats) Self washing unit | E5: May | F5: Annual | G5: 1 | I5: =SUM(G5*H5) -> 0
A6: D003 | B6: 61 | C6: 3 | D6: Bakery (fryer - donuts) L 9' X W 5' X H 3' (2 throats) Self washing unit | E6: May | F6: Annual | G6: 1 | I6: =SUM(G6*H6) -> 0
A7: D004 | B7: 61 | C7: 4 | D7: Oven in Bakery L 4' x W 2'4" x H 2'5" (1 throat) | E7: May | F7: Annual | G7: 1 | I7: =SUM(G7*H7) -> 0
B8: 195 | D8: Child Dev Center
A9: D005 | B9: 195 | C9: 1 | D9: Kitchen Stove top/Oven L 8' x W4' x H2' (1 throat) | E9: Dec | F9: Annual | G9: 1 | I9: =SUM(G9*H9) -> 0
B10: 204 | D10: TBD
A11: D006 | B11: 204 | C11: 1 | D11: TBD | E11: TBD | F11: TBD | G11: TBD
B12: 239 | D12: TBD
A13: D007 | B13: 239 | C13: 1 | D13: TBD | E13: TBD | F13: TBD | G13: TBD
A14: D008 | B14: 239 | C14: 2 | D14: TBD | E14: TBD | F14: TBD | G14: TBD
B15: 318 | D15: S. Bowling Lane
A16: D009 | B16: 318 | C16: 1 | D16: Fryer/Grill combo L 6' x W 4' x H 3' (1 throat) | E16: Jan/Apr/ Jul/Oct | F16: Every 3 months | G16: 4 | I16: =SUM(G16*H16) -> 0
D17: Lift Rental
B18: 740 | D18: MiniMall Food Court
A19: D010 | B19: 740 | C19: 1 | D19: Taco Bell Steamer L 3' x W 3' x H 1'4" (1 throat) | E19: Feb/May/ Aug/Nov | F19: Every 3 months | G19: 4 | I19: =SUM(G19*H19) -> 0
A20: D011 | B20: 740 | C20: 2 | D20: Panda Express L 21' x W 5' x H2' (1 Throat) | E20: Jan/Apr/ Jul/Oct | F20: Every 3 Months | G20: 4 | I20: =SUM(G20*H20) -> 0
A21: D012 | B21: 740 | C21: 3 | D21: Panda Express L 21' x W 5' x H2' (1 Throat) | E21: Jan/Apr/ Jul/Oct | F21: Every 3 Months | G21: 4 | I21: =SUM(G21*H21) -> 0
A22: D013 | B22: 740 | C22: 4 | D22: Popeye Chicken L 11' x W 2' x H 1' (1 throat) | E22: Jan through Dec | F22: monthly | G22: 12 | I22: =SUM(G22*H22) -> 0
A23: D014 | B23: 740 | C23: 5 | D23: TBD | E23: TBD | F23: TBD | G23: TBD
B24: 805 | D24: Dining Hall
A25: D016 | B25: 805 | C25: 1 | D25: Serving Line Grill L 9 x W 5' x H 4' (1 throat) Water wash system | E25: Mar/Jun/ Sep/Dec | F25: Every 3 months | G25: 4 | I25: =SUM(G25*H25) -> 0
A26: D017 | B26: 805 | C26: 2 | D26: Serving Line Grill L 9 x W 5' x H 4' (1 throat) Water wash system | E26: Mar/Jun/ Sep/Dec | F26: Every 3 months | G26: 4 | I26: =SUM(G26*H26) -> 0
A27: D018 | B27: 805 | C27: 3 | D27: Serving Line Fryer/grill/B-B-Q combo L 10' x W 5' x H 4' (1 throat) Water wash system | E27: Jan through Dec | F27: monthly | G27: 12 | I27: =SUM(G27*H27) -> 0
A28: D019 | B28: 805 | C28: 4 | D28: Serving Line Fryer/grill/B-B-Q combo L 10' x W 5' x H 4' (1 throat) Water wash system | E28: Jan through Dec | F28: monthly | G28: 12 | I28: =SUM(G28*H28) -> 0
A29: D020 | B29: 805 | C29: 5 | D29: Kitchen Ovens/Till grill/Fryer L 26' x W 5' x H 4' (2 throats with 2 turbines) Water wash system | E29: Jan through Dec | F29: monthly | G29: 12 | I29: =SUM(G29*H29) -> 0
A30: D021 | B30: 805 | C30: 6 | D30: Kitchen Kettle pots L 20' x W 5' x H 4' (2 throats) Water wash system | E30: Jun/Dec | F30: Every 6 months | G30: 2 | I30: =SUM(G30*H30) -> 0
B31: 811 | D31: N. Bowling Lane
A32: D022 | B32: 811 | C32: 1 | D32: Grill/Fryer Combo L 10' x W 3' x H 2' (1 throat) | E32: Jan/Jul | F32: Every 6 months | G32: 2 | I32: =SUM(G32*H32) -> 0
B33: 1320 | D33: Dining Hall
A34: D023 | B34: 1320 | C34: 1 | D34: Serving Line Grill L 9 x W 5' x H 4' (1 throat) Water wash system | E34: Mar/Jun/ Sep/Dec | F34: Every 3 months | G34: 4 | I34: =SUM(G34*H34) -> 0
A35: D024 | B35: 1320 | C35: 2 | D35: Serving Line Grill L 9 x W 5' x H 4' (1 throat) Water wash system | E35: Mar/Jun/ Sep/Dec | F35: Every 3 months | G35: 4 | I35: =SUM(G35*H35) -> 0
A36: D025 | B36: 1320 | C36: 3 | D36: Serving Line Fryer/grill/B-B-Q combo L 10' x W 5' x H 4' (1 throat) Water wash system | E36: Jan through Dec | F36: monthly | G36: 12 | I36: =SUM(G36*H36) -> 0
A37: D026 | B37: 1320 | C37: 4 | D37: Serving Line Fryer/grill/B-B-Q combo L 10' x W 5' x H 4' (1 throat) Water wash system | E37: Jan through Dec | F37: monthly | G37: 12 | I37: =SUM(G37*H37) -> 0
A38: D027 | B38: 1320 | C38: 5 | D38: Kitchen Ovens/Till grill/Fryer L 26' x W 5' x H 4' (2 throats with 2 turbines) Water wash system | E38: Jan through Dec | F38: monthly | G38: 12 | I38: =SUM(G38*H38) -> 0
A39: D028 | B39: 1320 | C39: 6 | D39: Kitchen Kettle pots L 20' x W 5' x H 4' (2 throats) Water wash system | E39: Jun/Dec | F39: Every 6 months | G39: 2 | I39: =SUM(G39*H39) -> 0
B40: 1368 | D40: Dining Hall
...

Sheet FY31
A1: FY31 Ordering Period 1 Oct 30 - 30 Sep 31
A2: Item # | B2: Bldg | C2: Hood label # | D2: Description | E2: months | F2: Frequency | G2: Annual # of Cleanings | H2: Unit Price | I2: Total cost
B3: 61 | D3: Food Service
A4: E001 | B4: 61 | C4: 1 | D4: Steam kettle area L 9' x W 6' x H 2' (2 throats) Self washing unit | E4: May | F4: Annual | G4: 1 | I4: =SUM(G4*H4) -> 0
A5: E002 | B5: 61 | C5: 2 | D5: Steam kettle area L 9' x W 6' x H 2' (2 throats) Self washing unit | E5: May | F5: Annual | G5: 1 | I5: =SUM(G5*H5) -> 0
A6: E003 | B6: 61 | C6: 3 | D6: Bakery (fryer - donuts) L 9' X W 5' X H 3' (2 throats) Self washing unit | E6: May | F6: Annual | G6: 1 | I6: =SUM(G6*H6) -> 0
A7: E004 | B7: 61 | C7: 4 | D7: Oven in Bakery L 4' x W 2'4" x H 2'5" (1 throat) | E7: May | F7: Annual | G7: 1 | I7: =SUM(G7*H7) -> 0
B8: 195 | D8: Child Dev Center
A9: E005 | B9: 195 | C9: 1 | D9: Kitchen Stove top/Oven L 8' x W4' x H2' (1 throat) | E9: Dec | F9: Annual | G9: 1 | I9: =SUM(G9*H9) -> 0
B10: 204 | D10: TBD
A11: E006 | B11: 204 | C11: 1 | D11: TBD | E11: TBD | F11: TBD | G11: TBD
B12: 239 | D12: TBD
A13: E007 | B13: 239 | C13: 1 | D13: TBD | E13: TBD | F13: TBD | G13: TBD
A14: E008 | B14: 239 | C14: 2 | D14: TBD | E14: TBD | F14: TBD | G14: TBD
B15: 318 | D15: S. Bowling Lane
A16: E009 | B16: 318 | C16: 1 | D16: Fryer/Grill combo L 6' x W 4' x H 3' (1 throat) | E16: Jan/Apr/ Jul/Oct | F16: Every 3 months | G16: 4 | I16: =SUM(G16*H16) -> 0
D17: Lift Rental
B18: 740 | D18: MiniMall Food Court
A19: E010 | B19: 740 | C19: 1 | D19: Taco Bell Steamer L 3' x W 3' x H 1'4" (1 throat) | E19: Feb/May/ Aug/Nov | F19: Every 3 months | G19: 4 | I19: =SUM(G19*H19) -> 0
A20: E011 | B20: 740 | C20: 2 | D20: Panda Express L 21' x W 5' x H2' (1 Throat) | E20: Jan/Apr/ Jul/Oct | F20: Every 3 Months | G20: 4 | I20: =SUM(G20*H20) -> 0
A21: E012 | B21: 740 | C21: 3 | D21: Panda Express L 21' x W 5' x H2' (1 Throat) | E21: Jan/Apr/ Jul/Oct | F21: Every 3 Months | G21: 4 | I21: =SUM(G21*H21) -> 0
A22: E013 | B22: 740 | C22: 4 | D22: Popeye Chicken L 11' x W 2' x H 1' (1 throat) | E22: Jan through Dec | F22: monthly | G22: 12 | I22: =SUM(G22*H22) -> 0
A23: E014 | B23: 740 | C23: 5 | D23: TBD | E23: TBD | F23: TBD | G23: TBD
B24: 805 | D24: Dining Hall
A25: E016 | B25: 805 | C25: 1 | D25: Serving Line Grill L 9 x W 5' x H 4' (1 throat) Water wash system | E25: Mar/Jun/ Sep/Dec | F25: Every 3 months | G25: 4 | I25: =SUM(G25*H25) -> 0
A26: E017 | B26: 805 | C26: 2 | D26: Serving Line Grill L 9 x W 5' x H 4' (1 throat) Water wash system | E26: Mar/Jun/ Sep/Dec | F26: Every 3 months | G26: 4 | I26: =SUM(G26*H26) -> 0
A27: E018 | B27: 805 | C27: 3 | D27: Serving Line Fryer/grill/B-B-Q combo L 10' x W 5' x H 4' (1 throat) Water wash system | E27: Jan through Dec | F27: monthly | G27: 12 | I27: =SUM(G27*H27) -> 0
A28: E019 | B28: 805 | C28: 4 | D28: Serving Line Fryer/grill/B-B-Q combo L 10' x W 5' x H 4' (1 throat) Water wash system | E28: Jan through Dec | F28: monthly | G28: 12 | I28: =SUM(G28*H28) -> 0
A29: E020 | B29: 805 | C29: 5 | D29: Kitchen Ovens/Till grill/Fryer L 26' x W 5' x H 4' (2 throats with 2 turbines) Water wash system | E29: Jan through Dec | F29: monthly | G29: 12 | I29: =SUM(G29*H29) -> 0
A30: E021 | B30: 805 | C30: 6 | D30: Kitchen Kettle pots L 20' x W 5' x H 4' (2 throats) Water wash system | E30: Jun/Dec | F30: Every 6 months | G30: 2 | I30: =SUM(G30*H30) -> 0
B31: 811 | D31: N. Bowling Lane
A32: E022 | B32: 811 | C32: 1 | D32: Grill/Fryer Combo L 10' x W 3' x H 2' (1 throat) | E32: Jan/Jul | F32: Every 6 months | G32: 2 | I32: =SUM(G32*H32) -> 0
B33: 1320 | D33: Dining Hall
A34: E023 | B34: 1320 | C34: 1 | D34: Serving Line Grill L 9 x W 5' x H 4' (1 throat) Water wash system | E34: Mar/Jun/ Sep/Dec | F34: Every 3 months | G34: 4 | I34: =SUM(G34*H34) -> 0
A35: E024 | B35: 1320 | C35: 2 | D35: Serving Line Grill L 9 x W 5' x H 4' (1 throat) Water wash system | E35: Mar/Jun/ Sep/Dec | F35: Every 3 months | G35: 4 | I35: =SUM(G35*H35) -> 0
A36: E025 | B36: 1320 | C36: 3 | D36: Serving Line Fryer/grill/B-B-Q combo L 10' x W 5' x H 4' (1 throat) Water wash system | E36: Jan through Dec | F36: monthly | G36: 12 | I36: =SUM(G36*H36) -> 0
A37: E026 | B37: 1320 | C37: 4 | D37: Serving Line Fryer/grill/B-B-Q combo L 10' x W 5' x H 4' (1 throat) Water wash system | E37: Jan through Dec | F37: monthly | G37: 12 | I37: =SUM(G37*H37) -> 0
A38: E027 | B38: 1320 | C38: 5 | D38: Kitchen Ovens/Till grill/Fryer L 26' x W 5' x H 4' (2 throats with 2 turbines) Water wash system | E38: Jan through Dec | F38: monthly | G38: 12 | I38: =SUM(G38*H38) -> 0
A39: E028 | B39: 1320 | C39: 6 | D39: Kitchen Kettle pots L 20' x W 5' x H 4' (2 throats) Water wash system | E39: Jun/Dec | F39: Every 6 months | G39: 2 | I39: =SUM(G39*H39) -> 0
B40: 1368 | D40: Dining Hall
...
