Workbook

Sheet 2023 MASTER LIST
A1: BLDG | B1: ='2024 DO NOT TOUCH'!B1 -> BLDG NAME | C1: ='2024 DO NOT TOUCH'!C1 -> SERIAL # | D1: ='2024 DO NOT TOUCH'!D1 -> MAKE | E1: ='2024 DO NOT TOUCH'!E1 -> MODEL | F1: ='2024 DO NOT TOUCH'!F1 -> BF TYPE | G1: ='2024 DO NOT TOUCH'!G1 -> SIZE | H1: ='2024 DO NOT TOUCH'!H1 -> LOCATION | I1: ='2024 DO NOT TOUCH'!I1 -> PREMISE/ INPREMISE | ... Y1: ='2024 DO NOT TOUCH'!Y1 -> NOTES
A2: ='2024 DO NOT TOUCH'!A2 -> 0001 | B2: ='2024 DO NOT TOUCH'!B2 -> BASE OPS | C2: ='2024 DO NOT TOUCH'!C2 -> A03206 | D2: ='2024 DO NOT TOUCH'!D2 -> WATTS | E2: ='2024 DO NOT TOUCH'!E2 -> 007QT | F2: ='2024 DO NOT TOUCH'!F2 -> DC | G2: ='2024 DO NOT TOUCH'!G2 -> 0.5 | H2: ='2024 DO NOT TOUCH'!H2 -> RM 102 UNDER SINK | ... Y2: ='2024 DO NOT TOUCH'!Y2 -> OUT OF SERVICE
A3: ='2024 DO NOT TOUCH'!A3 -> 0001 | B3: ='2024 DO NOT TOUCH'!B3 -> Base Ops | C3: ='2024 DO NOT TOUCH'!C3 -> 3336495 | D3: ='2024 DO NOT TOUCH'!D3 -> WILKINS | E3: ='2024 DO NOT TOUCH'!E3 -> 975XL | F3: ='2024 DO NOT TOUCH'!F3 -> RP | G3: ='2024 DO NOT TOUCH'!G3 -> 0.75 | H3: ='2024 DO NOT TOUCH'!H3 -> Basement | ... Y3: ='2024 DO NOT TOUCH'!Y3 -> 0
A4: ='2024 DO NOT TOUCH'!A4 -> 0001 | B4: ='2024 DO NOT TOUCH'!B4 -> BASE OPS | C4: ='2024 DO NOT TOUCH'!C4 -> 3080317 | D4: ='2024 DO NOT TOUCH'!D4 -> WILKINS | E4: ='2024 DO NOT TOUCH'!E4 -> 950XLT | F4: ='2024 DO NOT TOUCH'!F4 -> DC | G4: ='2024 DO NOT TOUCH'!G4 -> 1.5 | H4: ='2024 DO NOT TOUCH'!H4 -> FIRE SYS IN BASEMENT SHREADER RM | ... Y4: ='2024 DO NOT TOUCH'!Y4 -> 0
A5: ='2024 DO NOT TOUCH'!A5 -> 0001 | B5: ='2024 DO NOT TOUCH'!B5 -> BASE OPS | C5: ='2024 DO NOT TOUCH'!C5 -> 92420 | D5: ='2024 DO NOT TOUCH'!D5 -> WATTS | E5: ='2024 DO NOT TOUCH'!E5 -> 007QT | F5: ='2024 DO NOT TOUCH'!F5 -> PVB | G5: ='2024 DO NOT TOUCH'!G5 -> 3.0 | H5: ='2024 DO NOT TOUCH'!H5 -> IN FRONT OF BLDG ON FLIGHT LINE | ... Y5: ='2024 DO NOT TOUCH'!Y5 -> 0
A6: ='2024 DO NOT TOUCH'!A6 -> 0003 | B6: ='2024 DO NOT TOUCH'!B6 -> FIRE DEPT | C6: ='2024 DO NOT TOUCH'!C6 -> H005173 | D6: ='2024 DO NOT TOUCH'!D6 -> FEBCO | E6: ='2024 DO NOT TOUCH'!E6 -> 825YA | F6: ='2024 DO NOT TOUCH'!F6 -> RP | G6: ='2024 DO NOT TOUCH'!G6 -> 0.75 | H6: ='2024 DO NOT TOUCH'!H6 -> MECH RM ON HVAC | ... Y6: ='2024 DO NOT TOUCH'!Y6 -> 0
A7: ='2024 DO NOT TOUCH'!A7 -> 0003 | B7: ='2024 DO NOT TOUCH'!B7 -> FIRE DEPT | C7: ='2024 DO NOT TOUCH'!C7 -> W358317 | D7: ='2024 DO NOT TOUCH'!D7 -> WILKINS | E7: ='2024 DO NOT TOUCH'!E7 -> 975XL | F7: ='2024 DO NOT TOUCH'!F7 -> RP | G7: ='2024 DO NOT TOUCH'!G7 -> 0.5 | H7: ='2024 DO NOT TOUCH'!H7 -> ON ICE MACHINE | ... Y7: ='2024 DO NOT TOUCH'!Y7 -> 0
A8: ='2024 DO NOT TOUCH'!A8 -> 0003 | B8: ='2024 DO NOT TOUCH'!B8 -> FIRE DEPT | C8: ='2024 DO NOT TOUCH'!C8 -> 3338565 | D8: ='2024 DO NOT TOUCH'!D8 -> WILKINS | E8: ='2024 DO NOT TOUCH'!E8 -> 975XL | F8: ='2024 DO NOT TOUCH'!F8 -> RP | G8: ='2024 DO NOT TOUCH'!G8 -> 0.75 | H8: ='2024 DO NOT TOUCH'!H8 -> IN INDUSTRIAL LAUNDRY RM | ... Y8: ='2024 DO NOT TOUCH'!Y8 -> water line removed
A9: ='2024 DO NOT TOUCH'!A9 -> 0003 | B9: ='2024 DO NOT TOUCH'!B9 -> FIRE DEPT | C9: ='2024 DO NOT TOUCH'!C9 -> H00402 | D9: ='2024 DO NOT TOUCH'!D9 -> FEBCO | E9: ='2024 DO NOT TOUCH'!E9 -> 850 | F9: ='2024 DO NOT TOUCH'!F9 -> DC | G9: ='2024 DO NOT TOUCH'!G9 -> 0.5 | H9: ='2024 DO NOT TOUCH'!H9 -> ALARM RM UNDER SINK COFFEE | ... Y9: ='2024 DO NOT TOUCH'!Y9 -> 0
A10: ='2024 DO NOT TOUCH'!A10 -> 0003 | B10: ='2024 DO NOT TOUCH'!B10 -> FIRE DEPT | C10: ='2024 DO NOT TOUCH'!C10 -> F0303051105 | D10: ='2024 DO NOT TOUCH'!D10 -> FEBCO | E10: ='2024 DO NOT TOUCH'!E10 -> 850 | F10: ='2024 DO NOT TOUCH'!F10 -> DC | G10: ='2024 DO NOT TOUCH'!G10 -> 2.5 | H10: ='2024 DO NOT TOUCH'!H10 -> GYM RM BEHIND CABINET PANEL | ... Y10: ='2024 DO NOT TOUCH'!Y10 -> 0
A11: ='2024 DO NOT TOUCH'!A11 -> 0003 | B11: ='2024 DO NOT TOUCH'!B11 -> FIRE DEPT | C11: ='2024 DO NOT TOUCH'!C11 -> 2KM1479 | D11: ='2024 DO NOT TOUCH'!D11 -> AMES | E11: ='2024 DO NOT TOUCH'!E11 -> 2000SS | F11: ='2024 DO NOT TOUCH'!F11 -> DC | G11: ='2024 DO NOT TOUCH'!G11 -> 6.0 | H11: ='2024 DO NOT TOUCH'!H11 -> MECHANICS AREA ON FIRE SYS | ... Y11: ='2024 DO NOT TOUCH'!Y11 -> 0
A12: ='2024 DO NOT TOUCH'!A12 -> 0003 | B12: ='2024 DO NOT TOUCH'!B12 -> FIRE DEPT | C12: ='2024 DO NOT TOUCH'!C12 -> 1945116 | D12: ='2024 DO NOT TOUCH'!D12 -> WILKINS | E12: ='2024 DO NOT TOUCH'!E12 -> 950XLT | F12: ='2024 DO NOT TOUCH'!F12 -> DC | G12: ='2024 DO NOT TOUCH'!G12 -> 2.0 | H12: ='2024 DO NOT TOUCH'!H12 -> MECH RM IRRIGATION | ... Y12: ='2024 DO NOT TOUCH'!Y12 -> iso
A13: ='2024 DO NOT TOUCH'!A13 -> 0109 | B13: ='2024 DO NOT TOUCH'!B13 -> TANKER TAILS | C13: ='2024 DO NOT TOUCH'!C13 -> 26377 | D13: ='2024 DO NOT TOUCH'!D13 -> WATTS | E13: ='2024 DO NOT TOUCH'!E13 -> 007M2QT | F13: ='2024 DO NOT TOUCH'!F13 -> DC | G13: ='2024 DO NOT TOUCH'!G13 -> 1.5 | H13: ='2024 DO NOT TOUCH'!H13 -> STORAGE CLOSET NEAR WATER HEATER | ... Y13: ='2024 DO NOT TOUCH'!Y13 -> 0
... A31: ='2024 DO NOT TOUCH'!A31 -> 0445 | B31: ='2024 DO NOT TOUCH'!B31 -> 141 | C31: ='2024 DO NOT TOUCH'!C31 -> H05044 | D31: ='2024 DO NOT TOUCH'!D31 -> FEBCO | E31: ='2024 DO NOT TOUCH'!E31 -> 850 | F31: ='2024 DO NOT TOUCH'!F31 -> DC | G31: ='2024 DO NOT TOUCH'!G31 -> 1.5 | H31: ='2024 DO NOT TOUCH'!H31 -> MENCH ROOM | ... Y31: ='2024 DO NOT TOUCH'!Y31 -> 0
A32: ='2024 DO NOT TOUCH'!A32 -> 446 | B32: ='2024 DO NOT TOUCH'!B32 -> 141 | C32: ='2024 DO NOT TOUCH'!C32 -> 28862 | D32: ='2024 DO NOT TOUCH'!D32 -> WILKINS | E32: ='2024 DO NOT TOUCH'!E32 -> 350A | F32: ='2024 DO NOT TOUCH'!F32 -> DC | G32: ='2024 DO NOT TOUCH'!G32 -> 6 | H32: ='2024 DO NOT TOUCH'!H32 -> MECH ROOM FIRE | ... M32: ='2024 DO NOT TOUCH'!M32 -> FALSE | N32: ='2024 DO NOT TOUCH'!O32 -> Ted | O32: ='2024 DO NOT TOUCH'!#REF! -> #REF! | P32: ='2024 DO NOT TOUCH'!P32 -> 4 | Q32: ='2024 DO NOT TOUCH'!Q32 -> 3.6 | R32: ='2024 DO NOT TOUCH'!R32 -> 0 | S32: ='2024 DO NOT TOUCH'!S32 -> TESTED | T32: ='2024 DO NOT TOUCH'!T32 -> PASSED | U32: ='2024 DO NOT TOUCH'!U32 -> y | V32: ='2024 DO NOT TOUCH'!V32 -> 0 | W32: ='2024 DO NOT TOUCH'!W32 -> 0 | ... Y32: ='2024 DO NOT TOUCH'!Y32 -> 0
A33: ='2024 DO NOT TOUCH'!A33 -> 446 | B33: ='2024 DO NOT TOUCH'!B33 -> 141 | C33: ='2024 DO NOT TOUCH'!C33 -> 3335495 | D33: ='2024 DO NOT TOUCH'!D33 -> WILKINS | E33: ='2024 DO NOT TOUCH'!E33 -> 975XL | F33: ='2024 DO NOT TOUCH'!F33 -> RP | G33: ='2024 DO NOT TOUCH'!G33 -> .75 | H33: ='2024 DO NOT TOUCH'!H33 -> MECH ROOM | ... Y33: ='2024 DO NOT TOUCH'!Y33 -> 0
A34: ='2024 DO NOT TOUCH'!A34 -> 447 | B34: ='2024 DO NOT TOUCH'!B34 -> 141 | C34: ='2024 DO NOT TOUCH'!C34 -> H08097 | D34: ='2024 DO NOT TOUCH'!D34 -> FEBCO | E34: ='2024 DO NOT TOUCH'!E34 -> 850 | F34: ='2024 DO NOT TOUCH'!F34 -> DC | G34: ='2024 DO NOT TOUCH'!G34 -> 2 | H34: ='2024 DO NOT TOUCH'!H34 -> MECH ROOM | ... Y34: ='2024 DO NOT TOUCH'!Y34 -> 0
A35: ='2024 DO NOT TOUCH'!A35 -> 447 | B35: ='2024 DO NOT TOUCH'!B35 -> 141 | C35: ='2024 DO NOT TOUCH'!C35 -> H17256 | D35: ='2024 DO NOT TOUCH'!D35 -> FEBCO | E35: ='2024 DO NOT TOUCH'!E35 -> 850 | F35: ='2024 DO NOT TOUCH'!F35 -> DC | G35: ='2024 DO NOT TOUCH'!G35 -> 2 | H35: ='2024 DO NOT TOUCH'!H35 -> MECH ROOM | ... Y35: ='2024 DO NOT TOUCH'!Y35 -> 0
A36: ='2024 DO NOT TOUCH'!A36 -> 456 | B36: ='2024 DO NOT TOUCH'!B36 -> 141 | C36: ='2024 DO NOT TOUCH'!C36 -> H00431 | D36: ='2024 DO NOT TOUCH'!D36 -> FEBCO | E36: ='2024 DO NOT TOUCH'!E36 -> 850 | F36: ='2024 DO NOT TOUCH'!F36 -> DC | G36: ='2024 DO NOT TOUCH'!G36 -> 0.5 | H36: ='2024 DO NOT TOUCH'!H36 -> Break Room Under Sink | ... Y36: ='2024 DO NOT TOUCH'!Y36 -> 0
A37: ='2024 DO NOT TOUCH'!A37 -> 456 | B37: ='2024 DO NOT TOUCH'!B37 -> 141 | C37: ='2024 DO NOT TOUCH'!C37 -> 01515 | D37: ='2024 DO NOT TOUCH'!D37 -> FEBCO | E37: ='2024 DO NOT TOUCH'!E37 -> 850 | F37: ='2024 DO NOT TOUCH'!F37 -> DC | G37: ='2024 DO NOT TOUCH'!G37 -> 2 | H37: ='2024 DO NOT TOUCH'!H37 -> MECH ROOM | ... Y37: ='2024 DO NOT TOUCH'!Y37 -> 0
A38: ='2024 DO NOT TOUCH'!A38 -> 456 | B38: ='2024 DO NOT TOUCH'!B38 -> 141 | C38: ='2024 DO NOT TOUCH'!C38 -> 01621 | D38: ='2024 DO NOT TOUCH'!D38 -> FEBCO | E38: ='2024 DO NOT TOUCH'!E38 -> 850 | F38: ='2024 DO NOT TOUCH'!F38 -> DC | G38: ='2024 DO NOT TOUCH'!G38 -> 2 | H38: ='2024 DO NOT TOUCH'!H38 -> WOOD SHOP | ... Y38: ='2024 DO NOT TOUCH'!Y38 -> 0
A39: ='2024 DO NOT TOUCH'!A39 -> 456 | B39: ='2024 DO NOT TOUCH'!B39 -> 141 | C39: ='2024 DO NOT TOUCH'!C39 -> 358582 | D39: ='2024 DO NOT TOUCH'!D39 -> WILKINS | E39: ='2024 DO NOT TOUCH'!E39 -> 975XL | F39: ='2024 DO NOT TOUCH'!F39 -> RP | G39: ='2024 DO NOT TOUCH'!G39 -> .5 | H39: ='2024 DO NOT TOUCH'!H39 -> ICE MACHINE | ... Y39: ='2024 DO NOT TOUCH'!Y39 -> 0
A40: ='2024 DO NOT TOUCH'!A40 -> 456 | B40: ='2024 DO NOT TOUCH'!B40 -> 141 | C40: ='2024 DO NOT TOUCH'!C40 -> 08705 | D40: ='2024 DO NOT TOUCH'!D40 -> AMES | E40: ='2024 DO NOT TOUCH'!E40 -> 2000BM3 | F40: ='2024 DO NOT TOUCH'!F40 -> DC | G40: ='2024 DO NOT TOUCH'!G40 -> .75 | H40: ='2024 DO NOT TOUCH'!H40 -> SHOP WELDER | ... Y40: ='2024 DO NOT TOUCH'!Y40 -> 0
A41: ='2024 DO NOT TOUCH'!A41 -> 459 | B41: ='2024 DO NOT TOUCH'!B41 -> 141 | C41: ='2024 DO NOT TOUCH'!C41 -> 192003 | D41: ='2024 DO NOT TOUCH'!D41 -> WATTS | E41: ='2024 DO NOT TOUCH'!E41 -> 007M1QT | F41: ='2024 DO NOT TOUCH'!F41 -> DC | G41: ='2024 DO NOT TOUCH'!G41 -> 2 | H41: ='2024 DO NOT TOUCH'!H41 -> SOUTH SIDE OF ROCK BED 459 | ... Y41: ='2024 DO NOT TOUCH'!Y41 -> 0
A42: ='2024 DO NOT TOUCH'!A42 -> 459 | B42: ='2024 DO NOT TOUCH'!B42 -> 141 | C42: ='2024 DO NOT TOUCH'!C42 -> 15973 | D42: ='2024 DO NOT TOUCH'!D42 -> WATTS | E42: ='2024 DO NOT TOUCH'!E42 -> 007M2 | F42: ='2024 DO NOT TOUCH'!F42 -> DC | G42: ='2024 DO NOT TOUCH'!G42 -> .75 | H42: ='2024 DO NOT TOUCH'!H42 -> MECH ROOM | ... Y42: ='2024 DO NOT TOUCH'!Y42 -> 0
A43: ='2024 DO NOT TOUCH'!A43 -> 459 | B43: ='2024 DO NOT TOUCH'!B43 -> 141 | C43: ='2024 DO NOT TOUCH'!C43 -> 113842 | D43: ='2024 DO NOT TOUCH'!D43 -> AMES | E43: ='2024 DO NOT TOUCH'!E43 -> 3000ss | F43: ='2024 DO NOT TOUCH'!F43 -> DC | G43: ='2024 DO NOT TOUCH'!G43 -> 4.0 | H43: ='2024 DO NOT TOUCH'!H43 -> Mech room | ... Y43: ='2024 DO NOT TOUCH'!Y43 -> 0
A44: ='2024 DO NOT TOUCH'!A44 -> 0610 | B44: ='2024 DO NOT TOUCH'!B44 -> BASE THEATER | C44: ='2024 DO NOT TOUCH'!C44 -> H006780 | D44: ='2024 DO NOT TOUCH'!D44 -> FEBCO | E44: ='2024 DO NOT TOUCH'!E44 -> 765 | F44: ='2024 DO NOT TOUCH'!F44 -> PVB | G44: ='2024 DO NOT TOUCH'!G44 -> 2.0 | H44: ='2024 DO NOT TOUCH'!H44 -> IRR WEST OF THEATER CASTLE & SEATTLE | ... Y44: ='2024 DO NOT TOUCH'!Y44 -> ISOLATED
... A110: ='2024 DO NOT TOUCH'!A110 -> 1255 | B110: ='2024 DO NOT TOUCH'!B110 -> SERE INTEL | C110: ='2024 DO NOT TOUCH'!C110 -> 2HJ0943 | D110: ='2024 DO NOT TOUCH'!D110 -> AMES | E110: ='2024 DO NOT TOUCH'!E110 -> 2000 SS | F110: ='2024 DO NOT TOUCH'!F110 -> DC | G110: ='2024 DO NOT TOUCH'!G110 -> 6.0 | H110: ='2024 DO NOT TOUCH'!H110 -> MECH RM ON FIRE SYS | ... Y110: ='2024 DO NOT TOUCH'!Y110 -> 0
A111: ='2024 DO NOT TOUCH'!A111 -> 1255 | B111: ='2024 DO NOT TOUCH'!B111 -> SERE INTEL | C111: ='2024 DO NOT TOUCH'!C111 -> H00368 | D111: ='2024 DO NOT TOUCH'!D111 -> FEBCO | E111: ='2024 DO NOT TOUCH'!E111 -> 850 | F111: ='2024 DO NOT TOUCH'!F111 -> DC | G111: ='2024 DO NOT TOUCH'!G111 -> 0.5 | H111: ='2024 DO NOT TOUCH'!H111 -> RM 118 UNDER SINK COFFEE | ... U111: ='2024 DO NOT TOUCH'!U111 -> 0 | V111: ='2024 DO NOT TOUCH'!#REF! -> #REF! | W111: ='2024 DO NOT TOUCH'!W111 -> YES | X111: ='2024 DO NOT TOUCH'!X111 -> 0 | Y111: ='2024 DO NOT TOUCH'!Y111 -> REMOVED
A112: ='2024 DO NOT TOUCH'!A112 -> 1256 | B112: ='2024 DO NOT TOUCH'!B112 -> BUD DAY | C112: ='2024 DO NOT TOUCH'!C112 -> 407637 | D112: ='2024 DO NOT TOUCH'!D112 -> WATTS | E112: ='2024 DO NOT TOUCH'!E112 -> 909QT | F112: ='2024 DO NOT TOUCH'!F112 -> RP | G112: ='2024 DO NOT TOUCH'!G112 -> 1.0 | H112: ='2024 DO NOT TOUCH'!H112 -> MECH RM HVAC | ... Y112: ='2024 DO NOT TOUCH'!Y112 -> 0
A113: ='2024 DO NOT TOUCH'!A113 -> 1256 | B113: ='2024 DO NOT TOUCH'!B113 -> BUD DAY | C113: ='2024 DO NOT TOUCH'!C113 -> 9605070900 | D113: ='2024 DO NOT TOUCH'!D113 -> FEBCO | E113: ='2024 DO NOT TOUCH'!E113 -> 850 | F113: ='2024 DO NOT TOUCH'!F113 -> DC | G113: ='2024 DO NOT TOUCH'!G113 -> 6.0 | H113: ='2024 DO NOT TOUCH'!H113 -> FIRE SYS | ... Y113: ='2024 DO NOT TOUCH'!Y113 -> 0
A114: ='2024 DO NOT TOUCH'!A114 -> 1256 | B114: ='2024 DO NOT TOUCH'!B114 -> BUD DAY | C114: ='2024 DO NOT TOUCH'!C114 -> 17858 | D114: ='2024 DO NOT TOUCH'!D114 -> WATTS | E114: ='2024 DO NOT TOUCH'!E114 -> 007M2QT | F114: ='2024 DO NOT TOUCH'!F114 -> DC | G114: ='2024 DO NOT TOUCH'!G114 -> 1.5 | H114: ='2024 DO NOT TOUCH'!H114 -> IRRIGATION | ... Y114: ='2024 DO NOT TOUCH'!Y114 -> 0
A115: ='2024 DO NOT TOUCH'!A115 -> 1257 | B115: ='2024 DO NOT TOUCH'!B115 -> THE FINAL POINT | C115: ='2024 DO NOT TOUCH'!C115 -> W358336 | D115: ='2024 DO NOT TOUCH'!D115 -> WILKINS | E115: ='2024 DO NOT TOUCH'!E115 -> 975XL | F115: ='2024 DO NOT TOUCH'!F115 -> RP | G115: ='2024 DO NOT TOUCH'!G115 -> 0.5 | H115: ='2024 DO NOT TOUCH'!H115 -> BEHIND BEER TAPS ON POP MACHINE | ... Y115: ='2024 DO NOT TOUCH'!Y115 -> 0
A116: ='2024 DO NOT TOUCH'!A116 -> 1257 | B116: ='2024 DO NOT TOUCH'!B116 -> THE FINAL POINT | C116: ='2024 DO NOT TOUCH'!C116 -> W358323 | D116: ='2024 DO NOT TOUCH'!D116 -> WILKINS | E116: ='2024 DO NOT TOUCH'!E116 -> 975XL | F116: ='2024 DO NOT TOUCH'!F116 -> RP | G116: ='2024 DO NOT TOUCH'!G116 -> 0.5 | H116: ='2024 DO NOT TOUCH'!H116 -> BEHIND ICE MACHINE | ... Y116: ='2024 DO NOT TOUCH'!Y116 -> 0
A117: ='2024 DO NOT TOUCH'!A117 -> 1257 | B117: ='2024 DO NOT TOUCH'!B117 -> THE FINAL POINT | C117: ='2024 DO NOT TOUCH'!C117 -> 9706051305 | D117: ='2024 DO NOT TOUCH'!D117 -> FEBCO | E117: ='2024 DO NOT TOUCH'!E117 -> 850 | F117: ='2024 DO NOT TOUCH'!F117 -> DC | G117: ='2024 DO NOT TOUCH'!G117 -> 4.0 | H117: ='2024 DO NOT TOUCH'!H117 -> MECH RM FIRE | ... Y117: ='2024 DO NOT TOUCH'!Y117 -> 0
A118: ='2024 DO NOT TOUCH'!A118 -> 1257 | B118: ='2024 DO NOT TOUCH'!B118 -> THE FINAL POINT | C118: ='2024 DO NOT TOUCH'!C118 -> 511704 | D118: ='2024 DO NOT TOUCH'!D118 -> WILKINS | E118: ='2024 DO NOT TOUCH'!E118 -> 950XL | F118: ='2024 DO NOT TOUCH'!F118 -> DC | G118: ='2024 DO NOT TOUCH'!G118 -> 1.5 | H118: ='2024 DO NOT TOUCH'!H118 -> MECH RM IRRIGATION | ... Y118: ='2024 DO NOT TOUCH'!Y118 -> ISO
A119: ='2024 DO NOT TOUCH'!A119 -> 1257 | B119: ='2024 DO NOT TOUCH'!B119 -> THE FINAL POINT | C119: ='2024 DO NOT TOUCH'!C119 -> 542732 | D119: ='2024 DO NOT TOUCH'!D119 -> WILKINS | E119: ='2024 DO NOT TOUCH'!E119 -> 950XL | F119: ='2024 DO NOT TOUCH'!F119 -> DC | G119: ='2024 DO NOT TOUCH'!G119 -> 2.0 | H119: ='2024 DO NOT TOUCH'!H119 -> MECH RM PREMISE | ... Y119: ='2024 DO NOT TOUCH'!Y119 -> 0
A120: ='2024 DO NOT TOUCH'!A120 -> 1258 | B120: ='2024 DO NOT TOUCH'!B120 -> ROSS DINNING | C120: ='2024 DO NOT TOUCH'!C120 -> W358529 | D120: ='2024 DO NOT TOUCH'!D120 -> WILKINS | E120: ='2024 DO NOT TOUCH'!E120 -> 975XL | F120: ='2024 DO NOT TOUCH'!F120 -> RP | G120: ='2024 DO NOT TOUCH'!G120 -> 0.5 | H120: ='2024 DO NOT TOUCH'!H120 -> ICE MACHINE | ... Y120: ='2024 DO NOT TOUCH'!Y120 -> 0
A121: ='2024 DO NOT TOUCH'!A121 -> 1258 | B121: ='2024 DO NOT TOUCH'!B121 -> ROSS DINNING | C121: ='2024 DO NOT TOUCH'!C121 -> 3080479 | D121: ='2024 DO NOT TOUCH'!D121 -> WILKINS | E121: ='2024 DO NOT TOUCH'!E121 -> 975XL | F121: ='2024 DO NOT TOUCH'!F121 -> RP | G121: ='2024 DO NOT TOUCH'!G121 -> 1.5 | H121: ='2024 DO NOT TOUCH'!H121 -> MECH RM ON WATER SOFTNER | ... Y121: ='2024 DO NOT TOUCH'!Y121 -> 0
A122: ='2024 DO NOT TOUCH'!A122 -> 1258 | B122: ='2024 DO NOT TOUCH'!B122 -> ROSS DINNING | C122: ='2024 DO NOT TOUCH'!C122 -> W091273 | D122: ='2024 DO NOT TOUCH'!D122 -> WILKINS | E122: ='2024 DO NOT TOUCH'!E122 -> 975XL | F122: ='2024 DO NOT TOUCH'!F122 -> RP | G122: ='2024 DO NOT TOUCH'!G122 -> 0.5 | H122: ='2024 DO NOT TOUCH'!H122 -> MECH RM HVAC | ... V122: ='2024 DO NOT TOUCH'!V122 -> 0 | W122: ='2024 DO NOT TOUCH'!X122 -> 0 | X122: ='2024 DO NOT TOUCH'!#REF! -> #REF! | Y122: ='2024 DO NOT TOUCH'!Y122 -> ISO
...

Sheet 2023 CONTRACTOR Master List 
A1: ='2022 CONTRACTOR DO NOT TOUCH'!A1 | B1: ='2024 CONTRACTOR DO NOT TOUCH'!B1 -> BLDG NAME | C1: ='2024 CONTRACTOR DO NOT TOUCH'!C1 -> SERIAL # | D1: ='2024 CONTRACTOR DO NOT TOUCH'!D1 -> MAKE | E1: ='2024 CONTRACTOR DO NOT TOUCH'!E1 -> MODEL | F1: ='2024 CONTRACTOR DO NOT TOUCH'!F1 -> BF TYPE | G1: ='2024 CONTRACTOR DO NOT TOUCH'!G1 -> SIZE | H1: ='2024 CONTRACTOR DO NOT TOUCH'!H1 -> LAST TEST | I1: ='2024 CONTRACTOR DO NOT TOUCH'!I1 -> LOCATION | ... Y1: ='2024 CONTRACTOR DO NOT TOUCH'!Y1 -> NOTES
A2: SCHOOL | B2: ='2024 CONTRACTOR DO NOT TOUCH'!B2 -> MICHAEL ANDERSON | C2: ='2024 CONTRACTOR DO NOT TOUCH'!C2 -> F0204080725 | D2: ='2024 CONTRACTOR DO NOT TOUCH'!D2 -> FEBCO | E2: ='2024 CONTRACTOR DO NOT TOUCH'!E2 -> 850 | F2: ='2024 CONTRACTOR DO NOT TOUCH'!F2 -> DC | G2: ='2024 CONTRACTOR DO NOT TOUCH'!G2 -> 4.0 | H2: ='2024 CONTRACTOR DO NOT TOUCH'!H2 -> 0 | I2: ='2024 CONTRACTOR DO NOT TOUCH'!I2 -> IRR WEST OF SCHOOL FENCED AREA | ... Y2: ='2024 CONTRACTOR DO NOT TOUCH'!Y2 -> 0
A3: ='2024 CONTRACTOR DO NOT TOUCH'!A3 -> SCHOOL | B3: ='2024 CONTRACTOR DO NOT TOUCH'!B3 -> MICHAEL ANDERSON | C3: ='2024 CONTRACTOR DO NOT TOUCH'!C3 -> 1339754 | D3: ='2024 CONTRACTOR DO NOT TOUCH'!D3 -> WILKINS | E3: ='2024 CONTRACTOR DO NOT TOUCH'!E3 -> 975XL | F3: ='2024 CONTRACTOR DO NOT TOUCH'!F3 -> RP | G3: ='2024 CONTRACTOR DO NOT TOUCH'!G3 -> 0.75 | H3: ='2024 CONTRACTOR DO NOT TOUCH'!H3 -> 0 | ... Y3: ='2024 CONTRACTOR DO NOT TOUCH'!Y3 -> 0
A4: ='2024 CONTRACTOR DO NOT TOUCH'!A4 -> SCHOOL | B4: ='2024 CONTRACTOR DO NOT TOUCH'!B4 -> MICHAEL ANDERSON | C4: ='2024 CONTRACTOR DO NOT TOUCH'!C4 -> U28838 | D4: ='2024 CONTRACTOR DO NOT TOUCH'!D4 -> WILKINS | E4: ='2024 CONTRACTOR DO NOT TOUCH'!E4 -> 350A | F4: ='2024 CONTRACTOR DO NOT TOUCH'!F4 -> DC | G4: ='2024 CONTRACTOR DO NOT TOUCH'!G4 -> 4.0 | H4: ='2024 CONTRACTOR DO NOT TOUCH'!H4 -> 0 | ... Y4: ='2024 CONTRACTOR DO NOT TOUCH'!Y4 -> 0
A5: ='2024 CONTRACTOR DO NOT TOUCH'!A5 -> SCHOOL | B5: ='2024 CONTRACTOR DO NOT TOUCH'!B5 -> MICHAEL ANDERSON | C5: ='2024 CONTRACTOR DO NOT TOUCH'!C5 -> J08247 | D5: ='2024 CONTRACTOR DO NOT TOUCH'!D5 -> WILKINS | E5: ='2024 CONTRACTOR DO NOT TOUCH'!E5 -> 350 | F5: ='2024 CONTRACTOR DO NOT TOUCH'!F5 -> DC | G5: ='2024 CONTRACTOR DO NOT TOUCH'!G5 -> 3.0 | H5: ='2024 CONTRACTOR DO NOT TOUCH'!H5 -> 43822 | ... Y5: ='2024 CONTRACTOR DO NOT TOUCH'!Y5 -> 0
A6: ='2024 CONTRACTOR DO NOT TOUCH'!A6 -> HOUSING | B6: ='2024 CONTRACTOR DO NOT TOUCH'!B6 -> FAFB HOUSING | C6: ='2024 CONTRACTOR DO NOT TOUCH'!C6 -> 008307 | D6: ='2024 CONTRACTOR DO NOT TOUCH'!D6 -> WATTS | E6: ='2024 CONTRACTOR DO NOT TOUCH'!E6 -> LF007M1QT | F6: ='2024 CONTRACTOR DO NOT TOUCH'!F6 -> DC | G6: ='2024 CONTRACTOR DO NOT TOUCH'!G6 -> 2.0 | H6: ='2024 CONTRACTOR DO NOT TOUCH'!H6 -> 0 | ... Y6: ='2024 CONTRACTOR DO NOT TOUCH'!Y6 -> 0
A7: ='2024 CONTRACTOR DO NOT TOUCH'!A7 -> HOUSING | B7: ='2024 CONTRACTOR DO NOT TOUCH'!B7 -> FAFB HOUSING | C7: ='2024 CONTRACTOR DO NOT TOUCH'!C7 -> X13788 | D7: ='2024 CONTRACTOR DO NOT TOUCH'!D7 -> WILKINS | E7: ='2024 CONTRACTOR DO NOT TOUCH'!E7 -> 375A | F7: ='2024 CONTRACTOR DO NOT TOUCH'!F7 -> RP | G7: ='2024 CONTRACTOR DO NOT TOUCH'!G7 -> 8.0 | H7: ='2024 CONTRACTOR DO NOT TOUCH'!H7 -> 0 | ... Y7: ='2024 CONTRACTOR DO NOT TOUCH'!Y7 -> 0
A8: ='2024 CONTRACTOR DO NOT TOUCH'!A8 -> HOUSING | B8: ='2024 CONTRACTOR DO NOT TOUCH'!B8 -> FAFB HOUSING | C8: ='2024 CONTRACTOR DO NOT TOUCH'!C8 -> L50441 | D8: ='2024 CONTRACTOR DO NOT TOUCH'!D8 -> WILKINS | E8: ='2024 CONTRACTOR DO NOT TOUCH'!E8 -> 375 | F8: ='2024 CONTRACTOR DO NOT TOUCH'!F8 -> RP | G8: ='2024 CONTRACTOR DO NOT TOUCH'!G8 -> 10.0 | H8: ='2024 CONTRACTOR DO NOT TOUCH'!H8 -> 0 | ... Y8: ='2024 CONTRACTOR DO NOT TOUCH'!Y8 -> 0
A9: ='2024 CONTRACTOR DO NOT TOUCH'!A9 -> HOUSING | B9: ='2024 CONTRACTOR DO NOT TOUCH'!B9 -> FAFB HOUSING | C9: ='2024 CONTRACTOR DO NOT TOUCH'!C9 -> L50440 | D9: ='2024 CONTRACTOR DO NOT TOUCH'!D9 -> WILKINS | E9: ='2024 CONTRACTOR DO NOT TOUCH'!E9 -> 375 | F9: ='2024 CONTRACTOR DO NOT TOUCH'!F9 -> RP | G9: ='2024 CONTRACTOR DO NOT TOUCH'!G9 -> 10.0 | H9: ='2024 CONTRACTOR DO NOT TOUCH'!H9 -> 0 | ... Y9: ='2024 CONTRACTOR DO NOT TOUCH'!Y9 -> 0
A10: ='2024 CONTRACTOR DO NOT TOUCH'!A10 -> HOUSING | B10: ='2024 CONTRACTOR DO NOT TOUCH'!B10 -> FAFB HOUSING | C10: ='2024 CONTRACTOR DO NOT TOUCH'!C10 -> L50442 | D10: ='2024 CONTRACTOR DO NOT TOUCH'!D10 -> WILKINS | E10: ='2024 CONTRACTOR DO NOT TOUCH'!E10 -> 375A | F10: ='2024 CONTRACTOR DO NOT TOUCH'!F10 -> RP | G10: ='2024 CONTRACTOR DO NOT TOUCH'!G10 -> 10.0 | H10: ='2024 CONTRACTOR DO NOT TOUCH'!H10 -> 0 | ... Y10: ='2024 CONTRACTOR DO NOT TOUCH'!Y10 -> 0
A11: ='2024 CONTRACTOR DO NOT TOUCH'!A11 -> 0001 | B11: ='2024 CONTRACTOR DO NOT TOUCH'!B11 -> ALASKA BOILER | C11: ='2024 CONTRACTOR DO NOT TOUCH'!C11 -> 3336495 | D11: ='2024 CONTRACTOR DO NOT TOUCH'!D11 -> WILKINS | E11: ='2024 CONTRACTOR DO NOT TOUCH'!E11 -> 975XL | F11: ='2024 CONTRACTOR DO NOT TOUCH'!F11 -> RP | G11: ='2024 CONTRACTOR DO NOT TOUCH'!G11 -> 0.75 | H11: ='2024 CONTRACTOR DO NOT TOUCH'!H11 -> 0 | ... Y11: ='2024 CONTRACTOR DO NOT TOUCH'!Y11 -> 0
A12: ='2024 CONTRACTOR DO NOT TOUCH'!A12 -> 0001 | B12: ='2024 CONTRACTOR DO NOT TOUCH'!B12 -> ALASKA BOILER | C12: ='2024 CONTRACTOR DO NOT TOUCH'!C12 -> 1363820 | D12: ='2024 CONTRACTOR DO NOT TOUCH'!D12 -> WILKINS | E12: ='2024 CONTRACTOR DO NOT TOUCH'!E12 -> 975XL | F12: ='2024 CONTRACTOR DO NOT TOUCH'!F12 -> RP | G12: ='2024 CONTRACTOR DO NOT TOUCH'!G12 -> 0.75 | H12: ='2024 CONTRACTOR DO NOT TOUCH'!H12 -> 0 | ... Y12: ='2024 CONTRACTOR DO NOT TOUCH'!Y12 -> 0
A13: ='2024 CONTRACTOR DO NOT TOUCH'!A13 -> 0285 | B13: ='2024 CONTRACTOR DO NOT TOUCH'!B13 -> ALASKA BOILER | C13: ='2024 CONTRACTOR DO NOT TOUCH'!C13 -> 1394537 | D13: ='2024 CONTRACTOR DO NOT TOUCH'!D13 -> WILKINS | E13: ='2024 CONTRACTOR DO NOT TOUCH'!E13 -> 975XL | F13: ='2024 CONTRACTOR DO NOT TOUCH'!F13 -> RP | G13: ='2024 CONTRACTOR DO NOT TOUCH'!G13 -> 0.75 | H13: ='2024 CONTRACTOR DO NOT TOUCH'!H13 -> 0 | ... Y13: ='2024 CONTRACTOR DO NOT TOUCH'!Y13 -> 0
A14: ='2024 CONTRACTOR DO NOT TOUCH'!A14 -> 1029 | B14: ='2024 CONTRACTOR DO NOT TOUCH'!B14 -> ALASKA BOILER | C14: ='2024 CONTRACTOR DO NOT TOUCH'!C14 -> 1363765 | D14: ='2024 CONTRACTOR DO NOT TOUCH'!D14 -> WILKINS | E14: ='2024 CONTRACTOR DO NOT TOUCH'!E14 -> 975XL | F14: ='2024 CONTRACTOR DO NOT TOUCH'!F14 -> RP | G14: ='2024 CONTRACTOR DO NOT TOUCH'!G14 -> 0.75 | H14: ='2024 CONTRACTOR DO NOT TOUCH'!H14 -> 0 | ... Y14: ='2024 CONTRACTOR DO NOT TOUCH'!Y14 -> 0
... A80: ='2024 CONTRACTOR DO NOT TOUCH'!A80 -> 2424 | B80: ='2024 CONTRACTOR DO NOT TOUCH'!B80 -> CLINIC | C80: ='2024 CONTRACTOR DO NOT TOUCH'!C80 -> V38798 | D80: ='2024 CONTRACTOR DO NOT TOUCH'!D80 -> WILKINS | E80: ='2024 CONTRACTOR DO NOT TOUCH'!E80 -> 350ADA | F80: ='2024 CONTRACTOR DO NOT TOUCH'!F80 -> DCDA | G80: ='2024 CONTRACTOR DO NOT TOUCH'!G80 -> 2.5 | H80: ='2024 CONTRACTOR DO NOT TOUCH'!H80 -> 0 | ... Y80: ='2024 CONTRACTOR DO NOT TOUCH'!Y80 -> 0
A81: ='2024 CONTRACTOR DO NOT TOUCH'!A82 -> 2424 | B81: ='2024 CONTRACTOR DO NOT TOUCH'!B82 -> CLINIC | C81: ='2024 CONTRACTOR DO NOT TOUCH'!C82 -> 384426 | D81: ='2024 CONTRACTOR DO NOT TOUCH'!D82 -> WILKINS | E81: ='2024 CONTRACTOR DO NOT TOUCH'!E82 -> 950XL | F81: ='2024 CONTRACTOR DO NOT TOUCH'!F82 -> DCDA | G81: ='2024 CONTRACTOR DO NOT TOUCH'!G82 -> 0.75 | H81: ='2024 CONTRACTOR DO NOT TOUCH'!H82 -> 0 | ... Y81: ='2024 CONTRACTOR DO NOT TOUCH'!Y82 -> 0
A82: ='2024 CONTRACTOR DO NOT TOUCH'!A83 -> 2425 | B82: ='2024 CONTRACTOR DO NOT TOUCH'!B83 -> CLINIC | C82: ='2024 CONTRACTOR DO NOT TOUCH'!C83 -> 384427 | D82: ='2024 CONTRACTOR DO NOT TOUCH'!D83 -> WILKINS | E82: ='2024 CONTRACTOR DO NOT TOUCH'!E83 -> 950XL | F82: ='2024 CONTRACTOR DO NOT TOUCH'!F83 -> DCDA | G82: ='2024 CONTRACTOR DO NOT TOUCH'!G83 -> 0.76 | H82: ='2024 CONTRACTOR DO NOT TOUCH'!H83 -> 0 | ... Y82: ='2024 CONTRACTOR DO NOT TOUCH'!Y83 -> 0
A83: ='2024 CONTRACTOR DO NOT TOUCH'!A84 -> 2426 | B83: ='2024 CONTRACTOR DO NOT TOUCH'!B84 -> CLINIC | C83: ='2024 CONTRACTOR DO NOT TOUCH'!C84 -> 384428 | D83: ='2024 CONTRACTOR DO NOT TOUCH'!D84 -> WILKINS | E83: ='2024 CONTRACTOR DO NOT TOUCH'!E84 -> 950XL | F83: ='2024 CONTRACTOR DO NOT TOUCH'!F84 -> DCDA | G83: ='2024 CONTRACTOR DO NOT TOUCH'!G84 -> 0.77 | H83: ='2024 CONTRACTOR DO NOT TOUCH'!H84 -> 0 | ... Y83: ='2024 CONTRACTOR DO NOT TOUCH'!Y84 -> 0
A84: ='2024 CONTRACTOR DO NOT TOUCH'!A85 -> 2427 | B84: ='2024 CONTRACTOR DO NOT TOUCH'!B85 -> CLINIC | C84: ='2024 CONTRACTOR DO NOT TOUCH'!C85 -> 384429 | D84: ='2024 CONTRACTOR DO NOT TOUCH'!D85 -> WILKINS | E84: ='2024 CONTRACTOR DO NOT TOUCH'!E85 -> 950XL | F84: ='2024 CONTRACTOR DO NOT TOUCH'!F85 -> DCDA | G84: ='2024 CONTRACTOR DO NOT TOUCH'!G85 -> 0.78 | H84: ='2024 CONTRACTOR DO NOT TOUCH'!H85 -> 0 | ... Y84: ='2024 CONTRACTOR DO NOT TOUCH'!Y85 -> 0

Sheet Data Sets
A1: OPERATOR NAME DATASET | F1: BF MAKE | H1: BF TYPE | J1: HAZARD NAMES | M1: CONTRACTOR INFO
A2: BACKFLOW ID | B2: Operator Nick Names | C2: First Name | D2: Last Name | F2: MAKE | H2: BACKFLOW TYPE | J2: HAZARD TYPES | K2: FULL NAME | M2: FIRST NAME | N2: LAST NAME | O2: B.A.T. NUMBER | P2: COMPANY | Q2: TEST KIT I.D. | R2: SITE TESTING | S2: YEAR TESTED
A3: B6244 | B3: ELI | C3: ELI | D3: COX | F3: WILKINS | H3: RP | J3: PREMISE | K3: MAIN COLD WATER | M3: TOM | N3: MAJOR | O3: B3988 | P3: FIRE CONTROL | Q3: 7121204 | R3: SCHOOL | S3: 2021
A4: B4527 | B4: PASS | C4: CHRISTOPHER | D4: PASSMORE | F4: AMES | H4: DC | J4: AOI | K4: INPREMISE (ALL OTHER) | M4: SCOTT | N4: JINKENS | O4: B6141 | P4: MCKINSTRY CO. | Q4: 771454 | R4: HOUSING | S4: 2021
A5: B7324 | B5: REED | C5: MATTHEW | D5: REED | F5: FEBCO | H5: RPDA | J5: FIRE | K5: FIRE SUPPLY | M5: GARY | N5: Hartman | O5: B5725 | P5: FIRE CONTROL | Q5: 6132321 | R5: SCHOOL | S5: 2023
A6: B7341 | B6: Ram | C6: Ivan | D6: Ramirez | F6: WATTS | H6: SVB | M6: WAYNE | N6: GORDON | O6: B5725 | P6: PATRIOT FIRE | Q6: 7112810 | R6: CLINIC | S6: 2021
A7: B7314 | B7: GRIFF | C7: MICHAEL | D7: GRIFFITH | F7: APOLLO
A8: B6780 | B8: PARK | C8: BONNIE | D8: PARKER | F8: DERINGER
A9: B7184 | B9: BARC | C9: CHRISTOBAL | D9: BARCENAS
A10: B6945 | B10: Black | C10: Timothy | D10: Black
A11: B7357 | B11: Ted | C11: Ted | D11: Anderson
A12: B6966 | B12: CONTR | C12: CONTRACTOR | D12: CONTRACTOR
A13: B7476 | B13: JAKE | C13: JAKE | D13: SAUER
A14: B7545 | B14: LARIOS | C14: ANTHONY | D14: LARIOS
A15: B7479 | B15: TROUNG | C15: QUOC | D15: TROUNG
A16: B7498 | B16: Bruce | C16: Bruce | D16: Kennedy
A17: B3677 | B17: JEFF | C17: JEFF | D17: JEWERLL
A18: B6141 | B18: Scott | C18: Scott | D18: Jnkens
A19: B5159 | B19: BILL | C19: BILL | D19: ROE
A20: B7907 | B20: Haveron | C20: AUSTIN | D20: HAVERON
A21: B5725 | B21: GARY | C21: GARY | D21: HARTMAN

Sheet 2024 ASR NUMBERS
B2: FAFB 92CES TESTED
B4: PREMISE TOTALS | D4: ACTIVE | E4: TESTED | F4: FAILED | H4: INPREMISE TOTALS | J4: ACTIVE | K4: TESTED | L4: FAILED | N4: TOTAL ACTIVE
B5: DC | C5: =COUNTIFS('2023 MASTER LIST'!I:I,"PREMISE",'2023 MASTER LIST'!F:F,"DC") -> 235 | D5: =COUNTIFS('2023 MASTER LIST'!I:I,"PREMISE",'2023 MASTER LIST'!F:F,"DC",'2023 MASTER LIST'!K:K,"ACTIVE") -> 211 | E5: =COUNTIFS('2023 MASTER LIST'!I:I,"PREMISE",'2023 MASTER LIST'!F:F,"DC",'2023 MASTER LIST'!K:K,"ACTIVE",'2023 MASTER LIST'!S:S,"TESTED") -> 172 | F5: =COUNTIFS('2023 MASTER LIST'!I:I,"PREMISE",'2023 MASTER LIST'!F:F,"DC",'2023 MASTER LIST'!S:S,"TESTED",'2023 MASTER LIST'!T:T,"FAILED") -> 0 | H5: DC | I5: =COUNTIFS('2023 MASTER LIST'!I:I,"INPREMISE",'2023 MASTER LIST'!F:F,"DC") -> 22 | J5: =COUNTIFS('2023 MASTER LIST'!I:I,"INPREMISE",'2023 MASTER LIST'!F:F,"DC",'2023 MASTER LIST'!K:K,"ACTIVE") -> 18 | K5: =COUNTIFS('2023 MASTER LIST'!I:I,"INPREMISE",'2023 MASTER LIST'!F:F,"DC",'2023 MASTER LIST'!K:K,"ACTIVE",'2023 MASTER LIST'!S:S,"TESTED") -> 13 | L5: =COUNTIFS('2023 MASTER LIST'!I:I,"PREMISE",'2023 MASTER LIST'!F:F,"DC",'2023 MASTER LIST'!S:S,"TESTED",'2023 MASTER LIST'!T:T,"FAILED") -> 0 | N5: =D5+J5 -> 229
B6: RP | C6: =COUNTIFS('2023 MASTER LIST'!I:I,"PREMISE",'2023 MASTER LIST'!F:F,"RP") -> 51 | D6: =COUNTIFS('2023 MASTER LIST'!I:I,"PREMISE",'2023 MASTER LIST'!F:F,"RP",'2023 MASTER LIST'!K:K,"ACTIVE") -> 50 | E6: =COUNTIFS('2023 MASTER LIST'!I:I,"PREMISE",'2023 MASTER LIST'!F:F,"RP",'2023 MASTER LIST'!K:K,"ACTIVE",'2023 MASTER LIST'!S:S,"TESTED") -> 48 | F6: =COUNTIFS('2023 MASTER LIST'!I:I,"PREMISE",'2023 MASTER LIST'!F:F,"RP",'2023 MASTER LIST'!S:S,"TESTED",'2023 MASTER LIST'!T:T,"FAILED") -> 1 | H6: RP | I6: =COUNTIFS('2023 MASTER LIST'!I:I,"INPREMISE",'2023 MASTER LIST'!F:F,"RP") -> 149 | J6: =COUNTIFS('2023 MASTER LIST'!I:I,"INPREMISE",'2023 MASTER LIST'!F:F,"RP",'2023 MASTER LIST'!K:K,"ACTIVE") -> 127 | K6: =COUNTIFS('2023 MASTER LIST'!I:I,"INPREMISE",'2023 MASTER LIST'!F:F,"RP",'2023 MASTER LIST'!K:K,"ACTIVE",'2023 MASTER LIST'!S:S,"TESTED") -> 110 | L6: =COUNTIFS('2023 MASTER LIST'!I:I,"PREMISE",'2023 MASTER LIST'!F:F,"RP",'2023 MASTER LIST'!S:S,"TESTED",'2023 MASTER LIST'!T:T,"FAILED") -> 1 | N6: =D6+J6 -> 177
B7: PVB | C7: =COUNTIFS('2023 MASTER LIST'!I:I,"PREMISE",'2023 MASTER LIST'!F:F,"PVB") -> 13 | D7: =COUNTIFS('2023 MASTER LIST'!I:I,"PREMISE",'2023 MASTER LIST'!F:F,"PVB",'2023 MASTER LIST'!K:K,"ACTIVE") -> 6 | E7: =COUNTIFS('2023 MASTER LIST'!I:I,"PREMISE",'2023 MASTER LIST'!F:F,"PVB",'2023 MASTER LIST'!K:K,"ACTIVE",'2023 MASTER LIST'!S:S,"TESTED") -> 4 | F7: =COUNTIFS('2023 MASTER LIST'!I:I,"PREMISE",'2023 MASTER LIST'!F:F,"PVB",'2023 MASTER LIST'!S:S,"TESTED",'2023 MASTER LIST'!T:T,"FAILED") -> 1 | H7: PVB | I7: =COUNTIFS('2023 MASTER LIST'!I:I,"INPREMISE",'2023 MASTER LIST'!F:F,"PVB") -> 2 | J7: =COUNTIFS('2023 MASTER LIST'!I:I,"INPREMISE",'2023 MASTER LIST'!F:F,"PVB",'2023 MASTER LIST'!K:K,"ACTIVE") -> 2 | K7: =COUNTIFS('2023 MASTER LIST'!I:I,"INPREMISE",'2023 MASTER LIST'!F:F,"PVB",'2023 MASTER LIST'!K:K,"ACTIVE",'2023 MASTER LIST'!S:S,"TESTED") -> 2 | L7: =COUNTIFS('2024 DO NOT TOUCH'!J:J,"PREMISE",#REF!,"PVB",'2024 DO NOT TOUCH'!S:S,"TESTED",'2024 DO NOT TOUCH'!T:T,"FAILED") -> #REF! | N7: =D7+J7 -> 8
B8: DCDA | C8: =COUNTIFS('2023 MASTER LIST'!I:I,"PREMISE",'2023 MASTER LIST'!F:F,"DCDA")/2 -> 7.5 | D8: =COUNTIFS('2023 MASTER LIST'!I:I,"PREMISE",'2023 MASTER LIST'!F:F,"DCDA",'2023 MASTER LIST'!K:K,"ACTIVE")/2 -> 7 | E8: =COUNTIFS('2023 MASTER LIST'!I:I,"PREMISE",'2023 MASTER LIST'!F:F,"DCDA",'2023 MASTER LIST'!K:K,"ACTIVE",'2023 MASTER LIST'!S:S,"TESTED")/2 -> 7 | F8: =COUNTIFS('2023 MASTER LIST'!I:I,"PREMISE",'2023 MASTER LIST'!F:F,"DCDA",'2023 MASTER LIST'!S:S,"TESTED",'2023 MASTER LIST'!T:T,"FAILED") -> 0 | H8: DCDA | I8: =COUNTIFS('2023 MASTER LIST'!I:I,"INPREMISE",'2023 MASTER LIST'!F:F,"DCDA")/2 -> 0 | J8: =COUNTIFS('2023 MASTER LIST'!I:I,"INPREMISE",'2023 MASTER LIST'!F:F,"DCDA",'2023 MASTER LIST'!K:K,"ACTIVE")/2 -> 0 | K8: =COUNTIFS('2023 MASTER LIST'!I:I,"INPREMISE",'2023 MASTER LIST'!F:F,"DCDA",'2023 MASTER LIST'!K:K,"ACTIVE",'2023 MASTER LIST'!S:S,"TESTED")/2 -> 0 | L8: =COUNTIFS('2023 MASTER LIST'!I:I,"PREMISE",'2023 MASTER LIST'!F:F,"DCDA",'2023 MASTER LIST'!S:S,"TESTED",'2023 MASTER LIST'!T:T,"FAILED") -> 0 | N8: =D8+J8 -> 7
B9: SVB | C9: =COUNTIFS('2023 MASTER LIST'!I:I,"PREMISE",'2023 MASTER LIST'!F:F,"SVB") -> 0 | D9: =COUNTIFS('2023 MASTER LIST'!I:I,"PREMISE",'2023 MASTER LIST'!F:F,"SVB",'2023 MASTER LIST'!K:K,"ACTIVE") -> 0 | E9: =COUNTIFS('2023 MASTER LIST'!I:I,"PREMISE",'2023 MASTER LIST'!F:F,"SVB",'2023 MASTER LIST'!K:K,"ACTIVE",'2023 MASTER LIST'!S:S,"TESTED") -> 0 | F9: =COUNTIFS('2023 MASTER LIST'!I:I,"PREMISE",'2023 MASTER LIST'!F:F,"SVB",'2023 MASTER LIST'!S:S,"TESTED",'2023 MASTER LIST'!T:T,"FAILED") -> 0 | H9: SVB | I9: =COUNTIFS('2023 MASTER LIST'!I:I,"INPREMISE",'2023 MASTER LIST'!F:F,"SVB") -> 2 | J9: =COUNTIFS('2023 MASTER LIST'!I:I,"INPREMISE",'2023 MASTER LIST'!F:F,"SVB",'2023 MASTER LIST'!K:K,"ACTIVE") -> 2 | K9: =COUNTIFS('2023 MASTER LIST'!I:I,"INPREMISE",'2023 MASTER LIST'!F:F,"SVB",'2023 MASTER LIST'!K:K,"ACTIVE",'2023 MASTER LIST'!S:S,"TESTED") -> 2 | L9: =COUNTIFS('2023 MASTER LIST'!I:I,"PREMISE",'2023 MASTER LIST'!F:F,"SVB",'2023 MASTER LIST'!S:S,"TESTED",'2023 MASTER LIST'!T:T,"FAILED") -> 0 | N9: =D9+J9 -> 2
M10: ACTIVE | N10: =SUM(N5:N9) -> 423
B13: TOTAL DEVICES | C13: TOTAL INACTIVE | D13: TOTAL ACTIVE | E13: TOTAL TESTED | F13: TOTAL FAILED | G13: TOTAL UNTESTED | N13: PERCENT COMPLETE
B14: =SUM(C5:C9,I5:I9) -> 481.5 | C14: =B14-D14 -> 58.5 | D14: =N10 -> 423 | E14: =SUM(E5:E9,K5:K9) -> 358 | F14: =SUM(F5:F9,L5:L9) -> #REF! | G14: =D14-E14 -> 65 | N14: =E14/D14 -> 0.8463357
B16: CONTRACTOR TESTED
B18: PREMISE TOTALS | D18: ACTIVE | E18: TESTED | F18: FAILED | H18: INPREMISE TOTALS | J18: ACTIVE | K18: TESTED | L18: FAILED | N18: TOTAL
B19: DC | C19: =COUNTIFS('2023 CONTRACTOR Master List '!J:J,"PREMISE",'2023 CONTRACTOR Master List '!F:F,"DC") -> 8 | D19: =COUNTIFS('2023 CONTRACTOR Master List '!J:J,"PREMISE",'2023 CONTRACTOR Master List '!F:F,"DC",'2023 CONTRACTOR Master List '!L:L,"ACTIVE") -> 8 | E19: =COUNTIFS('2023 CONTRACTOR Master List '!J:J,"PREMISE",'2023 CONTRACTOR Master List '!F:F,"DC",'2023 CONTRACTOR Master List '!L:L,"ACTIVE",'2023 CONTRACTOR Master List '!S:S,"TESTED") -> 5 | F19: =COUNTIFS('2023 CONTRACTOR Master List '!J:J,"PREMISE",'2023 CONTRACTOR Master List '!F:F,"DC",'2023 CONTRACTOR Master List '!L:L,"ACTIVE",'2023 CONTRACTOR Master List '!S:S,"TESTED",'2023 CONTRACTOR Master List '!T:T,"FAILED") -> 0 | H19: DC | I19: =COUNTIFS('2023 CONTRACTOR Master List '!J:J,"INPREMISE",'2023 CONTRACTOR Master List '!F:F,"DC") -> 1 | J19: =COUNTIFS('2023 CONTRACTOR Master List '!J:J,"INPREMISE",'2023 CONTRACTOR Master List '!F:F,"DC",'2023 CONTRACTOR Master List '!L:L,"ACTIVE") -> 1 | K19: =COUNTIFS('2023 CONTRACTOR Master List '!J:J,"INPREMISE",'2023 CONTRACTOR Master List '!F:F,"DC",'2023 CONTRACTOR Master List '!L:L,"ACTIVE",'2023 CONTRACTOR Master List '!S:S,"TESTED") -> 1 | L19: =COUNTIFS('2023 CONTRACTOR Master List '!J:J,"INPREMISE",'2023 CONTRACTOR Master List '!F:F,"DC",'2023 CONTRACTOR Master List '!L:L,"ACTIVE",'2023 CONTRACTOR Master List '!S:S,"TESTED",'2023 CONTRACTOR Master List '!T:T,"FAILED") -> 0 | N19: =D19+J19 -> 9
B20: RP | C20: =COUNTIFS('2023 CONTRACTOR Master List '!J:J,"PREMISE",'2023 CONTRACTOR Master List '!F:F,"RP") -> 11 | D20: =COUNTIFS('2023 CONTRACTOR Master List '!J:J,"PREMISE",'2023 CONTRACTOR Master List '!F:F,"RP",'2023 CONTRACTOR Master List '!L:L,"ACTIVE") -> 11 | E20: =COUNTIFS('2023 CONTRACTOR Master List '!J:J,"PREMISE",'2023 CONTRACTOR Master List '!F:F,"RP",'2023 CONTRACTOR Master List '!L:L,"ACTIVE",'2023 CONTRACTOR Master List '!S:S,"TESTED") -> 11 | F20: =COUNTIFS('2023 CONTRACTOR Master List '!J:J,"PREMISE",'2023 CONTRACTOR Master List '!F:F,"RP",'2023 CONTRACTOR Master List '!L:L,"ACTIVE",'2023 CONTRACTOR Master List '!S:S,"TESTED",'2023 CONTRACTOR Master List '!T:T,"FAILED") -> 1 | H20: RP | I20: =COUNTIFS('2023 CONTRACTOR Master List '!J:J,"INPREMISE",'2023 CONTRACTOR Master List '!F:F,"RP") -> 56 | J20: =COUNTIFS('2023 CONTRACTOR Master List '!J:J,"INPREMISE",'2023 CONTRACTOR Master List '!F:F,"RP",'2023 CONTRACTOR Master List '!L:L,"ACTIVE") -> 56 | K20: =COUNTIFS('2023 CONTRACTOR Master List '!J:J,"INPREMISE",'2023 CONTRACTOR Master List '!F:F,"RP",'2023 CONTRACTOR Master List '!L:L,"ACTIVE",'2023 CONTRACTOR Master List '!S:S,"TESTED") -> 54 | L20: =COUNTIFS('2023 CONTRACTOR Master List '!J:J,"INPREMISE",'2023 CONTRACTOR Master List '!F:F,"RP",'2023 CONTRACTOR Master List '!L:L,"ACTIVE",'2023 CONTRACTOR Master List '!S:S,"TESTED",'2023 CONTRACTOR Master List '!T:T,"FAILED") -> 1 | N20: =D20+J20 -> 67
B21: PVB | C21: =COUNTIFS('2023 CONTRACTOR Master List '!J:J,"PREMISE",'2023 CONTRACTOR Master List '!F:F,"PVB") -> 0 | D21: =COUNTIFS('2023 CONTRACTOR Master List '!J:J,"PREMISE",'2023 CONTRACTOR Master List '!F:F,"PVB",'2023 CONTRACTOR Master List '!L:L,"ACTIVE") -> 0 | E21: =COUNTIFS('2023 CONTRACTOR Master List '!J:J,"PREMISE",'2023 CONTRACTOR Master List '!F:F,"PVB",'2023 CONTRACTOR Master List '!L:L,"ACTIVE",'2023 CONTRACTOR Master List '!S:S,"TESTED") -> 0 | F21: =COUNTIFS('2023 CONTRACTOR Master List '!J:J,"PREMISE",'2023 CONTRACTOR Master List '!F:F,"PVB",'2023 CONTRACTOR Master List '!L:L,"ACTIVE",'2023 CONTRACTOR Master List '!S:S,"TESTED",'2023 CONTRACTOR Master List '!T:T,"FAILED") -> 0 | H21: PVB | I21: =COUNTIFS('2023 CONTRACTOR Master List '!J:J,"INPREMISE",'2023 CONTRACTOR Master List '!F:F,"PVB") -> 0 | J21: =COUNTIFS('2023 CONTRACTOR Master List '!J:J,"INPREMISE",'2023 CONTRACTOR Master List '!F:F,"PVB",'2023 CONTRACTOR Master List '!L:L,"ACTIVE") -> 0 | K21: =COUNTIFS('2023 CONTRACTOR Master List '!J:J,"INPREMISE",'2023 CONTRACTOR Master List '!F:F,"PVB",'2023 CONTRACTOR Master List '!L:L,"ACTIVE",'2023 CONTRACTOR Master List '!S:S,"TESTED") -> 0 | L21: =COUNTIFS('2023 CONTRACTOR Master List '!J:J,"INPREMISE",'2023 CONTRACTOR Master List '!F:F,"PVB",'2023 CONTRACTOR Master List '!L:L,"ACTIVE",'2023 CONTRACTOR Master List '!S:S,"TESTED",'2023 CONTRACTOR Master List '!T:T,"FAILED") -> 0 | N21: =D21+J21 -> 0
B22: DCDA | C22: =COUNTIFS('2023 CONTRACTOR Master List '!J:J,"PREMISE",'2023 CONTRACTOR Master List '!F:F,"DCDA")/2 -> 3.5 | D22: =COUNTIFS('2023 CONTRACTOR Master List '!J:J,"PREMISE",'2023 CONTRACTOR Master List '!F:F,"DCDA",'2023 CONTRACTOR Master List '!L:L,"ACTIVE")/2 -> 3.5 | E22: =COUNTIFS('2023 CONTRACTOR Master List '!J:J,"PREMISE",'2023 CONTRACTOR Master List '!F:F,"DCDA",'2023 CONTRACTOR Master List '!L:L,"ACTIVE",'2023 CONTRACTOR Master List '!S:S,"TESTED") -> 0 | F22: =COUNTIFS('2023 CONTRACTOR Master List '!J:J,"PREMISE",'2023 CONTRACTOR Master List '!F:F,"DCDA",'2023 CONTRACTOR Master List '!L:L,"ACTIVE",'2023 CONTRACTOR Master List '!S:S,"TESTED",'2023 CONTRACTOR Master List '!T:T,"FAILED") -> 0 | H22: DCDA | I22: =COUNTIFS('2023 CONTRACTOR Master List '!J:J,"INPREMISE",'2023 CONTRACTOR Master List '!F:F,"DCDA")/2 -> 0 | J22: =COUNTIFS('2023 CONTRACTOR Master List '!J:J,"INPREMISE",'2023 CONTRACTOR Master List '!F:F,"DCDA",'2023 CONTRACTOR Master List '!L:L,"ACTIVE")/2 -> 0 | K22: =COUNTIFS('2023 CONTRACTOR Master List '!J:J,"INPREMISE",'2023 CONTRACTOR Master List '!F:F,"DCDA",'2023 CONTRACTOR Master List '!L:L,"ACTIVE",'2023 CONTRACTOR Master List '!S:S,"TESTED")/2 -> 0 | L22: =COUNTIFS('2023 CONTRACTOR Master List '!J:J,"INPREMISE",'2023 CONTRACTOR Master List '!F:F,"DCDA",'2023 CONTRACTOR Master List '!L:L,"ACTIVE",'2023 CONTRACTOR Master List '!S:S,"TESTED",'2023 CONTRACTOR Master List '!T:T,"FAILED") -> 0 | N22: =D22+J22 -> 3.5
B23: SVB | C23: =COUNTIFS('2023 CONTRACTOR Master List '!J:J,"PREMISE",'2023 CONTRACTOR Master List '!F:F,"SVB") -> 0 | D23: =COUNTIFS('2023 CONTRACTOR Master List '!J:J,"PREMISE",'2023 CONTRACTOR Master List '!F:F,"SVB",'2023 CONTRACTOR Master List '!L:L,"ACTIVE") -> 0 | E23: =COUNTIFS('2023 CONTRACTOR Master List '!J:J,"PREMISE",'2023 CONTRACTOR Master List '!F:F,"SVB",'2023 CONTRACTOR Master List '!L:L,"ACTIVE",'2023 CONTRACTOR Master List '!S:S,"TESTED") -> 0 | F23: =COUNTIFS('2023 CONTRACTOR Master List '!J:J,"PREMISE",'2023 CONTRACTOR Master List '!F:F,"SVB",'2023 CONTRACTOR Master List '!L:L,"ACTIVE",'2023 CONTRACTOR Master List '!S:S,"TESTED",'2023 CONTRACTOR Master List '!T:T,"FAILED") -> 0 | H23: SVB | I23: =COUNTIFS('2023 CONTRACTOR Master List '!J:J,"INPREMISE",'2023 CONTRACTOR Master List '!F:F,"SVB") -> 0 | J23: =COUNTIFS('2023 CONTRACTOR Master List '!J:J,"INPREMISE",'2023 CONTRACTOR Master List '!F:F,"SVB",'2023 CONTRACTOR Master List '!L:L,"ACTIVE") -> 0 | K23: =COUNTIFS('2023 CONTRACTOR Master List '!J:J,"INPREMISE",'2023 CONTRACTOR Master List '!F:F,"SVB",'2023 CONTRACTOR Master List '!L:L,"ACTIVE",'2023 CONTRACTOR Master List '!S:S,"TESTED") -> 0 | L23: =COUNTIFS('2023 CONTRACTOR Master List '!J:J,"INPREMISE",'2023 CONTRACTOR Master List '!F:F,"SVB",'2023 CONTRACTOR Master List '!L:L,"ACTIVE",'2023 CONTRACTOR Master List '!S:S,"TESTED",'2023 CONTRACTOR Master List '!T:T,"FAILED") -> 0 | N23: =D23+J23 -> 0
M24: ACTIVE | N24: =SUM(N19:N23) -> 79.5
B27: TOTAL DEVICES | C27: TOTAL INACTIVE | D27: TOTAL ACTIVE | E27: TOTAL TESTED | F27: Total | G27: TOTAL UNTESTED | N27: PERCENT COMPLETE
B28: =SUM(C19:C23,I19:I23) -> 79.5 | C28: =B28-D28 -> 0 | D28: =N24 -> 79.5 | E28: =SUM(E19:E23,K19:K23) -> 71 | F28: =SUM(F19:F23,L19:L23) -> 2 | G28: =D28-E28 -> 8.5 | N28: =E28/D28 -> 0.89308176
B30: FAFB COMBINED TOTALS
B32: PREMISE TOTALS | D32: ACTIVE | E32: TESTED | F32: FAILED | H32: INPREMISE TOTALS | J32: ACTIVE | K32: TESTED | L32: FAILED | N32: TOTAL
B33: DC | C33: =C5+C19 -> 243 | D33: =D5+D19 -> 219 | E33: =E5+E19 -> 177 | F33: =F5+F19 -> 0 | H33: DC | I33: =I5+I19 -> 23 | J33: =J5+J19 -> 19 | K33: =K5+K19 -> 14 | L33: =L5+L19 -> 0 | N33: =D33+J33 -> 238
B34: RP | C34: =C6+C20 -> 62 | D34: =D6+D20 -> 61 | E34: =E6+E20 -> 59 | F34: =F6+F20 -> 2 | H34: RP | I34: =I6+I20 -> 205 | J34: =J6+J20 -> 183 | K34: =K6+K20 -> 164 | L34: =L6+L20 -> 2 | N34: =D34+J34 -> 244
B35: PVB | C35: =C7+C21 -> 13 | D35: =D7+D21 -> 6 | E35: =E7+E21 -> 4 | F35: =F7+F21 -> 1 | H35: PVB | I35: =I7+I21 -> 2 | J35: =J7+J21 -> 2 | K35: =K7+K21 -> 2 | L35: =L7+L21 -> #REF! | N35: =D35+J35 -> 8
B36: DCDA | C36: =C8+C22 -> 11 | D36: =D8+D22 -> 10.5 | E36: =E8+E22 -> 7 | F36: =F8+F22 -> 0 | H36: DCDA | I36: =I8+I22 -> 0 | J36: =J8+J22 -> 0 | K36: =K8+K22 -> 0 | L36: =L8+L22 -> 0 | N36: =D36+J36 -> 10.5
B37: SVB | C37: =C9+C23 -> 0 | D37: =D9+D23 -> 0 | E37: =E9+E23 -> 0 | F37: =F9+F23 -> 0 | H37: SVB | I37: =I9+I23 -> 2 | J37: =J9+J23 -> 2 | K37: =K9+K23 -> 2 | L37: =L9+L23 -> 0 | N37: =D37+J37 -> 2
C38: =SUM(C33:C37) -> 329 | D38: =SUM(D33:D37) -> 296.5 | I38: =SUM(I33:I37) -> 232 | M38: ACTIVE | N38: =SUM(N33:N37) -> 502.5
C39: =C38+D38 -> 625.5
B41: TOTAL DEVICES | C41: TOTAL INACTIVE | D41: TOTAL ACTIVE | E41: TOTAL TESTED | F41: TOTAL FAILED | G41: TOTAL UNTESTED | N41: PERCENT COMPLETE
B42: =SUM(C33:C37,I33:I37) -> 561 | C42: =B42-D42 -> 58.5 | D42: =N38 -> 502.5 | E42: =SUM(E33:E37,K33:K37) -> 429 | F42: =SUM(F33:F37,L33:L37) -> #REF! | G42: =D42-E42 -> 73.5 | N42: =E42/D42 -> 0.85373134

Sheet 2024 DO NOT TOUCH
A1: BLDG | B1: BLDG NAME | C1: SERIAL # | D1: MAKE | E1: MODEL | F1: BF TYPE | G1: SIZE | H1: LOCATION | I1: PREMISE/ INPREMISE | J1: HAZ | K1: Inactive | L1: Last Test | M1: IRR OOC | N1: DATE | O1: OPER | P1: CV1 | Q1: CV2 | R1: REL/POP | S1: Tested | T1: PASSED | U1: Repaired | V1: Replaced | W1: Removed | X1: OLD S/N | Y1: NOTES
A2: 0001 | B2: BASE OPS | C2: A03206 | D2: WATTS | E2: 007QT | F2: DC | G2: 0.5 | H2: RM 102 UNDER SINK | I2: INPREMISE | J2: AOI | K2: ACTIVE | M2: FALSE | S2: UNTESTED | T2: FAILED | U2: PASSED | V2: EXISTING | W2: REMOVED | Y2: OUT OF SERVICE
A3: 0001 | B3: Base Ops | C3: 3336495 | D3: WILKINS | E3: 975XL | F3: RP | G3: 0.75 | H3: Basement | I3: INPREMISE | J3: AOI | K3: ACTIVE | L3: 44655 | M3: FALSE | S3: TESTED | T3: PASSED
A4: 0001 | B4: BASE OPS | C4: 3080317 | D4: WILKINS | E4: 950XLT | F4: DC | G4: 1.5 | H4: FIRE SYS IN BASEMENT SHREADER RM | I4: PREMISE | J4: FIRE | K4: ACTIVE | L4: 44565 | M4: FALSE | S4: TESTED | T4: PASSED | W4: SHREADERTE
A5: 0001 | B5: BASE OPS | C5: 92420 | D5: WATTS | E5: 007QT | F5: PVB | G5: 3.0 | H5: IN FRONT OF BLDG ON FLIGHT LINE | I5: PREMISE | J5: IRR | K5: INACTIVE | M5: FALSE | S5: UNTESTED | T5: FAILED | U5: PASSED | V5: EXISTING | W5: EXISTING
A6: 0003 | B6: FIRE DEPT | C6: H005173 | D6: FEBCO | E6: 825YA | F6: RP | G6: 0.75 | H6: MECH RM ON HVAC | I6: INPREMISE | J6: AOI | K6: ACTIVE | M6: FALSE | S6: UNTESTED | T6: FAILED | U6: PASSED | V6: EXISTING | W6: REMOVED
A7: 0003 | B7: FIRE DEPT | C7: W358317 | D7: WILKINS | E7: 975XL | F7: RP | G7: 0.5 | H7: ON ICE MACHINE | I7: INPREMISE | J7: AOI | K7: ACTIVE | L7: 44810 | M7: FALSE | N7: 45293 | O7: Ram | S7: TESTED
A8: 0003 | B8: FIRE DEPT | C8: 3338565 | D8: WILKINS | E8: 975XL | F8: RP | G8: 0.75 | H8: IN INDUSTRIAL LAUNDRY RM | I8: INPREMISE | J8: AOI | K8: ACTIVE | L8: 44566 | M8: FALSE | N8: 45293 | O8: Ram | S8: UNTESTED | W8: YES | Y8: water line removed
A9: 0003 | B9: FIRE DEPT | C9: H00402 | D9: FEBCO | E9: 850 | F9: DC | G9: 0.5 | H9: ALARM RM UNDER SINK COFFEE | I9: INPREMISE | J9: AOI | K9: ACTIVE | L9: 44565 | M9: FALSE | N9: 45295 | O9: Ram | P9: 2 | Q9: 3.1 | S9: TESTED | T9: PASSED | U9: Y
A10: 0003 | B10: FIRE DEPT | C10: F0303051105 | D10: FEBCO | E10: 850 | F10: DC | G10: 2.5 | H10: GYM RM BEHIND CABINET PANEL | I10: PREMISE | J10: PREMISE | K10: ACTIVE | L10: 44566 | M10: FALSE | N10: 45293 | O10: Ram | P10: 1.2 | Q10: 1.6 | S10: TESTED | T10: PASSED | Z10: 44655
A11: 0003 | B11: FIRE DEPT | C11: 2KM1479 | D11: AMES | E11: 2000SS | F11: DC | G11: 6.0 | H11: MECHANICS AREA ON FIRE SYS | I11: PREMISE | J11: FIRE | K11: ACTIVE | L11: 44566 | M11: FALSE | N11: 45293 | O11: Ram | P11: 4 | Q11: 3.1 | S11: TESTED | T11: PASSED | Z11: 44565
A12: 0003 | B12: FIRE DEPT | C12: 1945116 | D12: WILKINS | E12: 950XLT | F12: DC | G12: 2.0 | H12: MECH RM IRRIGATION | I12: PREMISE | J12: IRR | K12: ACTIVE | L12: 44753 | M12: FALSE | N12: 45509 | O12: PASS | S12: UNTESTED | Y12: iso
A13: 0109 | B13: TANKER TAILS | C13: 26377 | D13: WATTS | E13: 007M2QT | F13: DC | G13: 1.5 | H13: STORAGE CLOSET NEAR WATER HEATER | I13: PREMISE | J13: PREMISE | K13: ACTIVE | L13: 44564 | M13: FALSE | S13: TESTED | T13: PASSED
A14: 0152 | B14: 141 | C14: AB3965 | D14: FEBCO | E14: 765 | F14: DC | G14: 2.0 | H14: OUTSIDE 152 WEST SIDE | I14: PREMISE | J14: IRR | K14: ACTIVE | M14: TRUE | S14: UNTESTED | T14: FAILED | U14: PASSED | V14: EXISTING | W14: EXISTING | Z14: 44810
A15: 160 | B15: 141 | C15: U28836 | D15: WILKINS | E15: 350A | F15: DC | G15: 2.5 | H15: MECH ROOMN | I15: PREMISE | J15: FIRE | K15: ACTIVE | L15: 44676 | M15: FALSE | S15: TESTED | T15: PASSED | U15: PASSED | V15: EXISTING | W15: EXISTING | Z15: 44566
A16: 0285 | B16: 141 | C16: H81856 | D16: FEBCO | E16: 850 | F16: DC | G16: 1.0 | H16: MECH ROOM | I16: PREMISE | J16: AOI | K16: ACTIVE | L16: 44574 | M16: FALSE | N16: 45517 | O16: Bruce | P16: 2 | Q16: 2.6 | S16: TESTED | T16: PASSED | Z16: 44565
A17: 0285 | B17: 141 | C17: 1394537 | D17: WILKINS | E17: 975XL | F17: RP | G17: .75 | H17: BOILER | I17: PREMISE | J17: AOI | K17: ACTIVE | L17: 44574 | M17: FALSE | S17: TESTED | T17: PASSED | U17: PASSED | V17: EXISTING | W17: EXISTING | Z17: 44566
A18: 0326 | B18: FAM CAMP | C18: J002794 | D18: FEBCO | E18: 825Y | F18: RP | G18: 2.0 | H18: CENTER OF ALL PARKING SPOTS/ ABOVE GROUND | I18: PREMISE | J18: IRR | K18: ACTIVE | L18: 44644 | M18: FALSE | N18: 45454 | O18: TROUNG | P18: 7.6 | R18: 3.2 | S18: TESTED | T18: PASSED | Z18: 44566
A19: 0326 | B19: FAM CAMP | C19: W358305 | D19: WILKINS | E19: 975XL | F19: RP | G19: 1.0 | H19: IRRIGATION | I19: PREMISE | J19: IRR | K19: ACTIVE | M19: TRUE | S19: UNTESTED | X19: 3078471 | Y19: iso | Z19: 44753
A20: 0326 | B20: FAM CAMP | C20: 3772095 | D20: WILKINS | E20: 975XL2 | F20: RP | G20: 2.0 | H20: DOMESTIC SUPPLY CENTER OF FAM CAMP | I20: PREMISE | J20: PREMISE | K20: ACTIVE | L20: 44644 | M20: FALSE | S20: TESTED | T20: PASSED | Z20: 44564
A21: 0399 | B21: 141 | C21: H81852 | D21: FEBCO | E21: 850 | F21: DC | G21: 2.0 | H21: MECH ROOM | I21: PREMISE | J21: PREMISE | K21: ACTIVE | L21: 44641 | M21: FALSE | S21: TESTED | T21: PASSED | U21: PASSED | V21: EXISTING
A22: 0399 | B22: 141 | C22: 199742 | D22: FEBCO | E22: 850 | F22: DC | G22: 2.0 | H22: Mech Room | I22: PREMISE | J22: PREMISE | K22: ACTIVE | L22: 44673 | M22: FALSE | N22: 45530 | O22: Bruce | P22: 2.2 | Q22: 2.8 | S22: TESTED | T22: PASSED | U22: y | Z22: 44676
A23: 399 | B23: 141 | C23: U47987 | D23: WILKINS | E23: 350A | F23: DC | G23: 4.0 | H23: Mech Room | I23: PREMISE | J23: PREMISE | K23: ACTIVE | L23: 44651 | M23: FALSE | S23: TESTED | T23: PASSED | Z23: 44574
A24: 0430 | B24: 141 | C24: A36420 | D24: WILKINS | E24: 350XL | F24: DC | G24: 1.5 | H24: MECH ROOM | I24: PREMISE | J24: AOI | K24: ACTIVE | L24: 44643 | M24: FALSE | N24: 45517 | O24: Bruce | P24: 2.8 | Q24: 3 | S24: TESTED | T24: PASSED | Z24: 44574
A25: 0430 | B25: 141 | C25: 4094341 | D25: WILKINS | E25: 350 | F25: DC | G25: .75 | H25: FIRE | I25: PREMISE | J25: FIRE | K25: ACTIVE | L25: 44651 | M25: FALSE | N25: 45525 | O25: Bruce | P25: 3 | Q25: 2.6 | S25: TESTED | Z25: 44644
A26: 430 | B26: 141 | C26: V43790 | D26: WILKINS | E26: 350ADA | F26: DCDA | G26: 6.0 | H26: Fire | I26: PREMISE | J26: FIRE | K26: ACTIVE | L26: 44651 | M26: FALSE | N26: 45525 | O26: Bruce | P26: 3.8 | Q26: 2.8 | S26: TESTED | T26: PASSED
A27: 0443 | B27: 141 | C27: H42134 | D27: FEBCO | E27: 850 | F27: DC | G27: 2 | H27: 443 EAST LOT ROCK BED | I27: INPREMISE | J27: IRR | K27: ACTIVE | L27: 44644 | M27: TRUE | N27: 45517 | O27: Bruce | P27: 2.8 | Q27: 2.6 | S27: TESTED | T27: PASSED | Z27: 44644
A28: 0443 | B28: 141 | C28: 1136042 | D28: WILKINS | E28: 950XL | F28: RP | G28: 2 | H28: MECH ROOM | I28: PREMISE | J28: AOI | K28: ACTIVE | L28: 44676 | M28: FALSE | N28: 45320 | O28: Ted | P28: 8.6 | R28: 3.8 | S28: TESTED | T28: PASSED | Z28: 44641
A29: 0443 | B29: 141 | C29: 1833446 | D29: WILKINS | E29: 975XLT | F29: DC | G29: 2 | H29: MECH ROOM | I29: PREMISE | J29: AOI | K29: ACTIVE | L29: 44642 | M29: FALSE | N29: 45517 | O29: Bruce | P29: 3.2 | Q29: 3.2 | S29: TESTED | T29: PASSED | Z29: 44673
A30: 443 | B30: 141 | C30: EC-0936 | D30: COLT | E30: 200A | F30: DC | G30: 4.0 | H30: Mech Room | I30: PREMISE | J30: FIRE | K30: ACTIVE | L30: 44676 | M30: FALSE | S30: TESTED | T30: PASSED | U30: PASSED | V30: EXISTING | W30: EXISTING | Z30: 44651
A31: 0445 | B31: 141 | C31: H05044 | D31: FEBCO | E31: 850 | F31: DC | G31: 1.5 | H31: MENCH ROOM | I31: PREMISE | J31: IRR | K31: ACTIVE | L31: 44643 | M31: FALSE | S31: TESTED | T31: PASSED | U31: PASSED | V31: EXISTING | W31: EXISTING | Z31: 44643
A32: 446 | B32: 141 | C32: 28862 | D32: WILKINS | E32: 350A | F32: DC | G32: 6 | H32: MECH ROOM FIRE | I32: PREMISE | J32: FIRE | K32: ACTIVE | L32: 44573 | M32: FALSE | N32: 45320 | O32: Ted | P32: 4 | Q32: 3.6 | S32: TESTED | T32: PASSED | U32: y | Z32: 44651
A33: 446 | B33: 141 | C33: 3335495 | D33: WILKINS | E33: 975XL | F33: RP | G33: .75 | H33: MECH ROOM | I33: PREMISE | J33: AOI | K33: ACTIVE | L33: 44573 | M33: FALSE | N33: 45320 | O33: Ted | P33: 8.2 | R33: 2.6 | S33: TESTED | T33: PASSED | U33: Y | Z33: 44651
A34: 447 | B34: 141 | C34: H08097 | D34: FEBCO | E34: 850 | F34: DC | G34: 2 | H34: MECH ROOM | I34: PREMISE | J34: IRR | K34: ACTIVE | L34: 44643 | M34: FALSE | N34: 45517 | O34: Bruce | P34: 1.2 | Q34: 2 | S34: TESTED | T34: PASSED | Z34: 44644
A35: 447 | B35: 141 | C35: H17256 | D35: FEBCO | E35: 850 | F35: DC | G35: 2 | H35: MECH ROOM | I35: PREMISE | J35: AOI | K35: ACTIVE | L35: 44844 | M35: FALSE | N35: 45523 | O35: Bruce | P35: 2.4 | Q35: 3 | S35: TESTED | T35: PASSED | Z35: 44676
A36: 456 | B36: 141 | C36: H00431 | D36: FEBCO | E36: 850 | F36: DC | G36: 0.5 | H36: Break Room Under Sink | I36: INPREMISE | J36: AOI | K36: INACTIVE | L36: 44572 | M36: FALSE | S36: TESTED | T36: PASSED | U36: PASSED | V36: EXISTING | W36: EXISTING | Z36: 44642
A37: 456 | B37: 141 | C37: 01515 | D37: FEBCO | E37: 850 | F37: DC | G37: 2 | H37: MECH ROOM | I37: PREMISE | J37: IRR | K37: ACTIVE | L37: 44676 | M37: FALSE | N37: 45320 | O37: Ted | P37: 3.4 | Q37: 3 | S37: TESTED | T37: PASSED | Z37: 44676
A38: 456 | B38: 141 | C38: 01621 | D38: FEBCO | E38: 850 | F38: DC | G38: 2 | H38: WOOD SHOP | I38: PREMISE | J38: AOI | K38: ACTIVE | L38: 44572 | M38: FALSE | N38: 45320 | O38: Ted | P38: 2.8 | Q38: 2.8 | S38: TESTED | T38: PASSED | Z38: 44643
A39: 456 | B39: 141 | C39: 358582 | D39: WILKINS | E39: 975XL | F39: RP | G39: .5 | H39: ICE MACHINE | I39: PREMISE | J39: AOI | K39: ACTIVE | L39: 44572 | M39: FALSE | S39: TESTED | T39: PASSED | U39: PASSED | V39: EXISTING | W39: EXISTING | Z39: 44573
A40: 456 | B40: 141 | C40: 08705 | D40: AMES | E40: 2000BM3 | F40: DC | G40: .75 | H40: SHOP WELDER | I40: PREMISE | J40: AOI | K40: ACTIVE | L40: 44572 | M40: FALSE | N40: 45320 | O40: Ted | P40: 2.8 | Q40: 2 | S40: TESTED | T40: PASSED | Z40: 44573
...

Sheet 2024 CONTRACTOR DO NOT TOUCH
A1: BLDG | B1: BLDG NAME | C1: SERIAL # | D1: MAKE | E1: MODEL | F1: BF TYPE | G1: SIZE | H1: LAST TEST | I1: LOCATION | J1: PREMISE/ INPREMISE | K1: HAZ | L1: Inactive | M1: LAST TEST | N1: DATE | O1: OPER | P1: CV1 | Q1: CV2 | R1: REL/POP | S1: Tested | T1: Passed | U1: Repaired | V1: Replaced | W1: Removed | X1: OLD S/N | Y1: NOTES
A2: SCHOOL | B2: MICHAEL ANDERSON | C2: F0204080725 | D2: FEBCO | E2: 850 | F2: DC | G2: 4.0 | I2: IRR WEST OF SCHOOL FENCED AREA | J2: PREMISE | K2: IRR | L2: ACTIVE | M2: 44750 | S2: TESTED | T2: PASSED
A3: SCHOOL | B3: MICHAEL ANDERSON | C3: 1339754 | D3: WILKINS | E3: 975XL | F3: RP | G3: 0.75 | I3: MECH ROOM HOT WATER | J3: INPREMISE | K3: AOI | L3: ACTIVE | M3: 44750 | S3: TESTED | T3: PASSED
A4: SCHOOL | B4: MICHAEL ANDERSON | C4: U28838 | D4: WILKINS | E4: 350A | F4: DC | G4: 4.0 | I4: MECH ROOM FIRE SYS | J4: PREMISE | K4: FIRE | L4: ACTIVE | M4: 44750 | S4: TESTED | T4: PASSED
A5: SCHOOL | B5: MICHAEL ANDERSON | C5: J08247 | D5: WILKINS | E5: 350 | F5: DC | G5: 3.0 | H5: 43822 | I5: VAULT NEXT TO PIV | J5: PREMISE | K5: PREMISE | L5: ACTIVE | M5: 44750 | S5: TESTED | T5: PASSED
A6: HOUSING | B6: FAFB HOUSING | C6: 008307 | D6: WATTS | E6: LF007M1QT | F6: DC | G6: 2.0 | I6: FRONT CIRCLE DRIVE HOT BOX ROCK | J6: PREMISE | K6: PREMISE | L6: ACTIVE | M6: 44672 | S6: TESTED | T6: PASSED
A7: HOUSING | B7: FAFB HOUSING | C7: X13788 | D7: WILKINS | E7: 375A | F7: RP | G7: 8.0 | I7: GALENA STATION HOT BOX #1 | J7: PREMISE | K7: PREMISE | L7: ACTIVE | S7: TESTED | T7: FAILED | U7: Y
A8: HOUSING | B8: FAFB HOUSING | C8: L50441 | D8: WILKINS | E8: 375 | F8: RP | G8: 10.0 | I8: GALENA STATION HOT BOX #2 | J8: PREMISE | K8: PREMISE | L8: ACTIVE | M8: 44654 | S8: TESTED | T8: PASSED
A9: HOUSING | B9: FAFB HOUSING | C9: L50440 | D9: WILKINS | E9: 375 | F9: RP | G9: 10.0 | I9: KAMIAKIN HOT BOX #1 | J9: PREMISE | K9: PREMISE | L9: ACTIVE | M9: 44719 | S9: TESTED | T9: PASSED
A10: HOUSING | B10: FAFB HOUSING | C10: L50442 | D10: WILKINS | E10: 375A | F10: RP | G10: 10.0 | I10: KAMIAKIN HOT BOX #2 | J10: PREMISE | K10: PREMISE | L10: ACTIVE | M10: 44719 | S10: TESTED | T10: PASSED
A11: 0001 | B11: ALASKA BOILER | C11: 3336495 | D11: WILKINS | E11: 975XL | F11: RP | G11: 0.75 | I11: #1 BOILER | J11: INPREMISE | K11: AOI | L11: ACTIVE | M11: 44824 | S11: TESTED | T11: PASSED
A12: 0001 | B12: ALASKA BOILER | C12: 1363820 | D12: WILKINS | E12: 975XL | F12: RP | G12: 0.75 | I12: #2 BOILER | J12: INPREMISE | K12: AOI | L12: ACTIVE | M12: 44824 | S12: TESTED | T12: PASSED
A13: 0285 | B13: ALASKA BOILER | C13: 1394537 | D13: WILKINS | E13: 975XL | F13: RP | G13: 0.75 | I13: BOILER | J13: INPREMISE | K13: AOI | L13: ACTIVE | M13: 44824 | S13: TESTED | T13: PASSED | U13: PASSED | V13: EXISTING | W13: EXISTING
A14: 1029 | B14: ALASKA BOILER | C14: 1363765 | D14: WILKINS | E14: 975XL | F14: RP | G14: 0.75 | I14: BOILER | J14: INPREMISE | K14: AOI | L14: ACTIVE | M14: 10/102022 | N14: 45320 | O14: Ted | P14: 7.4 | R14: 2.6 | S14: TESTED | T14: PASSED | U14: PASSED | V14: EXISTING | W14: EXISTING
A15: 1033 | B15: ALASKA BOILER | C15: 1363764 | D15: WILKINS | E15: 975XL | F15: RP | G15: 0.75 | I15: BOILER | J15: INPREMISE | K15: AOI | L15: ACTIVE | M15: 44574 | S15: TESTED | T15: PASSED | U15: PASSED | V15: EXISTING | W15: EXISTING
A16: 1034 | B16: ALASKA BOILER | C16: 1363757 | D16: WILKINS | E16: 975XL | F16: RP | G16: 0.75 | I16: BOILER | J16: INPREMISE | K16: AOI | L16: ACTIVE | M16: 44573 | S16: TESTED | T16: PASSED | U16: PASSED | V16: EXISTING | W16: EXISTING
A17: 1037 | B17: ALASKA BOILER | C17: 1363767 | D17: WILKINS | E17: 975XL | F17: RP | G17: 0.75 | I17: BOILER | J17: INPREMISE | K17: AOI | L17: ACTIVE | M17: 44573 | N17: 45320 | O17: Ted | P17: 6.2 | R17: 2.4 | S17: TESTED | T17: PASSED | U17: PASSED | V17: EXISTING | W17: EXISTING
A18: 2025 | B18: ALASKA BOILER | C18: W043053 | D18: WILKINS | E18: 975XL | F18: RP | G18: 0.75 | I18: BOILER | J18: INPREMISE | K18: AOI | L18: ACTIVE | M18: 44824 | S18: TESTED | T18: PASSED
A19: 2048 | B19: ALASKA BOILER | C19: 1419513 | D19: WILKINS | E19: 975XL | F19: RP | G19: 0.75 | I19: BOILER | J19: INPREMISE | K19: AOI | L19: ACTIVE | M19: 44824 | S19: TESTED | T19: Passed
A20: 2050 | B20: ALASKA BOILER | C20: W017036 | D20: WILKINS | E20: 975XL | F20: RP | G20: 0.75 | I20: BOILER | J20: INPREMISE | K20: AOI | L20: ACTIVE | M20: 44825 | N20: 45355 | O20: PASS | P20: 7.8 | R20: 3.2 | S20: TESTED | T20: PASSED
A21: 2060 | B21: ALASKA BOILER | C21: 1339756 | D21: WILKINS | E21: 975XL | F21: RP | G21: 0.75 | I21: BOILER | J21: INPREMISE | K21: AOI | L21: ACTIVE | M21: 44824 | S21: TESTED | T21: PASSED
A22: 2120 | B22: ALASKA BOILER | C22: 1363777 | D22: WILKINS | E22: 975XL | F22: RP | G22: 0.75 | I22: BOILER | J22: INPREMISE | K22: AOI | L22: ACTIVE | M22: 44824 | S22: TESTED | T22: Passed
A23: 2185 | B23: ALASKA BOILER | C23: W184146 | D23: WILKINS | E23: 975XL | F23: RP | G23: 0.75 | I23: BOILER | J23: INPREMISE | K23: AOI | L23: ACTIVE | M23: 44824 | S23: TESTED | T23: PASSED
A24: 2262 | B24: ALASKA BOILER | C24: 1394550 | D24: WILKINS | E24: 975XL | F24: RP | G24: 0.75 | I24: BOILER | J24: INPREMISE | K24: AOI | L24: ACTIVE | M24: 44824 | S24: TESTED | T24: PASSED | U24: PASSED | V24: EXISTING | W24: EXISTING
A25: 2276 | B25: ALASKA BOILER | C25: D8305 | D25: FEBCO | E25: 825Y | F25: RP | G25: .75 | I25: BOILER | J25: INPREMISE | K25: AOI | L25: ACTIVE | M25: 44824 | S25: Tested | T25: Passed
A26: 2411 | B26: ALASKA BOILER | C26: 3105740 | D26: WILKINS | E26: 975XL | F26: RP | G26: 0.75 | I26: BOILER | J26: INPREMISE | K26: AOI | L26: ACTIVE | M26: 44824 | S26: TESTED | T26: PASSED
A27: 2447 | B27: ALASKA BOILER | C27: 1419502 | D27: WILKINS | E27: 975XL | F27: RP | G27: 0.75 | I27: BOILER | J27: INPREMISE | K27: AOI | L27: ACTIVE | M27: 44824 | S27: UNTESTED | W27: yes
A28: 2447 | B28: ALASKA BOILER | C28: W254050 | D28: WILKINS | E28: 975XL | F28: RP | G28: 0.75 | I28: BOILER | J28: INPREMISE | K28: AOI | L28: ACTIVE | M28: 44824 | S28: TESTED | T28: PASSED
A29: 2464 | B29: ALASKA BOILER | C29: W358507 | D29: WILKINS | E29: 975XL | F29: RP | G29: 0.5 | I29: PRODUCE PREP | J29: INPREMISE | K29: AOI | L29: ACTIVE | M29: 44824 | S29: TESTED | T29: PASSED | U29: PASSED | V29: EXISTING | W29: EXISTING
A30: 2464 | B30: ALASKA BOILER | C30: A03077 | D30: FEBCO | E30: 860 | F30: RP | G30: .075 | I30: BOILER | J30: INPREMISE | K30: AOI | L30: ACTIVE | M30: 44824 | S30: TESTED | T30: PASSED | U30: PASSED | V30: EXISTING | W30: EXISTING
A31: 2464 | B31: ALASKA BOILER | C31: 1363759 | D31: WILKINS | E31: 975XL | F31: RP | G31: 0.75 | I31: BOILER | J31: INPREMISE | K31: AOI | L31: ACTIVE | S31: UNTESTED | T31: FAILED | U31: PASSED | V31: EXISTING | W31: EXISTING
A32: 9000 | B32: CLINIC | C32: 9607081244 | D32: FEBCO | E32: 805YD | F32: DC | G32: 6.0 | I32: FIRE PUMP RM 006A | J32: PREMISE | K32: FIRE | L32: ACTIVE | S32: UNTESTED | T32: FAILED | U32: PASSED | V32: EXISTING | W32: EXISTING
A33: 9000 | B33: CLINIC | C33: 9607081245 | D33: FEBCO | E33: 805YD | F33: DC | G33: 6.0 | I33: FIRE PUMP RM 006A | J33: PREMISE | K33: FIRE | L33: ACTIVE | S33: UNTESTED | T33: FAILED | U33: PASSED | V33: EXISTING | W33: EXISTING
A34: 9000 | B34: CLINIC | C34: 78583 | D34: WATTS | E34: LF009M2QT | F34: RP | G34: 0.5 | I34: HOUSEKEEPING RM 008 | J34: INPREMISE | K34: AOI | L34: ACTIVE | M34: 44756 | S34: TESTED | T34: PASSED | U34: Y
A35: 9000 | B35: CLINIC | C35: 95606 | D35: WATTS | E35: LF009M2QT | F35: RP | G35: 0.5 | I35: HOUSEKEEPING RM 008 | J35: INPREMISE | K35: AOI | L35: ACTIVE | M35: 44756 | S35: TESTED | T35: PASSED
A36: 9000 | B36: CLINIC | C36: 1396006 | D36: WILKINS | E36: 975XL | F36: RP | G36: 1.0 | I36: RM 026 BOILER | J36: INPREMISE | K36: AOI | L36: ACTIVE | M36: 44764 | S36: TESTED | T36: Passed
