Workbook
Name DL_Subtotal: 'Base Year'!$F$10
Name DL_Subtotal: 'Option Year 1'!$F$10
Name DL_Subtotal: 'Option Year 2'!$F$10
Name DL_Subtotal: 'Option Year 3'!$F$10
Name DL_Subtotal: 'Option Year 4'!$F$10
Name DL_Subtotal: #REF!
Name EP_Subtotal: 'Base Year'!$F$17
Name EP_Subtotal: 'Option Year 1'!$F$17
Name EP_Subtotal: 'Option Year 2'!$F$17
Name EP_Subtotal: 'Option Year 3'!$F$17
Name EP_Subtotal: 'Option Year 4'!$F$17
Name EP_Subtotal: #REF!
Name FY_Subtotal: 'Base Year'!#REF!
Name FY_Subtotal: 'Option Year 1'!#REF!
Name FY_Subtotal: 'Option Year 2'!#REF!
Name FY_Subtotal: 'Option Year 3'!#REF!
Name FY_Subtotal: 'Option Year 4'!#REF!
Name FY_Subtotal: #REF!
Name FY_Total: 'Base Year'!$F$48
Name FY_Total: 'Option Year 1'!$F$48
Name FY_Total: 'Option Year 2'!$F$48
Name FY_Total: 'Option Year 3'!$F$48
Name FY_Total: 'Option Year 4'!$F$48
Name FY_Total: #REF!
Name Labor_Subtotal: 'Base Year'!$F$10
Name Labor_Subtotal: 'Option Year 1'!$F$10
Name Labor_Subtotal: 'Option Year 2'!$F$10
Name Labor_Subtotal: 'Option Year 3'!$F$10
Name Labor_Subtotal: 'Option Year 4'!$F$10
Name Labor_Subtotal: #REF!
Name ODC_MS_Subtotal: 'Base Year'!$F$39
Name ODC_MS_Subtotal: 'Option Year 1'!$F$39
Name ODC_MS_Subtotal: 'Option Year 2'!$F$39
Name ODC_MS_Subtotal: 'Option Year 3'!$F$39
Name ODC_MS_Subtotal: 'Option Year 4'!$F$39
Name ODC_MS_Subtotal: #REF!
Name ODC_Other_Subtotal: 'Base Year'!$F$46
Name ODC_Other_Subtotal: 'Option Year 1'!$F$46
Name ODC_Other_Subtotal: 'Option Year 2'!$F$46
Name ODC_Other_Subtotal: 'Option Year 3'!$F$46
Name ODC_Other_Subtotal: 'Option Year 4'!$F$46
Name ODC_Other_Subtotal: #REF!
Name ODC_Travel_Subtotal: 'Base Year'!$F$32
Name ODC_Travel_Subtotal: 'Option Year 1'!$F$32
Name ODC_Travel_Subtotal: 'Option Year 2'!$F$32
Name ODC_Travel_Subtotal: 'Option Year 3'!$F$32
Name ODC_Travel_Subtotal: 'Option Year 4'!$F$32
Name ODC_Travel_Subtotal: #REF!
Name ODCtravel_Subtotal: 'Base Year'!$F$32
Name ODCtravel_Subtotal: 'Option Year 1'!$F$32
Name ODCtravel_Subtotal: 'Option Year 2'!$F$32
Name ODCtravel_Subtotal: 'Option Year 3'!$F$32
Name ODCtravel_Subtotal: 'Option Year 4'!$F$32
Name ODCtravel_Subtotal: #REF!
Name Other_sub_total: #REF!
Name SP_Subtotal: 'Base Year'!$F$24
Name SP_Subtotal: 'Option Year 1'!$F$24
Name SP_Subtotal: 'Option Year 2'!$F$24
Name SP_Subtotal: 'Option Year 3'!$F$24
Name SP_Subtotal: 'Option Year 4'!$F$24

Sheet Summary
A1: IDIQ Price Workbook
A2: SUMMARY DATA | E2: TOTAL | F2: WITH FEES
A3: BASE YEAR SUBTOTAL: | E3: ='Base Year'!D3 -> 24792 | F3: =E3*1.03 -> 25535.76
A4: OPTION YEAR 1 SUBTOTAL: | E4: ='Option Year 1'!D3 -> 49584 | F4: =E4*1.03 -> 51071.52
A5: OPTION YEAR 2 SUBTOTAL: | E5: ='Option Year 2'!D3 -> 49584 | F5: =E5*1.03 -> 51071.52
A6: OPTION YEAR 3 SUBTOTAL: | E6: ='Option Year 3'!D3 -> 49584 | F6: =E6*1.03 -> 51071.52
A7: OPTION YEAR 4 SUBTOTAL: | E7: ='Option Year 4'!D3 -> 49584 | F7: =E7*1.03 -> 51071.52
A8: PROCUREMENT TOTAL: | E8: =SUM(E3:E7) -> 223128 | F8: =SUM(F3:F7) -> 229821.84
A10: Insturctions: Complete yellow highlighted cells for all tabs. Travel is government populated.
A11: The hours are estimates only for the purposes of conducting price analysis. They are not actuals.

Sheet Base Year
B1: INDEPENDENT GOVERNMENT COST ESTIMATE
B2: BASE YEAR: 06-01-2026 - 05-31-27
B3: Total | D3: =FY_Total -> 24792
B5: DIRECT LABOR (BURDENED RATES)
C6: Labor Category | D6: Hours | E6: Labor Rate | F6: Amount
B7: 1 | C7: Senior Environmental and Social Specialist | D7: 1240 | F7: =+D7*E7 -> 0
B8: 2 | C8: Environmental and Social Specialist | D8: 128 | F8: =+D8*E8 -> 0
B9: 3 | C9: Subject Matter Expert (SME) | D9: 480 | F9: =+D9*E9 -> 0
B10: SUBTOTAL | F10: =SUM(F7:F9) -> 0
B12: EQUIPMENT PURCHASES
C13: Item Description | D13: Quantity | E13: Unit Price | F13: Total
B14: 1 | D14: 0 | E14: 0 | F14: =(D14*E14) -> 0
B15: 2 | D15: 0 | E15: 0 | F15: =(D15*E15) -> 0
B16: 3 | D16: 0 | E16: 0 | F16: =(D16*E16) -> 0
B17: SUBTOTAL | F17: =SUM(F14:F16) -> 0
B19: SOFTWARE PURCHASES
C20: Item Description | D20: Quantity | E20: Unit Price | F20: Total
B21: 1 | D21: 0 | E21: 0 | F21: =(D21*E21) -> 0
B22: 2 | D22: 0 | E22: 0 | F22: =(D22*E22) -> 0
B23: 3 | D23: 0 | E23: 0 | F23: =(D23*E23) -> 0
B24: SUBTOTAL | F24: =SUM(F21:F23) -> 0
B26: OTHER DIRECT COST (ODCs)
B27: REQUIRED TRAVEL: (Not-to-Exceed Amount; Worse Case)
C28: Travel (To/From) | D28: No. of Trips | E28: Price Per Trip | F28: Total
B29: 1 | C29: France/Burundi/Ecuador | D29: 4 | E29: 6198 | F29: =(D29*E29) -> 24792
B30: 2 | D30: 0 | E30: 0 | F30: =(D30*E30) -> 0
B31: 3 | D31: 0 | E31: 0 | F31: =(D31*E31) -> 0
B32: SUBTOTAL | F32: =SUM(F29:F31) -> 24792
B34: MATERIAL/SUPPLIES: (List Below)
C35: Item Description | D35: Quantity | E35: Unit Price | F35: Total
B36: 1 | D36: 0 | E36: 0 | F36: =(D36*E36) -> 0
B37: 2 | D37: 0 | E37: 0 | F37: =(D37*E37) -> 0
B38: 3 | D38: 0 | E38: 0 | F38: =(D38*E38) -> 0
B39: SUBTOTAL | F39: =SUM(F36:F38) -> 0
B41: OTHER: (Anything not covered above)
C42: Item Description | D42: Quantity | E42: Unit Price | F42: Total
B43: 1 | D43: 0 | E43: 0 | F43: =(D43*E43) -> 0
B44: 2 | D44: 0 | E44: 0 | F44: =(D44*E44) -> 0
B45: 3 | D45: 0 | E45: 0 | F45: =(D45*E45) -> 0
B46: SUBTOTAL | F46: =SUM(F43:F45) -> 0
...

Sheet Option Year 1
B1: INDEPENDENT GOVERNMENT COST ESTIMATE
B2: OPTION YEAR 1: 06-01-2027 - 05-31-28
B3: Total | D3: =FY_Total -> 49584
B5: DIRECT LABOR (BURDENED RATES)
C6: Labor Category | D6: Hours | E6: Rate | F6: Amount
B7: 1 | C7: Senior Environmental and Social Specialist | D7: 2480 | F7: =(D7*E7) -> 0
B8: 2 | C8: Environmental and Social Specialist | D8: 256 | F8: =(D8*E8) -> 0
B9: 3 | C9: Subject Matter Expert (SME) | D9: 960 | F9: =(D9*E9) -> 0
B10: SUBTOTAL | F10: =SUM(F7:F9) -> 0
B12: EQUIPMENT PURCHASES
C13: Item Description | D13: Quantity | E13: Unit Price | F13: Total
B14: 1 | D14: 0 | E14: 0 | F14: =(D14*E14) -> 0
B15: 2 | D15: 0 | E15: 0 | F15: =(D15*E15) -> 0
B16: 3 | D16: 0 | E16: 0 | F16: =(D16*E16) -> 0
B17: SUBTOTAL | F17: =SUM(F14:F16) -> 0
B19: SOFTWARE PURCHASES
C20: Item Description | D20: Quantity | E20: Unit Price | F20: Total
B21: 1 | D21: 0 | E21: 0 | F21: =(D21*E21) -> 0
B22: 2 | D22: 0 | E22: 0 | F22: =(D22*E22) -> 0
B23: 3 | D23: 0 | E23: 0 | F23: =(D23*E23) -> 0
B24: SUBTOTAL | F24: =SUM(F21:F23) -> 0
B26: OTHER DIRECT COST
B27: REQUIRED TRAVEL: (Not-to-Exceed Amount; Worse Case)
C28: Travel (To/From) | D28: No. of Trips | E28: Price Per Trip | F28: Total
B29: 1 | C29: France/Burundi/Ecuador | D29: 8 | E29: 6198 | F29: =(D29*E29) -> 49584
B30: 2 | D30: 0 | E30: 0 | F30: =(D30*E30) -> 0
B31: 3 | D31: 0 | E31: 0 | F31: =(D31*E31) -> 0
B32: SUBTOTAL | F32: =SUM(F29:F31) -> 49584
B34: MATERIAL/SUPPLIES: (List Below)
C35: Item Description | D35: Quantity | E35: Unit Price | F35: Total
B36: 1 | D36: 0 | E36: 0 | F36: =(D36*E36) -> 0
B37: 2 | D37: 0 | E37: 0 | F37: =(D37*E37) -> 0
B38: 3 | D38: 0 | E38: 0 | F38: =(D38*E38) -> 0
B39: SUBTOTAL | F39: =SUM(F36:F38) -> 0
B41: OTHER: (Anything not covered above)
C42: Item Description | D42: Quantity | E42: Unit Price | F42: Total
B43: 1 | D43: 0 | E43: 0 | F43: =(D43*E43) -> 0
B44: 2 | D44: 0 | E44: 0 | F44: =(D44*E44) -> 0
B45: 3 | D45: 0 | E45: 0 | F45: =(D45*E45) -> 0
B46: SUBTOTAL | F46: =SUM(F43:F45) -> 0
...

Sheet Option Year 2
B1: INDEPENDENT GOVERNMENT COST ESTIMATE
B2: OPTION YEAR 2: 06-01-2028 - 05-31-29
B3: Total | D3: =FY_Total -> 49584
B5: DIRECT LABOR (BURDENED RATES)
C6: Labor Category | D6: Hours | E6: Rate | F6: Amount
B7: 1 | C7: Senior Environmental and Social Specialist | D7: 2480 | F7: =(D7*E7) -> 0
B8: 2 | C8: Environmental and Social Specialist | D8: 256 | F8: =(D8*E8) -> 0
B9: 3 | C9: Subject Matter Expert (SME) | D9: 960 | F9: =(D9*E9) -> 0
B10: SUBTOTAL | F10: =SUM(F7:F9) -> 0
B12: EQUIPMENT PURCHASES
C13: Item Description | D13: Quantity | E13: Unit Price | F13: Total
B14: 1 | D14: 0 | E14: 0 | F14: =(D14*E14) -> 0
B15: 2 | D15: 0 | E15: 0 | F15: =(D15*E15) -> 0
B16: 3 | D16: 0 | E16: 0 | F16: =(D16*E16) -> 0
B17: SUBTOTAL | F17: =SUM(F14:F16) -> 0
B19: SOFTWARE PURCHASES
C20: Item Description | D20: Quantity | E20: Unit Price | F20: Total
B21: 1 | D21: 0 | E21: 0 | F21: =(D21*E21) -> 0
B22: 2 | D22: 0 | E22: 0 | F22: =(D22*E22) -> 0
B23: 3 | D23: 0 | E23: 0 | F23: =(D23*E23) -> 0
B24: SUBTOTAL | F24: =SUM(F21:F23) -> 0
B26: OTHER DIRECT COST
B27: REQUIRED TRAVEL: (Not-to-Exceed Amount; Worse Case)
C28: Travel (To/From) | D28: No. of Trips | E28: Price Per Trip | F28: Total
B29: 1 | C29: France/Burundi/Ecuador | D29: 8 | E29: 6198 | F29: =(D29*E29) -> 49584
B30: 2 | D30: 0 | E30: 0 | F30: =(D30*E30) -> 0
B31: 3 | D31: 0 | E31: 0 | F31: =(D31*E31) -> 0
B32: SUBTOTAL | F32: =SUM(F29:F31) -> 49584
B34: MATERIAL/SUPPLIES: (List Below)
C35: Item Description | D35: Quantity | E35: Unit Price | F35: Total
B36: 1 | D36: 0 | E36: 0 | F36: =(D36*E36) -> 0
B37: 2 | D37: 0 | E37: 0 | F37: =(D37*E37) -> 0
B38: 3 | D38: 0 | E38: 0 | F38: =(D38*E38) -> 0
B39: SUBTOTAL | F39: =SUM(F36:F38) -> 0
B41: OTHER: (Anything not covered above)
C42: Item Description | D42: Quantity | E42: Unit Price | F42: Total
B43: 1 | D43: 0 | E43: 0 | F43: =(D43*E43) -> 0
B44: 2 | D44: 0 | E44: 0 | F44: =(D44*E44) -> 0
B45: 3 | D45: 0 | E45: 0 | F45: =(D45*E45) -> 0
B46: SUBTOTAL | F46: =SUM(F43:F45) -> 0
...

Sheet Option Year 3
B1: INDEPENDENT GOVERNMENT COST ESTIMATE
B2: OPTION YEAR 3: 06-01-2029 - 05-31-30
B3: Total | D3: =FY_Total -> 49584
B5: DIRECT LABOR (BURDENED RATES)
C6: Labor Category | D6: Hours | E6: Rate | F6: Amount
B7: 1 | C7: Senior Environmental and Social Specialist | D7: 2480 | F7: =(D7*E7) -> 0
B8: 2 | C8: Environmental and Social Specialist | D8: 256 | F8: =(D8*E8) -> 0
B9: 3 | C9: Subject Matter Expert (SME) | D9: 960 | F9: =(D9*E9) -> 0
B10: SUBTOTAL | F10: =SUM(F7:F9) -> 0
B12: EQUIPMENT PURCHASES
C13: Item Description | D13: Quantity | E13: Unit Price | F13: Total
B14: 1 | D14: 0 | E14: 0 | F14: =(D14*E14) -> 0
B15: 2 | D15: 0 | E15: 0 | F15: =(D15*E15) -> 0
B16: 3 | D16: 0 | E16: 0 | F16: =(D16*E16) -> 0
B17: SUBTOTAL | F17: =SUM(F14:F16) -> 0
B19: SOFTWARE PURCHASES
C20: Item Description | D20: Quantity | E20: Unit Price | F20: Total
B21: 1 | D21: 0 | E21: 0 | F21: =(D21*E21) -> 0
B22: 2 | D22: 0 | E22: 0 | F22: =(D22*E22) -> 0
B23: 3 | D23: 0 | E23: 0 | F23: =(D23*E23) -> 0
B24: SUBTOTAL | F24: =SUM(F21:F23) -> 0
B26: OTHER DIRECT COST
B27: REQUIRED TRAVEL: (Not-to-Exceed Amount; Worse Case)
C28: Travel (To/From) | D28: No. of Trips | E28: Price Per Trip | F28: Total
B29: 1 | C29: France/Burundi/Ecuador | D29: 8 | E29: 6198 | F29: =(D29*E29) -> 49584
B30: 2 | D30: 0 | E30: 0 | F30: =(D30*E30) -> 0
B31: 3 | D31: 0 | E31: 0 | F31: =(D31*E31) -> 0
B32: SUBTOTAL | F32: =SUM(F29:F31) -> 49584
B34: MATERIAL/SUPPLIES: (List Below)
C35: Item Description | D35: Quantity | E35: Unit Price | F35: Total
B36: 1 | D36: 0 | E36: 0 | F36: =(D36*E36) -> 0
B37: 2 | D37: 0 | E37: 0 | F37: =(D37*E37) -> 0
B38: 3 | D38: 0 | E38: 0 | F38: =(D38*E38) -> 0
B39: SUBTOTAL | F39: =SUM(F36:F38) -> 0
B41: OTHER: (Anything not covered above)
C42: Item Description | D42: Quantity | E42: Unit Price | F42: Total
B43: 1 | D43: 0 | E43: 0 | F43: =(D43*E43) -> 0
B44: 2 | D44: 0 | E44: 0 | F44: =(D44*E44) -> 0
B45: 3 | D45: 0 | E45: 0 | F45: =(D45*E45) -> 0
B46: SUBTOTAL | F46: =SUM(F43:F45) -> 0
...

Sheet Option Year 4
B1: INDEPENDENT GOVERNMENT COST ESTIMATE
B2: OPTION YEAR 4: 06-01-2030 - 05-31-31
B3: Total | D3: =FY_Total -> 49584
B5: DIRECT LABOR (BURDENED RATES)
C6: Labor Category | D6: Hours | E6: Rate | F6: Amount
B7: 1 | C7: Senior Environmental and Social Specialist | D7: 2480 | F7: =(D7*E7) -> 0
B8: 2 | C8: Environmental and Social Specialist | D8: 256 | F8: =(D8*E8) -> 0
B9: 3 | C9: Subject Matter Expert (SME) | D9: 960 | F9: =(D9*E9) -> 0
B10: SUBTOTAL | F10: =SUM(F7:F9) -> 0
B12: EQUIPMENT PURCHASES
C13: Item Description | D13: Quantity | E13: Unit Price | F13: Total
B14: 1 | D14: 0 | E14: 0 | F14: =(D14*E14) -> 0
B15: 2 | D15: 0 | E15: 0 | F15: =(D15*E15) -> 0
B16: 3 | D16: 0 | E16: 0 | F16: =(D16*E16) -> 0
B17: SUBTOTAL | F17: =SUM(F14:F16) -> 0
B19: SOFTWARE PURCHASES
C20: Item Description | D20: Quantity | E20: Unit Price | F20: Total
B21: 1 | D21: 0 | E21: 0 | F21: =(D21*E21) -> 0
B22: 2 | D22: 0 | E22: 0 | F22: =(D22*E22) -> 0
B23: 3 | D23: 0 | E23: 0 | F23: =(D23*E23) -> 0
B24: SUBTOTAL | F24: =SUM(F21:F23) -> 0
B26: OTHER DIRECT COST
B27: REQUIRED TRAVEL: (Not-to-Exceed Amount; Worse Case)
C28: Travel (To/From) | D28: No. of Trips | E28: Price Per Trip | F28: Total
B29: 1 | C29: France/Burundi/Ecuador | D29: 8 | E29: 6198 | F29: =(D29*E29) -> 49584
B30: 2 | D30: 0 | E30: 0 | F30: =(D30*E30) -> 0
B31: 3 | D31: 0 | E31: 0 | F31: =(D31*E31) -> 0
B32: SUBTOTAL | F32: =SUM(F29:F31) -> 49584
B34: MATERIAL/SUPPLIES: (List Below)
C35: Item Description | D35: Quantity | E35: Unit Price | F35: Total
B36: 1 | D36: 0 | E36: 0 | F36: =(D36*E36) -> 0
B37: 2 | D37: 0 | E37: 0 | F37: =(D37*E37) -> 0
B38: 3 | D38: 0 | E38: 0 | F38: =(D38*E38) -> 0
B39: SUBTOTAL | F39: =SUM(F36:F38) -> 0
B41: OTHER: (Anything not covered above)
C42: Item Description | D42: Quantity | E42: Unit Price | F42: Total
B43: 1 | D43: 0 | E43: 0 | F43: =(D43*E43) -> 0
B44: 2 | D44: 0 | E44: 0 | F44: =(D44*E44) -> 0
B45: 3 | D45: 0 | E45: 0 | F45: =(D45*E45) -> 0
B46: SUBTOTAL | F46: =SUM(F43:F45) -> 0
...
