Workbook

Sheet Summary
B1: CONTROLLED UNCLASSIFIED INFORMATION
B2: Source Selection Information – see FAR 2.101 and 3.104
B3: IGE
B4: DoDEA Pacific South HE125426QE044
B5: Okinawa Safety Aides and Attendants Services
B6: Summary of Base plus Option Periods
B8: Period of Performance | C8: Estimated FX Price (YEN)
B9: Base Year | C9: ='Pricing Input'!H10 -> 0
B10: Option Period Year 1 | C10: ='Pricing Input'!H18 -> 0
B11: Option Period Year 2 | C11: ='Pricing Input'!H26 -> 0
B12: Option Period Year 3 | C12: ='Pricing Input'!H34 -> 0
B13: Option Period Year 4 | C13: ='Pricing Input'!H42 -> 0
B14: Base + 4 Option Years Estimate | C14: =SUM(C9:C13) -> 0
B15: FAR 52.217-8 Option for up to 6mths | C15: ='Pricing Input'!H50 -> 0
B16: Total Estimated Price | C16: =SUM(C14:C15) -> 0

Sheet Pricing Input
B1: CONTROLLED UNCLASSIFIED INFORMATION | D1: CONTROLLED UNCLASSIFIED INFORMATION
B2: Source Selection Information – see FAR 2.101 and 3.104 | D2: Source Selection Information – see FAR 2.101 and 3.104
E3: Ordering Vehicle QTY
A4: PAC South Safety Attendant/Aide | E4: Base Year SY 2026-2027 | I4: FY26 Exchange Rate | J4: 150.4415
A5: CLIN | B5: PR Line Item | C5: Accounting Classification | D5: Description | E5: Unit of Issue | F5: Estimated Maximum Quantity | G5: Estimated Unit Price | H5: Estimated Max Total Cost | I5: Unit Cost in $ | J5: Total Cost in $
A6: Okinawa Safety Attendant/Aide Services - Base Year 8/1/2026 - 7/31/2027
A7: 0001 | D7: PAC South Safety Attendant | K7: Methodology for Estimated Maximum Quantities:
A8: 0001A | D8: Safety Attendants | E8: Runs | F8: 15120 | H8: =F8*G8 -> 0 | I8: =G8/$J$4 -> 0 | J8: =H8/$J$4 -> 0 | K8: Regular SY: 175 instructional days + 5 makeup days = 180 days, multiplied by 42 daily routes = total 7560 Safety Attendant Routes for the regular SY
A9: 0001B | D9: SPED Safety Aides | E9: Runs | F9: 4110 | H9: =F9*G9 -> 0 | I9: =G9/$J$4 -> 0 | J9: =H9/$J$4 -> 0 | K9: Regular SY plus ESY: 180 days x 11 daily SPED routes = 1980 regular SY Safety Aide Routes, plus ESY (15 days x 5 routes = 75 ESY routes) =1980+75 = 2055 total annual SPED/Safety Aide Routes
A10: Base Year | C10: Fort Campbell | D10: TOTAL: | H10: =SUM(H8:H9) -> 0 | J10: =H10/$J$4 -> 0
A12: PAC South Safety Attendant/Aide | E12: Option Year 1 SY 2027-2028
A13: CLIN | B13: PR Line Item | C13: Accounting Classification | D13: Description | E13: Unit of Issue | F13: Estimated Maximum Quantity | G13: Estimated Unit Price | H13: Estimated Max Total Cost | I13: Unit Cost in $ | J13: Total Cost in $
A14: PAC South SA/A - Option Year One 08/01/2027-07/31/2028 3% Industry Inflation | U14: =180*11+75 -> 2055
A15: 1001 | D15: PAC South Safety Attendant
A16: 1001A | B16: 0001 | C16: LOG_DAILYCOMMUTE_FY22^3300 AS REG STUD^210.51 Student | D16: Safety Attendants | E16: Runs | F16: 15120 | H16: =SUM(G16*F16) -> 0 | I16: =G16/$J$4 -> 0 | J16: =H16/$J$4 -> 0
A17: 1001B | D17: SPED Safety Aides | E17: Runs | F17: 4110 | H17: =SUM(G17*F17) -> 0 | I17: =G17/$J$4 -> 0 | J17: =H17/$J$4 -> 0
A18: Option Year 1 | C18: Fort Campbell | D18: TOTAL: | H18: =SUM(H16:H17) -> 0 | J18: =H18/$J$4 -> 0
A20: PAC South Safety Attendant/Aide | E20: Option Year 2 SY 2028-2029
A21: CLIN | B21: PR Line Item | C21: Accounting Classification | D21: Description | E21: Unit of Issue | F21: Estimated Maximum Quantity | G21: Estimated Unit Price | H21: Estimated Max Total Cost | I21: Unit Cost in $ | J21: Total Cost in $
A22: PAC South SA/A - Option Year Two 08/01/2028-07/31/2029 3% Industry Inflation
A23: 2001 | D23: PAC South Safety Attendant
A24: 2001A | B24: 0001 | C24: LOG_DAILYCOMMUTE_FY22^3300 AS REG STUD^210.51 Student | D24: Safety Attendants | E24: Runs | F24: 15120 | H24: =SUM(G24*F24) -> 0 | I24: =G24/$J$4 -> 0 | J24: =H24/$J$4 -> 0
A25: 2001B | D25: SPED Safety Aides | E25: Runs | F25: 4110 | H25: =SUM(G25*F25) -> 0 | I25: =G25/$J$4 -> 0 | J25: =H25/$J$4 -> 0
A26: Option Year 2 | C26: Fort Campbell | D26: TOTAL: | H26: =SUM(H24:H25) -> 0 | J26: =H26/$J$4 -> 0
A28: PAC South Safety Attendant/Aide | E28: Option Year 3 SY 2029-2030
A29: CLIN | B29: PR Line Item | C29: Accounting Classification | D29: Description | E29: Unit of Issue | F29: Estimated Maximum Quantity | G29: Estimated Unit Price | H29: Estimated Max Total Cost | I29: Unit Cost in $ | J29: Total Cost in $
A30: PAC South SA/A - Option Year Three 08/01/2029-07/31/2030 3% Industry Inflation
A31: 3001 | D31: PAC South Safety Attendant
A32: 3001A | B32: 0001 | C32: LOG_DAILYCOMMUTE_FY22^3300 AS REG STUD^210.51 Student | D32: Safety Attendants | E32: Runs | F32: 15120 | H32: =SUM(G32*F32) -> 0 | I32: =G32/$J$4 -> 0 | J32: =H32/$J$4 -> 0
A33: 3001B | D33: SPED Safety Aides | E33: Runs | F33: 4110 | H33: =SUM(G33*F33) -> 0 | I33: =G33/$J$4 -> 0 | J33: =H33/$J$4 -> 0
A34: Option Year 3 | C34: Fort Campbell | D34: TOTAL: | H34: =SUM(H32:H33) -> 0 | J34: =H34/$J$4 -> 0
A36: PAC South Safety Attendant/Aide | E36: Option Year 4 SY 2030-2031
A37: CLIN | B37: PR Line Item | C37: Accounting Classification | D37: Description | E37: Unit of Issue | F37: Estimated Maximum Quantity | G37: Estimated Unit Price | H37: Estimated Max Total Cost | I37: Unit Cost in $ | J37: Total Cost in $
A38: Yokota Bus Driver Services - Option Year Four 08/01/2030-07/31/2031 3% Industry Inflation
A39: 4001 | D39: PAC South Safety Attendant
A40: 4001A | B40: 0001 | C40: LOG_DAILYCOMMUTE_FY22^3300 AS REG STUD^210.51 Student | D40: Safety Attendants | E40: Runs | F40: 15120 | H40: =SUM(G40*F40) -> 0 | I40: =G40/$J$4 -> 0 | J40: =H40/$J$4 -> 0
A41: 4001B | D41: SPED Safety Aides | E41: Runs | F41: 4110 | H41: =SUM(G41*F41) -> 0 | I41: =G41/$J$4 -> 0 | J41: =H41/$J$4 -> 0
A42: Option Year 4 | C42: Fort Campbell | D42: TOTAL: | H42: =SUM(H40:H41) -> 0 | J42: =H42/$J$4 -> 0
A44: PAC South Safety Attendant/Aide | E44: FAR 52.217-8
A45: CLIN | B45: PR Line Item | C45: Accounting Classification | D45: Description | E45: Unit of Issue | F45: Estimated Maximum Quantity | G45: Estimated Unit Price | H45: Estimated Max Total Cost | I45: Unit Cost in $ | J45: Total Cost in $
...

Sheet Route Data 05 Nov 2025
B2: DoDDS-Pacific / DDESS-Guam
B3: Okinawa Student Transportation Office
B5: SCHOOL BUS ROUTE DATA
G7: SY25-26
A9: SINGLE / DOUBLE ROUTES
A12: AEIS/RSPS Amelia Earhart Intermediate School / Ralph F. Stearley Primary School | B12: 1 | D12: KDHS/KDMS Kadena High School / Kadena Middle School | E12: 69 | G12: Double Run | J12: Single Run | N12: Total Number of Buses | P12: 56 | Q12: 11 New | R12: 1 Tour | S12: 3 micro buses | T12: Total 71 buses
B13: 2 | E13: 70 | G13: 69 | H13: 42 | J13: 20
B14: 3 | E14: 71 | G14: 70 | H14: 3 | J14: 21 | N14: Total Buses AM Used | P14: 48
B15: 4 | E15: 72 | G15: 71 | H15: 6 | J15: 22 | K15: AM double | L15: PM single | N15: Total Buses PM Used | P15: 51
B16: 5 | E16: 73 | G16: 72 | H16: 44 | J16: 23
B17: 6 | E17: 74 | G17: 74 | H17: 40 | J17: 24 | N17: Total AM Single Routes | P17: 15
B18: 7 | E18: 75 | G18: 75 | H18: 2 | J18: 28 | K18: AM double | L18: PM single | N18: Total PM Single Routes | P18: 20
B19: 8 | E19: 76 | G19: 76 | H19: 45 | J19: 61
B20: 9 | E20: 77 | G20: 78 | H20: 8 | J20: 62 | N20: Total AM Double Routes | P20: 33
B21: 10 | E21: 78 | G21: 79 | H21: 11 | J21: 64 | N21: Total PM Double Routes | P21: 31
B22: 11 | E22: 79 | G22: 82 | H22: 25 | J22: 73
A23: BTES Bechtel Elementary School | B23: 20 | E23: 80 | G23: 83 | H23: 43 | J23: 77
B24: 21 | E24: 81 | G24: 90 | H24: 32 | J24: 80 | N24: Total AM Routes | P24: 82
B25: 22 | E25: 82 | G25: 91 | H25: 30 | J25: 81 | N25: Total PM Routes | P25: 82
B26: 23 | E26: 83 | G26: 92 | H26: 1 | J26: 84
B27: 24 | E27: 84 | G27: 93 | H27: 34 | J27: 95 | K27: AM single | L27: PM double | N27: Total Stops Used | P27: =R27+T27 -> 240 | Q27: ON BAESE | R27: 33 | S27: OFF BASE | T27: 207
B28: 25 | D28: LSMS Lester Middle School | E28: 90 | G28: 94 | H28: 35 | J28: 102
B29: 26 | E29: 91 | G29: 95 | H29: 51 (PM) | J29: 103 | K29: AM double | L29: PM single
B30: 27 | E30: 92 | G30: 96 | H30: 50 | J30: 116 | N30: Total AM Standby Buses | P30: 19
B31: 28 | E31: 93 | G31: 130 | H31: 60 | J31: 117 | K31: AM double | L31: PM single | N31: Total PM Standby Buses | P31: 20
A32: KLES E.C. Killin Elementary School | B32: 30 | E32: 94 | G32: 131 | H32: 63 | J32: 118
B33: 31 | E33: 95 | G33: 100 | H33: 27 | J33: 119 | K33: AM double | L33: PM single
B34: 32 | E34: 96 | G34: 101 | H34: 4
B35: 33 | E35: 130 | G35: 103 | H35: 28 (AM)
B36: 34 | E36: 131 | G36: 105 | H36: 9
B37: 35 | D37: RYMS Ryukyu Middle School | E37: 100 | G37: 110 | H37: 7
B38: 36 | E38: 101 | G38: 111 | H38: 10
A39: KDES Kadena Elementary School | B39: 40 | E39: 102 | G39: 112 | H39: 33
B40: 41 | E40: 103 | G40: 113 | H40: 41
B41: 42 | E41: 105 | G41: 114 | H41: 5
B42: 43 | D42: KBHS Kubasaki High School | E42: 110 | G42: 115 | H42: 31
B43: 44 | E43: 111 | G43: 117 | H43: 51 (AM)
B44: 45 | E44: 112 | G44: 119 | H44: 22 (AM)
A45: KSES Kinser Elementary School | B45: 50 | E45: 113 | G45: 140 | H45: 26
B46: 51 | E46: 114 | G46: 141 | H46: 36
...
